File: example/461_test/PLD50nmFe2O3_Al2O3/XRR_Lab/2TW_XRR_RIDGE_p1x2mm.ras
*RAS_DATA_START
*RAS_HEADER_START
*DISP_LINE_COLOR "4286611584"
*FILE_COMMENT ""
*FILE_MD5 ""
*FILE_MEMO ""
*FILE_OPERATOR "Administrator"
*FILE_PACKAGE_NAME ""
*FILE_PART_ID ""
*FILE_SAMPLE ""
*FILE_SYSTEM_NAME "SmartLab"
*FILE_TYPE "RAS_RAW"
*FILE_USERGROUP "Administrators"
*FILE_VERSION "1"
*HW_ATTACHMENT_ID "ATT0022"
*HW_ATTACHMENT_NAME "RxRy"
*HW_ATTACHMENT_NAME_INTERNAL "RxRy"
*HW_COUNTER_ID-0 "CUT0021"
*HW_COUNTER_ID-1 "CMC0020"
*HW_COUNTER_MONOCHRO_ID "CMC0020"
*HW_COUNTER_MONOCHRO_NAME "None"
*HW_COUNTER_MONOCHRO_NAME_INTERNAL "None"
*HW_COUNTER_NAME_INTERNAL "SC70"
*HW_COUNTER_NAME-0 "SC70"
*HW_COUNTER_NAME-1 "None"
*HW_COUNTER_SELECT_NAME "SC70"
*HW_EXTERNAL_CONTROLLER_NAME "None"
*HW_EXTERNAL_CONTROLLER_NAME_INTERNAL "None"
*HW_GONIOMETER_ID "GON0022"
*HW_GONIOMETER_NAME "StandardInplaneEnc"
*HW_GONIOMETER_NAME_INTERNAL "StandardInplaneEnc"
*HW_GONIOMETER_RADIUS-0 "90.0"
*HW_GONIOMETER_RADIUS-1 "114.0"
*HW_GONIOMETER_RADIUS-2 "190.0"
*HW_GONIOMETER_RADIUS-3 "300.0"
*HW_GONIOMETER_RADIUS-4 "187.0"
*HW_GONIOMETER_RADIUS-5 "300.0"
*HW_GONIOMETER_RADIUS-6 "113.0000"
*HW_GONIOMETER_RADIUS-7 "331.0"
*HW_I_CBO_ID "CBO0021"
*HW_I_CBO_NAME "CBO"
*HW_I_CBO_NAME_INTERNAL "CBO"
*HW_I_MONOCHRO_ID "ISO0021"
*HW_I_MONOCHRO_NAME "IPS_adaptor"
*HW_I_MONOCHRO_NAME_INTERNAL "IPS_adaptor"
*HW_I_OPT_ID-0 "CBO0021"
*HW_I_OPT_ID-1 "ISL0021"
*HW_I_PRIMARY_NAME_INTERNAL "Standard"
*HW_I_SLIT_ID "ISL0021"
*HW_I_SLIT_NAME "Auto"
*HW_I_SLIT_NAME_INTERNAL "Auto"
*HW_R_ATTENUATER_AUTOMODE "1"
*HW_R_ATTENUATER_ID "ATN0021"
*HW_R_ATTENUATER_NAME "Auto"
*HW_R_ATTENUATOR_NAME_INTERNAL "Auto"
*HW_R_OPT_ID-0 "RSS0021"
*HW_R_OPT_ID-1 "RCR0022"
*HW_R_OPT_ID-2 "RSO0021"
*HW_R_OPT_ID-3 "RRS0021"
*HW_R_OPT_ID-4 "ATN0021"
*HW_R_ROD_ID "RCR0022"
*HW_R_ROD_NAME "ROD_adaptor"
*HW_R_ROD_NAME_INTERNAL "ROD_adaptor"
*HW_R_RPS_ID "RSO0021"
*HW_R_RPS_NAME "RPS_adaptor"
*HW_R_RPS_NAME_INTERNAL "RPS_adaptor"
*HW_R_RS_ID "RRS0021"
*HW_R_RS_NAME "Auto"
*HW_R_RS_NAME_INTERNAL "Auto"
*HW_R_SS_ID "RSS0021"
*HW_R_SS_NAME "Auto"
*HW_R_SS_NAME_INTERNAL "Auto"
*HW_ROBOT_NAME "No_unit"
*HW_ROBOT_NAME_INTERNAL "No_unit"
*HW_SAMPLE_CAMERA_NAME "None"
*HW_SAMPLE_CAMERA_NAME_INTERNAL "None"
*HW_SAMPLE_HOLDER_ID "SMP0021"
*HW_SAMPLE_HOLDER_NAME "Z_ChiPhi"
*HW_SAMPLE_HOLDER_NAME_INTERNAL "Z_ChiPhi"
*HW_SAMPLE_NAME "CenterSlit"
*HW_SAMPLE_NAME_INTERNAL "CenterSlit"
*HW_SAMPLE_PLATE_NAME "HeightReference"
*HW_SAMPLE_PLATE_NAME_INTERNAL "HeightReference"
*HW_SAMPLE_SPACER_NAME "None"
*HW_SAMPLE_SPACER_NAME_INTERNAL "None"
*HW_USERINFO_CATALOG_NO ""
*HW_USERINFO_INSTRUMENT_ID ""
*HW_USERINFO_INSTRUMENT_NAME ""
*HW_USERINFO_INSTRUMENT_NO ""
*HW_USERINFO_MODEL ""
*HW_USERINFO_ORDER_NO ""
*HW_USERINFO_SERIAL_NO ""
*HW_USERINFO_VERIFY_INSTRUMENT_ID "00-07-fe-01-03-ce"
*HW_VER_RCD_COUNTER_UNIT "1.0.1"
*HW_VER_RCD_CPU "3.3.7"
*HW_VER_RCD_FPGA "1.2.2"
*HW_VER_RCD_GONIO_UNIT "6.2.0"
*HW_VER_RCD_INCIDENT_UNIT "6.2.0"
*HW_VER_RCD_RECEIVING_UNIT "6.2.0"
*HW_VER_RCD_TYPE "RINC"
*HW_VER_XGC_CPU "3.3.7"
*HW_VER_XGC_CW "1.2.0"
*HW_VER_XGC_HV "1.2.0"
*HW_VER_XGC_RS1 "1.3.4"
*HW_VER_XGC_RS2 "N/A"
*HW_VER_XGC_RT "1.2.0"
*HW_VER_XGC_TYPE "RINC"
*HW_XG_CURRENT_UNIT "mA"
*HW_XG_FOCUS "0.4mm x 8mm"
*HW_XG_FOCUS_TYPE "Fine"
*HW_XG_TARGET_ATOMIC_NUMBER "29"
*HW_XG_TARGET_NAME "Cu"
*HW_XG_TYPE "ROTA"
*HW_XG_VOLTAGE_UNIT "kV"
*HW_XG_WAVE_LENGTH_ALPHA1 "1.540593"
*HW_XG_WAVE_LENGTH_ALPHA2 "1.544414"
*HW_XG_WAVE_LENGTH_BETA "1.392246"
*HW_XG_WAVE_LENGTH_UNIT "Angstrom"
*MEAS_COND_AXIS_NAME_INTERNAL-0 "ThetaS"
*MEAS_COND_AXIS_NAME_INTERNAL-1 "ThetaD"
*MEAS_COND_AXIS_NAME_INTERNAL-10 "PrimaryGeometry"
*MEAS_COND_AXIS_NAME_INTERNAL-100 "ReceivingOptics"
*MEAS_COND_AXIS_NAME_INTERNAL-101 "CounterMonochromatorKind"
*MEAS_COND_AXIS_NAME_INTERNAL-11 "PrimaryMirrorType"
*MEAS_COND_AXIS_NAME_INTERNAL-12 "CBOType"
*MEAS_COND_AXIS_NAME_INTERNAL-13 "CBO-M"
*MEAS_COND_AXIS_NAME_INTERNAL-14 "CBO"
*MEAS_COND_AXIS_NAME_INTERNAL-15 "IncidentSollerSlit"
*MEAS_COND_AXIS_NAME_INTERNAL-16 "IncidentSlitBox"
*MEAS_COND_AXIS_NAME_INTERNAL-17 "IncidentSlitBox-_Axis"
*MEAS_COND_AXIS_NAME_INTERNAL-18 "SlitDS"
*MEAS_COND_AXIS_NAME_INTERNAL-19 "Zs"
*MEAS_COND_AXIS_NAME_INTERNAL-2 "TwoTheta"
*MEAS_COND_AXIS_NAME_INTERNAL-20 "IncidentAxdSlit"
*MEAS_COND_AXIS_NAME_INTERNAL-21 "LLS"
*MEAS_COND_AXIS_NAME_INTERNAL-22 "DHLSlit"
*MEAS_COND_AXIS_NAME_INTERNAL-23 "Chi"
*MEAS_COND_AXIS_NAME_INTERNAL-24 "Phi"
*MEAS_COND_AXIS_NAME_INTERNAL-25 "Z"
*MEAS_COND_AXIS_NAME_INTERNAL-26 "Alpha"
*MEAS_COND_AXIS_NAME_INTERNAL-27 "Beta"
*MEAS_COND_AXIS_NAME_INTERNAL-28 "TwoThetaChiPhi"
*MEAS_COND_AXIS_NAME_INTERNAL-29 "AlphaI"
*MEAS_COND_AXIS_NAME_INTERNAL-3 "Omega"
*MEAS_COND_AXIS_NAME_INTERNAL-30 "BetaI"
*MEAS_COND_AXIS_NAME_INTERNAL-31 "TwoThetaB"
*MEAS_COND_AXIS_NAME_INTERNAL-32 "Rx"
*MEAS_COND_AXIS_NAME_INTERNAL-33 "Ry"
*MEAS_COND_AXIS_NAME_INTERNAL-34 "ReceivingSlitBox1"
*MEAS_COND_AXIS_NAME_INTERNAL-35 "ReceivingSlitBox1-_Axis"
*MEAS_COND_AXIS_NAME_INTERNAL-36 "SlitSS"
*MEAS_COND_AXIS_NAME_INTERNAL-37 "Filter"
*MEAS_COND_AXIS_NAME_INTERNAL-38 "PSA"
*MEAS_COND_AXIS_NAME_INTERNAL-39 "ReceivingSollerSlit"
*MEAS_COND_AXIS_NAME_INTERNAL-4 "TwoThetaTheta"
*MEAS_COND_AXIS_NAME_INTERNAL-40 "ReceivingSlitBox2"
*MEAS_COND_AXIS_NAME_INTERNAL-41 "ReceivingSlitBox2-_Axis"
*MEAS_COND_AXIS_NAME_INTERNAL-42 "SlitRS"
*MEAS_COND_AXIS_NAME_INTERNAL-43 "ReceivingSlitBox2-Zd"
*MEAS_COND_AXIS_NAME_INTERNAL-44 "Filter2"
*MEAS_COND_AXIS_NAME_INTERNAL-45 "Attenuator"
*MEAS_COND_AXIS_NAME_INTERNAL-46 "HV"
*MEAS_COND_AXIS_NAME_INTERNAL-47 "PHA"
*MEAS_COND_AXIS_NAME_INTERNAL-48 "DedicatedHolder"
*MEAS_COND_AXIS_NAME_INTERNAL-49 "Target_TargetTime"
*MEAS_COND_AXIS_NAME_INTERNAL-5 "TwoThetaOmega"
*MEAS_COND_AXIS_NAME_INTERNAL-50 "Target_XrayOnTime"
*MEAS_COND_AXIS_NAME_INTERNAL-51 "Target_TMPTime"
*MEAS_COND_AXIS_NAME_INTERNAL-52 "Target_RPTime"
*MEAS_COND_AXIS_NAME_INTERNAL-53 "Target_FilamentTime"
*MEAS_COND_AXIS_NAME_INTERNAL-54 "Target_IG"
*MEAS_COND_AXIS_NAME_INTERNAL-55 "Target_GP"
*MEAS_COND_AXIS_NAME_INTERNAL-56 "Target_FC"
*MEAS_COND_AXIS_NAME_INTERNAL-57 "HVPS_Bias"
*MEAS_COND_AXIS_NAME_INTERNAL-58 "HVPS_HVPSTime"
*MEAS_COND_AXIS_NAME_INTERNAL-59 "HVPS_Type1Time"
*MEAS_COND_AXIS_NAME_INTERNAL-6 "OmegaTwoTheta"
*MEAS_COND_AXIS_NAME_INTERNAL-60 "HVPS_Type2Time"
*MEAS_COND_AXIS_NAME_INTERNAL-61 "HVPS_Type3Time"
*MEAS_COND_AXIS_NAME_INTERNAL-62 "CW_IERTime"
*MEAS_COND_AXIS_NAME_INTERNAL-63 "CW_ECTime"
*MEAS_COND_AXIS_NAME_INTERNAL-64 "CW_Flow1"
*MEAS_COND_AXIS_NAME_INTERNAL-65 "CW_Temperature1"
*MEAS_COND_AXIS_NAME_INTERNAL-66 "CW_Pressure1"
*MEAS_COND_AXIS_NAME_INTERNAL-67 "CW_PressureIn"
*MEAS_COND_AXIS_NAME_INTERNAL-68 "CW_PressureOut"
*MEAS_COND_AXIS_NAME_INTERNAL-69 "CW_Flow2"
*MEAS_COND_AXIS_NAME_INTERNAL-7 "TwoThetaChi"
*MEAS_COND_AXIS_NAME_INTERNAL-70 "CW_Temperature2"
*MEAS_COND_AXIS_NAME_INTERNAL-71 "CW_Pressure2"
*MEAS_COND_AXIS_NAME_INTERNAL-72 "RE_EnclosureTemp"
*MEAS_COND_AXIS_NAME_INTERNAL-73 "RE_EnclosureHummidity"
*MEAS_COND_AXIS_NAME_INTERNAL-74 "RE_CabinetTemp"
*MEAS_COND_AXIS_NAME_INTERNAL-75 "RE_RPTemp"
*MEAS_COND_AXIS_NAME_INTERNAL-76 "RE_ShutterAXrayOnTime"
*MEAS_COND_AXIS_NAME_INTERNAL-77 "RE_ShutterATimes"
*MEAS_COND_AXIS_NAME_INTERNAL-78 "RE_ShutterAOpenCloseTime"
*MEAS_COND_AXIS_NAME_INTERNAL-79 "RE_ShutterACloseOpenTime"
*MEAS_COND_AXIS_NAME_INTERNAL-8 "GonioDirectBeamStop"
*MEAS_COND_AXIS_NAME_INTERNAL-80 "RE_ShutterBXrayOnTime"
*MEAS_COND_AXIS_NAME_INTERNAL-81 "RE_ShutterBTimes"
*MEAS_COND_AXIS_NAME_INTERNAL-82 "RE_ShutterBOpenCloseTime"
*MEAS_COND_AXIS_NAME_INTERNAL-83 "RE_ShutterBCloseOpenTime"
*MEAS_COND_AXIS_NAME_INTERNAL-84 "RE_XrayWarningRamp"
*MEAS_COND_AXIS_NAME_INTERNAL-85 "RE_ShutterAInstallation"
*MEAS_COND_AXIS_NAME_INTERNAL-86 "RE_ShutterARamp"
*MEAS_COND_AXIS_NAME_INTERNAL-87 "RE_ShutterBInstallation"
*MEAS_COND_AXIS_NAME_INTERNAL-88 "RE_ShutterBRamp"
*MEAS_COND_AXIS_NAME_INTERNAL-89 "RE_ExtShutterCLS"
*MEAS_COND_AXIS_NAME_INTERNAL-9 "Ts"
*MEAS_COND_AXIS_NAME_INTERNAL-90 "RE_ExtXrayOFF"
*MEAS_COND_AXIS_NAME_INTERNAL-91 "RE_ExtSafetyCircuit"
*MEAS_COND_AXIS_NAME_INTERNAL-92 "Version_CPU"
*MEAS_COND_AXIS_NAME_INTERNAL-93 "Version_RS1"
*MEAS_COND_AXIS_NAME_INTERNAL-94 "Version_RS2"
*MEAS_COND_AXIS_NAME_INTERNAL-95 "Version_HV"
*MEAS_COND_AXIS_NAME_INTERNAL-96 "Version_CW"
*MEAS_COND_AXIS_NAME_INTERNAL-97 "Version_RT"
*MEAS_COND_AXIS_NAME_INTERNAL-98 "IncidentPrimary"
*MEAS_COND_AXIS_NAME_INTERNAL-99 "IncidentMonochromator"
*MEAS_COND_AXIS_NAME-0 "ThetaS"
*MEAS_COND_AXIS_NAME-1 "ThetaD"
*MEAS_COND_AXIS_NAME-10 "PrimaryGeometry"
*MEAS_COND_AXIS_NAME-100 "ReceivingOptics"
*MEAS_COND_AXIS_NAME-101 "CounterMonochromatorKind"
*MEAS_COND_AXIS_NAME-11 "PrimaryMirrorType"
*MEAS_COND_AXIS_NAME-12 "CBOType"
*MEAS_COND_AXIS_NAME-13 "CBO-M"
*MEAS_COND_AXIS_NAME-14 "CBO"
*MEAS_COND_AXIS_NAME-15 "IncidentSollerSlit"
*MEAS_COND_AXIS_NAME-16 "IncidentSlitBox"
*MEAS_COND_AXIS_NAME-17 "IncidentSlitBox-_Axis"
*MEAS_COND_AXIS_NAME-18 "SlitDS"
*MEAS_COND_AXIS_NAME-19 "Zs"
*MEAS_COND_AXIS_NAME-2 "TwoTheta"
*MEAS_COND_AXIS_NAME-20 "IncidentAxdSlit"
*MEAS_COND_AXIS_NAME-21 "LLS"
*MEAS_COND_AXIS_NAME-22 "DHLSlit"
*MEAS_COND_AXIS_NAME-23 "Chi"
*MEAS_COND_AXIS_NAME-24 "Phi"
*MEAS_COND_AXIS_NAME-25 "Z"
*MEAS_COND_AXIS_NAME-26 "Alpha"
*MEAS_COND_AXIS_NAME-27 "Beta"
*MEAS_COND_AXIS_NAME-28 "TwoThetaChiPhi"
*MEAS_COND_AXIS_NAME-29 "AlphaI"
*MEAS_COND_AXIS_NAME-3 "Omega"
*MEAS_COND_AXIS_NAME-30 "BetaI"
*MEAS_COND_AXIS_NAME-31 "TwoThetaB"
*MEAS_COND_AXIS_NAME-32 "Rx"
*MEAS_COND_AXIS_NAME-33 "Ry"
*MEAS_COND_AXIS_NAME-34 "ReceivingSlitBox1"
*MEAS_COND_AXIS_NAME-35 "ReceivingSlitBox1-_Axis"
*MEAS_COND_AXIS_NAME-36 "SlitSS"
*MEAS_COND_AXIS_NAME-37 "Filter"
*MEAS_COND_AXIS_NAME-38 "PSA"
*MEAS_COND_AXIS_NAME-39 "ReceivingSollerSlit"
*MEAS_COND_AXIS_NAME-4 "TwoThetaTheta"
*MEAS_COND_AXIS_NAME-40 "ReceivingSlitBox2"
*MEAS_COND_AXIS_NAME-41 "ReceivingSlitBox2-_Axis"
*MEAS_COND_AXIS_NAME-42 "SlitRS"
*MEAS_COND_AXIS_NAME-43 "ReceivingSlitBox2-Zd"
*MEAS_COND_AXIS_NAME-44 "Filter2"
*MEAS_COND_AXIS_NAME-45 "Attenuator"
*MEAS_COND_AXIS_NAME-46 "HV"
*MEAS_COND_AXIS_NAME-47 "PHA"
*MEAS_COND_AXIS_NAME-48 "DedicatedHolder"
*MEAS_COND_AXIS_NAME-49 "Target_TargetTime"
*MEAS_COND_AXIS_NAME-5 "TwoThetaOmega"
*MEAS_COND_AXIS_NAME-50 "Target_XrayOnTime"
*MEAS_COND_AXIS_NAME-51 "Target_TMPTime"
*MEAS_COND_AXIS_NAME-52 "Target_RPTime"
*MEAS_COND_AXIS_NAME-53 "Target_FilamentTime"
*MEAS_COND_AXIS_NAME-54 "Target_IG"
*MEAS_COND_AXIS_NAME-55 "Target_GP"
*MEAS_COND_AXIS_NAME-56 "Target_FC"
*MEAS_COND_AXIS_NAME-57 "HVPS_Bias"
*MEAS_COND_AXIS_NAME-58 "HVPS_HVPSTime"
*MEAS_COND_AXIS_NAME-59 "HVPS_Type1Time"
*MEAS_COND_AXIS_NAME-6 "OmegaTwoTheta"
*MEAS_COND_AXIS_NAME-60 "HVPS_Type2Time"
*MEAS_COND_AXIS_NAME-61 "HVPS_Type3Time"
*MEAS_COND_AXIS_NAME-62 "CW_IERTime"
*MEAS_COND_AXIS_NAME-63 "CW_ECTime"
*MEAS_COND_AXIS_NAME-64 "CW_Flow1"
*MEAS_COND_AXIS_NAME-65 "CW_Temperature1"
*MEAS_COND_AXIS_NAME-66 "CW_Pressure1"
*MEAS_COND_AXIS_NAME-67 "CW_PressureIn"
*MEAS_COND_AXIS_NAME-68 "CW_PressureOut"
*MEAS_COND_AXIS_NAME-69 "CW_Flow2"
*MEAS_COND_AXIS_NAME-7 "TwoThetaChi"
*MEAS_COND_AXIS_NAME-70 "CW_Temperature2"
*MEAS_COND_AXIS_NAME-71 "CW_Pressure2"
*MEAS_COND_AXIS_NAME-72 "RE_EnclosureTemp"
*MEAS_COND_AXIS_NAME-73 "RE_EnclosureHummidity"
*MEAS_COND_AXIS_NAME-74 "RE_CabinetTemp"
*MEAS_COND_AXIS_NAME-75 "RE_RPTemp"
*MEAS_COND_AXIS_NAME-76 "RE_ShutterAXrayOnTime"
*MEAS_COND_AXIS_NAME-77 "RE_ShutterATimes"
*MEAS_COND_AXIS_NAME-78 "RE_ShutterAOpenCloseTime"
*MEAS_COND_AXIS_NAME-79 "RE_ShutterACloseOpenTime"
*MEAS_COND_AXIS_NAME-8 "GonioDirectBeamStop"
*MEAS_COND_AXIS_NAME-80 "RE_ShutterBXrayOnTime"
*MEAS_COND_AXIS_NAME-81 "RE_ShutterBTimes"
*MEAS_COND_AXIS_NAME-82 "RE_ShutterBOpenCloseTime"
*MEAS_COND_AXIS_NAME-83 "RE_ShutterBCloseOpenTime"
*MEAS_COND_AXIS_NAME-84 "RE_XrayWarningRamp"
*MEAS_COND_AXIS_NAME-85 "RE_ShutterAInstallation"
*MEAS_COND_AXIS_NAME-86 "RE_ShutterARamp"
*MEAS_COND_AXIS_NAME-87 "RE_ShutterBInstallation"
*MEAS_COND_AXIS_NAME-88 "RE_ShutterBRamp"
*MEAS_COND_AXIS_NAME-89 "RE_ExtShutterCLS"
*MEAS_COND_AXIS_NAME-9 "Ts"
*MEAS_COND_AXIS_NAME-90 "RE_ExtXrayOFF"
*MEAS_COND_AXIS_NAME-91 "RE_ExtSafetyCircuit"
*MEAS_COND_AXIS_NAME-92 "Version_CPU"
*MEAS_COND_AXIS_NAME-93 "Version_RS1"
*MEAS_COND_AXIS_NAME-94 "Version_RS2"
*MEAS_COND_AXIS_NAME-95 "Version_HV"
*MEAS_COND_AXIS_NAME-96 "Version_CW"
*MEAS_COND_AXIS_NAME-97 "Version_RT"
*MEAS_COND_AXIS_NAME-98 "IncidentPrimary"
*MEAS_COND_AXIS_NAME-99 "IncidentMonochromator"
*MEAS_COND_AXIS_OFFSET-0 "1.118"
*MEAS_COND_AXIS_OFFSET-1 "0.1321"
*MEAS_COND_AXIS_OFFSET-10 "0"
*MEAS_COND_AXIS_OFFSET-100 "0"
*MEAS_COND_AXIS_OFFSET-101 "0"
*MEAS_COND_AXIS_OFFSET-11 "0"
*MEAS_COND_AXIS_OFFSET-12 "0"
*MEAS_COND_AXIS_OFFSET-13 "0"
*MEAS_COND_AXIS_OFFSET-14 "0"
*MEAS_COND_AXIS_OFFSET-15 "0"
*MEAS_COND_AXIS_OFFSET-16 "0"
*MEAS_COND_AXIS_OFFSET-17 "0"
*MEAS_COND_AXIS_OFFSET-18 "0"
*MEAS_COND_AXIS_OFFSET-19 "0"
*MEAS_COND_AXIS_OFFSET-2 "1.2501"
*MEAS_COND_AXIS_OFFSET-20 "0"
*MEAS_COND_AXIS_OFFSET-21 "0"
*MEAS_COND_AXIS_OFFSET-22 "0"
*MEAS_COND_AXIS_OFFSET-23 "0"
*MEAS_COND_AXIS_OFFSET-24 "0"
*MEAS_COND_AXIS_OFFSET-25 "0"
*MEAS_COND_AXIS_OFFSET-26 "0"
*MEAS_COND_AXIS_OFFSET-27 "0"
*MEAS_COND_AXIS_OFFSET-28 "0"
*MEAS_COND_AXIS_OFFSET-29 "0"
*MEAS_COND_AXIS_OFFSET-3 "1.118"
*MEAS_COND_AXIS_OFFSET-30 "0"
*MEAS_COND_AXIS_OFFSET-31 "0"
*MEAS_COND_AXIS_OFFSET-32 "0"
*MEAS_COND_AXIS_OFFSET-33 "0"
*MEAS_COND_AXIS_OFFSET-34 "0"
*MEAS_COND_AXIS_OFFSET-35 "0"
*MEAS_COND_AXIS_OFFSET-36 "0"
*MEAS_COND_AXIS_OFFSET-37 "0"
*MEAS_COND_AXIS_OFFSET-38 "0"
*MEAS_COND_AXIS_OFFSET-39 "0"
*MEAS_COND_AXIS_OFFSET-4 "0"
*MEAS_COND_AXIS_OFFSET-40 "0"
*MEAS_COND_AXIS_OFFSET-41 "0"
*MEAS_COND_AXIS_OFFSET-42 "0"
*MEAS_COND_AXIS_OFFSET-43 "0"
*MEAS_COND_AXIS_OFFSET-44 "0"
*MEAS_COND_AXIS_OFFSET-45 "0"
*MEAS_COND_AXIS_OFFSET-46 "0"
*MEAS_COND_AXIS_OFFSET-47 "0"
*MEAS_COND_AXIS_OFFSET-48 "0"
*MEAS_COND_AXIS_OFFSET-49 "0"
*MEAS_COND_AXIS_OFFSET-5 "0"
*MEAS_COND_AXIS_OFFSET-50 "0"
*MEAS_COND_AXIS_OFFSET-51 "0"
*MEAS_COND_AXIS_OFFSET-52 "0"
*MEAS_COND_AXIS_OFFSET-53 "0"
*MEAS_COND_AXIS_OFFSET-54 "0"
*MEAS_COND_AXIS_OFFSET-55 "0"
*MEAS_COND_AXIS_OFFSET-56 "0"
*MEAS_COND_AXIS_OFFSET-57 "0"
*MEAS_COND_AXIS_OFFSET-58 "0"
*MEAS_COND_AXIS_OFFSET-59 "0"
*MEAS_COND_AXIS_OFFSET-6 "0"
*MEAS_COND_AXIS_OFFSET-60 "0"
*MEAS_COND_AXIS_OFFSET-61 "0"
*MEAS_COND_AXIS_OFFSET-62 "0"
*MEAS_COND_AXIS_OFFSET-63 "0"
*MEAS_COND_AXIS_OFFSET-64 "0"
*MEAS_COND_AXIS_OFFSET-65 "0"
*MEAS_COND_AXIS_OFFSET-66 "0"
*MEAS_COND_AXIS_OFFSET-67 "0"
*MEAS_COND_AXIS_OFFSET-68 "0"
*MEAS_COND_AXIS_OFFSET-69 "0"
*MEAS_COND_AXIS_OFFSET-7 "0"
*MEAS_COND_AXIS_OFFSET-70 "0"
*MEAS_COND_AXIS_OFFSET-71 "0"
*MEAS_COND_AXIS_OFFSET-72 "0"
*MEAS_COND_AXIS_OFFSET-73 "0"
*MEAS_COND_AXIS_OFFSET-74 "0"
*MEAS_COND_AXIS_OFFSET-75 "0"
*MEAS_COND_AXIS_OFFSET-76 "0"
*MEAS_COND_AXIS_OFFSET-77 "0"
*MEAS_COND_AXIS_OFFSET-78 "0"
*MEAS_COND_AXIS_OFFSET-79 "0"
*MEAS_COND_AXIS_OFFSET-8 "0"
*MEAS_COND_AXIS_OFFSET-80 "0"
*MEAS_COND_AXIS_OFFSET-81 "0"
*MEAS_COND_AXIS_OFFSET-82 "0"
*MEAS_COND_AXIS_OFFSET-83 "0"
*MEAS_COND_AXIS_OFFSET-84 "0"
*MEAS_COND_AXIS_OFFSET-85 "0"
*MEAS_COND_AXIS_OFFSET-86 "0"
*MEAS_COND_AXIS_OFFSET-87 "0"
*MEAS_COND_AXIS_OFFSET-88 "0"
*MEAS_COND_AXIS_OFFSET-89 "0"
*MEAS_COND_AXIS_OFFSET-9 "0"
*MEAS_COND_AXIS_OFFSET-90 "0"
*MEAS_COND_AXIS_OFFSET-91 "0"
*MEAS_COND_AXIS_OFFSET-92 "0"
*MEAS_COND_AXIS_OFFSET-93 "0"
*MEAS_COND_AXIS_OFFSET-94 "0"
*MEAS_COND_AXIS_OFFSET-95 "0"
*MEAS_COND_AXIS_OFFSET-96 "0"
*MEAS_COND_AXIS_OFFSET-97 "0"
*MEAS_COND_AXIS_OFFSET-98 "0"
*MEAS_COND_AXIS_OFFSET-99 "0"
*MEAS_COND_AXIS_POSITION-0 "0.2000"
*MEAS_COND_AXIS_POSITION-1 "0.2000"
*MEAS_COND_AXIS_POSITION-10 "Right"
*MEAS_COND_AXIS_POSITION-100 "PSA_open"
*MEAS_COND_AXIS_POSITION-101 "None"
*MEAS_COND_AXIS_POSITION-11 "None"
*MEAS_COND_AXIS_POSITION-12 "Type1"
*MEAS_COND_AXIS_POSITION-13 "0"
*MEAS_COND_AXIS_POSITION-14 "PB"
*MEAS_COND_AXIS_POSITION-15 "Soller_slit_5.0deg"
*MEAS_COND_AXIS_POSITION-16 "0.100mm"
*MEAS_COND_AXIS_POSITION-17 "0.100000"
*MEAS_COND_AXIS_POSITION-18 "0.100mm"
*MEAS_COND_AXIS_POSITION-19 "-2.0290625"
*MEAS_COND_AXIS_POSITION-2 "0.4000"
*MEAS_COND_AXIS_POSITION-20 "5mm"
*MEAS_COND_AXIS_POSITION-21 "5mm"
*MEAS_COND_AXIS_POSITION-22 "5mm"
*MEAS_COND_AXIS_POSITION-23 "0.000"
*MEAS_COND_AXIS_POSITION-24 "0.000"
*MEAS_COND_AXIS_POSITION-25 "-1.0734"
*MEAS_COND_AXIS_POSITION-26 "90.000"
*MEAS_COND_AXIS_POSITION-27 "0.000"
*MEAS_COND_AXIS_POSITION-28 "0.000"
*MEAS_COND_AXIS_POSITION-29 "90.00"
*MEAS_COND_AXIS_POSITION-3 "0.2000"
*MEAS_COND_AXIS_POSITION-30 "0.000"
*MEAS_COND_AXIS_POSITION-31 "0.4000"
*MEAS_COND_AXIS_POSITION-32 "0.00000"
*MEAS_COND_AXIS_POSITION-33 "0.22780"
*MEAS_COND_AXIS_POSITION-34 "0.200mm"
*MEAS_COND_AXIS_POSITION-35 "0.200000"
*MEAS_COND_AXIS_POSITION-36 "0.200mm"
*MEAS_COND_AXIS_POSITION-37 "None"
*MEAS_COND_AXIS_POSITION-38 "PSA_open"
*MEAS_COND_AXIS_POSITION-39 "Soller_slit_5.0deg"
*MEAS_COND_AXIS_POSITION-4 "0.4000"
*MEAS_COND_AXIS_POSITION-40 "0.200mm"
*MEAS_COND_AXIS_POSITION-41 "0.200000"
*MEAS_COND_AXIS_POSITION-42 "0.200mm"
*MEAS_COND_AXIS_POSITION-43 "-0.5256250"
*MEAS_COND_AXIS_POSITION-44 "None"
*MEAS_COND_AXIS_POSITION-45 "Open"
*MEAS_COND_AXIS_POSITION-46 "647.0"
*MEAS_COND_AXIS_POSITION-47 "572.50"
*MEAS_COND_AXIS_POSITION-48 "None"
*MEAS_COND_AXIS_POSITION-49 ""
*MEAS_COND_AXIS_POSITION-5 "0.4000"
*MEAS_COND_AXIS_POSITION-50 ""
*MEAS_COND_AXIS_POSITION-51 ""
*MEAS_COND_AXIS_POSITION-52 ""
*MEAS_COND_AXIS_POSITION-53 ""
*MEAS_COND_AXIS_POSITION-54 ""
*MEAS_COND_AXIS_POSITION-55 ""
*MEAS_COND_AXIS_POSITION-56 ""
*MEAS_COND_AXIS_POSITION-57 ""
*MEAS_COND_AXIS_POSITION-58 ""
*MEAS_COND_AXIS_POSITION-59 ""
*MEAS_COND_AXIS_POSITION-6 "0.2000"
*MEAS_COND_AXIS_POSITION-60 ""
*MEAS_COND_AXIS_POSITION-61 ""
*MEAS_COND_AXIS_POSITION-62 ""
*MEAS_COND_AXIS_POSITION-63 ""
*MEAS_COND_AXIS_POSITION-64 ""
*MEAS_COND_AXIS_POSITION-65 ""
*MEAS_COND_AXIS_POSITION-66 ""
*MEAS_COND_AXIS_POSITION-67 ""
*MEAS_COND_AXIS_POSITION-68 ""
*MEAS_COND_AXIS_POSITION-69 ""
*MEAS_COND_AXIS_POSITION-7 "0.0000"
*MEAS_COND_AXIS_POSITION-70 ""
*MEAS_COND_AXIS_POSITION-71 ""
*MEAS_COND_AXIS_POSITION-72 ""
*MEAS_COND_AXIS_POSITION-73 ""
*MEAS_COND_AXIS_POSITION-74 ""
*MEAS_COND_AXIS_POSITION-75 ""
*MEAS_COND_AXIS_POSITION-76 ""
*MEAS_COND_AXIS_POSITION-77 ""
*MEAS_COND_AXIS_POSITION-78 ""
*MEAS_COND_AXIS_POSITION-79 ""
*MEAS_COND_AXIS_POSITION-8 "None"
*MEAS_COND_AXIS_POSITION-80 ""
*MEAS_COND_AXIS_POSITION-81 ""
*MEAS_COND_AXIS_POSITION-82 ""
*MEAS_COND_AXIS_POSITION-83 ""
*MEAS_COND_AXIS_POSITION-84 ""
*MEAS_COND_AXIS_POSITION-85 ""
*MEAS_COND_AXIS_POSITION-86 ""
*MEAS_COND_AXIS_POSITION-87 ""
*MEAS_COND_AXIS_POSITION-88 ""
*MEAS_COND_AXIS_POSITION-89 ""
*MEAS_COND_AXIS_POSITION-9 "-0.1009375"
*MEAS_COND_AXIS_POSITION-90 ""
*MEAS_COND_AXIS_POSITION-91 ""
*MEAS_COND_AXIS_POSITION-92 ""
*MEAS_COND_AXIS_POSITION-93 ""
*MEAS_COND_AXIS_POSITION-94 ""
*MEAS_COND_AXIS_POSITION-95 ""
*MEAS_COND_AXIS_POSITION-96 ""
*MEAS_COND_AXIS_POSITION-97 ""
*MEAS_COND_AXIS_POSITION-98 "Standard"
*MEAS_COND_AXIS_POSITION-99 "IPS_adaptor"
*MEAS_COND_AXIS_RESOLUTION-0 "0.0001"
*MEAS_COND_AXIS_RESOLUTION-1 "0.0001"
*MEAS_COND_AXIS_RESOLUTION-10 ""
*MEAS_COND_AXIS_RESOLUTION-11 ""
*MEAS_COND_AXIS_RESOLUTION-12 ""
*MEAS_COND_AXIS_RESOLUTION-13 "1"
*MEAS_COND_AXIS_RESOLUTION-14 ""
*MEAS_COND_AXIS_RESOLUTION-15 ""
*MEAS_COND_AXIS_RESOLUTION-16 "1/1600"
*MEAS_COND_AXIS_RESOLUTION-17 "1/1600"
*MEAS_COND_AXIS_RESOLUTION-18 "1/1600"
*MEAS_COND_AXIS_RESOLUTION-19 "0.0003125"
*MEAS_COND_AXIS_RESOLUTION-2 "0.0001"
*MEAS_COND_AXIS_RESOLUTION-20 ""
*MEAS_COND_AXIS_RESOLUTION-21 ""
*MEAS_COND_AXIS_RESOLUTION-22 ""
*MEAS_COND_AXIS_RESOLUTION-23 "0.001"
*MEAS_COND_AXIS_RESOLUTION-24 "0.002"
*MEAS_COND_AXIS_RESOLUTION-25 "0.0001"
*MEAS_COND_AXIS_RESOLUTION-26 "0.001"
*MEAS_COND_AXIS_RESOLUTION-27 "0.002"
*MEAS_COND_AXIS_RESOLUTION-28 "0.004"
*MEAS_COND_AXIS_RESOLUTION-29 "0.01"
*MEAS_COND_AXIS_RESOLUTION-3 "0.0001"
*MEAS_COND_AXIS_RESOLUTION-30 "0.002"
*MEAS_COND_AXIS_RESOLUTION-31 "0.0001"
*MEAS_COND_AXIS_RESOLUTION-32 "0.00099"
*MEAS_COND_AXIS_RESOLUTION-33 "0.00134"
*MEAS_COND_AXIS_RESOLUTION-34 "1/1600"
*MEAS_COND_AXIS_RESOLUTION-35 "1/1600"
*MEAS_COND_AXIS_RESOLUTION-36 "1/1600"
*MEAS_COND_AXIS_RESOLUTION-37 ""
*MEAS_COND_AXIS_RESOLUTION-38 ""
*MEAS_COND_AXIS_RESOLUTION-39 ""
*MEAS_COND_AXIS_RESOLUTION-4 "0.0002"
*MEAS_COND_AXIS_RESOLUTION-40 "1/1600"
*MEAS_COND_AXIS_RESOLUTION-41 "1/1600"
*MEAS_COND_AXIS_RESOLUTION-42 "1/1600"
*MEAS_COND_AXIS_RESOLUTION-43 "0.0003125"
*MEAS_COND_AXIS_RESOLUTION-44 ""
*MEAS_COND_AXIS_RESOLUTION-45 "1/800"
*MEAS_COND_AXIS_RESOLUTION-46 "0.5"
*MEAS_COND_AXIS_RESOLUTION-47 "1.25"
*MEAS_COND_AXIS_RESOLUTION-48 ""
*MEAS_COND_AXIS_RESOLUTION-49 "0.010000"
*MEAS_COND_AXIS_RESOLUTION-5 "0.0002"
*MEAS_COND_AXIS_RESOLUTION-50 "0.010000"
*MEAS_COND_AXIS_RESOLUTION-51 "0.01"
*MEAS_COND_AXIS_RESOLUTION-52 "0.010000"
*MEAS_COND_AXIS_RESOLUTION-53 "0.01"
*MEAS_COND_AXIS_RESOLUTION-54 "1.000000"
*MEAS_COND_AXIS_RESOLUTION-55 "1.000000"
*MEAS_COND_AXIS_RESOLUTION-56 "1"
*MEAS_COND_AXIS_RESOLUTION-57 "1"
*MEAS_COND_AXIS_RESOLUTION-58 "0.01"
*MEAS_COND_AXIS_RESOLUTION-59 "0.01"
*MEAS_COND_AXIS_RESOLUTION-6 "0.0001"
*MEAS_COND_AXIS_RESOLUTION-60 "0.01"
*MEAS_COND_AXIS_RESOLUTION-61 "0.01"
*MEAS_COND_AXIS_RESOLUTION-62 "0.010000"
*MEAS_COND_AXIS_RESOLUTION-63 "1"
*MEAS_COND_AXIS_RESOLUTION-64 "0.1"
*MEAS_COND_AXIS_RESOLUTION-65 "1"
*MEAS_COND_AXIS_RESOLUTION-66 "0.010000"
*MEAS_COND_AXIS_RESOLUTION-67 "0.01"
*MEAS_COND_AXIS_RESOLUTION-68 "0.01"
*MEAS_COND_AXIS_RESOLUTION-69 "0.100000"
*MEAS_COND_AXIS_RESOLUTION-7 "0.0005"
*MEAS_COND_AXIS_RESOLUTION-70 "1.000000"
*MEAS_COND_AXIS_RESOLUTION-71 "0.01"
*MEAS_COND_AXIS_RESOLUTION-72 "1.000000"
*MEAS_COND_AXIS_RESOLUTION-73 "1"
*MEAS_COND_AXIS_RESOLUTION-74 "1.000000"
*MEAS_COND_AXIS_RESOLUTION-75 "1"
*MEAS_COND_AXIS_RESOLUTION-76 "0.01"
*MEAS_COND_AXIS_RESOLUTION-77 "1"
*MEAS_COND_AXIS_RESOLUTION-78 "1"
*MEAS_COND_AXIS_RESOLUTION-79 "1"
*MEAS_COND_AXIS_RESOLUTION-8 ""
*MEAS_COND_AXIS_RESOLUTION-80 "0.01"
*MEAS_COND_AXIS_RESOLUTION-81 "1.000000"
*MEAS_COND_AXIS_RESOLUTION-82 "1.000000"
*MEAS_COND_AXIS_RESOLUTION-83 "1.000000"
*MEAS_COND_AXIS_RESOLUTION-84 "-"
*MEAS_COND_AXIS_RESOLUTION-85 "-"
*MEAS_COND_AXIS_RESOLUTION-86 "-"
*MEAS_COND_AXIS_RESOLUTION-87 "1.000000"
*MEAS_COND_AXIS_RESOLUTION-88 "-"
*MEAS_COND_AXIS_RESOLUTION-89 "-"
*MEAS_COND_AXIS_RESOLUTION-9 "0.0000625"
*MEAS_COND_AXIS_RESOLUTION-90 "-"
*MEAS_COND_AXIS_RESOLUTION-91 "1.000000"
*MEAS_COND_AXIS_RESOLUTION-92 "1.000000"
*MEAS_COND_AXIS_RESOLUTION-93 "1.000000"
*MEAS_COND_AXIS_RESOLUTION-94 "1.000000"
*MEAS_COND_AXIS_RESOLUTION-95 "1.000000"
*MEAS_COND_AXIS_RESOLUTION-96 "1.000000"
*MEAS_COND_AXIS_RESOLUTION-97 "1.000000"
*MEAS_COND_AXIS_STATE-0 "Fixed"
*MEAS_COND_AXIS_STATE-1 "Fixed"
*MEAS_COND_AXIS_STATE-10 "Fixed"
*MEAS_COND_AXIS_STATE-11 "Fixed"
*MEAS_COND_AXIS_STATE-12 "Fixed"
*MEAS_COND_AXIS_STATE-13 "Fixed"
*MEAS_COND_AXIS_STATE-14 "Fixed"
*MEAS_COND_AXIS_STATE-15 "Fixed"
*MEAS_COND_AXIS_STATE-16 "Fixed"
*MEAS_COND_AXIS_STATE-17 "Fixed"
*MEAS_COND_AXIS_STATE-18 "Fixed"
*MEAS_COND_AXIS_STATE-19 "Fixed"
*MEAS_COND_AXIS_STATE-2 "Fixed"
*MEAS_COND_AXIS_STATE-20 "Fixed"
*MEAS_COND_AXIS_STATE-21 "Fixed"
*MEAS_COND_AXIS_STATE-22 "Fixed"
*MEAS_COND_AXIS_STATE-23 "Fixed"
*MEAS_COND_AXIS_STATE-24 "Fixed"
*MEAS_COND_AXIS_STATE-25 "Fixed"
*MEAS_COND_AXIS_STATE-26 "Fixed"
*MEAS_COND_AXIS_STATE-27 "Fixed"
*MEAS_COND_AXIS_STATE-28 "Fixed"
*MEAS_COND_AXIS_STATE-29 "Fixed"
*MEAS_COND_AXIS_STATE-3 "Fixed"
*MEAS_COND_AXIS_STATE-30 "Fixed"
*MEAS_COND_AXIS_STATE-31 "Fixed"
*MEAS_COND_AXIS_STATE-32 "Fixed"
*MEAS_COND_AXIS_STATE-33 "Fixed"
*MEAS_COND_AXIS_STATE-34 "Fixed"
*MEAS_COND_AXIS_STATE-35 "Fixed"
*MEAS_COND_AXIS_STATE-36 "Fixed"
*MEAS_COND_AXIS_STATE-37 "Fixed"
*MEAS_COND_AXIS_STATE-38 "Fixed"
*MEAS_COND_AXIS_STATE-39 "Fixed"
*MEAS_COND_AXIS_STATE-4 "Fixed"
*MEAS_COND_AXIS_STATE-40 "Fixed"
*MEAS_COND_AXIS_STATE-41 "Fixed"
*MEAS_COND_AXIS_STATE-42 "Fixed"
*MEAS_COND_AXIS_STATE-43 "Fixed"
*MEAS_COND_AXIS_STATE-44 "Fixed"
*MEAS_COND_AXIS_STATE-45 "Fixed"
*MEAS_COND_AXIS_STATE-46 "Fixed"
*MEAS_COND_AXIS_STATE-47 "Fixed"
*MEAS_COND_AXIS_STATE-48 "Fixed"
*MEAS_COND_AXIS_STATE-49 "Fixed"
*MEAS_COND_AXIS_STATE-5 "Scan"
*MEAS_COND_AXIS_STATE-50 "Fixed"
*MEAS_COND_AXIS_STATE-51 "Fixed"
*MEAS_COND_AXIS_STATE-52 "Fixed"
*MEAS_COND_AXIS_STATE-53 "Fixed"
*MEAS_COND_AXIS_STATE-54 "Fixed"
*MEAS_COND_AXIS_STATE-55 "Fixed"
*MEAS_COND_AXIS_STATE-56 "Fixed"
*MEAS_COND_AXIS_STATE-57 "Fixed"
*MEAS_COND_AXIS_STATE-58 "Fixed"
*MEAS_COND_AXIS_STATE-59 "Fixed"
*MEAS_COND_AXIS_STATE-6 "Fixed"
*MEAS_COND_AXIS_STATE-60 "Fixed"
*MEAS_COND_AXIS_STATE-61 "Fixed"
*MEAS_COND_AXIS_STATE-62 "Fixed"
*MEAS_COND_AXIS_STATE-63 "Fixed"
*MEAS_COND_AXIS_STATE-64 "Fixed"
*MEAS_COND_AXIS_STATE-65 "Fixed"
*MEAS_COND_AXIS_STATE-66 "Fixed"
*MEAS_COND_AXIS_STATE-67 "Fixed"
*MEAS_COND_AXIS_STATE-68 "Fixed"
*MEAS_COND_AXIS_STATE-69 "Fixed"
*MEAS_COND_AXIS_STATE-7 "Fixed"
*MEAS_COND_AXIS_STATE-70 "Fixed"
*MEAS_COND_AXIS_STATE-71 "Fixed"
*MEAS_COND_AXIS_STATE-72 "Fixed"
*MEAS_COND_AXIS_STATE-73 "Fixed"
*MEAS_COND_AXIS_STATE-74 "Fixed"
*MEAS_COND_AXIS_STATE-75 "Fixed"
*MEAS_COND_AXIS_STATE-76 "Fixed"
*MEAS_COND_AXIS_STATE-77 "Fixed"
*MEAS_COND_AXIS_STATE-78 "Fixed"
*MEAS_COND_AXIS_STATE-79 "Fixed"
*MEAS_COND_AXIS_STATE-8 "Fixed"
*MEAS_COND_AXIS_STATE-80 "Fixed"
*MEAS_COND_AXIS_STATE-81 "Fixed"
*MEAS_COND_AXIS_STATE-82 "Fixed"
*MEAS_COND_AXIS_STATE-83 "Fixed"
*MEAS_COND_AXIS_STATE-84 "Fixed"
*MEAS_COND_AXIS_STATE-85 "Fixed"
*MEAS_COND_AXIS_STATE-86 "Fixed"
*MEAS_COND_AXIS_STATE-87 "Fixed"
*MEAS_COND_AXIS_STATE-88 "Fixed"
*MEAS_COND_AXIS_STATE-89 "Fixed"
*MEAS_COND_AXIS_STATE-9 "Fixed"
*MEAS_COND_AXIS_STATE-90 "Fixed"
*MEAS_COND_AXIS_STATE-91 "Fixed"
*MEAS_COND_AXIS_STATE-92 "Fixed"
*MEAS_COND_AXIS_STATE-93 "Fixed"
*MEAS_COND_AXIS_STATE-94 "Fixed"
*MEAS_COND_AXIS_STATE-95 "Fixed"
*MEAS_COND_AXIS_STATE-96 "Fixed"
*MEAS_COND_AXIS_STATE-97 "Fixed"
*MEAS_COND_AXIS_UNIT-0 "deg"
*MEAS_COND_AXIS_UNIT-1 "deg"
*MEAS_COND_AXIS_UNIT-10 ""
*MEAS_COND_AXIS_UNIT-100 ""
*MEAS_COND_AXIS_UNIT-101 ""
*MEAS_COND_AXIS_UNIT-11 ""
*MEAS_COND_AXIS_UNIT-12 ""
*MEAS_COND_AXIS_UNIT-13 "pulse"
*MEAS_COND_AXIS_UNIT-14 ""
*MEAS_COND_AXIS_UNIT-15 ""
*MEAS_COND_AXIS_UNIT-16 ""
*MEAS_COND_AXIS_UNIT-17 "mm"
*MEAS_COND_AXIS_UNIT-18 ""
*MEAS_COND_AXIS_UNIT-19 "mm"
*MEAS_COND_AXIS_UNIT-2 "deg"
*MEAS_COND_AXIS_UNIT-20 ""
*MEAS_COND_AXIS_UNIT-21 ""
*MEAS_COND_AXIS_UNIT-22 ""
*MEAS_COND_AXIS_UNIT-23 "deg"
*MEAS_COND_AXIS_UNIT-24 "deg"
*MEAS_COND_AXIS_UNIT-25 "mm"
*MEAS_COND_AXIS_UNIT-26 "deg"
*MEAS_COND_AXIS_UNIT-27 "deg"
*MEAS_COND_AXIS_UNIT-28 "deg"
*MEAS_COND_AXIS_UNIT-29 "deg"
*MEAS_COND_AXIS_UNIT-3 "deg"
*MEAS_COND_AXIS_UNIT-30 "deg"
*MEAS_COND_AXIS_UNIT-31 "deg"
*MEAS_COND_AXIS_UNIT-32 "deg"
*MEAS_COND_AXIS_UNIT-33 "deg"
*MEAS_COND_AXIS_UNIT-34 ""
*MEAS_COND_AXIS_UNIT-35 "mm"
*MEAS_COND_AXIS_UNIT-36 ""
*MEAS_COND_AXIS_UNIT-37 ""
*MEAS_COND_AXIS_UNIT-38 ""
*MEAS_COND_AXIS_UNIT-39 ""
*MEAS_COND_AXIS_UNIT-4 "deg"
*MEAS_COND_AXIS_UNIT-40 ""
*MEAS_COND_AXIS_UNIT-41 "mm"
*MEAS_COND_AXIS_UNIT-42 ""
*MEAS_COND_AXIS_UNIT-43 "mm"
*MEAS_COND_AXIS_UNIT-44 ""
*MEAS_COND_AXIS_UNIT-45 ""
*MEAS_COND_AXIS_UNIT-46 "V"
*MEAS_COND_AXIS_UNIT-47 "mV"
*MEAS_COND_AXIS_UNIT-48 ""
*MEAS_COND_AXIS_UNIT-49 "H"
*MEAS_COND_AXIS_UNIT-5 "deg"
*MEAS_COND_AXIS_UNIT-50 "H"
*MEAS_COND_AXIS_UNIT-51 "H"
*MEAS_COND_AXIS_UNIT-52 "H"
*MEAS_COND_AXIS_UNIT-53 "H"
*MEAS_COND_AXIS_UNIT-54 "mV"
*MEAS_COND_AXIS_UNIT-55 "V"
*MEAS_COND_AXIS_UNIT-56 "V"
*MEAS_COND_AXIS_UNIT-57 "V"
*MEAS_COND_AXIS_UNIT-58 "H"
*MEAS_COND_AXIS_UNIT-59 "H"
*MEAS_COND_AXIS_UNIT-6 "deg"
*MEAS_COND_AXIS_UNIT-60 "H"
*MEAS_COND_AXIS_UNIT-61 "H"
*MEAS_COND_AXIS_UNIT-62 "H"
*MEAS_COND_AXIS_UNIT-63 "uS/m"
*MEAS_COND_AXIS_UNIT-64 "L/min"
*MEAS_COND_AXIS_UNIT-65 "C"
*MEAS_COND_AXIS_UNIT-66 "MPa"
*MEAS_COND_AXIS_UNIT-67 "MPa"
*MEAS_COND_AXIS_UNIT-68 "MPa"
*MEAS_COND_AXIS_UNIT-69 "L/min"
*MEAS_COND_AXIS_UNIT-7 "deg"
*MEAS_COND_AXIS_UNIT-70 "degree"
*MEAS_COND_AXIS_UNIT-71 "MPa"
*MEAS_COND_AXIS_UNIT-72 "degree"
*MEAS_COND_AXIS_UNIT-73 "percent"
*MEAS_COND_AXIS_UNIT-74 "degree"
*MEAS_COND_AXIS_UNIT-75 "C"
*MEAS_COND_AXIS_UNIT-76 "H"
*MEAS_COND_AXIS_UNIT-77 "time"
*MEAS_COND_AXIS_UNIT-78 "msec"
*MEAS_COND_AXIS_UNIT-79 "msec"
*MEAS_COND_AXIS_UNIT-8 ""
*MEAS_COND_AXIS_UNIT-80 "H"
*MEAS_COND_AXIS_UNIT-81 "times"
*MEAS_COND_AXIS_UNIT-82 "msec"
*MEAS_COND_AXIS_UNIT-83 "msec"
*MEAS_COND_AXIS_UNIT-84 "-"
*MEAS_COND_AXIS_UNIT-85 "-"
*MEAS_COND_AXIS_UNIT-86 "-"
*MEAS_COND_AXIS_UNIT-87 ""
*MEAS_COND_AXIS_UNIT-88 "-"
*MEAS_COND_AXIS_UNIT-89 "-"
*MEAS_COND_AXIS_UNIT-9 "mm"
*MEAS_COND_AXIS_UNIT-90 "-"
*MEAS_COND_AXIS_UNIT-91 ""
*MEAS_COND_AXIS_UNIT-92 ""
*MEAS_COND_AXIS_UNIT-93 ""
*MEAS_COND_AXIS_UNIT-94 ""
*MEAS_COND_AXIS_UNIT-95 ""
*MEAS_COND_AXIS_UNIT-96 ""
*MEAS_COND_AXIS_UNIT-97 ""
*MEAS_COND_AXIS_UNIT-98 ""
*MEAS_COND_AXIS_UNIT-99 ""
*MEAS_COND_OPT_ATTR "PB"
*MEAS_COND_OPT_NAME "User defined settings"
*MEAS_COND_XG_CURRENT "160"
*MEAS_COND_XG_VOLTAGE "45"
*MEAS_COND_XG_WAVE_TYPE "Ka"
*MEAS_DATA_COUNT "251"
*MEAS_SCAN_AXIS_X "TwoThetaOmega"
*MEAS_SCAN_AXIS_X_INTERNAL "TwoThetaOmega"
*MEAS_SCAN_END_TIME "08/05/2020 15:06:09"
*MEAS_SCAN_MODE "CONTINUOUS"
*MEAS_SCAN_MODE_INTERNAL "CONTINUOUS"
*MEAS_SCAN_RESOLUTION_X "0.0002"
*MEAS_SCAN_SPEED "5.0000"
*MEAS_SCAN_SPEED_UNIT "deg/min"
*MEAS_SCAN_START "0.0000"
*MEAS_SCAN_START_TIME "08/05/2020 15:04:30"
*MEAS_SCAN_STEP "0.0200"
*MEAS_SCAN_STOP "5.0000"
*MEAS_SCAN_UNIT_X "deg"
*MEAS_SCAN_UNIT_Y "counts"
*RAS_HEADER_END
*RAS_INT_START
0.0000 3308.0000 12284.3415
0.0200 4754.0000 12284.3415
0.0400 3414.0000 12284.3415
0.0600 1552.0000 12284.3415
0.0800 890.0000 12284.3415
0.1000 852.0000 12284.3415
0.1200 1052.0000 12284.3415
0.1400 1275.0000 12284.3415
0.1600 1513.0000 12284.3415
0.1800 1620.0000 12284.3415
0.2000 1823.0000 12284.3415
0.2200 1994.0000 12284.3415
0.2400 2276.0000 12284.3415
0.2600 2343.0000 12284.3415
0.2800 2654.0000 12284.3415
0.3000 2820.0000 12284.3415
0.3200 2966.0000 12284.3415
0.3400 3096.0000 12284.3415
0.3600 3219.0000 12284.3415
0.3800 3423.0000 12284.3415
0.4000 3449.0000 12284.3415
0.4200 3749.0000 12284.3415
0.4400 3824.0000 12284.3415
0.4600 3991.0000 12284.3415
0.4800 4063.0000 12284.3415
0.5000 4215.0000 12284.3415
0.5200 4269.0000 12284.3415
0.5400 4333.0000 12284.3415
0.5600 4062.0000 12284.3415
0.5800 3909.0000 12284.3415
0.6000 3466.0000 12284.3415
0.6200 2897.0000 12284.3415
0.6400 2453.0000 12284.3415
0.6600 1883.0000 12284.3415
0.6800 1408.0000 12284.3415
0.7000 1042.0000 12284.3415
0.7200 820.0000 12284.3415
0.7400 636.0000 12284.3415
0.7600 541.0000 12284.3415
0.7800 432.0000 12284.3415
0.8000 345.0000 12284.3415
0.8200 296.0000 12284.3415
0.8400 246.0000 12284.3415
0.8600 240.0000 12284.3415
0.8800 2912.0000 855.8620
0.9000 2570.0000 855.8620
0.9200 2104.0000 855.8620
0.9400 1731.0000 855.8620
0.9600 1531.0000 855.8620
0.9800 1427.0000 855.8620
1.0000 1359.0000 855.8620
1.0200 1291.0000 855.8620
1.0400 1177.0000 855.8620
1.0600 880.0000 855.8620
1.0800 807.0000 855.8620
1.1000 696.0000 855.8620
1.1200 716.0000 855.8620
1.1400 660.0000 855.8620
1.1600 660.0000 855.8620
1.1800 502.0000 855.8620
1.2000 415.0000 855.8620
1.2200 365.0000 855.8620
1.2400 332.0000 855.8620
1.2600 350.0000 855.8620
1.2800 309.0000 855.8620
1.3000 291.0000 855.8620
1.3200 279.0000 855.8620
1.3400 3282.0000 58.6391
1.3600 2793.0000 58.6391
1.3800 2538.0000 58.6391
1.4000 2494.0000 58.6391
1.4200 2625.0000 58.6391
1.4400 2474.0000 58.6391
1.4600 2244.0000 58.6391
1.4800 1765.0000 58.6391
1.5000 1472.0000 58.6391
1.5200 1360.0000 58.6391
1.5400 1252.0000 58.6391
1.5600 1328.0000 58.6391
1.5800 1340.0000 58.6391
1.6000 1237.0000 58.6391
1.6200 1125.0000 58.6391
1.6400 891.0000 58.6391
1.6600 722.0000 58.6391
1.6800 649.0000 58.6391
1.7000 642.0000 58.6391
1.7200 644.0000 58.6391
1.7400 734.0000 58.6391
1.7600 643.0000 58.6391
1.7800 562.0000 58.6391
1.8000 466.0000 58.6391
1.8200 386.0000 58.6391
1.8400 346.0000 58.6391
1.8600 347.0000 58.6391
1.8800 417.0000 58.6391
1.9000 392.0000 58.6391
1.9200 353.0000 58.6391
1.9400 310.0000 58.6391
1.9600 263.0000 58.6391
1.9800 13041.0000 1.0000
2.0000 12053.0000 1.0000
2.0200 12310.0000 1.0000
2.0400 13226.0000 1.0000
2.0600 13952.0000 1.0000
2.0800 13549.0000 1.0000
2.1000 11990.0000 1.0000
2.1200 10017.0000 1.0000
2.1400 8563.0000 1.0000
2.1600 7798.0000 1.0000
2.1800 8039.0000 1.0000
2.2000 8579.0000 1.0000
2.2200 9345.0000 1.0000
2.2400 9203.0000 1.0000
2.2600 8462.0000 1.0000
2.2800 7276.0000 1.0000
2.3000 6054.0000 1.0000
2.3200 5521.0000 1.0000
2.3400 5708.0000 1.0000
2.3600 6295.0000 1.0000
2.3800 6620.0000 1.0000
2.4000 6753.0000 1.0000
2.4200 6304.0000 1.0000
2.4400 5632.0000 1.0000
2.4600 4796.0000 1.0000
2.4800 4300.0000 1.0000
2.5000 4407.0000 1.0000
2.5200 4732.0000 1.0000
2.5400 5148.0000 1.0000
2.5600 5233.0000 1.0000
2.5800 4914.0000 1.0000
2.6000 4369.0000 1.0000
2.6200 3861.0000 1.0000
2.6400 3438.0000 1.0000
2.6600 3537.0000 1.0000
2.6800 3766.0000 1.0000
2.7000 4090.0000 1.0000
2.7200 3961.0000 1.0000
2.7400 3948.0000 1.0000
2.7600 3652.0000 1.0000
2.7800 3292.0000 1.0000
2.8000 2908.0000 1.0000
2.8200 2838.0000 1.0000
2.8400 3001.0000 1.0000
2.8600 3122.0000 1.0000
2.8800 3295.0000 1.0000
2.9000 3054.0000 1.0000
2.9200 3044.0000 1.0000
2.9400 2688.0000 1.0000
2.9600 2346.0000 1.0000
2.9800 2316.0000 1.0000
3.0000 2330.0000 1.0000
3.0200 2607.0000 1.0000
3.0400 2608.0000 1.0000
3.0600 2656.0000 1.0000
3.0800 2340.0000 1.0000
3.1000 2176.0000 1.0000
3.1200 1964.0000 1.0000
3.1400 1872.0000 1.0000
3.1600 1803.0000 1.0000
3.1800 1940.0000 1.0000
3.2000 2033.0000 1.0000
3.2200 2026.0000 1.0000
3.2400 1927.0000 1.0000
3.2600 1722.0000 1.0000
3.2800 1474.0000 1.0000
3.3000 1400.0000 1.0000
3.3200 1440.0000 1.0000
3.3400 1470.0000 1.0000
3.3600 1544.0000 1.0000
3.3800 1542.0000 1.0000
3.4000 1460.0000 1.0000
3.4200 1274.0000 1.0000
3.4400 1224.0000 1.0000
3.4600 1156.0000 1.0000
3.4800 1159.0000 1.0000
3.5000 1090.0000 1.0000
3.5200 1198.0000 1.0000
3.5400 1154.0000 1.0000
3.5600 1148.0000 1.0000
3.5800 990.0000 1.0000
3.6000 875.0000 1.0000
3.6200 796.0000 1.0000
3.6400 816.0000 1.0000
3.6600 867.0000 1.0000
3.6800 899.0000 1.0000
3.7000 848.0000 1.0000
3.7200 838.0000 1.0000
3.7400 717.0000 1.0000
3.7600 604.0000 1.0000
3.7800 605.0000 1.0000
3.8000 563.0000 1.0000
3.8200 587.0000 1.0000
3.8400 673.0000 1.0000
3.8600 667.0000 1.0000
3.8800 605.0000 1.0000
3.9000 540.0000 1.0000
3.9200 450.0000 1.0000
3.9400 440.0000 1.0000
3.9600 383.0000 1.0000
3.9800 428.0000 1.0000
4.0000 434.0000 1.0000
4.0200 468.0000 1.0000
4.0400 454.0000 1.0000
4.0600 371.0000 1.0000
4.0800 327.0000 1.0000
4.1000 309.0000 1.0000
4.1200 270.0000 1.0000
4.1400 300.0000 1.0000
4.1600 312.0000 1.0000
4.1800 352.0000 1.0000
4.2000 327.0000 1.0000
4.2200 277.0000 1.0000
4.2400 223.0000 1.0000
4.2600 219.0000 1.0000
4.2800 199.0000 1.0000
4.3000 193.0000 1.0000
4.3200 207.0000 1.0000
4.3400 241.0000 1.0000
4.3600 210.0000 1.0000
4.3800 177.0000 1.0000
4.4000 156.0000 1.0000
4.4200 163.0000 1.0000
4.4400 133.0000 1.0000
4.4600 139.0000 1.0000
4.4800 165.0000 1.0000
4.5000 158.0000 1.0000
4.5200 156.0000 1.0000
4.5400 147.0000 1.0000
4.5600 137.0000 1.0000
4.5800 105.0000 1.0000
4.6000 96.0000 1.0000
4.6200 109.0000 1.0000
4.6400 108.0000 1.0000
4.6600 103.0000 1.0000
4.6800 96.0000 1.0000
4.7000 88.0000 1.0000
4.7200 107.0000 1.0000
4.7400 60.0000 1.0000
4.7600 67.0000 1.0000
4.7800 79.0000 1.0000
4.8000 70.0000 1.0000
4.8200 87.0000 1.0000
4.8400 90.0000 1.0000
4.8600 69.0000 1.0000
4.8800 56.0000 1.0000
4.9000 62.0000 1.0000
4.9200 67.0000 1.0000
4.9400 56.0000 1.0000
4.9600 57.0000 1.0000
4.9800 66.0000 1.0000
5.0000 52.0000 1.0000
*RAS_INT_END
*RAS_HEADER_START
*DISP_LINE_COLOR "4286611584"
*FILE_COMMENT ""
*FILE_MD5 ""
*FILE_MEMO ""
*FILE_OPERATOR "Administrator"
*FILE_PACKAGE_NAME ""
*FILE_PART_ID ""
*FILE_SAMPLE ""
*FILE_SYSTEM_NAME "SmartLab"
*FILE_TYPE "RAS_RAW"
*FILE_USERGROUP "Administrators"
*FILE_VERSION "1"
*HW_ATTACHMENT_ID "ATT0022"
*HW_ATTACHMENT_NAME "RxRy"
*HW_ATTACHMENT_NAME_INTERNAL "RxRy"
*HW_COUNTER_ID-0 "CUT0021"
*HW_COUNTER_ID-1 "CMC0020"
*HW_COUNTER_MONOCHRO_ID "CMC0020"
*HW_COUNTER_MONOCHRO_NAME "None"
*HW_COUNTER_MONOCHRO_NAME_INTERNAL "None"
*HW_COUNTER_NAME_INTERNAL "SC70"
*HW_COUNTER_NAME-0 "SC70"
*HW_COUNTER_NAME-1 "None"
*HW_COUNTER_SELECT_NAME "SC70"
*HW_EXTERNAL_CONTROLLER_NAME "None"
*HW_EXTERNAL_CONTROLLER_NAME_INTERNAL "None"
*HW_GONIOMETER_ID "GON0022"
*HW_GONIOMETER_NAME "StandardInplaneEnc"
*HW_GONIOMETER_NAME_INTERNAL "StandardInplaneEnc"
*HW_GONIOMETER_RADIUS-0 "90.0"
*HW_GONIOMETER_RADIUS-1 "114.0"
*HW_GONIOMETER_RADIUS-2 "190.0"
*HW_GONIOMETER_RADIUS-3 "300.0"
*HW_GONIOMETER_RADIUS-4 "187.0"
*HW_GONIOMETER_RADIUS-5 "300.0"
*HW_GONIOMETER_RADIUS-6 "113.0000"
*HW_GONIOMETER_RADIUS-7 "331.0"
*HW_I_CBO_ID "CBO0021"
*HW_I_CBO_NAME "CBO"
*HW_I_CBO_NAME_INTERNAL "CBO"
*HW_I_MONOCHRO_ID "ISO0021"
*HW_I_MONOCHRO_NAME "IPS_adaptor"
*HW_I_MONOCHRO_NAME_INTERNAL "IPS_adaptor"
*HW_I_OPT_ID-0 "CBO0021"
*HW_I_OPT_ID-1 "ISL0021"
*HW_I_PRIMARY_NAME_INTERNAL "Standard"
*HW_I_SLIT_ID "ISL0021"
*HW_I_SLIT_NAME "Auto"
*HW_I_SLIT_NAME_INTERNAL "Auto"
*HW_R_ATTENUATER_AUTOMODE "1"
*HW_R_ATTENUATER_ID "ATN0021"
*HW_R_ATTENUATER_NAME "Auto"
*HW_R_ATTENUATOR_NAME_INTERNAL "Auto"
*HW_R_OPT_ID-0 "RSS0021"
*HW_R_OPT_ID-1 "RCR0022"
*HW_R_OPT_ID-2 "RSO0021"
*HW_R_OPT_ID-3 "RRS0021"
*HW_R_OPT_ID-4 "ATN0021"
*HW_R_ROD_ID "RCR0022"
*HW_R_ROD_NAME "ROD_adaptor"
*HW_R_ROD_NAME_INTERNAL "ROD_adaptor"
*HW_R_RPS_ID "RSO0021"
*HW_R_RPS_NAME "RPS_adaptor"
*HW_R_RPS_NAME_INTERNAL "RPS_adaptor"
*HW_R_RS_ID "RRS0021"
*HW_R_RS_NAME "Auto"
*HW_R_RS_NAME_INTERNAL "Auto"
*HW_R_SS_ID "RSS0021"
*HW_R_SS_NAME "Auto"
*HW_R_SS_NAME_INTERNAL "Auto"
*HW_ROBOT_NAME "No_unit"
*HW_ROBOT_NAME_INTERNAL "No_unit"
*HW_SAMPLE_CAMERA_NAME "None"
*HW_SAMPLE_CAMERA_NAME_INTERNAL "None"
*HW_SAMPLE_HOLDER_ID "SMP0021"
*HW_SAMPLE_HOLDER_NAME "Z_ChiPhi"
*HW_SAMPLE_HOLDER_NAME_INTERNAL "Z_ChiPhi"
*HW_SAMPLE_NAME "CenterSlit"
*HW_SAMPLE_NAME_INTERNAL "CenterSlit"
*HW_SAMPLE_PLATE_NAME "HeightReference"
*HW_SAMPLE_PLATE_NAME_INTERNAL "HeightReference"
*HW_SAMPLE_SPACER_NAME "None"
*HW_SAMPLE_SPACER_NAME_INTERNAL "None"
*HW_USERINFO_CATALOG_NO ""
*HW_USERINFO_INSTRUMENT_ID ""
*HW_USERINFO_INSTRUMENT_NAME ""
*HW_USERINFO_INSTRUMENT_NO ""
*HW_USERINFO_MODEL ""
*HW_USERINFO_ORDER_NO ""
*HW_USERINFO_SERIAL_NO ""
*HW_USERINFO_VERIFY_INSTRUMENT_ID "00-07-fe-01-03-ce"
*HW_VER_RCD_COUNTER_UNIT "1.0.1"
*HW_VER_RCD_CPU "3.3.7"
*HW_VER_RCD_FPGA "1.2.2"
*HW_VER_RCD_GONIO_UNIT "6.2.0"
*HW_VER_RCD_INCIDENT_UNIT "6.2.0"
*HW_VER_RCD_RECEIVING_UNIT "6.2.0"
*HW_VER_RCD_TYPE "RINC"
*HW_VER_XGC_CPU "3.3.7"
*HW_VER_XGC_CW "1.2.0"
*HW_VER_XGC_HV "1.2.0"
*HW_VER_XGC_RS1 "1.3.4"
*HW_VER_XGC_RS2 "N/A"
*HW_VER_XGC_RT "1.2.0"
*HW_VER_XGC_TYPE "RINC"
*HW_XG_CURRENT_UNIT "mA"
*HW_XG_FOCUS "0.4mm x 8mm"
*HW_XG_FOCUS_TYPE "Fine"
*HW_XG_TARGET_ATOMIC_NUMBER "29"
*HW_XG_TARGET_NAME "Cu"
*HW_XG_TYPE "ROTA"
*HW_XG_VOLTAGE_UNIT "kV"
*HW_XG_WAVE_LENGTH_ALPHA1 "1.540593"
*HW_XG_WAVE_LENGTH_ALPHA2 "1.544414"
*HW_XG_WAVE_LENGTH_BETA "1.392246"
*HW_XG_WAVE_LENGTH_UNIT "Angstrom"
*MEAS_COND_AXIS_NAME_INTERNAL-0 "ThetaS"
*MEAS_COND_AXIS_NAME_INTERNAL-1 "ThetaD"
*MEAS_COND_AXIS_NAME_INTERNAL-10 "PrimaryGeometry"
*MEAS_COND_AXIS_NAME_INTERNAL-100 "ReceivingOptics"
*MEAS_COND_AXIS_NAME_INTERNAL-101 "CounterMonochromatorKind"
*MEAS_COND_AXIS_NAME_INTERNAL-11 "PrimaryMirrorType"
*MEAS_COND_AXIS_NAME_INTERNAL-12 "CBOType"
*MEAS_COND_AXIS_NAME_INTERNAL-13 "CBO-M"
*MEAS_COND_AXIS_NAME_INTERNAL-14 "CBO"
*MEAS_COND_AXIS_NAME_INTERNAL-15 "IncidentSollerSlit"
*MEAS_COND_AXIS_NAME_INTERNAL-16 "IncidentSlitBox"
*MEAS_COND_AXIS_NAME_INTERNAL-17 "IncidentSlitBox-_Axis"
*MEAS_COND_AXIS_NAME_INTERNAL-18 "SlitDS"
*MEAS_COND_AXIS_NAME_INTERNAL-19 "Zs"
*MEAS_COND_AXIS_NAME_INTERNAL-2 "TwoTheta"
*MEAS_COND_AXIS_NAME_INTERNAL-20 "IncidentAxdSlit"
*MEAS_COND_AXIS_NAME_INTERNAL-21 "LLS"
*MEAS_COND_AXIS_NAME_INTERNAL-22 "DHLSlit"
*MEAS_COND_AXIS_NAME_INTERNAL-23 "Chi"
*MEAS_COND_AXIS_NAME_INTERNAL-24 "Phi"
*MEAS_COND_AXIS_NAME_INTERNAL-25 "Z"
*MEAS_COND_AXIS_NAME_INTERNAL-26 "Alpha"
[...]
*MEAS_COND_AXIS_POSITION-13 "0"
*MEAS_COND_AXIS_POSITION-14 "PB"
*MEAS_COND_AXIS_POSITION-15 "Soller_slit_5.0deg"
*MEAS_COND_AXIS_POSITION-16 "0.100mm"
*MEAS_COND_AXIS_POSITION-17 "0.100000"
*MEAS_COND_AXIS_POSITION-18 "0.100mm"
*MEAS_COND_AXIS_POSITION-19 "-2.0290625"
*MEAS_COND_AXIS_POSITION-2 "2.0601"
*MEAS_COND_AXIS_POSITION-20 "2mm"
*MEAS_COND_AXIS_POSITION-21 "2mm"
*MEAS_COND_AXIS_POSITION-22 "2mm"
*MEAS_COND_AXIS_POSITION-23 "0.000"
*MEAS_COND_AXIS_POSITION-24 "0.000"
*MEAS_COND_AXIS_POSITION-25 "-1.0734"
*MEAS_COND_AXIS_POSITION-26 "90.000"
*MEAS_COND_AXIS_POSITION-27 "0.000"
*MEAS_COND_AXIS_POSITION-28 "-0.176"
*MEAS_COND_AXIS_POSITION-29 "85.14"
*MEAS_COND_AXIS_POSITION-3 "1.0289"
*MEAS_COND_AXIS_POSITION-30 "-0.102"
*MEAS_COND_AXIS_POSITION-31 "2.0675"
*MEAS_COND_AXIS_POSITION-32 "-0.20295"
*MEAS_COND_AXIS_POSITION-33 "0.22378"
*MEAS_COND_AXIS_POSITION-34 "0.200mm"
*MEAS_COND_AXIS_POSITION-35 "0.200000"
*MEAS_COND_AXIS_POSITION-36 "0.200mm"
*MEAS_COND_AXIS_POSITION-37 "None"
*MEAS_COND_AXIS_POSITION-38 "PSA_open"
*MEAS_COND_AXIS_POSITION-39 "Soller_slit_5.0deg"
*MEAS_COND_AXIS_POSITION-4 "2.0602"
*MEAS_COND_AXIS_POSITION-40 "0.200mm"
*MEAS_COND_AXIS_POSITION-41 "0.200000"
*MEAS_COND_AXIS_POSITION-42 "0.200mm"
*MEAS_COND_AXIS_POSITION-43 "-0.5256250"
*MEAS_COND_AXIS_POSITION-44 "None"
*MEAS_COND_AXIS_POSITION-45 "Open"
*MEAS_COND_AXIS_POSITION-46 "647.0"
*MEAS_COND_AXIS_POSITION-47 "572.50"
*MEAS_COND_AXIS_POSITION-48 "None"
*MEAS_COND_AXIS_POSITION-49 ""
*MEAS_COND_AXIS_POSITION-5 "2.0602"
*MEAS_COND_AXIS_POSITION-50 ""
*MEAS_COND_AXIS_POSITION-51 ""
*MEAS_COND_AXIS_POSITION-52 ""
*MEAS_COND_AXIS_POSITION-53 ""
*MEAS_COND_AXIS_POSITION-54 ""
*MEAS_COND_AXIS_POSITION-55 ""
*MEAS_COND_AXIS_POSITION-56 ""
*MEAS_COND_AXIS_POSITION-57 ""
*MEAS_COND_AXIS_POSITION-58 ""
*MEAS_COND_AXIS_POSITION-59 ""
*MEAS_COND_AXIS_POSITION-6 "1.0289"
*MEAS_COND_AXIS_POSITION-60 ""
*MEAS_COND_AXIS_POSITION-61 ""
*MEAS_COND_AXIS_POSITION-62 ""
*MEAS_COND_AXIS_POSITION-63 ""
*MEAS_COND_AXIS_POSITION-64 ""
*MEAS_COND_AXIS_POSITION-65 ""
*MEAS_COND_AXIS_POSITION-66 ""
*MEAS_COND_AXIS_POSITION-67 ""
*MEAS_COND_AXIS_POSITION-68 ""
*MEAS_COND_AXIS_POSITION-69 ""
*MEAS_COND_AXIS_POSITION-7 "-0.1750"
*MEAS_COND_AXIS_POSITION-70 ""
*MEAS_COND_AXIS_POSITION-71 ""
*MEAS_COND_AXIS_POSITION-72 ""
*MEAS_COND_AXIS_POSITION-73 ""
*MEAS_COND_AXIS_POSITION-74 ""
*MEAS_COND_AXIS_POSITION-75 ""
*MEAS_COND_AXIS_POSITION-76 ""
*MEAS_COND_AXIS_POSITION-77 ""
*MEAS_COND_AXIS_POSITION-78 ""
*MEAS_COND_AXIS_POSITION-79 ""
*MEAS_COND_AXIS_POSITION-8 "None"
*MEAS_COND_AXIS_POSITION-80 ""
*MEAS_COND_AXIS_POSITION-81 ""
*MEAS_COND_AXIS_POSITION-82 ""
*MEAS_COND_AXIS_POSITION-83 ""
*MEAS_COND_AXIS_POSITION-84 ""
*MEAS_COND_AXIS_POSITION-85 ""
*MEAS_COND_AXIS_POSITION-86 ""
*MEAS_COND_AXIS_POSITION-87 ""
*MEAS_COND_AXIS_POSITION-88 ""
*MEAS_COND_AXIS_POSITION-89 ""
*MEAS_COND_AXIS_POSITION-9 "-0.1009375"
*MEAS_COND_AXIS_POSITION-90 ""
*MEAS_COND_AXIS_POSITION-91 ""
*MEAS_COND_AXIS_POSITION-92 ""
*MEAS_COND_AXIS_POSITION-93 ""
*MEAS_COND_AXIS_POSITION-94 ""
*MEAS_COND_AXIS_POSITION-95 ""
*MEAS_COND_AXIS_POSITION-96 ""
*MEAS_COND_AXIS_POSITION-97 ""
*MEAS_COND_AXIS_POSITION-98 "Standard"
*MEAS_COND_AXIS_POSITION-99 "IPS_adaptor"
*MEAS_COND_AXIS_RESOLUTION-0 "0.0001"
*MEAS_COND_AXIS_RESOLUTION-1 "0.0001"
*MEAS_COND_AXIS_RESOLUTION-10 ""
*MEAS_COND_AXIS_RESOLUTION-11 ""
*MEAS_COND_AXIS_RESOLUTION-12 ""
*MEAS_COND_AXIS_RESOLUTION-13 "1"
*MEAS_COND_AXIS_RESOLUTION-14 ""
*MEAS_COND_AXIS_RESOLUTION-15 ""
*MEAS_COND_AXIS_RESOLUTION-16 "1/1600"
*MEAS_COND_AXIS_RESOLUTION-17 "1/1600"
*MEAS_COND_AXIS_RESOLUTION-18 "1/1600"
*MEAS_COND_AXIS_RESOLUTION-19 "0.0003125"
*MEAS_COND_AXIS_RESOLUTION-2 "0.0001"
*MEAS_COND_AXIS_RESOLUTION-20 ""
*MEAS_COND_AXIS_RESOLUTION-21 ""
*MEAS_COND_AXIS_RESOLUTION-22 ""
*MEAS_COND_AXIS_RESOLUTION-23 "0.001"
*MEAS_COND_AXIS_RESOLUTION-24 "0.002"
*MEAS_COND_AXIS_RESOLUTION-25 "0.0001"
*MEAS_COND_AXIS_RESOLUTION-26 "0.001"
*MEAS_COND_AXIS_RESOLUTION-27 "0.002"
*MEAS_COND_AXIS_RESOLUTION-28 "0.004"
*MEAS_COND_AXIS_RESOLUTION-29 "0.01"
*MEAS_COND_AXIS_RESOLUTION-3 "0.0001"
*MEAS_COND_AXIS_RESOLUTION-30 "0.002"
*MEAS_COND_AXIS_RESOLUTION-31 "0.0001"
*MEAS_COND_AXIS_RESOLUTION-32 "0.00099"
*MEAS_COND_AXIS_RESOLUTION-33 "0.00134"
*MEAS_COND_AXIS_RESOLUTION-34 "1/1600"
*MEAS_COND_AXIS_RESOLUTION-35 "1/1600"
*MEAS_COND_AXIS_RESOLUTION-36 "1/1600"
*MEAS_COND_AXIS_RESOLUTION-37 ""
*MEAS_COND_AXIS_RESOLUTION-38 ""
*MEAS_COND_AXIS_RESOLUTION-39 ""
*MEAS_COND_AXIS_RESOLUTION-4 "0.0002"
*MEAS_COND_AXIS_RESOLUTION-40 "1/1600"
*MEAS_COND_AXIS_RESOLUTION-41 "1/1600"
*MEAS_COND_AXIS_RESOLUTION-42 "1/1600"
*MEAS_COND_AXIS_RESOLUTION-43 "0.0003125"
*MEAS_COND_AXIS_RESOLUTION-44 ""
*MEAS_COND_AXIS_RESOLUTION-45 "1/800"
*MEAS_COND_AXIS_RESOLUTION-46 "0.5"
*MEAS_COND_AXIS_RESOLUTION-47 "1.25"
*MEAS_COND_AXIS_RESOLUTION-48 ""
*MEAS_COND_AXIS_RESOLUTION-49 "0.010000"
*MEAS_COND_AXIS_RESOLUTION-5 "0.0002"
*MEAS_COND_AXIS_RESOLUTION-50 "0.010000"
*MEAS_COND_AXIS_RESOLUTION-51 "0.01"
*MEAS_COND_AXIS_RESOLUTION-52 "0.010000"
*MEAS_COND_AXIS_RESOLUTION-53 "0.01"
*MEAS_COND_AXIS_RESOLUTION-54 "1.000000"
*MEAS_COND_AXIS_RESOLUTION-55 "1.000000"
*MEAS_COND_AXIS_RESOLUTION-56 "1"
*MEAS_COND_AXIS_RESOLUTION-57 "1"
*MEAS_COND_AXIS_RESOLUTION-58 "0.01"
*MEAS_COND_AXIS_RESOLUTION-59 "0.01"
*MEAS_COND_AXIS_RESOLUTION-6 "0.0001"
*MEAS_COND_AXIS_RESOLUTION-60 "0.01"
*MEAS_COND_AXIS_RESOLUTION-61 "0.01"
*MEAS_COND_AXIS_RESOLUTION-62 "0.010000"
*MEAS_COND_AXIS_RESOLUTION-63 "1"
*MEAS_COND_AXIS_RESOLUTION-64 "0.1"
*MEAS_COND_AXIS_RESOLUTION-65 "1"
*MEAS_COND_AXIS_RESOLUTION-66 "0.010000"
*MEAS_COND_AXIS_RESOLUTION-67 "0.01"
*MEAS_COND_AXIS_RESOLUTION-68 "0.01"
*MEAS_COND_AXIS_RESOLUTION-69 "0.100000"
*MEAS_COND_AXIS_RESOLUTION-7 "0.0005"
*MEAS_COND_AXIS_RESOLUTION-70 "1.000000"
*MEAS_COND_AXIS_RESOLUTION-71 "0.01"
*MEAS_COND_AXIS_RESOLUTION-72 "1.000000"
*MEAS_COND_AXIS_RESOLUTION-73 "1"
*MEAS_COND_AXIS_RESOLUTION-74 "1.000000"
*MEAS_COND_AXIS_RESOLUTION-75 "1"
*MEAS_COND_AXIS_RESOLUTION-76 "0.01"
*MEAS_COND_AXIS_RESOLUTION-77 "1"
*MEAS_COND_AXIS_RESOLUTION-78 "1"
*MEAS_COND_AXIS_RESOLUTION-79 "1"
*MEAS_COND_AXIS_RESOLUTION-8 ""
*MEAS_COND_AXIS_RESOLUTION-80 "0.01"
*MEAS_COND_AXIS_RESOLUTION-81 "1.000000"
*MEAS_COND_AXIS_RESOLUTION-82 "1.000000"
*MEAS_COND_AXIS_RESOLUTION-83 "1.000000"
*MEAS_COND_AXIS_RESOLUTION-84 "-"
*MEAS_COND_AXIS_RESOLUTION-85 "-"
*MEAS_COND_AXIS_RESOLUTION-86 "-"
*MEAS_COND_AXIS_RESOLUTION-87 "1.000000"
*MEAS_COND_AXIS_RESOLUTION-88 "-"
*MEAS_COND_AXIS_RESOLUTION-89 "-"
*MEAS_COND_AXIS_RESOLUTION-9 "0.0000625"
*MEAS_COND_AXIS_RESOLUTION-90 "-"
*MEAS_COND_AXIS_RESOLUTION-91 "1.000000"
*MEAS_COND_AXIS_RESOLUTION-92 "1.000000"
*MEAS_COND_AXIS_RESOLUTION-93 "1.000000"
*MEAS_COND_AXIS_RESOLUTION-94 "1.000000"
*MEAS_COND_AXIS_RESOLUTION-95 "1.000000"
*MEAS_COND_AXIS_RESOLUTION-96 "1.000000"
*MEAS_COND_AXIS_RESOLUTION-97 "1.000000"
*MEAS_COND_AXIS_STATE-0 "Fixed"
*MEAS_COND_AXIS_STATE-1 "Fixed"
*MEAS_COND_AXIS_STATE-10 "Fixed"
*MEAS_COND_AXIS_STATE-11 "Fixed"
*MEAS_COND_AXIS_STATE-12 "Fixed"
*MEAS_COND_AXIS_STATE-13 "Fixed"
*MEAS_COND_AXIS_STATE-14 "Fixed"
*MEAS_COND_AXIS_STATE-15 "Fixed"
*MEAS_COND_AXIS_STATE-16 "Fixed"
*MEAS_COND_AXIS_STATE-17 "Fixed"
*MEAS_COND_AXIS_STATE-18 "Fixed"
*MEAS_COND_AXIS_STATE-19 "Fixed"
*MEAS_COND_AXIS_STATE-2 "Fixed"
*MEAS_COND_AXIS_STATE-20 "Fixed"
*MEAS_COND_AXIS_STATE-21 "Fixed"
*MEAS_COND_AXIS_STATE-22 "Fixed"
*MEAS_COND_AXIS_STATE-23 "Fixed"
*MEAS_COND_AXIS_STATE-24 "Fixed"
*MEAS_COND_AXIS_STATE-25 "Fixed"
*MEAS_COND_AXIS_STATE-26 "Fixed"
*MEAS_COND_AXIS_STATE-27 "Fixed"
*MEAS_COND_AXIS_STATE-28 "Fixed"
*MEAS_COND_AXIS_STATE-29 "Fixed"
*MEAS_COND_AXIS_STATE-3 "Fixed"
*MEAS_COND_AXIS_STATE-30 "Fixed"
*MEAS_COND_AXIS_STATE-31 "Fixed"
*MEAS_COND_AXIS_STATE-32 "Fixed"
*MEAS_COND_AXIS_STATE-33 "Fixed"
*MEAS_COND_AXIS_STATE-34 "Fixed"
*MEAS_COND_AXIS_STATE-35 "Fixed"
*MEAS_COND_AXIS_STATE-36 "Fixed"
*MEAS_COND_AXIS_STATE-37 "Fixed"
*MEAS_COND_AXIS_STATE-38 "Fixed"
*MEAS_COND_AXIS_STATE-39 "Fixed"
*MEAS_COND_AXIS_STATE-4 "Fixed"
*MEAS_COND_AXIS_STATE-40 "Fixed"
*MEAS_COND_AXIS_STATE-41 "Fixed"
*MEAS_COND_AXIS_STATE-42 "Fixed"
*MEAS_COND_AXIS_STATE-43 "Fixed"
*MEAS_COND_AXIS_STATE-44 "Fixed"
*MEAS_COND_AXIS_STATE-45 "Fixed"
*MEAS_COND_AXIS_STATE-46 "Fixed"
*MEAS_COND_AXIS_STATE-47 "Fixed"
*MEAS_COND_AXIS_STATE-48 "Fixed"
*MEAS_COND_AXIS_STATE-49 "Fixed"
*MEAS_COND_AXIS_STATE-5 "Scan"
*MEAS_COND_AXIS_STATE-50 "Fixed"
*MEAS_COND_AXIS_STATE-51 "Fixed"
*MEAS_COND_AXIS_STATE-52 "Fixed"
*MEAS_COND_AXIS_STATE-53 "Fixed"
*MEAS_COND_AXIS_STATE-54 "Fixed"
*MEAS_COND_AXIS_STATE-55 "Fixed"
*MEAS_COND_AXIS_STATE-56 "Fixed"
*MEAS_COND_AXIS_STATE-57 "Fixed"
*MEAS_COND_AXIS_STATE-58 "Fixed"
*MEAS_COND_AXIS_STATE-59 "Fixed"
*MEAS_COND_AXIS_STATE-6 "Fixed"
*MEAS_COND_AXIS_STATE-60 "Fixed"
*MEAS_COND_AXIS_STATE-61 "Fixed"
*MEAS_COND_AXIS_STATE-62 "Fixed"
*MEAS_COND_AXIS_STATE-63 "Fixed"
*MEAS_COND_AXIS_STATE-64 "Fixed"
*MEAS_COND_AXIS_STATE-65 "Fixed"
*MEAS_COND_AXIS_STATE-66 "Fixed"
*MEAS_COND_AXIS_STATE-67 "Fixed"
*MEAS_COND_AXIS_STATE-68 "Fixed"
*MEAS_COND_AXIS_STATE-69 "Fixed"
*MEAS_COND_AXIS_STATE-7 "Fixed"
*MEAS_COND_AXIS_STATE-70 "Fixed"
*MEAS_COND_AXIS_STATE-71 "Fixed"
*MEAS_COND_AXIS_STATE-72 "Fixed"
*MEAS_COND_AXIS_STATE-73 "Fixed"
*MEAS_COND_AXIS_STATE-74 "Fixed"
*MEAS_COND_AXIS_STATE-75 "Fixed"
*MEAS_COND_AXIS_STATE-76 "Fixed"
*MEAS_COND_AXIS_STATE-77 "Fixed"
*MEAS_COND_AXIS_STATE-78 "Fixed"
*MEAS_COND_AXIS_STATE-79 "Fixed"
*MEAS_COND_AXIS_STATE-8 "Fixed"
*MEAS_COND_AXIS_STATE-80 "Fixed"
*MEAS_COND_AXIS_STATE-81 "Fixed"
*MEAS_COND_AXIS_STATE-82 "Fixed"
*MEAS_COND_AXIS_STATE-83 "Fixed"
*MEAS_COND_AXIS_STATE-84 "Fixed"
*MEAS_COND_AXIS_STATE-85 "Fixed"
*MEAS_COND_AXIS_STATE-86 "Fixed"
*MEAS_COND_AXIS_STATE-87 "Fixed"
*MEAS_COND_AXIS_STATE-88 "Fixed"
*MEAS_COND_AXIS_STATE-89 "Fixed"
*MEAS_COND_AXIS_STATE-9 "Fixed"
*MEAS_COND_AXIS_STATE-90 "Fixed"
*MEAS_COND_AXIS_STATE-91 "Fixed"
*MEAS_COND_AXIS_STATE-92 "Fixed"
*MEAS_COND_AXIS_STATE-93 "Fixed"
*MEAS_COND_AXIS_STATE-94 "Fixed"
*MEAS_COND_AXIS_STATE-95 "Fixed"
*MEAS_COND_AXIS_STATE-96 "Fixed"
*MEAS_COND_AXIS_STATE-97 "Fixed"
*MEAS_COND_AXIS_UNIT-0 "deg"
*MEAS_COND_AXIS_UNIT-1 "deg"
*MEAS_COND_AXIS_UNIT-10 ""
*MEAS_COND_AXIS_UNIT-100 ""
*MEAS_COND_AXIS_UNIT-101 ""
*MEAS_COND_AXIS_UNIT-11 ""
*MEAS_COND_AXIS_UNIT-12 ""
*MEAS_COND_AXIS_UNIT-13 "pulse"
*MEAS_COND_AXIS_UNIT-14 ""
*MEAS_COND_AXIS_UNIT-15 ""
*MEAS_COND_AXIS_UNIT-16 ""
*MEAS_COND_AXIS_UNIT-17 "mm"
*MEAS_COND_AXIS_UNIT-18 ""
*MEAS_COND_AXIS_UNIT-19 "mm"
*MEAS_COND_AXIS_UNIT-2 "deg"
*MEAS_COND_AXIS_UNIT-20 ""
*MEAS_COND_AXIS_UNIT-21 ""
*MEAS_COND_AXIS_UNIT-22 ""
*MEAS_COND_AXIS_UNIT-23 "deg"
*MEAS_COND_AXIS_UNIT-24 "deg"
*MEAS_COND_AXIS_UNIT-25 "mm"
*MEAS_COND_AXIS_UNIT-26 "deg"
*MEAS_COND_AXIS_UNIT-27 "deg"
*MEAS_COND_AXIS_UNIT-28 "deg"
*MEAS_COND_AXIS_UNIT-29 "deg"
*MEAS_COND_AXIS_UNIT-3 "deg"
*MEAS_COND_AXIS_UNIT-30 "deg"
*MEAS_COND_AXIS_UNIT-31 "deg"
*MEAS_COND_AXIS_UNIT-32 "deg"
*MEAS_COND_AXIS_UNIT-33 "deg"
*MEAS_COND_AXIS_UNIT-34 ""
*MEAS_COND_AXIS_UNIT-35 "mm"
*MEAS_COND_AXIS_UNIT-36 ""
*MEAS_COND_AXIS_UNIT-37 ""
*MEAS_COND_AXIS_UNIT-38 ""
*MEAS_COND_AXIS_UNIT-39 ""
*MEAS_COND_AXIS_UNIT-4 "deg"
*MEAS_COND_AXIS_UNIT-40 ""
*MEAS_COND_AXIS_UNIT-41 "mm"
*MEAS_COND_AXIS_UNIT-42 ""
*MEAS_COND_AXIS_UNIT-43 "mm"
*MEAS_COND_AXIS_UNIT-44 ""
*MEAS_COND_AXIS_UNIT-45 ""
*MEAS_COND_AXIS_UNIT-46 "V"
*MEAS_COND_AXIS_UNIT-47 "mV"
*MEAS_COND_AXIS_UNIT-48 ""
*MEAS_COND_AXIS_UNIT-49 "H"
*MEAS_COND_AXIS_UNIT-5 "deg"
*MEAS_COND_AXIS_UNIT-50 "H"
*MEAS_COND_AXIS_UNIT-51 "H"
*MEAS_COND_AXIS_UNIT-52 "H"
*MEAS_COND_AXIS_UNIT-53 "H"
*MEAS_COND_AXIS_UNIT-54 "mV"
*MEAS_COND_AXIS_UNIT-55 "V"
*MEAS_COND_AXIS_UNIT-56 "V"
*MEAS_COND_AXIS_UNIT-57 "V"
*MEAS_COND_AXIS_UNIT-58 "H"
*MEAS_COND_AXIS_UNIT-59 "H"
*MEAS_COND_AXIS_UNIT-6 "deg"
*MEAS_COND_AXIS_UNIT-60 "H"
*MEAS_COND_AXIS_UNIT-61 "H"
*MEAS_COND_AXIS_UNIT-62 "H"
*MEAS_COND_AXIS_UNIT-63 "uS/m"
*MEAS_COND_AXIS_UNIT-64 "L/min"
*MEAS_COND_AXIS_UNIT-65 "C"
*MEAS_COND_AXIS_UNIT-66 "MPa"
*MEAS_COND_AXIS_UNIT-67 "MPa"
*MEAS_COND_AXIS_UNIT-68 "MPa"
*MEAS_COND_AXIS_UNIT-69 "L/min"
*MEAS_COND_AXIS_UNIT-7 "deg"
*MEAS_COND_AXIS_UNIT-70 "degree"
*MEAS_COND_AXIS_UNIT-71 "MPa"
*MEAS_COND_AXIS_UNIT-72 "degree"
*MEAS_COND_AXIS_UNIT-73 "percent"
*MEAS_COND_AXIS_UNIT-74 "degree"
*MEAS_COND_AXIS_UNIT-75 "C"
*MEAS_COND_AXIS_UNIT-76 "H"
*MEAS_COND_AXIS_UNIT-77 "time"
*MEAS_COND_AXIS_UNIT-78 "msec"
*MEAS_COND_AXIS_UNIT-79 "msec"
*MEAS_COND_AXIS_UNIT-8 ""
*MEAS_COND_AXIS_UNIT-80 "H"
*MEAS_COND_AXIS_UNIT-81 "times"
*MEAS_COND_AXIS_UNIT-82 "msec"
*MEAS_COND_AXIS_UNIT-83 "msec"
*MEAS_COND_AXIS_UNIT-84 "-"
*MEAS_COND_AXIS_UNIT-85 "-"
*MEAS_COND_AXIS_UNIT-86 "-"
*MEAS_COND_AXIS_UNIT-87 ""
*MEAS_COND_AXIS_UNIT-88 "-"
*MEAS_COND_AXIS_UNIT-89 "-"
*MEAS_COND_AXIS_UNIT-9 "mm"
*MEAS_COND_AXIS_UNIT-90 "-"
*MEAS_COND_AXIS_UNIT-91 ""
*MEAS_COND_AXIS_UNIT-92 ""
*MEAS_COND_AXIS_UNIT-93 ""
*MEAS_COND_AXIS_UNIT-94 ""
*MEAS_COND_AXIS_UNIT-95 ""
*MEAS_COND_AXIS_UNIT-96 ""
*MEAS_COND_AXIS_UNIT-97 ""
*MEAS_COND_AXIS_UNIT-98 ""
*MEAS_COND_AXIS_UNIT-99 ""
*MEAS_COND_OPT_ATTR "PB"
*MEAS_COND_OPT_NAME "User defined settings"
*MEAS_COND_XG_CURRENT "160"
*MEAS_COND_XG_VOLTAGE "45"
*MEAS_COND_XG_WAVE_TYPE "Ka"
*MEAS_DATA_COUNT "251"
*MEAS_SCAN_AXIS_X "TwoThetaOmega"
*MEAS_SCAN_AXIS_X_INTERNAL "TwoThetaOmega"
*MEAS_SCAN_END_TIME "08/05/2020 15:59:58"
*MEAS_SCAN_MODE "CONTINUOUS"
*MEAS_SCAN_MODE_INTERNAL "CONTINUOUS"
*MEAS_SCAN_RESOLUTION_X "0.0002"
*MEAS_SCAN_SPEED "1.0000"
*MEAS_SCAN_SPEED_UNIT "deg/min"
*MEAS_SCAN_START "0.0000"
*MEAS_SCAN_START_TIME "08/05/2020 15:54:08"
*MEAS_SCAN_STEP "0.0200"
*MEAS_SCAN_STOP "5.0000"
*MEAS_SCAN_UNIT_X "deg"
*MEAS_SCAN_UNIT_Y "counts"
*RAS_HEADER_END
*RAS_INT_START
0.0000 6576.0000 12284.3415
0.0200 10460.0000 12284.3415
0.0400 7698.0000 12284.3415
0.0600 3380.0000 12284.3415
0.0800 1874.0000 12284.3415
0.1000 1971.0000 12284.3415
0.1200 2507.0000 12284.3415
0.1400 2905.0000 12284.3415
0.1600 3421.0000 12284.3415
0.1800 3789.0000 12284.3415
0.2000 4218.0000 12284.3415
0.2200 4744.0000 12284.3415
0.2400 5014.0000 12284.3415
0.2600 5612.0000 12284.3415
0.2800 6028.0000 12284.3415
0.3000 6519.0000 12284.3415
0.3200 6890.0000 12284.3415
0.3400 7167.0000 12284.3415
0.3600 7561.0000 12284.3415
0.3800 8022.0000 12284.3415
0.4000 8368.0000 12284.3415
0.4200 8681.0000 12284.3415
0.4400 8989.0000 12284.3415
0.4600 9368.0000 12284.3415
0.4800 9417.0000 12284.3415
0.5000 9702.0000 12284.3415
0.5200 9936.0000 12284.3415
0.5400 9885.0000 12284.3415
0.5600 9863.0000 12284.3415
0.5800 9347.0000 12284.3415
0.6000 8459.0000 12284.3415
0.6200 7383.0000 12284.3415
0.6400 6119.0000 12284.3415
0.6600 4717.0000 12284.3415
0.6800 3405.0000 12284.3415
0.7000 2587.0000 12284.3415
0.7200 2028.0000 12284.3415
0.7400 1566.0000 12284.3415
0.7600 1298.0000 12284.3415
0.7800 15884.0000 855.8620
0.8000 13149.0000 855.8620
0.8200 10446.0000 855.8620
0.8400 8759.0000 855.8620
0.8600 7916.0000 855.8620
0.8800 7357.0000 855.8620
0.9000 6343.0000 855.8620
0.9200 5299.0000 855.8620
0.9400 4236.0000 855.8620
0.9600 3687.0000 855.8620
0.9800 3573.0000 855.8620
1.0000 3515.0000 855.8620
1.0200 3267.0000 855.8620
1.0400 2674.0000 855.8620
1.0600 2088.0000 855.8620
1.0800 1941.0000 855.8620
1.1000 1770.0000 855.8620
1.1200 1769.0000 855.8620
1.1400 1719.0000 855.8620
1.1600 1597.0000 855.8620
1.1800 1258.0000 855.8620
1.2000 15323.0000 58.6391
1.2200 13072.0000 58.6391
1.2400 12569.0000 58.6391
1.2600 12500.0000 58.6391
1.2800 12712.0000 58.6391
1.3000 11828.0000 58.6391
1.3200 9969.0000 58.6391
1.3400 7900.0000 58.6391
1.3600 6459.0000 58.6391
1.3800 6135.0000 58.6391
1.4000 6253.0000 58.6391
1.4200 6555.0000 58.6391
1.4400 6188.0000 58.6391
1.4600 5554.0000 58.6391
1.4800 4575.0000 58.6391
1.5000 3696.0000 58.6391
1.5200 3067.0000 58.6391
1.5400 2972.0000 58.6391
1.5600 3264.0000 58.6391
1.5800 3342.0000 58.6391
1.6000 3202.0000 58.6391
1.6200 2747.0000 58.6391
1.6400 2230.0000 58.6391
1.6600 1740.0000 58.6391
1.6800 1556.0000 58.6391
1.7000 1594.0000 58.6391
1.7200 1747.0000 58.6391
1.7400 1800.0000 58.6391
1.7600 1685.0000 58.6391
1.7800 1484.0000 58.6391
1.8000 65683.0000 1.0000
1.8200 51207.0000 1.0000
1.8400 45995.0000 1.0000
1.8600 48058.0000 1.0000
1.8800 54200.0000 1.0000
1.9000 57123.0000 1.0000
1.9200 55671.0000 1.0000
1.9400 47504.0000 1.0000
1.9600 37063.0000 1.0000
1.9800 28827.0000 1.0000
2.0000 25767.0000 1.0000
2.0200 27010.0000 1.0000
2.0400 31236.0000 1.0000
2.0600 34132.0000 1.0000
2.0800 33498.0000 1.0000
2.1000 29499.0000 1.0000
2.1200 23722.0000 1.0000
2.1400 18354.0000 1.0000
2.1600 16075.0000 1.0000
2.1800 16814.0000 1.0000
2.2000 19426.0000 1.0000
2.2200 22165.0000 1.0000
2.2400 22497.0000 1.0000
2.2600 20386.0000 1.0000
2.2800 16977.0000 1.0000
2.3000 13229.0000 1.0000
2.3200 11281.0000 1.0000
2.3400 11610.0000 1.0000
2.3600 13604.0000 1.0000
2.3800 15787.0000 1.0000
2.4000 16076.0000 1.0000
2.4200 15093.0000 1.0000
2.4400 12852.0000 1.0000
2.4600 10328.0000 1.0000
2.4800 8881.0000 1.0000
2.5000 8776.0000 1.0000
2.5200 9969.0000 1.0000
2.5400 11636.0000 1.0000
2.5600 12291.0000 1.0000
2.5800 11870.0000 1.0000
2.6000 10620.0000 1.0000
2.6200 8673.0000 1.0000
2.6400 7422.0000 1.0000
2.6600 6965.0000 1.0000
2.6800 7781.0000 1.0000
2.7000 8921.0000 1.0000
2.7200 9582.0000 1.0000
2.7400 9323.0000 1.0000
2.7600 8348.0000 1.0000
2.7800 7232.0000 1.0000
2.8000 6059.0000 1.0000
2.8200 5562.0000 1.0000
2.8400 6083.0000 1.0000
2.8600 6923.0000 1.0000
2.8800 7675.0000 1.0000
2.9000 7519.0000 1.0000
2.9200 6776.0000 1.0000
2.9400 5882.0000 1.0000
2.9600 5114.0000 1.0000
2.9800 4760.0000 1.0000
3.0000 4786.0000 1.0000
3.0200 5414.0000 1.0000
3.0400 5923.0000 1.0000
3.0600 6008.0000 1.0000
3.0800 5405.0000 1.0000
3.1000 4722.0000 1.0000
3.1200 4136.0000 1.0000
3.1400 3793.0000 1.0000
3.1600 3799.0000 1.0000
3.1800 4104.0000 1.0000
3.2000 4593.0000 1.0000
3.2200 4612.0000 1.0000
3.2400 4362.0000 1.0000
3.2600 3973.0000 1.0000
3.2800 3257.0000 1.0000
3.3000 2886.0000 1.0000
3.3200 3032.0000 1.0000
3.3400 3019.0000 1.0000
3.3600 3338.0000 1.0000
3.3800 3507.0000 1.0000
3.4000 3267.0000 1.0000
3.4200 2888.0000 1.0000
3.4400 2552.0000 1.0000
3.4600 2259.0000 1.0000
3.4800 2264.0000 1.0000
3.5000 2335.0000 1.0000
3.5200 2482.0000 1.0000
3.5400 2617.0000 1.0000
3.5600 2490.0000 1.0000
3.5800 2290.0000 1.0000
3.6000 1951.0000 1.0000
3.6200 1692.0000 1.0000
3.6400 1643.0000 1.0000
3.6600 1740.0000 1.0000
3.6800 1851.0000 1.0000
3.7000 1880.0000 1.0000
3.7200 1874.0000 1.0000
3.7400 1661.0000 1.0000
3.7600 1443.0000 1.0000
3.7800 1317.0000 1.0000
3.8000 1165.0000 1.0000
3.8200 1248.0000 1.0000
3.8400 1333.0000 1.0000
3.8600 1347.0000 1.0000
3.8800 1368.0000 1.0000
3.9000 1132.0000 1.0000
3.9200 1103.0000 1.0000
3.9400 920.0000 1.0000
3.9600 875.0000 1.0000
3.9800 856.0000 1.0000
4.0000 957.0000 1.0000
4.0200 1007.0000 1.0000
4.0400 1015.0000 1.0000
4.0600 885.0000 1.0000
4.0800 791.0000 1.0000
4.1000 671.0000 1.0000
4.1200 627.0000 1.0000
4.1400 607.0000 1.0000
4.1600 621.0000 1.0000
4.1800 664.0000 1.0000
4.2000 696.0000 1.0000
4.2200 625.0000 1.0000
4.2400 539.0000 1.0000
4.2600 473.0000 1.0000
4.2800 453.0000 1.0000
4.3000 442.0000 1.0000
4.3200 488.0000 1.0000
4.3400 499.0000 1.0000
4.3600 477.0000 1.0000
4.3800 446.0000 1.0000
4.4000 402.0000 1.0000
4.4200 376.0000 1.0000
4.4400 312.0000 1.0000
4.4600 319.0000 1.0000
4.4800 321.0000 1.0000
4.5000 334.0000 1.0000
4.5200 309.0000 1.0000
4.5400 321.0000 1.0000
4.5600 273.0000 1.0000
4.5800 232.0000 1.0000
4.6000 189.0000 1.0000
4.6200 214.0000 1.0000
4.6400 241.0000 1.0000
4.6600 227.0000 1.0000
4.6800 205.0000 1.0000
4.7000 233.0000 1.0000
4.7200 186.0000 1.0000
4.7400 195.0000 1.0000
4.7600 161.0000 1.0000
4.7800 157.0000 1.0000
4.8000 169.0000 1.0000
4.8200 166.0000 1.0000
4.8400 181.0000 1.0000
4.8600 162.0000 1.0000
4.8800 157.0000 1.0000
4.9000 145.0000 1.0000
4.9200 121.0000 1.0000
4.9400 127.0000 1.0000
4.9600 102.0000 1.0000
4.9800 123.0000 1.0000
5.0000 141.0000 1.0000
*RAS_INT_END
*RAS_DATA_END
*DSC_DATA_END