File: example/461_test/PLD10nmFe2O3_Al2O3/Off_Specular/2TWFINE_Al2O3_104_0002_Scan2020Oct15-122201.ras
*RAS_DATA_START
*RAS_HEADER_START
*DISP_LINE_COLOR "4286611584"
*FILE_COMMENT ""
*FILE_MD5 ""
*FILE_MEMO ""
*FILE_OPERATOR "Administrator"
*FILE_PACKAGE_NAME ""
*FILE_PART_ID ""
*FILE_SAMPLE ""
*FILE_SYSTEM_NAME "SmartLab"
*FILE_TYPE "RAS_RAW"
*FILE_USERGROUP "Administrators"
*FILE_VERSION "1"
*HW_ATTACHMENT_ID "ATT0022"
*HW_ATTACHMENT_NAME "RxRy"
*HW_ATTACHMENT_NAME_INTERNAL "RxRy"
*HW_COUNTER_ID-0 "CUT0021"
*HW_COUNTER_ID-1 "CMC0020"
*HW_COUNTER_MONOCHRO_ID "CMC0020"
*HW_COUNTER_MONOCHRO_NAME "None"
*HW_COUNTER_MONOCHRO_NAME_INTERNAL "None"
*HW_COUNTER_NAME_INTERNAL "SC70"
*HW_COUNTER_NAME-0 "SC70"
*HW_COUNTER_NAME-1 "None"
*HW_COUNTER_SELECT_NAME "SC70"
*HW_EXTERNAL_CONTROLLER_NAME "None"
*HW_EXTERNAL_CONTROLLER_NAME_INTERNAL "None"
*HW_GONIOMETER_ID "GON0022"
*HW_GONIOMETER_NAME "StandardInplaneEnc"
*HW_GONIOMETER_NAME_INTERNAL "StandardInplaneEnc"
*HW_GONIOMETER_RADIUS-0 "90.0"
*HW_GONIOMETER_RADIUS-1 "114.0"
*HW_GONIOMETER_RADIUS-2 "190.0"
*HW_GONIOMETER_RADIUS-3 "300.0"
*HW_GONIOMETER_RADIUS-4 "187.0"
*HW_GONIOMETER_RADIUS-5 "300.0"
*HW_GONIOMETER_RADIUS-6 "113.0000"
*HW_GONIOMETER_RADIUS-7 "331.0"
*HW_I_CBO_ID "CBO0021"
*HW_I_CBO_NAME "CBO"
*HW_I_CBO_NAME_INTERNAL "CBO"
*HW_I_MONOCHRO_ID "ICR0021"
*HW_I_MONOCHRO_NAME "Ge(220)x2"
*HW_I_MONOCHRO_NAME_INTERNAL "Ge(220)x2"
*HW_I_OPT_ID-0 "CBO0021"
*HW_I_OPT_ID-1 "ISL0021"
*HW_I_PRIMARY_NAME_INTERNAL "Standard"
*HW_I_SLIT_ID "ISL0021"
*HW_I_SLIT_NAME "Auto"
*HW_I_SLIT_NAME_INTERNAL "Auto"
*HW_R_ATTENUATER_AUTOMODE "1"
*HW_R_ATTENUATER_ID "ATN0021"
*HW_R_ATTENUATER_NAME "Auto"
*HW_R_ATTENUATOR_NAME_INTERNAL "Auto"
*HW_R_OPT_ID-0 "RSS0021"
*HW_R_OPT_ID-1 "RCR0022"
*HW_R_OPT_ID-2 "RSO0021"
*HW_R_OPT_ID-3 "RRS0021"
*HW_R_OPT_ID-4 "ATN0021"
*HW_R_ROD_ID "RCR0022"
*HW_R_ROD_NAME "ROD_adaptor"
*HW_R_ROD_NAME_INTERNAL "ROD_adaptor"
*HW_R_RPS_ID "RSO0021"
*HW_R_RPS_NAME "RPS_adaptor"
*HW_R_RPS_NAME_INTERNAL "RPS_adaptor"
*HW_R_RS_ID "RRS0021"
*HW_R_RS_NAME "Auto"
*HW_R_RS_NAME_INTERNAL "Auto"
*HW_R_SS_ID "RSS0021"
*HW_R_SS_NAME "Auto"
*HW_R_SS_NAME_INTERNAL "Auto"
*HW_ROBOT_NAME "No_unit"
*HW_ROBOT_NAME_INTERNAL "No_unit"
*HW_SAMPLE_CAMERA_NAME "None"
*HW_SAMPLE_CAMERA_NAME_INTERNAL "None"
*HW_SAMPLE_HOLDER_ID "SMP0021"
*HW_SAMPLE_HOLDER_NAME "Z_ChiPhi"
*HW_SAMPLE_HOLDER_NAME_INTERNAL "Z_ChiPhi"
*HW_SAMPLE_NAME "CenterSlit"
*HW_SAMPLE_NAME_INTERNAL "CenterSlit"
*HW_SAMPLE_PLATE_NAME "HeightReference"
*HW_SAMPLE_PLATE_NAME_INTERNAL "HeightReference"
*HW_SAMPLE_SPACER_NAME "None"
*HW_SAMPLE_SPACER_NAME_INTERNAL "None"
*HW_USERINFO_CATALOG_NO ""
*HW_USERINFO_INSTRUMENT_ID ""
*HW_USERINFO_INSTRUMENT_NAME ""
*HW_USERINFO_INSTRUMENT_NO ""
*HW_USERINFO_MODEL ""
*HW_USERINFO_ORDER_NO ""
*HW_USERINFO_SERIAL_NO ""
*HW_USERINFO_VERIFY_INSTRUMENT_ID "00-07-fe-01-03-ce"
*HW_VER_RCD_COUNTER_UNIT "1.0.1"
*HW_VER_RCD_CPU "3.3.7"
*HW_VER_RCD_FPGA "1.2.2"
*HW_VER_RCD_GONIO_UNIT "6.2.0"
*HW_VER_RCD_INCIDENT_UNIT "6.2.0"
*HW_VER_RCD_RECEIVING_UNIT "6.2.0"
*HW_VER_RCD_TYPE "RINC"
*HW_VER_XGC_CPU "3.3.7"
*HW_VER_XGC_CW "1.2.0"
*HW_VER_XGC_HV "1.2.0"
*HW_VER_XGC_RS1 "1.3.4"
*HW_VER_XGC_RS2 "N/A"
*HW_VER_XGC_RT "1.2.0"
*HW_VER_XGC_TYPE "RINC"
*HW_XG_CURRENT_UNIT "mA"
*HW_XG_FOCUS "0.4mm x 8mm"
*HW_XG_FOCUS_TYPE "Fine"
*HW_XG_TARGET_ATOMIC_NUMBER "29"
*HW_XG_TARGET_NAME "Cu"
*HW_XG_TYPE "ROTA"
*HW_XG_VOLTAGE_UNIT "kV"
*HW_XG_WAVE_LENGTH_ALPHA1 "1.540593"
*HW_XG_WAVE_LENGTH_ALPHA2 "1.544414"
*HW_XG_WAVE_LENGTH_BETA "1.392246"
*HW_XG_WAVE_LENGTH_UNIT "Angstrom"
*MEAS_COND_AXIS_NAME_INTERNAL-0 "ThetaS"
*MEAS_COND_AXIS_NAME_INTERNAL-1 "ThetaD"
*MEAS_COND_AXIS_NAME_INTERNAL-10 "PrimaryGeometry"
*MEAS_COND_AXIS_NAME_INTERNAL-100 "IncidentMonochromator"
*MEAS_COND_AXIS_NAME_INTERNAL-101 "ReceivingOptics"
*MEAS_COND_AXIS_NAME_INTERNAL-102 "CounterMonochromatorKind"
*MEAS_COND_AXIS_NAME_INTERNAL-11 "PrimaryMirrorType"
*MEAS_COND_AXIS_NAME_INTERNAL-12 "CBOType"
*MEAS_COND_AXIS_NAME_INTERNAL-13 "CBO-M"
*MEAS_COND_AXIS_NAME_INTERNAL-14 "CBO"
*MEAS_COND_AXIS_NAME_INTERNAL-15 "IncidentMonochromator-OmegaM"
*MEAS_COND_AXIS_NAME_INTERNAL-16 "IncidentSollerSlit"
*MEAS_COND_AXIS_NAME_INTERNAL-17 "IncidentSlitBox"
*MEAS_COND_AXIS_NAME_INTERNAL-18 "IncidentSlitBox-_Axis"
*MEAS_COND_AXIS_NAME_INTERNAL-19 "SlitDS"
*MEAS_COND_AXIS_NAME_INTERNAL-2 "TwoTheta"
*MEAS_COND_AXIS_NAME_INTERNAL-20 "Zs"
*MEAS_COND_AXIS_NAME_INTERNAL-21 "IncidentAxdSlit"
*MEAS_COND_AXIS_NAME_INTERNAL-22 "LLS"
*MEAS_COND_AXIS_NAME_INTERNAL-23 "DHLSlit"
*MEAS_COND_AXIS_NAME_INTERNAL-24 "Chi"
*MEAS_COND_AXIS_NAME_INTERNAL-25 "Phi"
*MEAS_COND_AXIS_NAME_INTERNAL-26 "Z"
*MEAS_COND_AXIS_NAME_INTERNAL-27 "Alpha"
*MEAS_COND_AXIS_NAME_INTERNAL-28 "Beta"
*MEAS_COND_AXIS_NAME_INTERNAL-29 "TwoThetaChiPhi"
*MEAS_COND_AXIS_NAME_INTERNAL-3 "Omega"
*MEAS_COND_AXIS_NAME_INTERNAL-30 "AlphaI"
*MEAS_COND_AXIS_NAME_INTERNAL-31 "BetaI"
*MEAS_COND_AXIS_NAME_INTERNAL-32 "TwoThetaB"
*MEAS_COND_AXIS_NAME_INTERNAL-33 "Rx"
*MEAS_COND_AXIS_NAME_INTERNAL-34 "Ry"
*MEAS_COND_AXIS_NAME_INTERNAL-35 "ReceivingSlitBox1"
*MEAS_COND_AXIS_NAME_INTERNAL-36 "ReceivingSlitBox1-_Axis"
*MEAS_COND_AXIS_NAME_INTERNAL-37 "SlitSS"
*MEAS_COND_AXIS_NAME_INTERNAL-38 "Filter"
*MEAS_COND_AXIS_NAME_INTERNAL-39 "PSA"
*MEAS_COND_AXIS_NAME_INTERNAL-4 "TwoThetaTheta"
*MEAS_COND_AXIS_NAME_INTERNAL-40 "ReceivingSollerSlit"
*MEAS_COND_AXIS_NAME_INTERNAL-41 "ReceivingSlitBox2"
*MEAS_COND_AXIS_NAME_INTERNAL-42 "ReceivingSlitBox2-_Axis"
*MEAS_COND_AXIS_NAME_INTERNAL-43 "SlitRS"
*MEAS_COND_AXIS_NAME_INTERNAL-44 "ReceivingSlitBox2-Zd"
*MEAS_COND_AXIS_NAME_INTERNAL-45 "Filter2"
*MEAS_COND_AXIS_NAME_INTERNAL-46 "Attenuator"
*MEAS_COND_AXIS_NAME_INTERNAL-47 "HV"
*MEAS_COND_AXIS_NAME_INTERNAL-48 "PHA"
*MEAS_COND_AXIS_NAME_INTERNAL-49 "DedicatedHolder"
*MEAS_COND_AXIS_NAME_INTERNAL-5 "TwoThetaOmega"
*MEAS_COND_AXIS_NAME_INTERNAL-50 "Target_TargetTime"
*MEAS_COND_AXIS_NAME_INTERNAL-51 "Target_XrayOnTime"
*MEAS_COND_AXIS_NAME_INTERNAL-52 "Target_TMPTime"
*MEAS_COND_AXIS_NAME_INTERNAL-53 "Target_RPTime"
*MEAS_COND_AXIS_NAME_INTERNAL-54 "Target_FilamentTime"
*MEAS_COND_AXIS_NAME_INTERNAL-55 "Target_IG"
*MEAS_COND_AXIS_NAME_INTERNAL-56 "Target_GP"
*MEAS_COND_AXIS_NAME_INTERNAL-57 "Target_FC"
*MEAS_COND_AXIS_NAME_INTERNAL-58 "HVPS_Bias"
*MEAS_COND_AXIS_NAME_INTERNAL-59 "HVPS_HVPSTime"
*MEAS_COND_AXIS_NAME_INTERNAL-6 "OmegaTwoTheta"
*MEAS_COND_AXIS_NAME_INTERNAL-60 "HVPS_Type1Time"
*MEAS_COND_AXIS_NAME_INTERNAL-61 "HVPS_Type2Time"
*MEAS_COND_AXIS_NAME_INTERNAL-62 "HVPS_Type3Time"
*MEAS_COND_AXIS_NAME_INTERNAL-63 "CW_IERTime"
*MEAS_COND_AXIS_NAME_INTERNAL-64 "CW_ECTime"
*MEAS_COND_AXIS_NAME_INTERNAL-65 "CW_Flow1"
*MEAS_COND_AXIS_NAME_INTERNAL-66 "CW_Temperature1"
*MEAS_COND_AXIS_NAME_INTERNAL-67 "CW_Pressure1"
*MEAS_COND_AXIS_NAME_INTERNAL-68 "CW_PressureIn"
*MEAS_COND_AXIS_NAME_INTERNAL-69 "CW_PressureOut"
*MEAS_COND_AXIS_NAME_INTERNAL-7 "TwoThetaChi"
*MEAS_COND_AXIS_NAME_INTERNAL-70 "CW_Flow2"
*MEAS_COND_AXIS_NAME_INTERNAL-71 "CW_Temperature2"
*MEAS_COND_AXIS_NAME_INTERNAL-72 "CW_Pressure2"
*MEAS_COND_AXIS_NAME_INTERNAL-73 "RE_EnclosureTemp"
*MEAS_COND_AXIS_NAME_INTERNAL-74 "RE_EnclosureHummidity"
*MEAS_COND_AXIS_NAME_INTERNAL-75 "RE_CabinetTemp"
*MEAS_COND_AXIS_NAME_INTERNAL-76 "RE_RPTemp"
*MEAS_COND_AXIS_NAME_INTERNAL-77 "RE_ShutterAXrayOnTime"
*MEAS_COND_AXIS_NAME_INTERNAL-78 "RE_ShutterATimes"
*MEAS_COND_AXIS_NAME_INTERNAL-79 "RE_ShutterAOpenCloseTime"
*MEAS_COND_AXIS_NAME_INTERNAL-8 "GonioDirectBeamStop"
*MEAS_COND_AXIS_NAME_INTERNAL-80 "RE_ShutterACloseOpenTime"
*MEAS_COND_AXIS_NAME_INTERNAL-81 "RE_ShutterBXrayOnTime"
*MEAS_COND_AXIS_NAME_INTERNAL-82 "RE_ShutterBTimes"
*MEAS_COND_AXIS_NAME_INTERNAL-83 "RE_ShutterBOpenCloseTime"
*MEAS_COND_AXIS_NAME_INTERNAL-84 "RE_ShutterBCloseOpenTime"
*MEAS_COND_AXIS_NAME_INTERNAL-85 "RE_XrayWarningRamp"
*MEAS_COND_AXIS_NAME_INTERNAL-86 "RE_ShutterAInstallation"
*MEAS_COND_AXIS_NAME_INTERNAL-87 "RE_ShutterARamp"
*MEAS_COND_AXIS_NAME_INTERNAL-88 "RE_ShutterBInstallation"
*MEAS_COND_AXIS_NAME_INTERNAL-89 "RE_ShutterBRamp"
*MEAS_COND_AXIS_NAME_INTERNAL-9 "Ts"
*MEAS_COND_AXIS_NAME_INTERNAL-90 "RE_ExtShutterCLS"
*MEAS_COND_AXIS_NAME_INTERNAL-91 "RE_ExtXrayOFF"
*MEAS_COND_AXIS_NAME_INTERNAL-92 "RE_ExtSafetyCircuit"
*MEAS_COND_AXIS_NAME_INTERNAL-93 "Version_CPU"
*MEAS_COND_AXIS_NAME_INTERNAL-94 "Version_RS1"
*MEAS_COND_AXIS_NAME_INTERNAL-95 "Version_RS2"
*MEAS_COND_AXIS_NAME_INTERNAL-96 "Version_HV"
*MEAS_COND_AXIS_NAME_INTERNAL-97 "Version_CW"
*MEAS_COND_AXIS_NAME_INTERNAL-98 "Version_RT"
*MEAS_COND_AXIS_NAME_INTERNAL-99 "IncidentPrimary"
*MEAS_COND_AXIS_NAME-0 "ThetaS"
*MEAS_COND_AXIS_NAME-1 "ThetaD"
*MEAS_COND_AXIS_NAME-10 "PrimaryGeometry"
*MEAS_COND_AXIS_NAME-100 "IncidentMonochromator"
*MEAS_COND_AXIS_NAME-101 "ReceivingOptics"
*MEAS_COND_AXIS_NAME-102 "CounterMonochromatorKind"
*MEAS_COND_AXIS_NAME-11 "PrimaryMirrorType"
*MEAS_COND_AXIS_NAME-12 "CBOType"
*MEAS_COND_AXIS_NAME-13 "CBO-M"
*MEAS_COND_AXIS_NAME-14 "CBO"
*MEAS_COND_AXIS_NAME-15 "IncidentMonochromator-OmegaM"
*MEAS_COND_AXIS_NAME-16 "IncidentSollerSlit"
*MEAS_COND_AXIS_NAME-17 "IncidentSlitBox"
*MEAS_COND_AXIS_NAME-18 "IncidentSlitBox-_Axis"
*MEAS_COND_AXIS_NAME-19 "SlitDS"
*MEAS_COND_AXIS_NAME-2 "TwoTheta"
*MEAS_COND_AXIS_NAME-20 "Zs"
*MEAS_COND_AXIS_NAME-21 "IncidentAxdSlit"
*MEAS_COND_AXIS_NAME-22 "LLS"
*MEAS_COND_AXIS_NAME-23 "DHLSlit"
*MEAS_COND_AXIS_NAME-24 "Chi"
*MEAS_COND_AXIS_NAME-25 "Phi"
*MEAS_COND_AXIS_NAME-26 "Z"
*MEAS_COND_AXIS_NAME-27 "Alpha"
*MEAS_COND_AXIS_NAME-28 "Beta"
*MEAS_COND_AXIS_NAME-29 "TwoThetaChiPhi"
*MEAS_COND_AXIS_NAME-3 "Omega"
*MEAS_COND_AXIS_NAME-30 "AlphaI"
*MEAS_COND_AXIS_NAME-31 "BetaI"
*MEAS_COND_AXIS_NAME-32 "TwoThetaB"
*MEAS_COND_AXIS_NAME-33 "Rx"
*MEAS_COND_AXIS_NAME-34 "Ry"
*MEAS_COND_AXIS_NAME-35 "ReceivingSlitBox1"
*MEAS_COND_AXIS_NAME-36 "ReceivingSlitBox1-_Axis"
*MEAS_COND_AXIS_NAME-37 "SlitSS"
*MEAS_COND_AXIS_NAME-38 "Filter"
*MEAS_COND_AXIS_NAME-39 "PSA"
*MEAS_COND_AXIS_NAME-4 "TwoThetaTheta"
*MEAS_COND_AXIS_NAME-40 "ReceivingSollerSlit"
*MEAS_COND_AXIS_NAME-41 "ReceivingSlitBox2"
*MEAS_COND_AXIS_NAME-42 "ReceivingSlitBox2-_Axis"
*MEAS_COND_AXIS_NAME-43 "SlitRS"
*MEAS_COND_AXIS_NAME-44 "ReceivingSlitBox2-Zd"
*MEAS_COND_AXIS_NAME-45 "Filter2"
*MEAS_COND_AXIS_NAME-46 "Attenuator"
*MEAS_COND_AXIS_NAME-47 "HV"
*MEAS_COND_AXIS_NAME-48 "PHA"
*MEAS_COND_AXIS_NAME-49 "DedicatedHolder"
*MEAS_COND_AXIS_NAME-5 "TwoThetaOmega"
*MEAS_COND_AXIS_NAME-50 "Target_TargetTime"
*MEAS_COND_AXIS_NAME-51 "Target_XrayOnTime"
*MEAS_COND_AXIS_NAME-52 "Target_TMPTime"
*MEAS_COND_AXIS_NAME-53 "Target_RPTime"
*MEAS_COND_AXIS_NAME-54 "Target_FilamentTime"
*MEAS_COND_AXIS_NAME-55 "Target_IG"
*MEAS_COND_AXIS_NAME-56 "Target_GP"
*MEAS_COND_AXIS_NAME-57 "Target_FC"
*MEAS_COND_AXIS_NAME-58 "HVPS_Bias"
*MEAS_COND_AXIS_NAME-59 "HVPS_HVPSTime"
*MEAS_COND_AXIS_NAME-6 "OmegaTwoTheta"
*MEAS_COND_AXIS_NAME-60 "HVPS_Type1Time"
*MEAS_COND_AXIS_NAME-61 "HVPS_Type2Time"
*MEAS_COND_AXIS_NAME-62 "HVPS_Type3Time"
*MEAS_COND_AXIS_NAME-63 "CW_IERTime"
*MEAS_COND_AXIS_NAME-64 "CW_ECTime"
*MEAS_COND_AXIS_NAME-65 "CW_Flow1"
*MEAS_COND_AXIS_NAME-66 "CW_Temperature1"
*MEAS_COND_AXIS_NAME-67 "CW_Pressure1"
*MEAS_COND_AXIS_NAME-68 "CW_PressureIn"
*MEAS_COND_AXIS_NAME-69 "CW_PressureOut"
*MEAS_COND_AXIS_NAME-7 "TwoThetaChi"
*MEAS_COND_AXIS_NAME-70 "CW_Flow2"
*MEAS_COND_AXIS_NAME-71 "CW_Temperature2"
*MEAS_COND_AXIS_NAME-72 "CW_Pressure2"
*MEAS_COND_AXIS_NAME-73 "RE_EnclosureTemp"
*MEAS_COND_AXIS_NAME-74 "RE_EnclosureHummidity"
*MEAS_COND_AXIS_NAME-75 "RE_CabinetTemp"
*MEAS_COND_AXIS_NAME-76 "RE_RPTemp"
*MEAS_COND_AXIS_NAME-77 "RE_ShutterAXrayOnTime"
*MEAS_COND_AXIS_NAME-78 "RE_ShutterATimes"
*MEAS_COND_AXIS_NAME-79 "RE_ShutterAOpenCloseTime"
*MEAS_COND_AXIS_NAME-8 "GonioDirectBeamStop"
*MEAS_COND_AXIS_NAME-80 "RE_ShutterACloseOpenTime"
*MEAS_COND_AXIS_NAME-81 "RE_ShutterBXrayOnTime"
*MEAS_COND_AXIS_NAME-82 "RE_ShutterBTimes"
*MEAS_COND_AXIS_NAME-83 "RE_ShutterBOpenCloseTime"
*MEAS_COND_AXIS_NAME-84 "RE_ShutterBCloseOpenTime"
*MEAS_COND_AXIS_NAME-85 "RE_XrayWarningRamp"
*MEAS_COND_AXIS_NAME-86 "RE_ShutterAInstallation"
*MEAS_COND_AXIS_NAME-87 "RE_ShutterARamp"
*MEAS_COND_AXIS_NAME-88 "RE_ShutterBInstallation"
*MEAS_COND_AXIS_NAME-89 "RE_ShutterBRamp"
*MEAS_COND_AXIS_NAME-9 "Ts"
*MEAS_COND_AXIS_NAME-90 "RE_ExtShutterCLS"
*MEAS_COND_AXIS_NAME-91 "RE_ExtXrayOFF"
*MEAS_COND_AXIS_NAME-92 "RE_ExtSafetyCircuit"
*MEAS_COND_AXIS_NAME-93 "Version_CPU"
*MEAS_COND_AXIS_NAME-94 "Version_RS1"
*MEAS_COND_AXIS_NAME-95 "Version_RS2"
*MEAS_COND_AXIS_NAME-96 "Version_HV"
*MEAS_COND_AXIS_NAME-97 "Version_CW"
*MEAS_COND_AXIS_NAME-98 "Version_RT"
*MEAS_COND_AXIS_NAME-99 "IncidentPrimary"
*MEAS_COND_AXIS_OFFSET-0 "1.0906"
*MEAS_COND_AXIS_OFFSET-1 "0.1456"
*MEAS_COND_AXIS_OFFSET-10 "0"
*MEAS_COND_AXIS_OFFSET-100 "0"
*MEAS_COND_AXIS_OFFSET-101 "0"
*MEAS_COND_AXIS_OFFSET-102 "0"
*MEAS_COND_AXIS_OFFSET-11 "0"
*MEAS_COND_AXIS_OFFSET-12 "0"
*MEAS_COND_AXIS_OFFSET-13 "0"
*MEAS_COND_AXIS_OFFSET-14 "0"
*MEAS_COND_AXIS_OFFSET-15 "0"
*MEAS_COND_AXIS_OFFSET-16 "0"
*MEAS_COND_AXIS_OFFSET-17 "0"
*MEAS_COND_AXIS_OFFSET-18 "0"
*MEAS_COND_AXIS_OFFSET-19 "0"
*MEAS_COND_AXIS_OFFSET-2 "1.2362"
*MEAS_COND_AXIS_OFFSET-20 "0"
*MEAS_COND_AXIS_OFFSET-21 "0"
*MEAS_COND_AXIS_OFFSET-22 "0"
*MEAS_COND_AXIS_OFFSET-23 "0"
*MEAS_COND_AXIS_OFFSET-24 "0"
*MEAS_COND_AXIS_OFFSET-25 "0"
*MEAS_COND_AXIS_OFFSET-26 "0"
*MEAS_COND_AXIS_OFFSET-27 "0"
*MEAS_COND_AXIS_OFFSET-28 "0"
*MEAS_COND_AXIS_OFFSET-29 "0"
*MEAS_COND_AXIS_OFFSET-3 "1.0906"
*MEAS_COND_AXIS_OFFSET-30 "0"
*MEAS_COND_AXIS_OFFSET-31 "0"
*MEAS_COND_AXIS_OFFSET-32 "0"
*MEAS_COND_AXIS_OFFSET-33 "0"
*MEAS_COND_AXIS_OFFSET-34 "0"
*MEAS_COND_AXIS_OFFSET-35 "0"
*MEAS_COND_AXIS_OFFSET-36 "0"
*MEAS_COND_AXIS_OFFSET-37 "0"
*MEAS_COND_AXIS_OFFSET-38 "0"
*MEAS_COND_AXIS_OFFSET-39 "0"
*MEAS_COND_AXIS_OFFSET-4 "0"
*MEAS_COND_AXIS_OFFSET-40 "0"
*MEAS_COND_AXIS_OFFSET-41 "0"
*MEAS_COND_AXIS_OFFSET-42 "0"
*MEAS_COND_AXIS_OFFSET-43 "0"
*MEAS_COND_AXIS_OFFSET-44 "0"
*MEAS_COND_AXIS_OFFSET-45 "0"
*MEAS_COND_AXIS_OFFSET-46 "0"
*MEAS_COND_AXIS_OFFSET-47 "0"
*MEAS_COND_AXIS_OFFSET-48 "0"
*MEAS_COND_AXIS_OFFSET-49 "0"
*MEAS_COND_AXIS_OFFSET-5 "0"
*MEAS_COND_AXIS_OFFSET-50 "0"
*MEAS_COND_AXIS_OFFSET-51 "0"
*MEAS_COND_AXIS_OFFSET-52 "0"
*MEAS_COND_AXIS_OFFSET-53 "0"
*MEAS_COND_AXIS_OFFSET-54 "0"
*MEAS_COND_AXIS_OFFSET-55 "0"
*MEAS_COND_AXIS_OFFSET-56 "0"
*MEAS_COND_AXIS_OFFSET-57 "0"
*MEAS_COND_AXIS_OFFSET-58 "0"
*MEAS_COND_AXIS_OFFSET-59 "0"
*MEAS_COND_AXIS_OFFSET-6 "0"
*MEAS_COND_AXIS_OFFSET-60 "0"
*MEAS_COND_AXIS_OFFSET-61 "0"
*MEAS_COND_AXIS_OFFSET-62 "0"
*MEAS_COND_AXIS_OFFSET-63 "0"
*MEAS_COND_AXIS_OFFSET-64 "0"
*MEAS_COND_AXIS_OFFSET-65 "0"
*MEAS_COND_AXIS_OFFSET-66 "0"
*MEAS_COND_AXIS_OFFSET-67 "0"
*MEAS_COND_AXIS_OFFSET-68 "0"
*MEAS_COND_AXIS_OFFSET-69 "0"
*MEAS_COND_AXIS_OFFSET-7 "0"
*MEAS_COND_AXIS_OFFSET-70 "0"
*MEAS_COND_AXIS_OFFSET-71 "0"
*MEAS_COND_AXIS_OFFSET-72 "0"
*MEAS_COND_AXIS_OFFSET-73 "0"
*MEAS_COND_AXIS_OFFSET-74 "0"
*MEAS_COND_AXIS_OFFSET-75 "0"
*MEAS_COND_AXIS_OFFSET-76 "0"
*MEAS_COND_AXIS_OFFSET-77 "0"
*MEAS_COND_AXIS_OFFSET-78 "0"
*MEAS_COND_AXIS_OFFSET-79 "0"
*MEAS_COND_AXIS_OFFSET-8 "0"
*MEAS_COND_AXIS_OFFSET-80 "0"
*MEAS_COND_AXIS_OFFSET-81 "0"
*MEAS_COND_AXIS_OFFSET-82 "0"
*MEAS_COND_AXIS_OFFSET-83 "0"
*MEAS_COND_AXIS_OFFSET-84 "0"
*MEAS_COND_AXIS_OFFSET-85 "0"
*MEAS_COND_AXIS_OFFSET-86 "0"
*MEAS_COND_AXIS_OFFSET-87 "0"
*MEAS_COND_AXIS_OFFSET-88 "0"
*MEAS_COND_AXIS_OFFSET-89 "0"
*MEAS_COND_AXIS_OFFSET-9 "0"
*MEAS_COND_AXIS_OFFSET-90 "0"
*MEAS_COND_AXIS_OFFSET-91 "0"
*MEAS_COND_AXIS_OFFSET-92 "0"
*MEAS_COND_AXIS_OFFSET-93 "0"
*MEAS_COND_AXIS_OFFSET-94 "0"
*MEAS_COND_AXIS_OFFSET-95 "0"
*MEAS_COND_AXIS_OFFSET-96 "0"
*MEAS_COND_AXIS_OFFSET-97 "0"
*MEAS_COND_AXIS_OFFSET-98 "0"
*MEAS_COND_AXIS_OFFSET-99 "0"
*MEAS_COND_AXIS_POSITION-0 "17.6245"
*MEAS_COND_AXIS_POSITION-1 "17.5277"
*MEAS_COND_AXIS_POSITION-10 "Right"
*MEAS_COND_AXIS_POSITION-100 "Ge(220)x2"
*MEAS_COND_AXIS_POSITION-101 "PSA_open"
*MEAS_COND_AXIS_POSITION-102 "None"
*MEAS_COND_AXIS_POSITION-11 "None"
*MEAS_COND_AXIS_POSITION-12 "Type1"
*MEAS_COND_AXIS_POSITION-13 "0"
*MEAS_COND_AXIS_POSITION-14 "PB"
*MEAS_COND_AXIS_POSITION-15 "0"
*MEAS_COND_AXIS_POSITION-16 "Soller_slit_open_s"
*MEAS_COND_AXIS_POSITION-17 "0.500mm"
*MEAS_COND_AXIS_POSITION-18 "0.500000"
*MEAS_COND_AXIS_POSITION-19 "0.500mm"
*MEAS_COND_AXIS_POSITION-2 "35.1522"
*MEAS_COND_AXIS_POSITION-20 "-1.9903125"
*MEAS_COND_AXIS_POSITION-21 "2mm"
*MEAS_COND_AXIS_POSITION-22 "2mm"
*MEAS_COND_AXIS_POSITION-23 "2mm"
*MEAS_COND_AXIS_POSITION-24 "38.200"
*MEAS_COND_AXIS_POSITION-25 "73.838"
*MEAS_COND_AXIS_POSITION-26 "-0.9396"
*MEAS_COND_AXIS_POSITION-27 "51.800"
*MEAS_COND_AXIS_POSITION-28 "73.838"
*MEAS_COND_AXIS_POSITION-29 "-0.204"
*MEAS_COND_AXIS_POSITION-3 "17.6245"
*MEAS_COND_AXIS_POSITION-30 "89.66"
*MEAS_COND_AXIS_POSITION-31 "-8.000"
*MEAS_COND_AXIS_POSITION-32 "35.1527"
*MEAS_COND_AXIS_POSITION-33 "0.12969"
*MEAS_COND_AXIS_POSITION-34 "-0.10720"
*MEAS_COND_AXIS_POSITION-35 "0.700mm"
*MEAS_COND_AXIS_POSITION-36 "0.700000"
*MEAS_COND_AXIS_POSITION-37 "0.700mm"
*MEAS_COND_AXIS_POSITION-38 "None"
*MEAS_COND_AXIS_POSITION-39 "PSA_open"
*MEAS_COND_AXIS_POSITION-4 "35.1522"
*MEAS_COND_AXIS_POSITION-40 "Soller_slit_5.0deg"
*MEAS_COND_AXIS_POSITION-41 "0.700mm"
*MEAS_COND_AXIS_POSITION-42 "0.700000"
*MEAS_COND_AXIS_POSITION-43 "0.700mm"
*MEAS_COND_AXIS_POSITION-44 "-0.5296875"
*MEAS_COND_AXIS_POSITION-45 "None"
*MEAS_COND_AXIS_POSITION-46 "Open"
*MEAS_COND_AXIS_POSITION-47 "647.0"
*MEAS_COND_AXIS_POSITION-48 "545.00"
*MEAS_COND_AXIS_POSITION-49 "None"
*MEAS_COND_AXIS_POSITION-5 "35.1522"
*MEAS_COND_AXIS_POSITION-50 ""
*MEAS_COND_AXIS_POSITION-51 ""
*MEAS_COND_AXIS_POSITION-52 ""
*MEAS_COND_AXIS_POSITION-53 ""
*MEAS_COND_AXIS_POSITION-54 ""
*MEAS_COND_AXIS_POSITION-55 ""
*MEAS_COND_AXIS_POSITION-56 ""
*MEAS_COND_AXIS_POSITION-57 ""
*MEAS_COND_AXIS_POSITION-58 ""
*MEAS_COND_AXIS_POSITION-59 ""
*MEAS_COND_AXIS_POSITION-6 "17.6245"
*MEAS_COND_AXIS_POSITION-60 ""
*MEAS_COND_AXIS_POSITION-61 ""
*MEAS_COND_AXIS_POSITION-62 ""
*MEAS_COND_AXIS_POSITION-63 ""
*MEAS_COND_AXIS_POSITION-64 ""
*MEAS_COND_AXIS_POSITION-65 ""
*MEAS_COND_AXIS_POSITION-66 ""
*MEAS_COND_AXIS_POSITION-67 ""
*MEAS_COND_AXIS_POSITION-68 ""
*MEAS_COND_AXIS_POSITION-69 ""
*MEAS_COND_AXIS_POSITION-7 "-0.2055"
*MEAS_COND_AXIS_POSITION-70 ""
*MEAS_COND_AXIS_POSITION-71 ""
*MEAS_COND_AXIS_POSITION-72 ""
*MEAS_COND_AXIS_POSITION-73 ""
*MEAS_COND_AXIS_POSITION-74 ""
*MEAS_COND_AXIS_POSITION-75 ""
*MEAS_COND_AXIS_POSITION-76 ""
*MEAS_COND_AXIS_POSITION-77 ""
*MEAS_COND_AXIS_POSITION-78 ""
*MEAS_COND_AXIS_POSITION-79 ""
*MEAS_COND_AXIS_POSITION-8 "None"
*MEAS_COND_AXIS_POSITION-80 ""
*MEAS_COND_AXIS_POSITION-81 ""
*MEAS_COND_AXIS_POSITION-82 ""
*MEAS_COND_AXIS_POSITION-83 ""
*MEAS_COND_AXIS_POSITION-84 ""
*MEAS_COND_AXIS_POSITION-85 ""
*MEAS_COND_AXIS_POSITION-86 ""
*MEAS_COND_AXIS_POSITION-87 ""
*MEAS_COND_AXIS_POSITION-88 ""
*MEAS_COND_AXIS_POSITION-89 ""
*MEAS_COND_AXIS_POSITION-9 "-5.4546875"
*MEAS_COND_AXIS_POSITION-90 ""
*MEAS_COND_AXIS_POSITION-91 ""
*MEAS_COND_AXIS_POSITION-92 ""
*MEAS_COND_AXIS_POSITION-93 ""
*MEAS_COND_AXIS_POSITION-94 ""
*MEAS_COND_AXIS_POSITION-95 ""
*MEAS_COND_AXIS_POSITION-96 ""
*MEAS_COND_AXIS_POSITION-97 ""
*MEAS_COND_AXIS_POSITION-98 ""
*MEAS_COND_AXIS_POSITION-99 "Standard"
*MEAS_COND_AXIS_RESOLUTION-0 "0.0001"
*MEAS_COND_AXIS_RESOLUTION-1 "0.0001"
*MEAS_COND_AXIS_RESOLUTION-10 ""
*MEAS_COND_AXIS_RESOLUTION-11 ""
*MEAS_COND_AXIS_RESOLUTION-12 ""
*MEAS_COND_AXIS_RESOLUTION-13 "1"
*MEAS_COND_AXIS_RESOLUTION-14 ""
*MEAS_COND_AXIS_RESOLUTION-15 "1"
*MEAS_COND_AXIS_RESOLUTION-16 ""
*MEAS_COND_AXIS_RESOLUTION-17 "1/1600"
*MEAS_COND_AXIS_RESOLUTION-18 "1/1600"
*MEAS_COND_AXIS_RESOLUTION-19 "1/1600"
*MEAS_COND_AXIS_RESOLUTION-2 "0.0001"
*MEAS_COND_AXIS_RESOLUTION-20 "0.0003125"
*MEAS_COND_AXIS_RESOLUTION-21 ""
*MEAS_COND_AXIS_RESOLUTION-22 ""
*MEAS_COND_AXIS_RESOLUTION-23 ""
*MEAS_COND_AXIS_RESOLUTION-24 "0.001"
*MEAS_COND_AXIS_RESOLUTION-25 "0.002"
*MEAS_COND_AXIS_RESOLUTION-26 "0.0001"
*MEAS_COND_AXIS_RESOLUTION-27 "0.001"
*MEAS_COND_AXIS_RESOLUTION-28 "0.002"
*MEAS_COND_AXIS_RESOLUTION-29 "0.004"
*MEAS_COND_AXIS_RESOLUTION-3 "0.0001"
*MEAS_COND_AXIS_RESOLUTION-30 "0.01"
*MEAS_COND_AXIS_RESOLUTION-31 "0.002"
*MEAS_COND_AXIS_RESOLUTION-32 "0.0001"
*MEAS_COND_AXIS_RESOLUTION-33 "0.00099"
*MEAS_COND_AXIS_RESOLUTION-34 "0.00134"
*MEAS_COND_AXIS_RESOLUTION-35 "1/1600"
*MEAS_COND_AXIS_RESOLUTION-36 "1/1600"
*MEAS_COND_AXIS_RESOLUTION-37 "1/1600"
*MEAS_COND_AXIS_RESOLUTION-38 ""
*MEAS_COND_AXIS_RESOLUTION-39 ""
*MEAS_COND_AXIS_RESOLUTION-4 "0.0002"
*MEAS_COND_AXIS_RESOLUTION-40 ""
*MEAS_COND_AXIS_RESOLUTION-41 "1/1600"
*MEAS_COND_AXIS_RESOLUTION-42 "1/1600"
*MEAS_COND_AXIS_RESOLUTION-43 "1/1600"
*MEAS_COND_AXIS_RESOLUTION-44 "0.0003125"
*MEAS_COND_AXIS_RESOLUTION-45 ""
*MEAS_COND_AXIS_RESOLUTION-46 "1/800"
*MEAS_COND_AXIS_RESOLUTION-47 "0.5"
*MEAS_COND_AXIS_RESOLUTION-48 "1.25"
*MEAS_COND_AXIS_RESOLUTION-49 ""
*MEAS_COND_AXIS_RESOLUTION-5 "0.0002"
*MEAS_COND_AXIS_RESOLUTION-50 "0.010000"
*MEAS_COND_AXIS_RESOLUTION-51 "0.010000"
*MEAS_COND_AXIS_RESOLUTION-52 "0.01"
*MEAS_COND_AXIS_RESOLUTION-53 "0.010000"
*MEAS_COND_AXIS_RESOLUTION-54 "0.01"
*MEAS_COND_AXIS_RESOLUTION-55 "1.000000"
*MEAS_COND_AXIS_RESOLUTION-56 "1.000000"
*MEAS_COND_AXIS_RESOLUTION-57 "1"
*MEAS_COND_AXIS_RESOLUTION-58 "1"
*MEAS_COND_AXIS_RESOLUTION-59 "0.01"
*MEAS_COND_AXIS_RESOLUTION-6 "0.0001"
*MEAS_COND_AXIS_RESOLUTION-60 "0.01"
*MEAS_COND_AXIS_RESOLUTION-61 "0.01"
*MEAS_COND_AXIS_RESOLUTION-62 "0.01"
*MEAS_COND_AXIS_RESOLUTION-63 "0.010000"
*MEAS_COND_AXIS_RESOLUTION-64 "1"
*MEAS_COND_AXIS_RESOLUTION-65 "0.1"
*MEAS_COND_AXIS_RESOLUTION-66 "1"
*MEAS_COND_AXIS_RESOLUTION-67 "0.010000"
*MEAS_COND_AXIS_RESOLUTION-68 "0.01"
*MEAS_COND_AXIS_RESOLUTION-69 "0.01"
*MEAS_COND_AXIS_RESOLUTION-7 "0.0005"
*MEAS_COND_AXIS_RESOLUTION-70 "0.100000"
*MEAS_COND_AXIS_RESOLUTION-71 "1.000000"
*MEAS_COND_AXIS_RESOLUTION-72 "0.01"
*MEAS_COND_AXIS_RESOLUTION-73 "1.000000"
*MEAS_COND_AXIS_RESOLUTION-74 "1"
*MEAS_COND_AXIS_RESOLUTION-75 "1.000000"
*MEAS_COND_AXIS_RESOLUTION-76 "1"
*MEAS_COND_AXIS_RESOLUTION-77 "0.01"
*MEAS_COND_AXIS_RESOLUTION-78 "1"
*MEAS_COND_AXIS_RESOLUTION-79 "1"
*MEAS_COND_AXIS_RESOLUTION-8 ""
*MEAS_COND_AXIS_RESOLUTION-80 "1"
*MEAS_COND_AXIS_RESOLUTION-81 "0.01"
*MEAS_COND_AXIS_RESOLUTION-82 "1.000000"
*MEAS_COND_AXIS_RESOLUTION-83 "1.000000"
*MEAS_COND_AXIS_RESOLUTION-84 "1.000000"
*MEAS_COND_AXIS_RESOLUTION-85 "-"
*MEAS_COND_AXIS_RESOLUTION-86 "-"
*MEAS_COND_AXIS_RESOLUTION-87 "-"
*MEAS_COND_AXIS_RESOLUTION-88 "1.000000"
*MEAS_COND_AXIS_RESOLUTION-89 "-"
*MEAS_COND_AXIS_RESOLUTION-9 "0.0000625"
*MEAS_COND_AXIS_RESOLUTION-90 "-"
*MEAS_COND_AXIS_RESOLUTION-91 "-"
*MEAS_COND_AXIS_RESOLUTION-92 "1.000000"
*MEAS_COND_AXIS_RESOLUTION-93 "1.000000"
*MEAS_COND_AXIS_RESOLUTION-94 "1.000000"
*MEAS_COND_AXIS_RESOLUTION-95 "1.000000"
*MEAS_COND_AXIS_RESOLUTION-96 "1.000000"
*MEAS_COND_AXIS_RESOLUTION-97 "1.000000"
*MEAS_COND_AXIS_RESOLUTION-98 "1.000000"
*MEAS_COND_AXIS_STATE-0 "Fixed"
*MEAS_COND_AXIS_STATE-1 "Fixed"
*MEAS_COND_AXIS_STATE-10 "Fixed"
*MEAS_COND_AXIS_STATE-11 "Fixed"
*MEAS_COND_AXIS_STATE-12 "Fixed"
*MEAS_COND_AXIS_STATE-13 "Fixed"
*MEAS_COND_AXIS_STATE-14 "Fixed"
*MEAS_COND_AXIS_STATE-15 "Fixed"
*MEAS_COND_AXIS_STATE-16 "Fixed"
*MEAS_COND_AXIS_STATE-17 "Fixed"
*MEAS_COND_AXIS_STATE-18 "Fixed"
*MEAS_COND_AXIS_STATE-19 "Fixed"
*MEAS_COND_AXIS_STATE-2 "Fixed"
*MEAS_COND_AXIS_STATE-20 "Fixed"
*MEAS_COND_AXIS_STATE-21 "Fixed"
*MEAS_COND_AXIS_STATE-22 "Fixed"
*MEAS_COND_AXIS_STATE-23 "Fixed"
*MEAS_COND_AXIS_STATE-24 "Fixed"
*MEAS_COND_AXIS_STATE-25 "Fixed"
*MEAS_COND_AXIS_STATE-26 "Fixed"
*MEAS_COND_AXIS_STATE-27 "Fixed"
*MEAS_COND_AXIS_STATE-28 "Fixed"
*MEAS_COND_AXIS_STATE-29 "Fixed"
*MEAS_COND_AXIS_STATE-3 "Fixed"
*MEAS_COND_AXIS_STATE-30 "Fixed"
*MEAS_COND_AXIS_STATE-31 "Fixed"
*MEAS_COND_AXIS_STATE-32 "Fixed"
*MEAS_COND_AXIS_STATE-33 "Fixed"
*MEAS_COND_AXIS_STATE-34 "Fixed"
*MEAS_COND_AXIS_STATE-35 "Fixed"
*MEAS_COND_AXIS_STATE-36 "Fixed"
*MEAS_COND_AXIS_STATE-37 "Fixed"
*MEAS_COND_AXIS_STATE-38 "Fixed"
*MEAS_COND_AXIS_STATE-39 "Fixed"
*MEAS_COND_AXIS_STATE-4 "Fixed"
*MEAS_COND_AXIS_STATE-40 "Fixed"
*MEAS_COND_AXIS_STATE-41 "Fixed"
*MEAS_COND_AXIS_STATE-42 "Fixed"
*MEAS_COND_AXIS_STATE-43 "Fixed"
*MEAS_COND_AXIS_STATE-44 "Fixed"
*MEAS_COND_AXIS_STATE-45 "Fixed"
*MEAS_COND_AXIS_STATE-46 "Fixed"
*MEAS_COND_AXIS_STATE-47 "Fixed"
*MEAS_COND_AXIS_STATE-48 "Fixed"
*MEAS_COND_AXIS_STATE-49 "Fixed"
*MEAS_COND_AXIS_STATE-5 "Scan"
*MEAS_COND_AXIS_STATE-50 "Fixed"
*MEAS_COND_AXIS_STATE-51 "Fixed"
*MEAS_COND_AXIS_STATE-52 "Fixed"
*MEAS_COND_AXIS_STATE-53 "Fixed"
*MEAS_COND_AXIS_STATE-54 "Fixed"
*MEAS_COND_AXIS_STATE-55 "Fixed"
*MEAS_COND_AXIS_STATE-56 "Fixed"
*MEAS_COND_AXIS_STATE-57 "Fixed"
*MEAS_COND_AXIS_STATE-58 "Fixed"
*MEAS_COND_AXIS_STATE-59 "Fixed"
*MEAS_COND_AXIS_STATE-6 "Fixed"
*MEAS_COND_AXIS_STATE-60 "Fixed"
*MEAS_COND_AXIS_STATE-61 "Fixed"
*MEAS_COND_AXIS_STATE-62 "Fixed"
*MEAS_COND_AXIS_STATE-63 "Fixed"
*MEAS_COND_AXIS_STATE-64 "Fixed"
*MEAS_COND_AXIS_STATE-65 "Fixed"
*MEAS_COND_AXIS_STATE-66 "Fixed"
*MEAS_COND_AXIS_STATE-67 "Fixed"
*MEAS_COND_AXIS_STATE-68 "Fixed"
*MEAS_COND_AXIS_STATE-69 "Fixed"
*MEAS_COND_AXIS_STATE-7 "Fixed"
*MEAS_COND_AXIS_STATE-70 "Fixed"
*MEAS_COND_AXIS_STATE-71 "Fixed"
*MEAS_COND_AXIS_STATE-72 "Fixed"
*MEAS_COND_AXIS_STATE-73 "Fixed"
*MEAS_COND_AXIS_STATE-74 "Fixed"
*MEAS_COND_AXIS_STATE-75 "Fixed"
*MEAS_COND_AXIS_STATE-76 "Fixed"
*MEAS_COND_AXIS_STATE-77 "Fixed"
*MEAS_COND_AXIS_STATE-78 "Fixed"
*MEAS_COND_AXIS_STATE-79 "Fixed"
*MEAS_COND_AXIS_STATE-8 "Fixed"
*MEAS_COND_AXIS_STATE-80 "Fixed"
*MEAS_COND_AXIS_STATE-81 "Fixed"
*MEAS_COND_AXIS_STATE-82 "Fixed"
*MEAS_COND_AXIS_STATE-83 "Fixed"
*MEAS_COND_AXIS_STATE-84 "Fixed"
*MEAS_COND_AXIS_STATE-85 "Fixed"
*MEAS_COND_AXIS_STATE-86 "Fixed"
*MEAS_COND_AXIS_STATE-87 "Fixed"
*MEAS_COND_AXIS_STATE-88 "Fixed"
*MEAS_COND_AXIS_STATE-89 "Fixed"
*MEAS_COND_AXIS_STATE-9 "Fixed"
*MEAS_COND_AXIS_STATE-90 "Fixed"
*MEAS_COND_AXIS_STATE-91 "Fixed"
*MEAS_COND_AXIS_STATE-92 "Fixed"
*MEAS_COND_AXIS_STATE-93 "Fixed"
*MEAS_COND_AXIS_STATE-94 "Fixed"
*MEAS_COND_AXIS_STATE-95 "Fixed"
*MEAS_COND_AXIS_STATE-96 "Fixed"
*MEAS_COND_AXIS_STATE-97 "Fixed"
*MEAS_COND_AXIS_STATE-98 "Fixed"
*MEAS_COND_AXIS_UNIT-0 "deg"
*MEAS_COND_AXIS_UNIT-1 "deg"
*MEAS_COND_AXIS_UNIT-10 ""
*MEAS_COND_AXIS_UNIT-100 ""
*MEAS_COND_AXIS_UNIT-101 ""
*MEAS_COND_AXIS_UNIT-102 ""
*MEAS_COND_AXIS_UNIT-11 ""
*MEAS_COND_AXIS_UNIT-12 ""
*MEAS_COND_AXIS_UNIT-13 "pulse"
*MEAS_COND_AXIS_UNIT-14 ""
*MEAS_COND_AXIS_UNIT-15 "pulse"
*MEAS_COND_AXIS_UNIT-16 ""
*MEAS_COND_AXIS_UNIT-17 ""
*MEAS_COND_AXIS_UNIT-18 "mm"
*MEAS_COND_AXIS_UNIT-19 ""
*MEAS_COND_AXIS_UNIT-2 "deg"
*MEAS_COND_AXIS_UNIT-20 "mm"
*MEAS_COND_AXIS_UNIT-21 ""
*MEAS_COND_AXIS_UNIT-22 ""
*MEAS_COND_AXIS_UNIT-23 ""
*MEAS_COND_AXIS_UNIT-24 "deg"
*MEAS_COND_AXIS_UNIT-25 "deg"
*MEAS_COND_AXIS_UNIT-26 "mm"
*MEAS_COND_AXIS_UNIT-27 "deg"
*MEAS_COND_AXIS_UNIT-28 "deg"
*MEAS_COND_AXIS_UNIT-29 "deg"
*MEAS_COND_AXIS_UNIT-3 "deg"
*MEAS_COND_AXIS_UNIT-30 "deg"
*MEAS_COND_AXIS_UNIT-31 "deg"
*MEAS_COND_AXIS_UNIT-32 "deg"
*MEAS_COND_AXIS_UNIT-33 "deg"
*MEAS_COND_AXIS_UNIT-34 "deg"
*MEAS_COND_AXIS_UNIT-35 ""
*MEAS_COND_AXIS_UNIT-36 "mm"
*MEAS_COND_AXIS_UNIT-37 ""
*MEAS_COND_AXIS_UNIT-38 ""
*MEAS_COND_AXIS_UNIT-39 ""
*MEAS_COND_AXIS_UNIT-4 "deg"
*MEAS_COND_AXIS_UNIT-40 ""
*MEAS_COND_AXIS_UNIT-41 ""
*MEAS_COND_AXIS_UNIT-42 "mm"
*MEAS_COND_AXIS_UNIT-43 ""
*MEAS_COND_AXIS_UNIT-44 "mm"
*MEAS_COND_AXIS_UNIT-45 ""
*MEAS_COND_AXIS_UNIT-46 ""
*MEAS_COND_AXIS_UNIT-47 "V"
*MEAS_COND_AXIS_UNIT-48 "mV"
*MEAS_COND_AXIS_UNIT-49 ""
*MEAS_COND_AXIS_UNIT-5 "deg"
*MEAS_COND_AXIS_UNIT-50 "H"
*MEAS_COND_AXIS_UNIT-51 "H"
*MEAS_COND_AXIS_UNIT-52 "H"
*MEAS_COND_AXIS_UNIT-53 "H"
*MEAS_COND_AXIS_UNIT-54 "H"
*MEAS_COND_AXIS_UNIT-55 "mV"
*MEAS_COND_AXIS_UNIT-56 "V"
*MEAS_COND_AXIS_UNIT-57 "V"
*MEAS_COND_AXIS_UNIT-58 "V"
*MEAS_COND_AXIS_UNIT-59 "H"
*MEAS_COND_AXIS_UNIT-6 "deg"
*MEAS_COND_AXIS_UNIT-60 "H"
*MEAS_COND_AXIS_UNIT-61 "H"
*MEAS_COND_AXIS_UNIT-62 "H"
*MEAS_COND_AXIS_UNIT-63 "H"
*MEAS_COND_AXIS_UNIT-64 "uS/m"
*MEAS_COND_AXIS_UNIT-65 "L/min"
*MEAS_COND_AXIS_UNIT-66 "C"
*MEAS_COND_AXIS_UNIT-67 "MPa"
*MEAS_COND_AXIS_UNIT-68 "MPa"
*MEAS_COND_AXIS_UNIT-69 "MPa"
*MEAS_COND_AXIS_UNIT-7 "deg"
*MEAS_COND_AXIS_UNIT-70 "L/min"
*MEAS_COND_AXIS_UNIT-71 "degree"
*MEAS_COND_AXIS_UNIT-72 "MPa"
*MEAS_COND_AXIS_UNIT-73 "degree"
*MEAS_COND_AXIS_UNIT-74 "percent"
*MEAS_COND_AXIS_UNIT-75 "degree"
*MEAS_COND_AXIS_UNIT-76 "C"
*MEAS_COND_AXIS_UNIT-77 "H"
*MEAS_COND_AXIS_UNIT-78 "time"
*MEAS_COND_AXIS_UNIT-79 "msec"
*MEAS_COND_AXIS_UNIT-8 ""
*MEAS_COND_AXIS_UNIT-80 "msec"
*MEAS_COND_AXIS_UNIT-81 "H"
*MEAS_COND_AXIS_UNIT-82 "times"
*MEAS_COND_AXIS_UNIT-83 "msec"
*MEAS_COND_AXIS_UNIT-84 "msec"
*MEAS_COND_AXIS_UNIT-85 "-"
*MEAS_COND_AXIS_UNIT-86 "-"
*MEAS_COND_AXIS_UNIT-87 "-"
*MEAS_COND_AXIS_UNIT-88 ""
*MEAS_COND_AXIS_UNIT-89 "-"
*MEAS_COND_AXIS_UNIT-9 "mm"
*MEAS_COND_AXIS_UNIT-90 "-"
*MEAS_COND_AXIS_UNIT-91 "-"
*MEAS_COND_AXIS_UNIT-92 ""
*MEAS_COND_AXIS_UNIT-93 ""
*MEAS_COND_AXIS_UNIT-94 ""
*MEAS_COND_AXIS_UNIT-95 ""
*MEAS_COND_AXIS_UNIT-96 ""
*MEAS_COND_AXIS_UNIT-97 ""
*MEAS_COND_AXIS_UNIT-98 ""
*MEAS_COND_AXIS_UNIT-99 ""
*MEAS_COND_OPT_ATTR "PB-Ge(220)x2"
*MEAS_COND_OPT_NAME "User defined settings"
*MEAS_COND_XG_CURRENT "160"
*MEAS_COND_XG_VOLTAGE "45"
*MEAS_COND_XG_WAVE_TYPE "Ka1"
*MEAS_DATA_COUNT "626"
*MEAS_SCAN_AXIS_X "TwoThetaOmega"
*MEAS_SCAN_AXIS_X_INTERNAL "TwoThetaOmega"
*MEAS_SCAN_END_TIME "10/15/2020 12:23:48"
*MEAS_SCAN_MODE "CONTINUOUS"
*MEAS_SCAN_MODE_INTERNAL "CONTINUOUS"
*MEAS_SCAN_RESOLUTION_X "0.0002"
*MEAS_SCAN_SPEED "0.5000"
*MEAS_SCAN_SPEED_UNIT "deg/min"
*MEAS_SCAN_START "34.9022"
*MEAS_SCAN_START_TIME "10/15/2020 12:22:01"
*MEAS_SCAN_STEP "0.0008"
*MEAS_SCAN_STOP "35.4022"
*MEAS_SCAN_UNIT_X "deg"
*MEAS_SCAN_UNIT_Y "counts"
*RAS_HEADER_END
*RAS_INT_START
34.9022 5.0000 1.0000
34.9030 4.0000 1.0000
34.9038 7.0000 1.0000
34.9046 3.0000 1.0000
34.9054 7.0000 1.0000
34.9062 6.0000 1.0000
34.9070 5.0000 1.0000
34.9078 5.0000 1.0000
34.9086 5.0000 1.0000
34.9094 6.0000 1.0000
34.9102 4.0000 1.0000
34.9110 2.0000 1.0000
34.9118 3.0000 1.0000
34.9126 4.0000 1.0000
34.9134 3.0000 1.0000
34.9142 6.0000 1.0000
34.9150 5.0000 1.0000
34.9158 4.0000 1.0000
34.9166 9.0000 1.0000
34.9174 4.0000 1.0000
34.9182 6.0000 1.0000
34.9190 7.0000 1.0000
34.9198 7.0000 1.0000
34.9206 9.0000 1.0000
34.9214 11.0000 1.0000
34.9222 3.0000 1.0000
34.9230 3.0000 1.0000
34.9238 4.0000 1.0000
34.9246 2.0000 1.0000
34.9254 8.0000 1.0000
34.9262 8.0000 1.0000
34.9270 4.0000 1.0000
34.9278 6.0000 1.0000
34.9286 2.0000 1.0000
34.9294 2.0000 1.0000
34.9302 7.0000 1.0000
34.9310 7.0000 1.0000
34.9318 3.0000 1.0000
34.9326 8.0000 1.0000
34.9334 9.0000 1.0000
34.9342 6.0000 1.0000
34.9350 4.0000 1.0000
34.9358 3.0000 1.0000
34.9366 11.0000 1.0000
34.9374 8.0000 1.0000
34.9382 4.0000 1.0000
34.9390 7.0000 1.0000
34.9398 5.0000 1.0000
34.9406 4.0000 1.0000
34.9414 7.0000 1.0000
34.9422 11.0000 1.0000
34.9430 8.0000 1.0000
34.9438 8.0000 1.0000
34.9446 6.0000 1.0000
34.9454 1.0000 1.0000
34.9462 3.0000 1.0000
34.9470 2.0000 1.0000
34.9478 10.0000 1.0000
34.9486 3.0000 1.0000
34.9494 10.0000 1.0000
34.9502 5.0000 1.0000
34.9510 7.0000 1.0000
34.9518 9.0000 1.0000
34.9526 7.0000 1.0000
34.9534 7.0000 1.0000
34.9542 3.0000 1.0000
34.9550 4.0000 1.0000
34.9558 7.0000 1.0000
34.9566 8.0000 1.0000
34.9574 5.0000 1.0000
34.9582 9.0000 1.0000
34.9590 9.0000 1.0000
34.9598 5.0000 1.0000
34.9606 9.0000 1.0000
34.9614 10.0000 1.0000
34.9622 6.0000 1.0000
34.9630 10.0000 1.0000
34.9638 4.0000 1.0000
34.9646 4.0000 1.0000
34.9654 9.0000 1.0000
34.9662 6.0000 1.0000
34.9670 9.0000 1.0000
34.9678 9.0000 1.0000
34.9686 10.0000 1.0000
34.9694 15.0000 1.0000
34.9702 9.0000 1.0000
34.9710 15.0000 1.0000
34.9718 14.0000 1.0000
34.9726 9.0000 1.0000
34.9734 11.0000 1.0000
34.9742 9.0000 1.0000
34.9750 10.0000 1.0000
34.9758 9.0000 1.0000
34.9766 13.0000 1.0000
34.9774 5.0000 1.0000
34.9782 10.0000 1.0000
34.9790 10.0000 1.0000
34.9798 9.0000 1.0000
34.9806 14.0000 1.0000
34.9814 13.0000 1.0000
34.9822 13.0000 1.0000
34.9830 8.0000 1.0000
34.9838 8.0000 1.0000
34.9846 8.0000 1.0000
34.9854 14.0000 1.0000
34.9862 6.0000 1.0000
34.9870 9.0000 1.0000
34.9878 10.0000 1.0000
34.9886 3.0000 1.0000
34.9894 12.0000 1.0000
34.9902 10.0000 1.0000
34.9910 3.0000 1.0000
34.9918 10.0000 1.0000
34.9926 11.0000 1.0000
34.9934 12.0000 1.0000
34.9942 19.0000 1.0000
34.9950 12.0000 1.0000
34.9958 12.0000 1.0000
34.9966 11.0000 1.0000
34.9974 9.0000 1.0000
34.9982 7.0000 1.0000
34.9990 11.0000 1.0000
34.9998 11.0000 1.0000
35.0006 13.0000 1.0000
35.0014 15.0000 1.0000
35.0022 13.0000 1.0000
35.0030 14.0000 1.0000
35.0038 7.0000 1.0000
35.0046 8.0000 1.0000
35.0054 9.0000 1.0000
35.0062 12.0000 1.0000
35.0070 10.0000 1.0000
35.0078 10.0000 1.0000
35.0086 10.0000 1.0000
35.0094 11.0000 1.0000
35.0102 12.0000 1.0000
35.0110 13.0000 1.0000
35.0118 19.0000 1.0000
35.0126 20.0000 1.0000
35.0134 15.0000 1.0000
35.0142 12.0000 1.0000
35.0150 16.0000 1.0000
35.0158 15.0000 1.0000
35.0166 13.0000 1.0000
35.0174 17.0000 1.0000
35.0182 16.0000 1.0000
35.0190 20.0000 1.0000
35.0198 22.0000 1.0000
35.0206 17.0000 1.0000
35.0214 13.0000 1.0000
35.0222 11.0000 1.0000
35.0230 15.0000 1.0000
35.0238 12.0000 1.0000
35.0246 26.0000 1.0000
35.0254 18.0000 1.0000
35.0262 6.0000 1.0000
35.0270 17.0000 1.0000
35.0278 23.0000 1.0000
35.0286 21.0000 1.0000
35.0294 13.0000 1.0000
35.0302 19.0000 1.0000
35.0310 15.0000 1.0000
35.0318 26.0000 1.0000
35.0326 18.0000 1.0000
35.0334 30.0000 1.0000
35.0342 27.0000 1.0000
35.0350 19.0000 1.0000
35.0358 22.0000 1.0000
35.0366 21.0000 1.0000
35.0374 17.0000 1.0000
35.0382 17.0000 1.0000
35.0390 24.0000 1.0000
35.0398 17.0000 1.0000
35.0406 29.0000 1.0000
35.0414 21.0000 1.0000
35.0422 21.0000 1.0000
35.0430 25.0000 1.0000
35.0438 18.0000 1.0000
35.0446 18.0000 1.0000
35.0454 18.0000 1.0000
35.0462 21.0000 1.0000
35.0470 34.0000 1.0000
35.0478 16.0000 1.0000
35.0486 21.0000 1.0000
35.0494 28.0000 1.0000
35.0502 23.0000 1.0000
35.0510 29.0000 1.0000
35.0518 25.0000 1.0000
35.0526 31.0000 1.0000
35.0534 33.0000 1.0000
35.0542 23.0000 1.0000
35.0550 32.0000 1.0000
35.0558 25.0000 1.0000
35.0566 31.0000 1.0000
35.0574 32.0000 1.0000
35.0582 25.0000 1.0000
35.0590 20.0000 1.0000
35.0598 30.0000 1.0000
35.0606 31.0000 1.0000
35.0614 35.0000 1.0000
35.0622 28.0000 1.0000
35.0630 32.0000 1.0000
35.0638 31.0000 1.0000
35.0646 31.0000 1.0000
35.0654 34.0000 1.0000
35.0662 39.0000 1.0000
35.0670 33.0000 1.0000
35.0678 35.0000 1.0000
35.0686 43.0000 1.0000
35.0694 41.0000 1.0000
35.0702 41.0000 1.0000
35.0710 44.0000 1.0000
35.0718 48.0000 1.0000
35.0726 34.0000 1.0000
35.0734 33.0000 1.0000
35.0742 34.0000 1.0000
35.0750 33.0000 1.0000
35.0758 39.0000 1.0000
35.0766 45.0000 1.0000
35.0774 50.0000 1.0000
35.0782 47.0000 1.0000
35.0790 36.0000 1.0000
35.0798 51.0000 1.0000
35.0806 49.0000 1.0000
35.0814 46.0000 1.0000
35.0822 42.0000 1.0000
35.0830 50.0000 1.0000
35.0838 54.0000 1.0000
35.0846 53.0000 1.0000
35.0854 68.0000 1.0000
35.0862 65.0000 1.0000
35.0870 62.0000 1.0000
35.0878 59.0000 1.0000
35.0886 53.0000 1.0000
35.0894 56.0000 1.0000
35.0902 52.0000 1.0000
35.0910 58.0000 1.0000
35.0918 74.0000 1.0000
35.0926 64.0000 1.0000
35.0934 78.0000 1.0000
35.0942 74.0000 1.0000
35.0950 74.0000 1.0000
35.0958 70.0000 1.0000
35.0966 67.0000 1.0000
35.0974 75.0000 1.0000
35.0982 81.0000 1.0000
35.0990 88.0000 1.0000
35.0998 91.0000 1.0000
35.1006 98.0000 1.0000
35.1014 80.0000 1.0000
35.1022 91.0000 1.0000
35.1030 85.0000 1.0000
35.1038 89.0000 1.0000
35.1046 106.0000 1.0000
35.1054 100.0000 1.0000
35.1062 119.0000 1.0000
35.1070 119.0000 1.0000
35.1078 109.0000 1.0000
35.1086 129.0000 1.0000
35.1094 120.0000 1.0000
35.1102 125.0000 1.0000
35.1110 139.0000 1.0000
35.1118 140.0000 1.0000
35.1126 137.0000 1.0000
35.1134 157.0000 1.0000
35.1142 167.0000 1.0000
35.1150 166.0000 1.0000
35.1158 147.0000 1.0000
35.1166 197.0000 1.0000
35.1174 202.0000 1.0000
35.1182 223.0000 1.0000
35.1190 207.0000 1.0000
35.1198 221.0000 1.0000
35.1206 241.0000 1.0000
35.1214 263.0000 1.0000
35.1222 289.0000 1.0000
35.1230 303.0000 1.0000
35.1238 300.0000 1.0000
35.1246 350.0000 1.0000
35.1254 395.0000 1.0000
35.1262 369.0000 1.0000
35.1270 416.0000 1.0000
35.1278 480.0000 1.0000
35.1286 502.0000 1.0000
35.1294 508.0000 1.0000
35.1302 502.0000 1.0000
35.1310 579.0000 1.0000
35.1318 578.0000 1.0000
35.1326 611.0000 1.0000
35.1334 664.0000 1.0000
35.1342 723.0000 1.0000
35.1350 754.0000 1.0000
35.1358 894.0000 1.0000
35.1366 890.0000 1.0000
35.1374 934.0000 1.0000
35.1382 1065.0000 1.0000
35.1390 1259.0000 1.0000
35.1398 1506.0000 1.0000
35.1406 1681.0000 1.0000
35.1414 2019.0000 1.0000
35.1422 2489.0000 1.0000
35.1430 2927.0000 1.0000
35.1438 3793.0000 1.0000
35.1446 4642.0000 1.0000
35.1454 116.0000 53.8780
35.1462 117.0000 53.8780
35.1470 196.0000 53.8780
35.1478 260.0000 53.8780
35.1486 402.0000 53.8780
35.1494 502.0000 53.8780
35.1502 712.0000 53.8780
35.1510 848.0000 53.8780
35.1518 1196.0000 53.8780
35.1526 1463.0000 53.8780
35.1534 1743.0000 53.8780
35.1542 2184.0000 53.8780
35.1550 2342.0000 53.8780
35.1558 2547.0000 53.8780
35.1566 2610.0000 53.8780
35.1574 2474.0000 53.8780
35.1582 2261.0000 53.8780
35.1590 1907.0000 53.8780
35.1598 1539.0000 53.8780
35.1606 1180.0000 53.8780
35.1614 849.0000 53.8780
35.1622 579.0000 53.8780
35.1630 440.0000 53.8780
35.1638 350.0000 53.8780
35.1646 269.0000 53.8780
35.1654 201.0000 53.8780
35.1662 142.0000 53.8780
35.1670 113.0000 53.8780
35.1678 5576.0000 1.0000
35.1686 5113.0000 1.0000
35.1694 3345.0000 1.0000
35.1702 2726.0000 1.0000
35.1710 2203.0000 1.0000
35.1718 1877.0000 1.0000
35.1726 1560.0000 1.0000
35.1734 1221.0000 1.0000
35.1742 1059.0000 1.0000
35.1750 896.0000 1.0000
35.1758 771.0000 1.0000
35.1766 711.0000 1.0000
35.1774 636.0000 1.0000
35.1782 564.0000 1.0000
35.1790 496.0000 1.0000
35.1798 502.0000 1.0000
35.1806 441.0000 1.0000
35.1814 434.0000 1.0000
35.1822 393.0000 1.0000
35.1830 335.0000 1.0000
35.1838 317.0000 1.0000
35.1846 301.0000 1.0000
35.1854 327.0000 1.0000
35.1862 246.0000 1.0000
35.1870 232.0000 1.0000
35.1878 270.0000 1.0000
35.1886 198.0000 1.0000
35.1894 224.0000 1.0000
35.1902 199.0000 1.0000
35.1910 189.0000 1.0000
35.1918 186.0000 1.0000
35.1926 175.0000 1.0000
35.1934 158.0000 1.0000
35.1942 146.0000 1.0000
35.1950 179.0000 1.0000
35.1958 141.0000 1.0000
35.1966 142.0000 1.0000
35.1974 154.0000 1.0000
35.1982 109.0000 1.0000
35.1990 133.0000 1.0000
35.1998 111.0000 1.0000
35.2006 108.0000 1.0000
35.2014 93.0000 1.0000
35.2022 109.0000 1.0000
35.2030 99.0000 1.0000
35.2038 111.0000 1.0000
35.2046 93.0000 1.0000
35.2054 104.0000 1.0000
35.2062 112.0000 1.0000
35.2070 96.0000 1.0000
35.2078 75.0000 1.0000
35.2086 81.0000 1.0000
35.2094 86.0000 1.0000
35.2102 71.0000 1.0000
35.2110 79.0000 1.0000
35.2118 71.0000 1.0000
35.2126 65.0000 1.0000
35.2134 54.0000 1.0000
35.2142 56.0000 1.0000
35.2150 61.0000 1.0000
35.2158 57.0000 1.0000
35.2166 70.0000 1.0000
35.2174 66.0000 1.0000
35.2182 55.0000 1.0000
35.2190 68.0000 1.0000
35.2198 60.0000 1.0000
35.2206 55.0000 1.0000
35.2214 58.0000 1.0000
35.2222 47.0000 1.0000
35.2230 50.0000 1.0000
35.2238 41.0000 1.0000
35.2246 47.0000 1.0000
35.2254 49.0000 1.0000
35.2262 38.0000 1.0000
35.2270 56.0000 1.0000
35.2278 31.0000 1.0000
35.2286 44.0000 1.0000
35.2294 32.0000 1.0000
35.2302 33.0000 1.0000
35.2310 43.0000 1.0000
35.2318 33.0000 1.0000
35.2326 35.0000 1.0000
35.2334 36.0000 1.0000
35.2342 36.0000 1.0000
35.2350 30.0000 1.0000
35.2358 31.0000 1.0000
35.2366 40.0000 1.0000
35.2374 37.0000 1.0000
35.2382 40.0000 1.0000
35.2390 41.0000 1.0000
35.2398 34.0000 1.0000
35.2406 28.0000 1.0000
35.2414 30.0000 1.0000
35.2422 20.0000 1.0000
35.2430 25.0000 1.0000
35.2438 17.0000 1.0000
35.2446 36.0000 1.0000
35.2454 25.0000 1.0000
35.2462 24.0000 1.0000
35.2470 22.0000 1.0000
35.2478 26.0000 1.0000
35.2486 25.0000 1.0000
35.2494 28.0000 1.0000
35.2502 29.0000 1.0000
35.2510 24.0000 1.0000
35.2518 30.0000 1.0000
35.2526 24.0000 1.0000
35.2534 22.0000 1.0000
35.2542 23.0000 1.0000
35.2550 18.0000 1.0000
35.2558 22.0000 1.0000
35.2566 22.0000 1.0000
35.2574 24.0000 1.0000
35.2582 26.0000 1.0000
35.2590 22.0000 1.0000
35.2598 15.0000 1.0000
35.2606 18.0000 1.0000
35.2614 17.0000 1.0000
35.2622 12.0000 1.0000
35.2630 13.0000 1.0000
35.2638 17.0000 1.0000
35.2646 22.0000 1.0000
35.2654 20.0000 1.0000
35.2662 17.0000 1.0000
35.2670 13.0000 1.0000
35.2678 15.0000 1.0000
35.2686 21.0000 1.0000
35.2694 24.0000 1.0000
35.2702 13.0000 1.0000
35.2710 20.0000 1.0000
35.2718 10.0000 1.0000
35.2726 20.0000 1.0000
35.2734 22.0000 1.0000
35.2742 18.0000 1.0000
35.2750 16.0000 1.0000
35.2758 13.0000 1.0000
35.2766 16.0000 1.0000
35.2774 7.0000 1.0000
35.2782 8.0000 1.0000
35.2790 14.0000 1.0000
35.2798 14.0000 1.0000
35.2806 9.0000 1.0000
35.2814 12.0000 1.0000
35.2822 17.0000 1.0000
35.2830 11.0000 1.0000
35.2838 14.0000 1.0000
35.2846 16.0000 1.0000
35.2854 23.0000 1.0000
35.2862 13.0000 1.0000
35.2870 13.0000 1.0000
35.2878 13.0000 1.0000
35.2886 14.0000 1.0000
35.2894 8.0000 1.0000
35.2902 13.0000 1.0000
35.2910 9.0000 1.0000
35.2918 14.0000 1.0000
35.2926 11.0000 1.0000
35.2934 12.0000 1.0000
35.2942 13.0000 1.0000
35.2950 16.0000 1.0000
35.2958 14.0000 1.0000
35.2966 9.0000 1.0000
35.2974 6.0000 1.0000
35.2982 9.0000 1.0000
35.2990 5.0000 1.0000
35.2998 13.0000 1.0000
35.3006 14.0000 1.0000
35.3014 10.0000 1.0000
35.3022 15.0000 1.0000
35.3030 9.0000 1.0000
35.3038 7.0000 1.0000
35.3046 8.0000 1.0000
35.3054 8.0000 1.0000
35.3062 11.0000 1.0000
35.3070 11.0000 1.0000
35.3078 5.0000 1.0000
35.3086 9.0000 1.0000
35.3094 11.0000 1.0000
35.3102 6.0000 1.0000
35.3110 8.0000 1.0000
35.3118 5.0000 1.0000
35.3126 8.0000 1.0000
35.3134 10.0000 1.0000
35.3142 1.0000 1.0000
35.3150 7.0000 1.0000
35.3158 8.0000 1.0000
35.3166 9.0000 1.0000
35.3174 10.0000 1.0000
35.3182 11.0000 1.0000
35.3190 15.0000 1.0000
35.3198 17.0000 1.0000
35.3206 9.0000 1.0000
35.3214 4.0000 1.0000
35.3222 7.0000 1.0000
35.3230 5.0000 1.0000
35.3238 8.0000 1.0000
35.3246 7.0000 1.0000
35.3254 8.0000 1.0000
35.3262 11.0000 1.0000
35.3270 10.0000 1.0000
35.3278 8.0000 1.0000
35.3286 9.0000 1.0000
35.3294 4.0000 1.0000
35.3302 12.0000 1.0000
35.3310 6.0000 1.0000
35.3318 5.0000 1.0000
35.3326 9.0000 1.0000
35.3334 10.0000 1.0000
35.3342 7.0000 1.0000
35.3350 2.0000 1.0000
35.3358 8.0000 1.0000
35.3366 5.0000 1.0000
35.3374 5.0000 1.0000
35.3382 9.0000 1.0000
35.3390 13.0000 1.0000
35.3398 4.0000 1.0000
35.3406 5.0000 1.0000
35.3414 10.0000 1.0000
35.3422 6.0000 1.0000
35.3430 12.0000 1.0000
35.3438 6.0000 1.0000
35.3446 7.0000 1.0000
35.3454 3.0000 1.0000
35.3462 7.0000 1.0000
35.3470 5.0000 1.0000
35.3478 6.0000 1.0000
35.3486 3.0000 1.0000
35.3494 6.0000 1.0000
35.3502 2.0000 1.0000
35.3510 5.0000 1.0000
35.3518 6.0000 1.0000
35.3526 6.0000 1.0000
35.3534 9.0000 1.0000
35.3542 5.0000 1.0000
35.3550 3.0000 1.0000
35.3558 4.0000 1.0000
35.3566 3.0000 1.0000
35.3574 8.0000 1.0000
35.3582 8.0000 1.0000
35.3590 1.0000 1.0000
35.3598 2.0000 1.0000
35.3606 8.0000 1.0000
35.3614 5.0000 1.0000
35.3622 7.0000 1.0000
35.3630 5.0000 1.0000
35.3638 6.0000 1.0000
35.3646 2.0000 1.0000
35.3654 6.0000 1.0000
35.3662 5.0000 1.0000
35.3670 5.0000 1.0000
35.3678 11.0000 1.0000
35.3686 4.0000 1.0000
35.3694 4.0000 1.0000
35.3702 6.0000 1.0000
35.3710 2.0000 1.0000
35.3718 8.0000 1.0000
35.3726 6.0000 1.0000
35.3734 2.0000 1.0000
35.3742 5.0000 1.0000
35.3750 2.0000 1.0000
35.3758 5.0000 1.0000
35.3766 5.0000 1.0000
35.3774 2.0000 1.0000
35.3782 4.0000 1.0000
35.3790 7.0000 1.0000
35.3798 4.0000 1.0000
35.3806 8.0000 1.0000
35.3814 5.0000 1.0000
35.3822 4.0000 1.0000
35.3830 3.0000 1.0000
35.3838 6.0000 1.0000
35.3846 5.0000 1.0000
35.3854 2.0000 1.0000
35.3862 5.0000 1.0000
35.3870 2.0000 1.0000
35.3878 2.0000 1.0000
35.3886 3.0000 1.0000
35.3894 1.0000 1.0000
35.3902 1.0000 1.0000
35.3910 5.0000 1.0000
35.3918 3.0000 1.0000
35.3926 3.0000 1.0000
35.3934 2.0000 1.0000
35.3942 4.0000 1.0000
35.3950 5.0000 1.0000
35.3958 1.0000 1.0000
35.3966 2.0000 1.0000
35.3974 3.0000 1.0000
35.3982 0.0000 1.0000
35.3990 6.0000 1.0000
35.3998 2.0000 1.0000
35.4006 3.0000 1.0000
35.4014 5.0000 1.0000
35.4022 4.0000 1.0000
*RAS_INT_END
*RAS_DATA_END
*DSC_DATA_END