File: example/461_test/PLD10nmFe2O3_Al2O3/Off_Specular/PhiFULL_Fe2O3_104_0007_Scan2020Oct15-125410.ras
*RAS_DATA_START
*RAS_HEADER_START
*DISP_LINE_COLOR "4294901760"
*FILE_COMMENT ""
*FILE_MD5 ""
*FILE_MEMO ""
*FILE_OPERATOR "Administrator"
*FILE_PACKAGE_NAME ""
*FILE_PART_ID ""
*FILE_SAMPLE ""
*FILE_SYSTEM_NAME "SmartLab"
*FILE_TYPE "RAS_RAW"
*FILE_USERGROUP "Administrators"
*FILE_VERSION "1"
*HW_ATTACHMENT_ID "ATT0022"
*HW_ATTACHMENT_NAME "RxRy"
*HW_ATTACHMENT_NAME_INTERNAL "RxRy"
*HW_COUNTER_ID-0 "CUT0021"
*HW_COUNTER_ID-1 "CMC0020"
*HW_COUNTER_MONOCHRO_ID "CMC0020"
*HW_COUNTER_MONOCHRO_NAME "None"
*HW_COUNTER_MONOCHRO_NAME_INTERNAL "None"
*HW_COUNTER_NAME_INTERNAL "SC70"
*HW_COUNTER_NAME-0 "SC70"
*HW_COUNTER_NAME-1 "None"
*HW_COUNTER_SELECT_NAME "SC70"
*HW_EXTERNAL_CONTROLLER_NAME "None"
*HW_EXTERNAL_CONTROLLER_NAME_INTERNAL "None"
*HW_GONIOMETER_ID "GON0022"
*HW_GONIOMETER_NAME "StandardInplaneEnc"
*HW_GONIOMETER_NAME_INTERNAL "StandardInplaneEnc"
*HW_GONIOMETER_RADIUS-0 "90.0"
*HW_GONIOMETER_RADIUS-1 "114.0"
*HW_GONIOMETER_RADIUS-2 "190.0"
*HW_GONIOMETER_RADIUS-3 "300.0"
*HW_GONIOMETER_RADIUS-4 "187.0"
*HW_GONIOMETER_RADIUS-5 "300.0"
*HW_GONIOMETER_RADIUS-6 "113.0000"
*HW_GONIOMETER_RADIUS-7 "331.0"
*HW_I_CBO_ID "CBO0021"
*HW_I_CBO_NAME "CBO"
*HW_I_CBO_NAME_INTERNAL "CBO"
*HW_I_MONOCHRO_ID "ICR0021"
*HW_I_MONOCHRO_NAME "Ge(220)x2"
*HW_I_MONOCHRO_NAME_INTERNAL "Ge(220)x2"
*HW_I_OPT_ID-0 "CBO0021"
*HW_I_OPT_ID-1 "ISL0021"
*HW_I_PRIMARY_NAME_INTERNAL "Standard"
*HW_I_SLIT_ID "ISL0021"
*HW_I_SLIT_NAME "Auto"
*HW_I_SLIT_NAME_INTERNAL "Auto"
*HW_R_ATTENUATER_AUTOMODE "1"
*HW_R_ATTENUATER_ID "ATN0021"
*HW_R_ATTENUATER_NAME "Auto"
*HW_R_ATTENUATOR_NAME_INTERNAL "Auto"
*HW_R_OPT_ID-0 "RSS0021"
*HW_R_OPT_ID-1 "RCR0022"
*HW_R_OPT_ID-2 "RSO0021"
*HW_R_OPT_ID-3 "RRS0021"
*HW_R_OPT_ID-4 "ATN0021"
*HW_R_ROD_ID "RCR0022"
*HW_R_ROD_NAME "ROD_adaptor"
*HW_R_ROD_NAME_INTERNAL "ROD_adaptor"
*HW_R_RPS_ID "RSO0021"
*HW_R_RPS_NAME "RPS_adaptor"
*HW_R_RPS_NAME_INTERNAL "RPS_adaptor"
*HW_R_RS_ID "RRS0021"
*HW_R_RS_NAME "Auto"
*HW_R_RS_NAME_INTERNAL "Auto"
*HW_R_SS_ID "RSS0021"
*HW_R_SS_NAME "Auto"
*HW_R_SS_NAME_INTERNAL "Auto"
*HW_ROBOT_NAME "No_unit"
*HW_ROBOT_NAME_INTERNAL "No_unit"
*HW_SAMPLE_CAMERA_NAME "None"
*HW_SAMPLE_CAMERA_NAME_INTERNAL "None"
*HW_SAMPLE_HOLDER_ID "SMP0021"
*HW_SAMPLE_HOLDER_NAME "Z_ChiPhi"
*HW_SAMPLE_HOLDER_NAME_INTERNAL "Z_ChiPhi"
*HW_SAMPLE_NAME "CenterSlit"
*HW_SAMPLE_NAME_INTERNAL "CenterSlit"
*HW_SAMPLE_PLATE_NAME "HeightReference"
*HW_SAMPLE_PLATE_NAME_INTERNAL "HeightReference"
*HW_SAMPLE_SPACER_NAME "None"
*HW_SAMPLE_SPACER_NAME_INTERNAL "None"
*HW_USERINFO_CATALOG_NO ""
*HW_USERINFO_INSTRUMENT_ID ""
*HW_USERINFO_INSTRUMENT_NAME ""
*HW_USERINFO_INSTRUMENT_NO ""
*HW_USERINFO_MODEL ""
*HW_USERINFO_ORDER_NO ""
*HW_USERINFO_SERIAL_NO ""
*HW_USERINFO_VERIFY_INSTRUMENT_ID "00-07-fe-01-03-ce"
*HW_VER_RCD_COUNTER_UNIT "1.0.1"
*HW_VER_RCD_CPU "3.3.7"
*HW_VER_RCD_FPGA "1.2.2"
*HW_VER_RCD_GONIO_UNIT "6.2.0"
*HW_VER_RCD_INCIDENT_UNIT "6.2.0"
*HW_VER_RCD_RECEIVING_UNIT "6.2.0"
*HW_VER_RCD_TYPE "RINC"
*HW_VER_XGC_CPU "3.3.7"
*HW_VER_XGC_CW "1.2.0"
*HW_VER_XGC_HV "1.2.0"
*HW_VER_XGC_RS1 "1.3.4"
*HW_VER_XGC_RS2 "N/A"
*HW_VER_XGC_RT "1.2.0"
*HW_VER_XGC_TYPE "RINC"
*HW_XG_CURRENT_UNIT "mA"
*HW_XG_FOCUS "0.4mm x 8mm"
*HW_XG_FOCUS_TYPE "Fine"
*HW_XG_TARGET_ATOMIC_NUMBER "29"
*HW_XG_TARGET_NAME "Cu"
*HW_XG_TYPE "ROTA"
*HW_XG_VOLTAGE_UNIT "kV"
*HW_XG_WAVE_LENGTH_ALPHA1 "1.540593"
*HW_XG_WAVE_LENGTH_ALPHA2 "1.544414"
*HW_XG_WAVE_LENGTH_BETA "1.392246"
*HW_XG_WAVE_LENGTH_UNIT "Angstrom"
*MEAS_COND_AXIS_NAME_INTERNAL-0 "ThetaS"
*MEAS_COND_AXIS_NAME_INTERNAL-1 "ThetaD"
*MEAS_COND_AXIS_NAME_INTERNAL-10 "PrimaryGeometry"
*MEAS_COND_AXIS_NAME_INTERNAL-100 "IncidentMonochromator"
*MEAS_COND_AXIS_NAME_INTERNAL-101 "ReceivingOptics"
*MEAS_COND_AXIS_NAME_INTERNAL-102 "CounterMonochromatorKind"
*MEAS_COND_AXIS_NAME_INTERNAL-11 "PrimaryMirrorType"
*MEAS_COND_AXIS_NAME_INTERNAL-12 "CBOType"
*MEAS_COND_AXIS_NAME_INTERNAL-13 "CBO-M"
*MEAS_COND_AXIS_NAME_INTERNAL-14 "CBO"
*MEAS_COND_AXIS_NAME_INTERNAL-15 "IncidentMonochromator-OmegaM"
*MEAS_COND_AXIS_NAME_INTERNAL-16 "IncidentSollerSlit"
*MEAS_COND_AXIS_NAME_INTERNAL-17 "IncidentSlitBox"
*MEAS_COND_AXIS_NAME_INTERNAL-18 "IncidentSlitBox-_Axis"
*MEAS_COND_AXIS_NAME_INTERNAL-19 "SlitDS"
*MEAS_COND_AXIS_NAME_INTERNAL-2 "TwoTheta"
*MEAS_COND_AXIS_NAME_INTERNAL-20 "Zs"
*MEAS_COND_AXIS_NAME_INTERNAL-21 "IncidentAxdSlit"
*MEAS_COND_AXIS_NAME_INTERNAL-22 "LLS"
*MEAS_COND_AXIS_NAME_INTERNAL-23 "DHLSlit"
*MEAS_COND_AXIS_NAME_INTERNAL-24 "Chi"
*MEAS_COND_AXIS_NAME_INTERNAL-25 "Phi"
*MEAS_COND_AXIS_NAME_INTERNAL-26 "Z"
*MEAS_COND_AXIS_NAME_INTERNAL-27 "Alpha"
*MEAS_COND_AXIS_NAME_INTERNAL-28 "Beta"
*MEAS_COND_AXIS_NAME_INTERNAL-29 "TwoThetaChiPhi"
*MEAS_COND_AXIS_NAME_INTERNAL-3 "Omega"
*MEAS_COND_AXIS_NAME_INTERNAL-30 "AlphaI"
*MEAS_COND_AXIS_NAME_INTERNAL-31 "BetaI"
*MEAS_COND_AXIS_NAME_INTERNAL-32 "TwoThetaB"
*MEAS_COND_AXIS_NAME_INTERNAL-33 "Rx"
*MEAS_COND_AXIS_NAME_INTERNAL-34 "Ry"
*MEAS_COND_AXIS_NAME_INTERNAL-35 "ReceivingSlitBox1"
*MEAS_COND_AXIS_NAME_INTERNAL-36 "ReceivingSlitBox1-_Axis"
*MEAS_COND_AXIS_NAME_INTERNAL-37 "SlitSS"
*MEAS_COND_AXIS_NAME_INTERNAL-38 "Filter"
*MEAS_COND_AXIS_NAME_INTERNAL-39 "PSA"
*MEAS_COND_AXIS_NAME_INTERNAL-4 "TwoThetaTheta"
*MEAS_COND_AXIS_NAME_INTERNAL-40 "ReceivingSollerSlit"
*MEAS_COND_AXIS_NAME_INTERNAL-41 "ReceivingSlitBox2"
*MEAS_COND_AXIS_NAME_INTERNAL-42 "ReceivingSlitBox2-_Axis"
*MEAS_COND_AXIS_NAME_INTERNAL-43 "SlitRS"
*MEAS_COND_AXIS_NAME_INTERNAL-44 "ReceivingSlitBox2-Zd"
*MEAS_COND_AXIS_NAME_INTERNAL-45 "Filter2"
*MEAS_COND_AXIS_NAME_INTERNAL-46 "Attenuator"
*MEAS_COND_AXIS_NAME_INTERNAL-47 "HV"
*MEAS_COND_AXIS_NAME_INTERNAL-48 "PHA"
*MEAS_COND_AXIS_NAME_INTERNAL-49 "DedicatedHolder"
*MEAS_COND_AXIS_NAME_INTERNAL-5 "TwoThetaOmega"
*MEAS_COND_AXIS_NAME_INTERNAL-50 "Target_TargetTime"
*MEAS_COND_AXIS_NAME_INTERNAL-51 "Target_XrayOnTime"
*MEAS_COND_AXIS_NAME_INTERNAL-52 "Target_TMPTime"
*MEAS_COND_AXIS_NAME_INTERNAL-53 "Target_RPTime"
*MEAS_COND_AXIS_NAME_INTERNAL-54 "Target_FilamentTime"
*MEAS_COND_AXIS_NAME_INTERNAL-55 "Target_IG"
*MEAS_COND_AXIS_NAME_INTERNAL-56 "Target_GP"
*MEAS_COND_AXIS_NAME_INTERNAL-57 "Target_FC"
*MEAS_COND_AXIS_NAME_INTERNAL-58 "HVPS_Bias"
*MEAS_COND_AXIS_NAME_INTERNAL-59 "HVPS_HVPSTime"
*MEAS_COND_AXIS_NAME_INTERNAL-6 "OmegaTwoTheta"
*MEAS_COND_AXIS_NAME_INTERNAL-60 "HVPS_Type1Time"
*MEAS_COND_AXIS_NAME_INTERNAL-61 "HVPS_Type2Time"
*MEAS_COND_AXIS_NAME_INTERNAL-62 "HVPS_Type3Time"
*MEAS_COND_AXIS_NAME_INTERNAL-63 "CW_IERTime"
*MEAS_COND_AXIS_NAME_INTERNAL-64 "CW_ECTime"
*MEAS_COND_AXIS_NAME_INTERNAL-65 "CW_Flow1"
*MEAS_COND_AXIS_NAME_INTERNAL-66 "CW_Temperature1"
*MEAS_COND_AXIS_NAME_INTERNAL-67 "CW_Pressure1"
*MEAS_COND_AXIS_NAME_INTERNAL-68 "CW_PressureIn"
*MEAS_COND_AXIS_NAME_INTERNAL-69 "CW_PressureOut"
*MEAS_COND_AXIS_NAME_INTERNAL-7 "TwoThetaChi"
*MEAS_COND_AXIS_NAME_INTERNAL-70 "CW_Flow2"
*MEAS_COND_AXIS_NAME_INTERNAL-71 "CW_Temperature2"
*MEAS_COND_AXIS_NAME_INTERNAL-72 "CW_Pressure2"
*MEAS_COND_AXIS_NAME_INTERNAL-73 "RE_EnclosureTemp"
*MEAS_COND_AXIS_NAME_INTERNAL-74 "RE_EnclosureHummidity"
*MEAS_COND_AXIS_NAME_INTERNAL-75 "RE_CabinetTemp"
*MEAS_COND_AXIS_NAME_INTERNAL-76 "RE_RPTemp"
*MEAS_COND_AXIS_NAME_INTERNAL-77 "RE_ShutterAXrayOnTime"
*MEAS_COND_AXIS_NAME_INTERNAL-78 "RE_ShutterATimes"
*MEAS_COND_AXIS_NAME_INTERNAL-79 "RE_ShutterAOpenCloseTime"
*MEAS_COND_AXIS_NAME_INTERNAL-8 "GonioDirectBeamStop"
*MEAS_COND_AXIS_NAME_INTERNAL-80 "RE_ShutterACloseOpenTime"
*MEAS_COND_AXIS_NAME_INTERNAL-81 "RE_ShutterBXrayOnTime"
*MEAS_COND_AXIS_NAME_INTERNAL-82 "RE_ShutterBTimes"
*MEAS_COND_AXIS_NAME_INTERNAL-83 "RE_ShutterBOpenCloseTime"
*MEAS_COND_AXIS_NAME_INTERNAL-84 "RE_ShutterBCloseOpenTime"
*MEAS_COND_AXIS_NAME_INTERNAL-85 "RE_XrayWarningRamp"
*MEAS_COND_AXIS_NAME_INTERNAL-86 "RE_ShutterAInstallation"
*MEAS_COND_AXIS_NAME_INTERNAL-87 "RE_ShutterARamp"
*MEAS_COND_AXIS_NAME_INTERNAL-88 "RE_ShutterBInstallation"
*MEAS_COND_AXIS_NAME_INTERNAL-89 "RE_ShutterBRamp"
*MEAS_COND_AXIS_NAME_INTERNAL-9 "Ts"
*MEAS_COND_AXIS_NAME_INTERNAL-90 "RE_ExtShutterCLS"
*MEAS_COND_AXIS_NAME_INTERNAL-91 "RE_ExtXrayOFF"
*MEAS_COND_AXIS_NAME_INTERNAL-92 "RE_ExtSafetyCircuit"
*MEAS_COND_AXIS_NAME_INTERNAL-93 "Version_CPU"
*MEAS_COND_AXIS_NAME_INTERNAL-94 "Version_RS1"
*MEAS_COND_AXIS_NAME_INTERNAL-95 "Version_RS2"
*MEAS_COND_AXIS_NAME_INTERNAL-96 "Version_HV"
*MEAS_COND_AXIS_NAME_INTERNAL-97 "Version_CW"
*MEAS_COND_AXIS_NAME_INTERNAL-98 "Version_RT"
*MEAS_COND_AXIS_NAME_INTERNAL-99 "IncidentPrimary"
*MEAS_COND_AXIS_NAME-0 "ThetaS"
*MEAS_COND_AXIS_NAME-1 "ThetaD"
*MEAS_COND_AXIS_NAME-10 "PrimaryGeometry"
*MEAS_COND_AXIS_NAME-100 "IncidentMonochromator"
*MEAS_COND_AXIS_NAME-101 "ReceivingOptics"
*MEAS_COND_AXIS_NAME-102 "CounterMonochromatorKind"
*MEAS_COND_AXIS_NAME-11 "PrimaryMirrorType"
*MEAS_COND_AXIS_NAME-12 "CBOType"
*MEAS_COND_AXIS_NAME-13 "CBO-M"
*MEAS_COND_AXIS_NAME-14 "CBO"
*MEAS_COND_AXIS_NAME-15 "IncidentMonochromator-OmegaM"
*MEAS_COND_AXIS_NAME-16 "IncidentSollerSlit"
*MEAS_COND_AXIS_NAME-17 "IncidentSlitBox"
*MEAS_COND_AXIS_NAME-18 "IncidentSlitBox-_Axis"
*MEAS_COND_AXIS_NAME-19 "SlitDS"
*MEAS_COND_AXIS_NAME-2 "TwoTheta"
*MEAS_COND_AXIS_NAME-20 "Zs"
*MEAS_COND_AXIS_NAME-21 "IncidentAxdSlit"
*MEAS_COND_AXIS_NAME-22 "LLS"
*MEAS_COND_AXIS_NAME-23 "DHLSlit"
*MEAS_COND_AXIS_NAME-24 "Chi"
*MEAS_COND_AXIS_NAME-25 "Phi"
*MEAS_COND_AXIS_NAME-26 "Z"
*MEAS_COND_AXIS_NAME-27 "Alpha"
*MEAS_COND_AXIS_NAME-28 "Beta"
*MEAS_COND_AXIS_NAME-29 "TwoThetaChiPhi"
*MEAS_COND_AXIS_NAME-3 "Omega"
*MEAS_COND_AXIS_NAME-30 "AlphaI"
*MEAS_COND_AXIS_NAME-31 "BetaI"
*MEAS_COND_AXIS_NAME-32 "TwoThetaB"
*MEAS_COND_AXIS_NAME-33 "Rx"
*MEAS_COND_AXIS_NAME-34 "Ry"
*MEAS_COND_AXIS_NAME-35 "ReceivingSlitBox1"
*MEAS_COND_AXIS_NAME-36 "ReceivingSlitBox1-_Axis"
*MEAS_COND_AXIS_NAME-37 "SlitSS"
*MEAS_COND_AXIS_NAME-38 "Filter"
*MEAS_COND_AXIS_NAME-39 "PSA"
*MEAS_COND_AXIS_NAME-4 "TwoThetaTheta"
*MEAS_COND_AXIS_NAME-40 "ReceivingSollerSlit"
*MEAS_COND_AXIS_NAME-41 "ReceivingSlitBox2"
*MEAS_COND_AXIS_NAME-42 "ReceivingSlitBox2-_Axis"
*MEAS_COND_AXIS_NAME-43 "SlitRS"
*MEAS_COND_AXIS_NAME-44 "ReceivingSlitBox2-Zd"
*MEAS_COND_AXIS_NAME-45 "Filter2"
*MEAS_COND_AXIS_NAME-46 "Attenuator"
*MEAS_COND_AXIS_NAME-47 "HV"
*MEAS_COND_AXIS_NAME-48 "PHA"
*MEAS_COND_AXIS_NAME-49 "DedicatedHolder"
*MEAS_COND_AXIS_NAME-5 "TwoThetaOmega"
*MEAS_COND_AXIS_NAME-50 "Target_TargetTime"
*MEAS_COND_AXIS_NAME-51 "Target_XrayOnTime"
*MEAS_COND_AXIS_NAME-52 "Target_TMPTime"
*MEAS_COND_AXIS_NAME-53 "Target_RPTime"
*MEAS_COND_AXIS_NAME-54 "Target_FilamentTime"
*MEAS_COND_AXIS_NAME-55 "Target_IG"
*MEAS_COND_AXIS_NAME-56 "Target_GP"
*MEAS_COND_AXIS_NAME-57 "Target_FC"
*MEAS_COND_AXIS_NAME-58 "HVPS_Bias"
*MEAS_COND_AXIS_NAME-59 "HVPS_HVPSTime"
*MEAS_COND_AXIS_NAME-6 "OmegaTwoTheta"
*MEAS_COND_AXIS_NAME-60 "HVPS_Type1Time"
*MEAS_COND_AXIS_NAME-61 "HVPS_Type2Time"
*MEAS_COND_AXIS_NAME-62 "HVPS_Type3Time"
*MEAS_COND_AXIS_NAME-63 "CW_IERTime"
*MEAS_COND_AXIS_NAME-64 "CW_ECTime"
*MEAS_COND_AXIS_NAME-65 "CW_Flow1"
*MEAS_COND_AXIS_NAME-66 "CW_Temperature1"
*MEAS_COND_AXIS_NAME-67 "CW_Pressure1"
*MEAS_COND_AXIS_NAME-68 "CW_PressureIn"
*MEAS_COND_AXIS_NAME-69 "CW_PressureOut"
*MEAS_COND_AXIS_NAME-7 "TwoThetaChi"
*MEAS_COND_AXIS_NAME-70 "CW_Flow2"
*MEAS_COND_AXIS_NAME-71 "CW_Temperature2"
*MEAS_COND_AXIS_NAME-72 "CW_Pressure2"
*MEAS_COND_AXIS_NAME-73 "RE_EnclosureTemp"
*MEAS_COND_AXIS_NAME-74 "RE_EnclosureHummidity"
*MEAS_COND_AXIS_NAME-75 "RE_CabinetTemp"
*MEAS_COND_AXIS_NAME-76 "RE_RPTemp"
*MEAS_COND_AXIS_NAME-77 "RE_ShutterAXrayOnTime"
*MEAS_COND_AXIS_NAME-78 "RE_ShutterATimes"
*MEAS_COND_AXIS_NAME-79 "RE_ShutterAOpenCloseTime"
*MEAS_COND_AXIS_NAME-8 "GonioDirectBeamStop"
*MEAS_COND_AXIS_NAME-80 "RE_ShutterACloseOpenTime"
*MEAS_COND_AXIS_NAME-81 "RE_ShutterBXrayOnTime"
*MEAS_COND_AXIS_NAME-82 "RE_ShutterBTimes"
*MEAS_COND_AXIS_NAME-83 "RE_ShutterBOpenCloseTime"
*MEAS_COND_AXIS_NAME-84 "RE_ShutterBCloseOpenTime"
*MEAS_COND_AXIS_NAME-85 "RE_XrayWarningRamp"
*MEAS_COND_AXIS_NAME-86 "RE_ShutterAInstallation"
*MEAS_COND_AXIS_NAME-87 "RE_ShutterARamp"
*MEAS_COND_AXIS_NAME-88 "RE_ShutterBInstallation"
*MEAS_COND_AXIS_NAME-89 "RE_ShutterBRamp"
*MEAS_COND_AXIS_NAME-9 "Ts"
*MEAS_COND_AXIS_NAME-90 "RE_ExtShutterCLS"
*MEAS_COND_AXIS_NAME-91 "RE_ExtXrayOFF"
*MEAS_COND_AXIS_NAME-92 "RE_ExtSafetyCircuit"
*MEAS_COND_AXIS_NAME-93 "Version_CPU"
*MEAS_COND_AXIS_NAME-94 "Version_RS1"
*MEAS_COND_AXIS_NAME-95 "Version_RS2"
*MEAS_COND_AXIS_NAME-96 "Version_HV"
*MEAS_COND_AXIS_NAME-97 "Version_CW"
*MEAS_COND_AXIS_NAME-98 "Version_RT"
*MEAS_COND_AXIS_NAME-99 "IncidentPrimary"
*MEAS_COND_AXIS_OFFSET-0 "1.0906"
*MEAS_COND_AXIS_OFFSET-1 "0.1456"
*MEAS_COND_AXIS_OFFSET-10 "0"
*MEAS_COND_AXIS_OFFSET-100 "0"
*MEAS_COND_AXIS_OFFSET-101 "0"
*MEAS_COND_AXIS_OFFSET-102 "0"
*MEAS_COND_AXIS_OFFSET-11 "0"
*MEAS_COND_AXIS_OFFSET-12 "0"
*MEAS_COND_AXIS_OFFSET-13 "0"
*MEAS_COND_AXIS_OFFSET-14 "0"
*MEAS_COND_AXIS_OFFSET-15 "0"
*MEAS_COND_AXIS_OFFSET-16 "0"
*MEAS_COND_AXIS_OFFSET-17 "0"
*MEAS_COND_AXIS_OFFSET-18 "0"
*MEAS_COND_AXIS_OFFSET-19 "0"
*MEAS_COND_AXIS_OFFSET-2 "1.2362"
*MEAS_COND_AXIS_OFFSET-20 "0"
*MEAS_COND_AXIS_OFFSET-21 "0"
*MEAS_COND_AXIS_OFFSET-22 "0"
*MEAS_COND_AXIS_OFFSET-23 "0"
*MEAS_COND_AXIS_OFFSET-24 "0"
*MEAS_COND_AXIS_OFFSET-25 "0"
*MEAS_COND_AXIS_OFFSET-26 "0"
*MEAS_COND_AXIS_OFFSET-27 "0"
*MEAS_COND_AXIS_OFFSET-28 "0"
*MEAS_COND_AXIS_OFFSET-29 "0"
*MEAS_COND_AXIS_OFFSET-3 "1.0906"
*MEAS_COND_AXIS_OFFSET-30 "0"
*MEAS_COND_AXIS_OFFSET-31 "0"
*MEAS_COND_AXIS_OFFSET-32 "0"
*MEAS_COND_AXIS_OFFSET-33 "0"
*MEAS_COND_AXIS_OFFSET-34 "0"
*MEAS_COND_AXIS_OFFSET-35 "0"
*MEAS_COND_AXIS_OFFSET-36 "0"
*MEAS_COND_AXIS_OFFSET-37 "0"
*MEAS_COND_AXIS_OFFSET-38 "0"
*MEAS_COND_AXIS_OFFSET-39 "0"
*MEAS_COND_AXIS_OFFSET-4 "0"
*MEAS_COND_AXIS_OFFSET-40 "0"
*MEAS_COND_AXIS_OFFSET-41 "0"
*MEAS_COND_AXIS_OFFSET-42 "0"
*MEAS_COND_AXIS_OFFSET-43 "0"
*MEAS_COND_AXIS_OFFSET-44 "0"
*MEAS_COND_AXIS_OFFSET-45 "0"
*MEAS_COND_AXIS_OFFSET-46 "0"
*MEAS_COND_AXIS_OFFSET-47 "0"
*MEAS_COND_AXIS_OFFSET-48 "0"
*MEAS_COND_AXIS_OFFSET-49 "0"
*MEAS_COND_AXIS_OFFSET-5 "0"
*MEAS_COND_AXIS_OFFSET-50 "0"
*MEAS_COND_AXIS_OFFSET-51 "0"
*MEAS_COND_AXIS_OFFSET-52 "0"
*MEAS_COND_AXIS_OFFSET-53 "0"
*MEAS_COND_AXIS_OFFSET-54 "0"
*MEAS_COND_AXIS_OFFSET-55 "0"
*MEAS_COND_AXIS_OFFSET-56 "0"
*MEAS_COND_AXIS_OFFSET-57 "0"
*MEAS_COND_AXIS_OFFSET-58 "0"
*MEAS_COND_AXIS_OFFSET-59 "0"
*MEAS_COND_AXIS_OFFSET-6 "0"
*MEAS_COND_AXIS_OFFSET-60 "0"
*MEAS_COND_AXIS_OFFSET-61 "0"
*MEAS_COND_AXIS_OFFSET-62 "0"
*MEAS_COND_AXIS_OFFSET-63 "0"
*MEAS_COND_AXIS_OFFSET-64 "0"
*MEAS_COND_AXIS_OFFSET-65 "0"
*MEAS_COND_AXIS_OFFSET-66 "0"
*MEAS_COND_AXIS_OFFSET-67 "0"
*MEAS_COND_AXIS_OFFSET-68 "0"
*MEAS_COND_AXIS_OFFSET-69 "0"
*MEAS_COND_AXIS_OFFSET-7 "0"
*MEAS_COND_AXIS_OFFSET-70 "0"
*MEAS_COND_AXIS_OFFSET-71 "0"
*MEAS_COND_AXIS_OFFSET-72 "0"
*MEAS_COND_AXIS_OFFSET-73 "0"
*MEAS_COND_AXIS_OFFSET-74 "0"
*MEAS_COND_AXIS_OFFSET-75 "0"
*MEAS_COND_AXIS_OFFSET-76 "0"
*MEAS_COND_AXIS_OFFSET-77 "0"
*MEAS_COND_AXIS_OFFSET-78 "0"
*MEAS_COND_AXIS_OFFSET-79 "0"
*MEAS_COND_AXIS_OFFSET-8 "0"
*MEAS_COND_AXIS_OFFSET-80 "0"
*MEAS_COND_AXIS_OFFSET-81 "0"
*MEAS_COND_AXIS_OFFSET-82 "0"
*MEAS_COND_AXIS_OFFSET-83 "0"
*MEAS_COND_AXIS_OFFSET-84 "0"
*MEAS_COND_AXIS_OFFSET-85 "0"
*MEAS_COND_AXIS_OFFSET-86 "0"
*MEAS_COND_AXIS_OFFSET-87 "0"
*MEAS_COND_AXIS_OFFSET-88 "0"
*MEAS_COND_AXIS_OFFSET-89 "0"
*MEAS_COND_AXIS_OFFSET-9 "0"
*MEAS_COND_AXIS_OFFSET-90 "0"
*MEAS_COND_AXIS_OFFSET-91 "0"
*MEAS_COND_AXIS_OFFSET-92 "0"
*MEAS_COND_AXIS_OFFSET-93 "0"
*MEAS_COND_AXIS_OFFSET-94 "0"
*MEAS_COND_AXIS_OFFSET-95 "0"
*MEAS_COND_AXIS_OFFSET-96 "0"
*MEAS_COND_AXIS_OFFSET-97 "0"
*MEAS_COND_AXIS_OFFSET-98 "0"
*MEAS_COND_AXIS_OFFSET-99 "0"
*MEAS_COND_AXIS_POSITION-0 "16.6214"
*MEAS_COND_AXIS_POSITION-1 "16.5246"
*MEAS_COND_AXIS_POSITION-10 "Right"
*MEAS_COND_AXIS_POSITION-100 "Ge(220)x2"
*MEAS_COND_AXIS_POSITION-101 "PSA_open"
*MEAS_COND_AXIS_POSITION-102 "None"
*MEAS_COND_AXIS_POSITION-11 "None"
*MEAS_COND_AXIS_POSITION-12 "Type1"
*MEAS_COND_AXIS_POSITION-13 "0"
*MEAS_COND_AXIS_POSITION-14 "PB"
*MEAS_COND_AXIS_POSITION-15 "0"
*MEAS_COND_AXIS_POSITION-16 "Soller_slit_open_s"
*MEAS_COND_AXIS_POSITION-17 "0.500mm"
*MEAS_COND_AXIS_POSITION-18 "0.500000"
*MEAS_COND_AXIS_POSITION-19 "0.500mm"
*MEAS_COND_AXIS_POSITION-2 "33.1460"
*MEAS_COND_AXIS_POSITION-20 "-1.9903125"
*MEAS_COND_AXIS_POSITION-21 "2mm"
*MEAS_COND_AXIS_POSITION-22 "2mm"
*MEAS_COND_AXIS_POSITION-23 "2mm"
*MEAS_COND_AXIS_POSITION-24 "38.300"
*MEAS_COND_AXIS_POSITION-25 "73.834"
*MEAS_COND_AXIS_POSITION-26 "-0.9396"
*MEAS_COND_AXIS_POSITION-27 "51.700"
*MEAS_COND_AXIS_POSITION-28 "73.834"
*MEAS_COND_AXIS_POSITION-29 "-0.204"
*MEAS_COND_AXIS_POSITION-3 "16.6214"
*MEAS_COND_AXIS_POSITION-30 "89.64"
*MEAS_COND_AXIS_POSITION-31 "66.092"
*MEAS_COND_AXIS_POSITION-32 "33.1466"
*MEAS_COND_AXIS_POSITION-33 "0.12969"
*MEAS_COND_AXIS_POSITION-34 "-0.10720"
*MEAS_COND_AXIS_POSITION-35 "0.700mm"
*MEAS_COND_AXIS_POSITION-36 "0.700000"
*MEAS_COND_AXIS_POSITION-37 "0.700mm"
*MEAS_COND_AXIS_POSITION-38 "None"
*MEAS_COND_AXIS_POSITION-39 "PSA_open"
*MEAS_COND_AXIS_POSITION-4 "33.1460"
*MEAS_COND_AXIS_POSITION-40 "Soller_slit_5.0deg"
*MEAS_COND_AXIS_POSITION-41 "0.700mm"
*MEAS_COND_AXIS_POSITION-42 "0.700000"
*MEAS_COND_AXIS_POSITION-43 "0.700mm"
*MEAS_COND_AXIS_POSITION-44 "-0.5296875"
*MEAS_COND_AXIS_POSITION-45 "None"
*MEAS_COND_AXIS_POSITION-46 "Open"
*MEAS_COND_AXIS_POSITION-47 "647.0"
*MEAS_COND_AXIS_POSITION-48 "545.00"
*MEAS_COND_AXIS_POSITION-49 "None"
*MEAS_COND_AXIS_POSITION-5 "33.1460"
*MEAS_COND_AXIS_POSITION-50 ""
*MEAS_COND_AXIS_POSITION-51 ""
*MEAS_COND_AXIS_POSITION-52 ""
*MEAS_COND_AXIS_POSITION-53 ""
*MEAS_COND_AXIS_POSITION-54 ""
*MEAS_COND_AXIS_POSITION-55 ""
*MEAS_COND_AXIS_POSITION-56 ""
*MEAS_COND_AXIS_POSITION-57 ""
*MEAS_COND_AXIS_POSITION-58 ""
*MEAS_COND_AXIS_POSITION-59 ""
*MEAS_COND_AXIS_POSITION-6 "16.6214"
*MEAS_COND_AXIS_POSITION-60 ""
*MEAS_COND_AXIS_POSITION-61 ""
*MEAS_COND_AXIS_POSITION-62 ""
*MEAS_COND_AXIS_POSITION-63 ""
*MEAS_COND_AXIS_POSITION-64 ""
*MEAS_COND_AXIS_POSITION-65 ""
*MEAS_COND_AXIS_POSITION-66 ""
*MEAS_COND_AXIS_POSITION-67 ""
*MEAS_COND_AXIS_POSITION-68 ""
*MEAS_COND_AXIS_POSITION-69 ""
*MEAS_COND_AXIS_POSITION-7 "-0.2055"
*MEAS_COND_AXIS_POSITION-70 ""
*MEAS_COND_AXIS_POSITION-71 ""
*MEAS_COND_AXIS_POSITION-72 ""
*MEAS_COND_AXIS_POSITION-73 ""
*MEAS_COND_AXIS_POSITION-74 ""
*MEAS_COND_AXIS_POSITION-75 ""
*MEAS_COND_AXIS_POSITION-76 ""
*MEAS_COND_AXIS_POSITION-77 ""
*MEAS_COND_AXIS_POSITION-78 ""
*MEAS_COND_AXIS_POSITION-79 ""
*MEAS_COND_AXIS_POSITION-8 "None"
*MEAS_COND_AXIS_POSITION-80 ""
*MEAS_COND_AXIS_POSITION-81 ""
*MEAS_COND_AXIS_POSITION-82 ""
*MEAS_COND_AXIS_POSITION-83 ""
*MEAS_COND_AXIS_POSITION-84 ""
*MEAS_COND_AXIS_POSITION-85 ""
*MEAS_COND_AXIS_POSITION-86 ""
*MEAS_COND_AXIS_POSITION-87 ""
*MEAS_COND_AXIS_POSITION-88 ""
*MEAS_COND_AXIS_POSITION-89 ""
*MEAS_COND_AXIS_POSITION-9 "-5.4546875"
*MEAS_COND_AXIS_POSITION-90 ""
*MEAS_COND_AXIS_POSITION-91 ""
*MEAS_COND_AXIS_POSITION-92 ""
*MEAS_COND_AXIS_POSITION-93 ""
*MEAS_COND_AXIS_POSITION-94 ""
*MEAS_COND_AXIS_POSITION-95 ""
*MEAS_COND_AXIS_POSITION-96 ""
*MEAS_COND_AXIS_POSITION-97 ""
*MEAS_COND_AXIS_POSITION-98 ""
*MEAS_COND_AXIS_POSITION-99 "Standard"
*MEAS_COND_AXIS_RESOLUTION-0 "0.0001"
*MEAS_COND_AXIS_RESOLUTION-1 "0.0001"
*MEAS_COND_AXIS_RESOLUTION-10 ""
*MEAS_COND_AXIS_RESOLUTION-11 ""
*MEAS_COND_AXIS_RESOLUTION-12 ""
*MEAS_COND_AXIS_RESOLUTION-13 "1"
*MEAS_COND_AXIS_RESOLUTION-14 ""
*MEAS_COND_AXIS_RESOLUTION-15 "1"
*MEAS_COND_AXIS_RESOLUTION-16 ""
*MEAS_COND_AXIS_RESOLUTION-17 "1/1600"
*MEAS_COND_AXIS_RESOLUTION-18 "1/1600"
*MEAS_COND_AXIS_RESOLUTION-19 "1/1600"
*MEAS_COND_AXIS_RESOLUTION-2 "0.0001"
*MEAS_COND_AXIS_RESOLUTION-20 "0.0003125"
*MEAS_COND_AXIS_RESOLUTION-21 ""
*MEAS_COND_AXIS_RESOLUTION-22 ""
*MEAS_COND_AXIS_RESOLUTION-23 ""
*MEAS_COND_AXIS_RESOLUTION-24 "0.001"
*MEAS_COND_AXIS_RESOLUTION-25 "0.002"
*MEAS_COND_AXIS_RESOLUTION-26 "0.0001"
*MEAS_COND_AXIS_RESOLUTION-27 "0.001"
*MEAS_COND_AXIS_RESOLUTION-28 "0.002"
*MEAS_COND_AXIS_RESOLUTION-29 "0.004"
*MEAS_COND_AXIS_RESOLUTION-3 "0.0001"
*MEAS_COND_AXIS_RESOLUTION-30 "0.01"
*MEAS_COND_AXIS_RESOLUTION-31 "0.002"
*MEAS_COND_AXIS_RESOLUTION-32 "0.0001"
*MEAS_COND_AXIS_RESOLUTION-33 "0.00099"
*MEAS_COND_AXIS_RESOLUTION-34 "0.00134"
*MEAS_COND_AXIS_RESOLUTION-35 "1/1600"
*MEAS_COND_AXIS_RESOLUTION-36 "1/1600"
*MEAS_COND_AXIS_RESOLUTION-37 "1/1600"
*MEAS_COND_AXIS_RESOLUTION-38 ""
*MEAS_COND_AXIS_RESOLUTION-39 ""
*MEAS_COND_AXIS_RESOLUTION-4 "0.0002"
*MEAS_COND_AXIS_RESOLUTION-40 ""
*MEAS_COND_AXIS_RESOLUTION-41 "1/1600"
*MEAS_COND_AXIS_RESOLUTION-42 "1/1600"
*MEAS_COND_AXIS_RESOLUTION-43 "1/1600"
*MEAS_COND_AXIS_RESOLUTION-44 "0.0003125"
*MEAS_COND_AXIS_RESOLUTION-45 ""
*MEAS_COND_AXIS_RESOLUTION-46 "1/800"
*MEAS_COND_AXIS_RESOLUTION-47 "0.5"
*MEAS_COND_AXIS_RESOLUTION-48 "1.25"
*MEAS_COND_AXIS_RESOLUTION-49 ""
*MEAS_COND_AXIS_RESOLUTION-5 "0.0002"
*MEAS_COND_AXIS_RESOLUTION-50 "0.010000"
*MEAS_COND_AXIS_RESOLUTION-51 "0.010000"
*MEAS_COND_AXIS_RESOLUTION-52 "0.01"
*MEAS_COND_AXIS_RESOLUTION-53 "0.010000"
*MEAS_COND_AXIS_RESOLUTION-54 "0.01"
*MEAS_COND_AXIS_RESOLUTION-55 "1.000000"
*MEAS_COND_AXIS_RESOLUTION-56 "1.000000"
*MEAS_COND_AXIS_RESOLUTION-57 "1"
*MEAS_COND_AXIS_RESOLUTION-58 "1"
*MEAS_COND_AXIS_RESOLUTION-59 "0.01"
*MEAS_COND_AXIS_RESOLUTION-6 "0.0001"
*MEAS_COND_AXIS_RESOLUTION-60 "0.01"
*MEAS_COND_AXIS_RESOLUTION-61 "0.01"
*MEAS_COND_AXIS_RESOLUTION-62 "0.01"
*MEAS_COND_AXIS_RESOLUTION-63 "0.010000"
*MEAS_COND_AXIS_RESOLUTION-64 "1"
*MEAS_COND_AXIS_RESOLUTION-65 "0.1"
*MEAS_COND_AXIS_RESOLUTION-66 "1"
*MEAS_COND_AXIS_RESOLUTION-67 "0.010000"
*MEAS_COND_AXIS_RESOLUTION-68 "0.01"
*MEAS_COND_AXIS_RESOLUTION-69 "0.01"
*MEAS_COND_AXIS_RESOLUTION-7 "0.0005"
*MEAS_COND_AXIS_RESOLUTION-70 "0.100000"
*MEAS_COND_AXIS_RESOLUTION-71 "1.000000"
*MEAS_COND_AXIS_RESOLUTION-72 "0.01"
*MEAS_COND_AXIS_RESOLUTION-73 "1.000000"
*MEAS_COND_AXIS_RESOLUTION-74 "1"
*MEAS_COND_AXIS_RESOLUTION-75 "1.000000"
*MEAS_COND_AXIS_RESOLUTION-76 "1"
*MEAS_COND_AXIS_RESOLUTION-77 "0.01"
*MEAS_COND_AXIS_RESOLUTION-78 "1"
*MEAS_COND_AXIS_RESOLUTION-79 "1"
*MEAS_COND_AXIS_RESOLUTION-8 ""
*MEAS_COND_AXIS_RESOLUTION-80 "1"
*MEAS_COND_AXIS_RESOLUTION-81 "0.01"
*MEAS_COND_AXIS_RESOLUTION-82 "1.000000"
*MEAS_COND_AXIS_RESOLUTION-83 "1.000000"
*MEAS_COND_AXIS_RESOLUTION-84 "1.000000"
*MEAS_COND_AXIS_RESOLUTION-85 "-"
*MEAS_COND_AXIS_RESOLUTION-86 "-"
*MEAS_COND_AXIS_RESOLUTION-87 "-"
*MEAS_COND_AXIS_RESOLUTION-88 "1.000000"
*MEAS_COND_AXIS_RESOLUTION-89 "-"
*MEAS_COND_AXIS_RESOLUTION-9 "0.0000625"
*MEAS_COND_AXIS_RESOLUTION-90 "-"
*MEAS_COND_AXIS_RESOLUTION-91 "-"
*MEAS_COND_AXIS_RESOLUTION-92 "1.000000"
*MEAS_COND_AXIS_RESOLUTION-93 "1.000000"
*MEAS_COND_AXIS_RESOLUTION-94 "1.000000"
*MEAS_COND_AXIS_RESOLUTION-95 "1.000000"
*MEAS_COND_AXIS_RESOLUTION-96 "1.000000"
*MEAS_COND_AXIS_RESOLUTION-97 "1.000000"
*MEAS_COND_AXIS_RESOLUTION-98 "1.000000"
*MEAS_COND_AXIS_STATE-0 "Fixed"
*MEAS_COND_AXIS_STATE-1 "Fixed"
*MEAS_COND_AXIS_STATE-10 "Fixed"
*MEAS_COND_AXIS_STATE-11 "Fixed"
*MEAS_COND_AXIS_STATE-12 "Fixed"
*MEAS_COND_AXIS_STATE-13 "Fixed"
*MEAS_COND_AXIS_STATE-14 "Fixed"
*MEAS_COND_AXIS_STATE-15 "Fixed"
*MEAS_COND_AXIS_STATE-16 "Fixed"
*MEAS_COND_AXIS_STATE-17 "Fixed"
*MEAS_COND_AXIS_STATE-18 "Fixed"
*MEAS_COND_AXIS_STATE-19 "Fixed"
*MEAS_COND_AXIS_STATE-2 "Fixed"
*MEAS_COND_AXIS_STATE-20 "Fixed"
*MEAS_COND_AXIS_STATE-21 "Fixed"
*MEAS_COND_AXIS_STATE-22 "Fixed"
*MEAS_COND_AXIS_STATE-23 "Fixed"
*MEAS_COND_AXIS_STATE-24 "Fixed"
*MEAS_COND_AXIS_STATE-25 "Scan"
*MEAS_COND_AXIS_STATE-26 "Fixed"
*MEAS_COND_AXIS_STATE-27 "Fixed"
*MEAS_COND_AXIS_STATE-28 "Fixed"
*MEAS_COND_AXIS_STATE-29 "Fixed"
*MEAS_COND_AXIS_STATE-3 "Fixed"
*MEAS_COND_AXIS_STATE-30 "Fixed"
*MEAS_COND_AXIS_STATE-31 "Fixed"
*MEAS_COND_AXIS_STATE-32 "Fixed"
*MEAS_COND_AXIS_STATE-33 "Fixed"
*MEAS_COND_AXIS_STATE-34 "Fixed"
*MEAS_COND_AXIS_STATE-35 "Fixed"
*MEAS_COND_AXIS_STATE-36 "Fixed"
*MEAS_COND_AXIS_STATE-37 "Fixed"
*MEAS_COND_AXIS_STATE-38 "Fixed"
*MEAS_COND_AXIS_STATE-39 "Fixed"
*MEAS_COND_AXIS_STATE-4 "Fixed"
*MEAS_COND_AXIS_STATE-40 "Fixed"
*MEAS_COND_AXIS_STATE-41 "Fixed"
*MEAS_COND_AXIS_STATE-42 "Fixed"
*MEAS_COND_AXIS_STATE-43 "Fixed"
*MEAS_COND_AXIS_STATE-44 "Fixed"
*MEAS_COND_AXIS_STATE-45 "Fixed"
*MEAS_COND_AXIS_STATE-46 "Fixed"
*MEAS_COND_AXIS_STATE-47 "Fixed"
*MEAS_COND_AXIS_STATE-48 "Fixed"
*MEAS_COND_AXIS_STATE-49 "Fixed"
*MEAS_COND_AXIS_STATE-5 "Fixed"
*MEAS_COND_AXIS_STATE-50 "Fixed"
*MEAS_COND_AXIS_STATE-51 "Fixed"
*MEAS_COND_AXIS_STATE-52 "Fixed"
*MEAS_COND_AXIS_STATE-53 "Fixed"
*MEAS_COND_AXIS_STATE-54 "Fixed"
*MEAS_COND_AXIS_STATE-55 "Fixed"
*MEAS_COND_AXIS_STATE-56 "Fixed"
*MEAS_COND_AXIS_STATE-57 "Fixed"
*MEAS_COND_AXIS_STATE-58 "Fixed"
*MEAS_COND_AXIS_STATE-59 "Fixed"
*MEAS_COND_AXIS_STATE-6 "Fixed"
*MEAS_COND_AXIS_STATE-60 "Fixed"
*MEAS_COND_AXIS_STATE-61 "Fixed"
*MEAS_COND_AXIS_STATE-62 "Fixed"
*MEAS_COND_AXIS_STATE-63 "Fixed"
*MEAS_COND_AXIS_STATE-64 "Fixed"
*MEAS_COND_AXIS_STATE-65 "Fixed"
*MEAS_COND_AXIS_STATE-66 "Fixed"
*MEAS_COND_AXIS_STATE-67 "Fixed"
*MEAS_COND_AXIS_STATE-68 "Fixed"
*MEAS_COND_AXIS_STATE-69 "Fixed"
*MEAS_COND_AXIS_STATE-7 "Fixed"
*MEAS_COND_AXIS_STATE-70 "Fixed"
*MEAS_COND_AXIS_STATE-71 "Fixed"
*MEAS_COND_AXIS_STATE-72 "Fixed"
*MEAS_COND_AXIS_STATE-73 "Fixed"
*MEAS_COND_AXIS_STATE-74 "Fixed"
*MEAS_COND_AXIS_STATE-75 "Fixed"
*MEAS_COND_AXIS_STATE-76 "Fixed"
*MEAS_COND_AXIS_STATE-77 "Fixed"
*MEAS_COND_AXIS_STATE-78 "Fixed"
*MEAS_COND_AXIS_STATE-79 "Fixed"
*MEAS_COND_AXIS_STATE-8 "Fixed"
*MEAS_COND_AXIS_STATE-80 "Fixed"
*MEAS_COND_AXIS_STATE-81 "Fixed"
*MEAS_COND_AXIS_STATE-82 "Fixed"
*MEAS_COND_AXIS_STATE-83 "Fixed"
*MEAS_COND_AXIS_STATE-84 "Fixed"
*MEAS_COND_AXIS_STATE-85 "Fixed"
*MEAS_COND_AXIS_STATE-86 "Fixed"
*MEAS_COND_AXIS_STATE-87 "Fixed"
*MEAS_COND_AXIS_STATE-88 "Fixed"
*MEAS_COND_AXIS_STATE-89 "Fixed"
*MEAS_COND_AXIS_STATE-9 "Fixed"
*MEAS_COND_AXIS_STATE-90 "Fixed"
*MEAS_COND_AXIS_STATE-91 "Fixed"
*MEAS_COND_AXIS_STATE-92 "Fixed"
*MEAS_COND_AXIS_STATE-93 "Fixed"
*MEAS_COND_AXIS_STATE-94 "Fixed"
*MEAS_COND_AXIS_STATE-95 "Fixed"
*MEAS_COND_AXIS_STATE-96 "Fixed"
*MEAS_COND_AXIS_STATE-97 "Fixed"
*MEAS_COND_AXIS_STATE-98 "Fixed"
*MEAS_COND_AXIS_UNIT-0 "deg"
*MEAS_COND_AXIS_UNIT-1 "deg"
*MEAS_COND_AXIS_UNIT-10 ""
*MEAS_COND_AXIS_UNIT-100 ""
*MEAS_COND_AXIS_UNIT-101 ""
*MEAS_COND_AXIS_UNIT-102 ""
*MEAS_COND_AXIS_UNIT-11 ""
*MEAS_COND_AXIS_UNIT-12 ""
*MEAS_COND_AXIS_UNIT-13 "pulse"
*MEAS_COND_AXIS_UNIT-14 ""
*MEAS_COND_AXIS_UNIT-15 "pulse"
*MEAS_COND_AXIS_UNIT-16 ""
*MEAS_COND_AXIS_UNIT-17 ""
*MEAS_COND_AXIS_UNIT-18 "mm"
*MEAS_COND_AXIS_UNIT-19 ""
*MEAS_COND_AXIS_UNIT-2 "deg"
*MEAS_COND_AXIS_UNIT-20 "mm"
*MEAS_COND_AXIS_UNIT-21 ""
*MEAS_COND_AXIS_UNIT-22 ""
*MEAS_COND_AXIS_UNIT-23 ""
*MEAS_COND_AXIS_UNIT-24 "deg"
*MEAS_COND_AXIS_UNIT-25 "deg"
*MEAS_COND_AXIS_UNIT-26 "mm"
*MEAS_COND_AXIS_UNIT-27 "deg"
*MEAS_COND_AXIS_UNIT-28 "deg"
*MEAS_COND_AXIS_UNIT-29 "deg"
*MEAS_COND_AXIS_UNIT-3 "deg"
*MEAS_COND_AXIS_UNIT-30 "deg"
*MEAS_COND_AXIS_UNIT-31 "deg"
*MEAS_COND_AXIS_UNIT-32 "deg"
*MEAS_COND_AXIS_UNIT-33 "deg"
*MEAS_COND_AXIS_UNIT-34 "deg"
*MEAS_COND_AXIS_UNIT-35 ""
*MEAS_COND_AXIS_UNIT-36 "mm"
*MEAS_COND_AXIS_UNIT-37 ""
*MEAS_COND_AXIS_UNIT-38 ""
*MEAS_COND_AXIS_UNIT-39 ""
*MEAS_COND_AXIS_UNIT-4 "deg"
*MEAS_COND_AXIS_UNIT-40 ""
*MEAS_COND_AXIS_UNIT-41 ""
*MEAS_COND_AXIS_UNIT-42 "mm"
*MEAS_COND_AXIS_UNIT-43 ""
*MEAS_COND_AXIS_UNIT-44 "mm"
*MEAS_COND_AXIS_UNIT-45 ""
*MEAS_COND_AXIS_UNIT-46 ""
*MEAS_COND_AXIS_UNIT-47 "V"
*MEAS_COND_AXIS_UNIT-48 "mV"
*MEAS_COND_AXIS_UNIT-49 ""
*MEAS_COND_AXIS_UNIT-5 "deg"
*MEAS_COND_AXIS_UNIT-50 "H"
*MEAS_COND_AXIS_UNIT-51 "H"
*MEAS_COND_AXIS_UNIT-52 "H"
*MEAS_COND_AXIS_UNIT-53 "H"
*MEAS_COND_AXIS_UNIT-54 "H"
*MEAS_COND_AXIS_UNIT-55 "mV"
*MEAS_COND_AXIS_UNIT-56 "V"
*MEAS_COND_AXIS_UNIT-57 "V"
*MEAS_COND_AXIS_UNIT-58 "V"
*MEAS_COND_AXIS_UNIT-59 "H"
*MEAS_COND_AXIS_UNIT-6 "deg"
*MEAS_COND_AXIS_UNIT-60 "H"
*MEAS_COND_AXIS_UNIT-61 "H"
*MEAS_COND_AXIS_UNIT-62 "H"
*MEAS_COND_AXIS_UNIT-63 "H"
*MEAS_COND_AXIS_UNIT-64 "uS/m"
*MEAS_COND_AXIS_UNIT-65 "L/min"
*MEAS_COND_AXIS_UNIT-66 "C"
*MEAS_COND_AXIS_UNIT-67 "MPa"
*MEAS_COND_AXIS_UNIT-68 "MPa"
*MEAS_COND_AXIS_UNIT-69 "MPa"
*MEAS_COND_AXIS_UNIT-7 "deg"
*MEAS_COND_AXIS_UNIT-70 "L/min"
*MEAS_COND_AXIS_UNIT-71 "degree"
*MEAS_COND_AXIS_UNIT-72 "MPa"
*MEAS_COND_AXIS_UNIT-73 "degree"
*MEAS_COND_AXIS_UNIT-74 "percent"
*MEAS_COND_AXIS_UNIT-75 "degree"
*MEAS_COND_AXIS_UNIT-76 "C"
*MEAS_COND_AXIS_UNIT-77 "H"
*MEAS_COND_AXIS_UNIT-78 "time"
*MEAS_COND_AXIS_UNIT-79 "msec"
*MEAS_COND_AXIS_UNIT-8 ""
*MEAS_COND_AXIS_UNIT-80 "msec"
*MEAS_COND_AXIS_UNIT-81 "H"
*MEAS_COND_AXIS_UNIT-82 "times"
*MEAS_COND_AXIS_UNIT-83 "msec"
*MEAS_COND_AXIS_UNIT-84 "msec"
*MEAS_COND_AXIS_UNIT-85 "-"
*MEAS_COND_AXIS_UNIT-86 "-"
*MEAS_COND_AXIS_UNIT-87 "-"
*MEAS_COND_AXIS_UNIT-88 ""
*MEAS_COND_AXIS_UNIT-89 "-"
*MEAS_COND_AXIS_UNIT-9 "mm"
*MEAS_COND_AXIS_UNIT-90 "-"
*MEAS_COND_AXIS_UNIT-91 "-"
*MEAS_COND_AXIS_UNIT-92 ""
*MEAS_COND_AXIS_UNIT-93 ""
*MEAS_COND_AXIS_UNIT-94 ""
*MEAS_COND_AXIS_UNIT-95 ""
*MEAS_COND_AXIS_UNIT-96 ""
*MEAS_COND_AXIS_UNIT-97 ""
*MEAS_COND_AXIS_UNIT-98 ""
*MEAS_COND_AXIS_UNIT-99 ""
*MEAS_COND_OPT_ATTR "PB-Ge(220)x2"
*MEAS_COND_OPT_NAME "User defined settings"
*MEAS_COND_XG_CURRENT "160"
*MEAS_COND_XG_VOLTAGE "45"
*MEAS_COND_XG_WAVE_TYPE "Ka1"
*MEAS_DATA_COUNT "3601"
*MEAS_SCAN_AXIS_X "Phi"
*MEAS_SCAN_AXIS_X_INTERNAL "Phi"
*MEAS_SCAN_END_TIME "10/15/2020 13:04:29"
*MEAS_SCAN_MODE "CONTINUOUS"
*MEAS_SCAN_MODE_INTERNAL "CONTINUOUS"
*MEAS_SCAN_RESOLUTION_X "0.002"
*MEAS_SCAN_SPEED "36.000"
*MEAS_SCAN_SPEED_UNIT "deg/min"
*MEAS_SCAN_START "0.000"
*MEAS_SCAN_START_TIME "10/15/2020 12:54:10"
*MEAS_SCAN_STEP "0.100"
*MEAS_SCAN_STOP "360.000"
*MEAS_SCAN_UNIT_X "deg"
*MEAS_SCAN_UNIT_Y "counts"
*RAS_HEADER_END
*RAS_INT_START
0.000 0.0000 1.0000
0.300 0.0000 1.0000
0.600 0.0000 1.0000
0.900 0.0000 1.0000
1.200 0.0000 1.0000
1.500 1.0000 1.0000
1.800 1.0000 1.0000
2.100 0.0000 1.0000
2.400 0.0000 1.0000
2.700 0.0000 1.0000
3.000 1.0000 1.0000
3.300 0.0000 1.0000
3.600 0.0000 1.0000
3.900 0.0000 1.0000
4.200 0.0000 1.0000
4.500 0.0000 1.0000
4.800 0.0000 1.0000
5.100 0.0000 1.0000
5.400 0.0000 1.0000
5.700 0.0000 1.0000
6.000 0.0000 1.0000
6.300 0.0000 1.0000
6.600 0.0000 1.0000
6.900 0.0000 1.0000
7.200 0.0000 1.0000
7.500 0.0000 1.0000
7.800 0.0000 1.0000
8.100 0.0000 1.0000
8.400 0.0000 1.0000
8.700 0.0000 1.0000
9.000 0.0000 1.0000
9.300 0.0000 1.0000
9.600 1.0000 1.0000
9.900 0.0000 1.0000
10.200 0.0000 1.0000
10.500 0.0000 1.0000
10.800 0.0000 1.0000
11.100 0.0000 1.0000
11.400 0.0000 1.0000
11.700 1.0000 1.0000
12.000 0.0000 1.0000
12.300 0.0000 1.0000
12.600 0.0000 1.0000
12.900 0.0000 1.0000
13.200 0.0000 1.0000
13.500 0.0000 1.0000
13.800 0.0000 1.0000
14.100 0.0000 1.0000
14.400 0.0000 1.0000
14.700 0.0000 1.0000
15.000 0.0000 1.0000
15.300 0.0000 1.0000
15.600 0.0000 1.0000
15.900 0.0000 1.0000
16.200 0.0000 1.0000
16.500 0.0000 1.0000
16.800 0.0000 1.0000
17.100 0.0000 1.0000
17.400 0.0000 1.0000
17.700 1.0000 1.0000
18.000 0.0000 1.0000
18.300 0.0000 1.0000
18.600 0.0000 1.0000
18.900 0.0000 1.0000
19.200 1.0000 1.0000
19.500 0.0000 1.0000
19.800 0.0000 1.0000
20.100 0.0000 1.0000
20.400 0.0000 1.0000
20.700 0.0000 1.0000
21.000 0.0000 1.0000
21.300 0.0000 1.0000
21.600 0.0000 1.0000
21.900 0.0000 1.0000
22.200 0.0000 1.0000
22.500 0.0000 1.0000
22.800 0.0000 1.0000
23.100 0.0000 1.0000
23.400 0.0000 1.0000
23.700 0.0000 1.0000
24.000 0.0000 1.0000
24.300 0.0000 1.0000
24.600 0.0000 1.0000
24.900 0.0000 1.0000
25.200 0.0000 1.0000
25.500 0.0000 1.0000
25.800 0.0000 1.0000
26.100 0.0000 1.0000
26.400 0.0000 1.0000
26.700 0.0000 1.0000
27.000 0.0000 1.0000
27.300 0.0000 1.0000
27.600 0.0000 1.0000
27.900 0.0000 1.0000
28.200 0.0000 1.0000
28.500 0.0000 1.0000
28.800 1.0000 1.0000
29.100 0.0000 1.0000
29.400 0.0000 1.0000
29.700 0.0000 1.0000
30.000 0.0000 1.0000
30.300 0.0000 1.0000
30.600 0.0000 1.0000
30.900 0.0000 1.0000
31.200 0.0000 1.0000
31.500 0.0000 1.0000
31.800 0.0000 1.0000
32.100 0.0000 1.0000
32.400 0.0000 1.0000
32.700 0.0000 1.0000
33.000 0.0000 1.0000
33.300 0.0000 1.0000
33.600 0.0000 1.0000
33.900 0.0000 1.0000
34.200 0.0000 1.0000
34.500 0.0000 1.0000
34.800 0.0000 1.0000
35.100 0.0000 1.0000
35.400 0.0000 1.0000
35.700 0.0000 1.0000
36.000 0.0000 1.0000
36.300 0.0000 1.0000
36.600 2.0000 1.0000
36.900 0.0000 1.0000
37.200 0.0000 1.0000
37.500 0.0000 1.0000
37.800 0.0000 1.0000
38.100 0.0000 1.0000
38.400 1.0000 1.0000
38.700 0.0000 1.0000
39.000 0.0000 1.0000
39.300 0.0000 1.0000
39.600 1.0000 1.0000
39.900 0.0000 1.0000
40.200 0.0000 1.0000
40.500 0.0000 1.0000
40.800 0.0000 1.0000
41.100 0.0000 1.0000
41.400 0.0000 1.0000
41.700 0.0000 1.0000
42.000 0.0000 1.0000
42.300 1.0000 1.0000
42.600 0.0000 1.0000
42.900 0.0000 1.0000
43.200 0.0000 1.0000
43.500 0.0000 1.0000
43.800 0.0000 1.0000
44.100 0.0000 1.0000
44.400 0.0000 1.0000
44.700 0.0000 1.0000
45.000 0.0000 1.0000
45.300 0.0000 1.0000
45.600 0.0000 1.0000
45.900 0.0000 1.0000
46.200 0.0000 1.0000
46.500 0.0000 1.0000
46.800 0.0000 1.0000
47.100 0.0000 1.0000
47.400 1.0000 1.0000
47.700 0.0000 1.0000
48.000 0.0000 1.0000
48.300 0.0000 1.0000
48.600 0.0000 1.0000
48.900 0.0000 1.0000
49.200 0.0000 1.0000
49.500 0.0000 1.0000
49.800 0.0000 1.0000
50.100 0.0000 1.0000
50.400 0.0000 1.0000
50.700 0.0000 1.0000
51.000 0.0000 1.0000
51.300 0.0000 1.0000
51.600 0.0000 1.0000
51.900 0.0000 1.0000
52.200 0.0000 1.0000
52.500 0.0000 1.0000
52.800 0.0000 1.0000
53.100 0.0000 1.0000
53.400 0.0000 1.0000
53.700 0.0000 1.0000
54.000 0.0000 1.0000
54.300 0.0000 1.0000
54.600 0.0000 1.0000
54.900 0.0000 1.0000
55.200 0.0000 1.0000
55.500 0.0000 1.0000
55.800 0.0000 1.0000
56.100 0.0000 1.0000
56.400 0.0000 1.0000
56.700 0.0000 1.0000
57.000 0.0000 1.0000
57.300 0.0000 1.0000
57.600 1.0000 1.0000
57.900 0.0000 1.0000
58.200 0.0000 1.0000
58.500 0.0000 1.0000
58.800 0.0000 1.0000
59.100 0.0000 1.0000
59.400 0.0000 1.0000
59.700 0.0000 1.0000
60.000 0.0000 1.0000
60.300 1.0000 1.0000
60.600 0.0000 1.0000
60.900 0.0000 1.0000
61.200 0.0000 1.0000
61.500 0.0000 1.0000
61.800 0.0000 1.0000
62.100 0.0000 1.0000
62.400 1.0000 1.0000
62.700 0.0000 1.0000
63.000 0.0000 1.0000
63.300 0.0000 1.0000
63.600 0.0000 1.0000
63.900 0.0000 1.0000
64.200 0.0000 1.0000
64.500 1.0000 1.0000
64.800 0.0000 1.0000
65.100 0.0000 1.0000
65.400 0.0000 1.0000
65.700 1.0000 1.0000
66.000 0.0000 1.0000
66.300 0.0000 1.0000
66.600 0.0000 1.0000
66.900 0.0000 1.0000
67.200 0.0000 1.0000
67.500 0.0000 1.0000
67.800 0.0000 1.0000
68.100 1.0000 1.0000
68.400 0.0000 1.0000
68.700 0.0000 1.0000
69.000 0.0000 1.0000
69.300 0.0000 1.0000
69.600 0.0000 1.0000
69.900 0.0000 1.0000
70.200 0.0000 1.0000
70.500 1.0000 1.0000
70.800 0.0000 1.0000
71.100 0.0000 1.0000
71.400 0.0000 1.0000
71.700 0.0000 1.0000
72.000 1.0000 1.0000
72.300 3.0000 1.0000
72.600 2.0000 1.0000
72.900 2.0000 1.0000
73.200 8.0000 1.0000
73.500 15.0000 1.0000
73.800 17.0000 1.0000
74.100 10.0000 1.0000
74.400 7.0000 1.0000
74.700 4.0000 1.0000
75.000 1.0000 1.0000
75.300 3.0000 1.0000
75.600 0.0000 1.0000
75.900 0.0000 1.0000
76.200 0.0000 1.0000
76.500 0.0000 1.0000
76.800 0.0000 1.0000
77.100 0.0000 1.0000
77.400 0.0000 1.0000
77.700 0.0000 1.0000
78.000 0.0000 1.0000
78.300 0.0000 1.0000
78.600 0.0000 1.0000
78.900 0.0000 1.0000
79.200 0.0000 1.0000
79.500 0.0000 1.0000
79.800 0.0000 1.0000
80.100 0.0000 1.0000
80.400 0.0000 1.0000
80.700 0.0000 1.0000
81.000 0.0000 1.0000
81.300 0.0000 1.0000
81.600 0.0000 1.0000
81.900 0.0000 1.0000
82.200 0.0000 1.0000
82.500 0.0000 1.0000
82.800 0.0000 1.0000
83.100 0.0000 1.0000
83.400 0.0000 1.0000
83.700 0.0000 1.0000
84.000 0.0000 1.0000
84.300 1.0000 1.0000
84.600 0.0000 1.0000
84.900 0.0000 1.0000
85.200 0.0000 1.0000
85.500 0.0000 1.0000
85.800 0.0000 1.0000
86.100 0.0000 1.0000
86.400 0.0000 1.0000
86.700 0.0000 1.0000
87.000 0.0000 1.0000
87.300 0.0000 1.0000
87.600 0.0000 1.0000
87.900 0.0000 1.0000
88.200 0.0000 1.0000
88.500 0.0000 1.0000
88.800 0.0000 1.0000
89.100 0.0000 1.0000
89.400 0.0000 1.0000
89.700 0.0000 1.0000
90.000 0.0000 1.0000
90.300 0.0000 1.0000
90.600 0.0000 1.0000
90.900 1.0000 1.0000
91.200 0.0000 1.0000
91.500 0.0000 1.0000
91.800 0.0000 1.0000
92.100 0.0000 1.0000
92.400 0.0000 1.0000
92.700 0.0000 1.0000
93.000 0.0000 1.0000
93.300 0.0000 1.0000
93.600 0.0000 1.0000
93.900 0.0000 1.0000
94.200 0.0000 1.0000
94.500 0.0000 1.0000
94.800 0.0000 1.0000
95.100 1.0000 1.0000
95.400 0.0000 1.0000
95.700 0.0000 1.0000
96.000 0.0000 1.0000
96.300 0.0000 1.0000
96.600 1.0000 1.0000
96.900 0.0000 1.0000
97.200 0.0000 1.0000
97.500 0.0000 1.0000
97.800 0.0000 1.0000
98.100 0.0000 1.0000
98.400 0.0000 1.0000
98.700 0.0000 1.0000
99.000 0.0000 1.0000
99.300 0.0000 1.0000
99.600 0.0000 1.0000
99.900 0.0000 1.0000
100.200 0.0000 1.0000
100.500 0.0000 1.0000
100.800 0.0000 1.0000
101.100 0.0000 1.0000
101.400 0.0000 1.0000
101.700 0.0000 1.0000
102.000 0.0000 1.0000
102.300 0.0000 1.0000
102.600 0.0000 1.0000
102.900 1.0000 1.0000
103.200 0.0000 1.0000
103.500 0.0000 1.0000
103.800 0.0000 1.0000
104.100 0.0000 1.0000
104.400 0.0000 1.0000
104.700 0.0000 1.0000
105.000 0.0000 1.0000
105.300 1.0000 1.0000
105.600 0.0000 1.0000
105.900 0.0000 1.0000
106.200 0.0000 1.0000
106.500 0.0000 1.0000
106.800 0.0000 1.0000
107.100 0.0000 1.0000
107.400 0.0000 1.0000
107.700 0.0000 1.0000
108.000 0.0000 1.0000
108.300 0.0000 1.0000
108.600 0.0000 1.0000
108.900 0.0000 1.0000
109.200 0.0000 1.0000
109.500 0.0000 1.0000
109.800 0.0000 1.0000
110.100 0.0000 1.0000
110.400 0.0000 1.0000
110.700 0.0000 1.0000
111.000 0.0000 1.0000
111.300 0.0000 1.0000
111.600 0.0000 1.0000
111.900 1.0000 1.0000
112.200 0.0000 1.0000
112.500 0.0000 1.0000
112.800 0.0000 1.0000
113.100 0.0000 1.0000
113.400 0.0000 1.0000
113.700 0.0000 1.0000
114.000 0.0000 1.0000
114.300 0.0000 1.0000
114.600 0.0000 1.0000
114.900 0.0000 1.0000
115.200 0.0000 1.0000
115.500 0.0000 1.0000
115.800 0.0000 1.0000
116.100 0.0000 1.0000
116.400 0.0000 1.0000
116.700 0.0000 1.0000
117.000 0.0000 1.0000
117.300 0.0000 1.0000
117.600 0.0000 1.0000
117.900 0.0000 1.0000
118.200 0.0000 1.0000
118.500 1.0000 1.0000
118.800 0.0000 1.0000
119.100 0.0000 1.0000
119.400 0.0000 1.0000
119.700 0.0000 1.0000
120.000 0.0000 1.0000
120.300 0.0000 1.0000
120.600 0.0000 1.0000
120.900 1.0000 1.0000
121.200 0.0000 1.0000
121.500 0.0000 1.0000
121.800 0.0000 1.0000
122.100 0.0000 1.0000
122.400 0.0000 1.0000
122.700 0.0000 1.0000
123.000 0.0000 1.0000
123.300 0.0000 1.0000
123.600 0.0000 1.0000
123.900 0.0000 1.0000
124.200 0.0000 1.0000
124.500 0.0000 1.0000
124.800 0.0000 1.0000
125.100 0.0000 1.0000
125.400 0.0000 1.0000
125.700 0.0000 1.0000
126.000 0.0000 1.0000
126.300 0.0000 1.0000
126.600 0.0000 1.0000
126.900 0.0000 1.0000
127.200 0.0000 1.0000
127.500 0.0000 1.0000
127.800 0.0000 1.0000
128.100 0.0000 1.0000
128.400 0.0000 1.0000
128.700 0.0000 1.0000
129.000 0.0000 1.0000
129.300 0.0000 1.0000
129.600 0.0000 1.0000
129.900 0.0000 1.0000
130.200 0.0000 1.0000
130.500 0.0000 1.0000
130.800 0.0000 1.0000
131.100 0.0000 1.0000
131.400 0.0000 1.0000
131.700 0.0000 1.0000
132.000 0.0000 1.0000
132.300 1.0000 1.0000
132.600 0.0000 1.0000
132.900 0.0000 1.0000
133.200 0.0000 1.0000
133.500 0.0000 1.0000
133.800 0.0000 1.0000
134.100 0.0000 1.0000
134.400 0.0000 1.0000
134.700 0.0000 1.0000
135.000 0.0000 1.0000
135.300 0.0000 1.0000
135.600 0.0000 1.0000
135.900 0.0000 1.0000
136.200 0.0000 1.0000
136.500 0.0000 1.0000
136.800 0.0000 1.0000
137.100 0.0000 1.0000
137.400 0.0000 1.0000
137.700 1.0000 1.0000
138.000 0.0000 1.0000
138.300 0.0000 1.0000
138.600 0.0000 1.0000
138.900 0.0000 1.0000
139.200 0.0000 1.0000
139.500 0.0000 1.0000
139.800 0.0000 1.0000
140.100 0.0000 1.0000
140.400 0.0000 1.0000
140.700 0.0000 1.0000
141.000 0.0000 1.0000
141.300 0.0000 1.0000
141.600 0.0000 1.0000
141.900 0.0000 1.0000
142.200 0.0000 1.0000
142.500 0.0000 1.0000
142.800 0.0000 1.0000
143.100 0.0000 1.0000
143.400 0.0000 1.0000
143.700 0.0000 1.0000
144.000 0.0000 1.0000
144.300 0.0000 1.0000
144.600 1.0000 1.0000
144.900 0.0000 1.0000
145.200 0.0000 1.0000
145.500 0.0000 1.0000
145.800 0.0000 1.0000
146.100 1.0000 1.0000
146.400 0.0000 1.0000
146.700 1.0000 1.0000
147.000 0.0000 1.0000
147.300 0.0000 1.0000
147.600 0.0000 1.0000
147.900 0.0000 1.0000
148.200 0.0000 1.0000
148.500 0.0000 1.0000
148.800 0.0000 1.0000
149.100 1.0000 1.0000
149.400 0.0000 1.0000
149.700 1.0000 1.0000
150.000 0.0000 1.0000
150.300 0.0000 1.0000
150.600 0.0000 1.0000
150.900 0.0000 1.0000
151.200 0.0000 1.0000
151.500 0.0000 1.0000
151.800 0.0000 1.0000
152.100 0.0000 1.0000
152.400 1.0000 1.0000
152.700 0.0000 1.0000
153.000 0.0000 1.0000
153.300 0.0000 1.0000
153.600 0.0000 1.0000
153.900 0.0000 1.0000
154.200 0.0000 1.0000
154.500 0.0000 1.0000
154.800 0.0000 1.0000
155.100 0.0000 1.0000
155.400 1.0000 1.0000
155.700 0.0000 1.0000
156.000 0.0000 1.0000
156.300 0.0000 1.0000
156.600 0.0000 1.0000
156.900 0.0000 1.0000
157.200 0.0000 1.0000
157.500 0.0000 1.0000
157.800 0.0000 1.0000
158.100 0.0000 1.0000
158.400 0.0000 1.0000
158.700 0.0000 1.0000
159.000 0.0000 1.0000
159.300 0.0000 1.0000
159.600 0.0000 1.0000
159.900 0.0000 1.0000
160.200 0.0000 1.0000
160.500 0.0000 1.0000
160.800 0.0000 1.0000
161.100 1.0000 1.0000
161.400 0.0000 1.0000
161.700 1.0000 1.0000
162.000 0.0000 1.0000
162.300 0.0000 1.0000
162.600 0.0000 1.0000
162.900 0.0000 1.0000
163.200 0.0000 1.0000
163.500 0.0000 1.0000
163.800 0.0000 1.0000
164.100 0.0000 1.0000
164.400 0.0000 1.0000
164.700 0.0000 1.0000
165.000 0.0000 1.0000
165.300 1.0000 1.0000
165.600 0.0000 1.0000
165.900 1.0000 1.0000
166.200 0.0000 1.0000
166.500 0.0000 1.0000
166.800 0.0000 1.0000
167.100 0.0000 1.0000
167.400 0.0000 1.0000
167.700 0.0000 1.0000
168.000 1.0000 1.0000
168.300 0.0000 1.0000
168.600 0.0000 1.0000
168.900 0.0000 1.0000
169.200 0.0000 1.0000
169.500 0.0000 1.0000
169.800 0.0000 1.0000
170.100 0.0000 1.0000
170.400 0.0000 1.0000
170.700 0.0000 1.0000
171.000 0.0000 1.0000
171.300 0.0000 1.0000
171.600 0.0000 1.0000
171.900 0.0000 1.0000
172.200 0.0000 1.0000
172.500 0.0000 1.0000
172.800 0.0000 1.0000
173.100 0.0000 1.0000
173.400 0.0000 1.0000
173.700 0.0000 1.0000
174.000 0.0000 1.0000
174.300 0.0000 1.0000
174.600 0.0000 1.0000
174.900 0.0000 1.0000
175.200 0.0000 1.0000
175.500 0.0000 1.0000
175.800 0.0000 1.0000
176.100 0.0000 1.0000
176.400 0.0000 1.0000
176.700 0.0000 1.0000
177.000 0.0000 1.0000
177.300 0.0000 1.0000
177.600 0.0000 1.0000
177.900 0.0000 1.0000
178.200 0.0000 1.0000
178.500 0.0000 1.0000
178.800 1.0000 1.0000
179.100 0.0000 1.0000
179.400 0.0000 1.0000
179.700 0.0000 1.0000
180.000 0.0000 1.0000
180.300 0.0000 1.0000
180.600 0.0000 1.0000
180.900 0.0000 1.0000
181.200 0.0000 1.0000
181.500 0.0000 1.0000
181.800 0.0000 1.0000
182.100 0.0000 1.0000
182.400 0.0000 1.0000
182.700 0.0000 1.0000
183.000 0.0000 1.0000
183.300 0.0000 1.0000
183.600 0.0000 1.0000
183.900 0.0000 1.0000
184.200 0.0000 1.0000
184.500 0.0000 1.0000
184.800 0.0000 1.0000
185.100 0.0000 1.0000
185.400 0.0000 1.0000
185.700 0.0000 1.0000
186.000 0.0000 1.0000
186.300 1.0000 1.0000
186.600 0.0000 1.0000
186.900 1.0000 1.0000
187.200 0.0000 1.0000
187.500 0.0000 1.0000
187.800 0.0000 1.0000
188.100 1.0000 1.0000
188.400 0.0000 1.0000
188.700 1.0000 1.0000
189.000 0.0000 1.0000
189.300 0.0000 1.0000
189.600 0.0000 1.0000
189.900 0.0000 1.0000
190.200 1.0000 1.0000
190.500 0.0000 1.0000
190.800 0.0000 1.0000
191.100 0.0000 1.0000
191.400 0.0000 1.0000
191.700 0.0000 1.0000
192.000 1.0000 1.0000
192.300 0.0000 1.0000
192.600 1.0000 1.0000
192.900 0.0000 1.0000
193.200 11.0000 1.0000
193.500 11.0000 1.0000
193.800 9.0000 1.0000
194.100 9.0000 1.0000
194.400 12.0000 1.0000
194.700 4.0000 1.0000
195.000 1.0000 1.0000
195.300 3.0000 1.0000
195.600 0.0000 1.0000
195.900 1.0000 1.0000
196.200 0.0000 1.0000
196.500 1.0000 1.0000
196.800 0.0000 1.0000
197.100 0.0000 1.0000
197.400 0.0000 1.0000
197.700 0.0000 1.0000
198.000 0.0000 1.0000
198.300 2.0000 1.0000
198.600 0.0000 1.0000
198.900 1.0000 1.0000
199.200 0.0000 1.0000
199.500 0.0000 1.0000
199.800 0.0000 1.0000
200.100 0.0000 1.0000
200.400 0.0000 1.0000
200.700 0.0000 1.0000
201.000 0.0000 1.0000
201.300 0.0000 1.0000
201.600 0.0000 1.0000
201.900 0.0000 1.0000
202.200 0.0000 1.0000
202.500 0.0000 1.0000
202.800 0.0000 1.0000
203.100 0.0000 1.0000
203.400 1.0000 1.0000
203.700 0.0000 1.0000
204.000 2.0000 1.0000
204.300 0.0000 1.0000
204.600 0.0000 1.0000
204.900 0.0000 1.0000
205.200 0.0000 1.0000
205.500 0.0000 1.0000
205.800 0.0000 1.0000
206.100 0.0000 1.0000
206.400 0.0000 1.0000
206.700 0.0000 1.0000
207.000 0.0000 1.0000
207.300 1.0000 1.0000
207.600 0.0000 1.0000
207.900 0.0000 1.0000
208.200 0.0000 1.0000
208.500 1.0000 1.0000
208.800 0.0000 1.0000
209.100 0.0000 1.0000
209.400 0.0000 1.0000
209.700 0.0000 1.0000
210.000 0.0000 1.0000
210.300 0.0000 1.0000
210.600 0.0000 1.0000
210.900 0.0000 1.0000
211.200 0.0000 1.0000
211.500 0.0000 1.0000
211.800 0.0000 1.0000
212.100 0.0000 1.0000
212.400 0.0000 1.0000
212.700 0.0000 1.0000
213.000 0.0000 1.0000
213.300 0.0000 1.0000
213.600 0.0000 1.0000
213.900 0.0000 1.0000
214.200 0.0000 1.0000
214.500 0.0000 1.0000
214.800 0.0000 1.0000
215.100 0.0000 1.0000
215.400 0.0000 1.0000
215.700 1.0000 1.0000
216.000 0.0000 1.0000
216.300 1.0000 1.0000
216.600 0.0000 1.0000
216.900 0.0000 1.0000
217.200 0.0000 1.0000
217.500 0.0000 1.0000
217.800 0.0000 1.0000
218.100 0.0000 1.0000
218.400 0.0000 1.0000
218.700 0.0000 1.0000
219.000 0.0000 1.0000
219.300 0.0000 1.0000
219.600 1.0000 1.0000
219.900 0.0000 1.0000
220.200 0.0000 1.0000
220.500 0.0000 1.0000
220.800 0.0000 1.0000
221.100 1.0000 1.0000
221.400 0.0000 1.0000
221.700 0.0000 1.0000
222.000 0.0000 1.0000
222.300 0.0000 1.0000
222.600 0.0000 1.0000
222.900 1.0000 1.0000
223.200 0.0000 1.0000
223.500 0.0000 1.0000
223.800 0.0000 1.0000
224.100 0.0000 1.0000
224.400 0.0000 1.0000
224.700 0.0000 1.0000
225.000 1.0000 1.0000
225.300 0.0000 1.0000
225.600 1.0000 1.0000
225.900 0.0000 1.0000
226.200 0.0000 1.0000
226.500 0.0000 1.0000
226.800 1.0000 1.0000
227.100 0.0000 1.0000
227.400 0.0000 1.0000
227.700 0.0000 1.0000
228.000 0.0000 1.0000
228.300 1.0000 1.0000
228.600 0.0000 1.0000
228.900 0.0000 1.0000
229.200 0.0000 1.0000
229.500 0.0000 1.0000
229.800 0.0000 1.0000
230.100 0.0000 1.0000
230.400 0.0000 1.0000
230.700 0.0000 1.0000
231.000 1.0000 1.0000
231.300 0.0000 1.0000
231.600 0.0000 1.0000
231.900 1.0000 1.0000
232.200 1.0000 1.0000
232.500 0.0000 1.0000
232.800 0.0000 1.0000
233.100 0.0000 1.0000
233.400 0.0000 1.0000
233.700 0.0000 1.0000
234.000 0.0000 1.0000
234.300 0.0000 1.0000
234.600 0.0000 1.0000
234.900 0.0000 1.0000
235.200 1.0000 1.0000
235.500 2.0000 1.0000
235.800 0.0000 1.0000
236.100 0.0000 1.0000
236.400 0.0000 1.0000
236.700 0.0000 1.0000
237.000 0.0000 1.0000
237.300 0.0000 1.0000
237.600 0.0000 1.0000
237.900 0.0000 1.0000
238.200 0.0000 1.0000
238.500 0.0000 1.0000
238.800 0.0000 1.0000
239.100 0.0000 1.0000
239.400 0.0000 1.0000
239.700 0.0000 1.0000
240.000 0.0000 1.0000
240.300 0.0000 1.0000
240.600 0.0000 1.0000
240.900 0.0000 1.0000
241.200 1.0000 1.0000
241.500 0.0000 1.0000
241.800 0.0000 1.0000
242.100 0.0000 1.0000
242.400 0.0000 1.0000
242.700 0.0000 1.0000
243.000 0.0000 1.0000
243.300 0.0000 1.0000
243.600 0.0000 1.0000
243.900 0.0000 1.0000
244.200 0.0000 1.0000
244.500 0.0000 1.0000
244.800 0.0000 1.0000
245.100 0.0000 1.0000
245.400 0.0000 1.0000
245.700 0.0000 1.0000
246.000 0.0000 1.0000
246.300 0.0000 1.0000
246.600 0.0000 1.0000
246.900 0.0000 1.0000
247.200 0.0000 1.0000
247.500 0.0000 1.0000
247.800 0.0000 1.0000
248.100 1.0000 1.0000
248.400 0.0000 1.0000
248.700 0.0000 1.0000
249.000 0.0000 1.0000
249.300 0.0000 1.0000
249.600 0.0000 1.0000
249.900 0.0000 1.0000
250.200 0.0000 1.0000
250.500 1.0000 1.0000
250.800 0.0000 1.0000
251.100 0.0000 1.0000
251.400 0.0000 1.0000
251.700 0.0000 1.0000
252.000 0.0000 1.0000
252.300 0.0000 1.0000
252.600 0.0000 1.0000
252.900 0.0000 1.0000
253.200 0.0000 1.0000
253.500 0.0000 1.0000
253.800 0.0000 1.0000
254.100 1.0000 1.0000
254.400 1.0000 1.0000
254.700 0.0000 1.0000
255.000 0.0000 1.0000
255.300 0.0000 1.0000
255.600 0.0000 1.0000
255.900 0.0000 1.0000
256.200 0.0000 1.0000
256.500 0.0000 1.0000
256.800 0.0000 1.0000
257.100 0.0000 1.0000
257.400 0.0000 1.0000
257.700 0.0000 1.0000
258.000 0.0000 1.0000
258.300 0.0000 1.0000
258.600 0.0000 1.0000
258.900 0.0000 1.0000
259.200 0.0000 1.0000
259.500 0.0000 1.0000
259.800 0.0000 1.0000
260.100 0.0000 1.0000
260.400 0.0000 1.0000
260.700 0.0000 1.0000
261.000 0.0000 1.0000
261.300 1.0000 1.0000
261.600 0.0000 1.0000
261.900 0.0000 1.0000
262.200 0.0000 1.0000
262.500 0.0000 1.0000
262.800 0.0000 1.0000
263.100 0.0000 1.0000
263.400 0.0000 1.0000
263.700 0.0000 1.0000
264.000 0.0000 1.0000
264.300 0.0000 1.0000
264.600 0.0000 1.0000
264.900 0.0000 1.0000
265.200 0.0000 1.0000
265.500 0.0000 1.0000
265.800 0.0000 1.0000
266.100 0.0000 1.0000
266.400 0.0000 1.0000
266.700 0.0000 1.0000
267.000 0.0000 1.0000
267.300 0.0000 1.0000
267.600 0.0000 1.0000
267.900 0.0000 1.0000
268.200 2.0000 1.0000
268.500 0.0000 1.0000
268.800 0.0000 1.0000
269.100 1.0000 1.0000
269.400 0.0000 1.0000
269.700 0.0000 1.0000
270.000 0.0000 1.0000
270.300 0.0000 1.0000
270.600 0.0000 1.0000
270.900 1.0000 1.0000
271.200 0.0000 1.0000
271.500 0.0000 1.0000
271.800 0.0000 1.0000
272.100 0.0000 1.0000
272.400 0.0000 1.0000
272.700 0.0000 1.0000
273.000 0.0000 1.0000
273.300 0.0000 1.0000
273.600 0.0000 1.0000
273.900 1.0000 1.0000
274.200 0.0000 1.0000
274.500 0.0000 1.0000
274.800 0.0000 1.0000
275.100 0.0000 1.0000
275.400 0.0000 1.0000
275.700 0.0000 1.0000
276.000 0.0000 1.0000
276.300 0.0000 1.0000
276.600 0.0000 1.0000
276.900 0.0000 1.0000
277.200 0.0000 1.0000
277.500 0.0000 1.0000
277.800 0.0000 1.0000
278.100 0.0000 1.0000
278.400 0.0000 1.0000
278.700 0.0000 1.0000
279.000 0.0000 1.0000
279.300 0.0000 1.0000
279.600 0.0000 1.0000
279.900 0.0000 1.0000
280.200 0.0000 1.0000
280.500 0.0000 1.0000
280.800 0.0000 1.0000
281.100 0.0000 1.0000
281.400 0.0000 1.0000
281.700 0.0000 1.0000
282.000 0.0000 1.0000
282.300 0.0000 1.0000
282.600 0.0000 1.0000
282.900 0.0000 1.0000
283.200 0.0000 1.0000
283.500 0.0000 1.0000
283.800 0.0000 1.0000
284.100 0.0000 1.0000
284.400 0.0000 1.0000
284.700 0.0000 1.0000
285.000 1.0000 1.0000
285.300 0.0000 1.0000
285.600 0.0000 1.0000
285.900 0.0000 1.0000
286.200 0.0000 1.0000
286.500 0.0000 1.0000
286.800 0.0000 1.0000
287.100 0.0000 1.0000
287.400 1.0000 1.0000
287.700 0.0000 1.0000
288.000 0.0000 1.0000
288.300 0.0000 1.0000
288.600 0.0000 1.0000
288.900 0.0000 1.0000
289.200 0.0000 1.0000
289.500 0.0000 1.0000
289.800 0.0000 1.0000
290.100 0.0000 1.0000
290.400 0.0000 1.0000
290.700 0.0000 1.0000
291.000 0.0000 1.0000
291.300 0.0000 1.0000
291.600 0.0000 1.0000
291.900 0.0000 1.0000
292.200 1.0000 1.0000
292.500 0.0000 1.0000
292.800 0.0000 1.0000
293.100 0.0000 1.0000
293.400 0.0000 1.0000
293.700 0.0000 1.0000
294.000 0.0000 1.0000
294.300 0.0000 1.0000
294.600 0.0000 1.0000
294.900 0.0000 1.0000
295.200 0.0000 1.0000
295.500 0.0000 1.0000
295.800 0.0000 1.0000
296.100 0.0000 1.0000
296.400 1.0000 1.0000
296.700 0.0000 1.0000
297.000 0.0000 1.0000
297.300 0.0000 1.0000
297.600 0.0000 1.0000
297.900 0.0000 1.0000
298.200 0.0000 1.0000
298.500 0.0000 1.0000
298.800 0.0000 1.0000
299.100 0.0000 1.0000
299.400 0.0000 1.0000
299.700 0.0000 1.0000
300.000 0.0000 1.0000
300.300 1.0000 1.0000
300.600 0.0000 1.0000
300.900 0.0000 1.0000
301.200 0.0000 1.0000
301.500 0.0000 1.0000
301.800 1.0000 1.0000
302.100 0.0000 1.0000
302.400 0.0000 1.0000
302.700 0.0000 1.0000
303.000 0.0000 1.0000
303.300 0.0000 1.0000
303.600 0.0000 1.0000
303.900 0.0000 1.0000
304.200 0.0000 1.0000
304.500 0.0000 1.0000
304.800 0.0000 1.0000
305.100 0.0000 1.0000
305.400 1.0000 1.0000
305.700 0.0000 1.0000
306.000 0.0000 1.0000
306.300 0.0000 1.0000
306.600 0.0000 1.0000
306.900 0.0000 1.0000
307.200 0.0000 1.0000
307.500 0.0000 1.0000
307.800 0.0000 1.0000
308.100 0.0000 1.0000
308.400 0.0000 1.0000
308.700 1.0000 1.0000
309.000 0.0000 1.0000
309.300 1.0000 1.0000
309.600 1.0000 1.0000
309.900 0.0000 1.0000
310.200 0.0000 1.0000
310.500 1.0000 1.0000
310.800 1.0000 1.0000
311.100 2.0000 1.0000
311.400 0.0000 1.0000
311.700 0.0000 1.0000
312.000 0.0000 1.0000
312.300 3.0000 1.0000
312.600 0.0000 1.0000
312.900 3.0000 1.0000
313.200 7.0000 1.0000
313.500 10.0000 1.0000
313.800 13.0000 1.0000
314.100 13.0000 1.0000
314.400 8.0000 1.0000
314.700 3.0000 1.0000
315.000 4.0000 1.0000
315.300 2.0000 1.0000
315.600 0.0000 1.0000
315.900 1.0000 1.0000
316.200 0.0000 1.0000
316.500 0.0000 1.0000
316.800 0.0000 1.0000
317.100 1.0000 1.0000
317.400 0.0000 1.0000
317.700 0.0000 1.0000
318.000 0.0000 1.0000
318.300 0.0000 1.0000
318.600 0.0000 1.0000
318.900 0.0000 1.0000
319.200 0.0000 1.0000
319.500 1.0000 1.0000
319.800 0.0000 1.0000
320.100 0.0000 1.0000
320.400 0.0000 1.0000
320.700 1.0000 1.0000
321.000 0.0000 1.0000
321.300 0.0000 1.0000
321.600 0.0000 1.0000
321.900 0.0000 1.0000
322.200 0.0000 1.0000
322.500 0.0000 1.0000
322.800 0.0000 1.0000
323.100 0.0000 1.0000
323.400 0.0000 1.0000
323.700 0.0000 1.0000
324.000 0.0000 1.0000
324.300 0.0000 1.0000
324.600 0.0000 1.0000
324.900 0.0000 1.0000
325.200 1.0000 1.0000
325.500 1.0000 1.0000
325.800 0.0000 1.0000
326.100 0.0000 1.0000
326.400 0.0000 1.0000
326.700 0.0000 1.0000
327.000 0.0000 1.0000
327.300 1.0000 1.0000
327.600 0.0000 1.0000
327.900 0.0000 1.0000
328.200 0.0000 1.0000
328.500 0.0000 1.0000
328.800 0.0000 1.0000
329.100 2.0000 1.0000
329.400 0.0000 1.0000
329.700 0.0000 1.0000
330.000 0.0000 1.0000
330.300 0.0000 1.0000
330.600 0.0000 1.0000
330.900 0.0000 1.0000
331.200 1.0000 1.0000
331.500 0.0000 1.0000
331.800 1.0000 1.0000
332.100 0.0000 1.0000
332.400 0.0000 1.0000
332.700 1.0000 1.0000
333.000 0.0000 1.0000
333.300 0.0000 1.0000
333.600 0.0000 1.0000
333.900 0.0000 1.0000
334.200 0.0000 1.0000
334.500 0.0000 1.0000
334.800 0.0000 1.0000
335.100 1.0000 1.0000
335.400 0.0000 1.0000
335.700 0.0000 1.0000
336.000 0.0000 1.0000
336.300 0.0000 1.0000
336.600 0.0000 1.0000
336.900 0.0000 1.0000
337.200 1.0000 1.0000
337.500 0.0000 1.0000
337.800 0.0000 1.0000
338.100 1.0000 1.0000
338.400 0.0000 1.0000
338.700 0.0000 1.0000
339.000 1.0000 1.0000
339.300 0.0000 1.0000
339.600 0.0000 1.0000
339.900 0.0000 1.0000
340.200 1.0000 1.0000
340.500 0.0000 1.0000
340.800 0.0000 1.0000
341.100 0.0000 1.0000
341.400 0.0000 1.0000
341.700 0.0000 1.0000
342.000 0.0000 1.0000
342.300 0.0000 1.0000
342.600 0.0000 1.0000
342.900 0.0000 1.0000
343.200 0.0000 1.0000
343.500 0.0000 1.0000
343.800 0.0000 1.0000
344.100 0.0000 1.0000
344.400 0.0000 1.0000
344.700 0.0000 1.0000
345.000 0.0000 1.0000
345.300 0.0000 1.0000
345.600 0.0000 1.0000
345.900 0.0000 1.0000
346.200 0.0000 1.0000
346.500 0.0000 1.0000
346.800 0.0000 1.0000
347.100 0.0000 1.0000
347.400 0.0000 1.0000
347.700 1.0000 1.0000
348.000 0.0000 1.0000
348.300 1.0000 1.0000
348.600 1.0000 1.0000
348.900 1.0000 1.0000
349.200 0.0000 1.0000
349.500 0.0000 1.0000
349.800 0.0000 1.0000
350.100 0.0000 1.0000
350.400 0.0000 1.0000
350.700 0.0000 1.0000
351.000 0.0000 1.0000
351.300 0.0000 1.0000
351.600 0.0000 1.0000
351.900 1.0000 1.0000
352.200 0.0000 1.0000
352.500 0.0000 1.0000
352.800 0.0000 1.0000
353.100 0.0000 1.0000
353.400 0.0000 1.0000
353.700 0.0000 1.0000
354.000 0.0000 1.0000
354.300 1.0000 1.0000
354.600 0.0000 1.0000
354.900 0.0000 1.0000
355.200 0.0000 1.0000
355.500 1.0000 1.0000
355.800 0.0000 1.0000
356.100 0.0000 1.0000
356.400 0.0000 1.0000
356.700 0.0000 1.0000
357.000 0.0000 1.0000
357.300 0.0000 1.0000
357.600 0.0000 1.0000
357.900 0.0000 1.0000
358.200 0.0000 1.0000
358.500 0.0000 1.0000
358.800 0.0000 1.0000
359.100 0.0000 1.0000
359.400 0.0000 1.0000
359.700 0.0000 1.0000
360.000 0.0000 1.0000
*RAS_INT_END
*RAS_DATA_END
*DSC_DATA_END