File: example/461_test/PLD50nmFe2O3_Al2O3/HRXRD_Lab/2thW_Survey_00L.ras
*RAS_DATA_START
*RAS_HEADER_START
*DISP_LINE_COLOR "4286611584"
*FILE_COMMENT ""
*FILE_MD5 ""
*FILE_MEMO ""
*FILE_OPERATOR "Administrator"
*FILE_PACKAGE_NAME ""
*FILE_PART_ID ""
*FILE_SAMPLE ""
*FILE_SYSTEM_NAME "SmartLab"
*FILE_TYPE "RAS_RAW"
*FILE_USERGROUP "Administrators"
*FILE_VERSION "1"
*HW_ATTACHMENT_ID "ATT0022"
*HW_ATTACHMENT_NAME "RxRy"
*HW_ATTACHMENT_NAME_INTERNAL "RxRy"
*HW_COUNTER_ID-0 "CUT0021"
*HW_COUNTER_ID-1 "CMC0020"
*HW_COUNTER_MONOCHRO_ID "CMC0020"
*HW_COUNTER_MONOCHRO_NAME "None"
*HW_COUNTER_MONOCHRO_NAME_INTERNAL "None"
*HW_COUNTER_NAME_INTERNAL "SC70"
*HW_COUNTER_NAME-0 "SC70"
*HW_COUNTER_NAME-1 "None"
*HW_COUNTER_SELECT_NAME "SC70"
*HW_EXTERNAL_CONTROLLER_NAME "None"
*HW_EXTERNAL_CONTROLLER_NAME_INTERNAL "None"
*HW_GONIOMETER_ID "GON0022"
*HW_GONIOMETER_NAME "StandardInplaneEnc"
*HW_GONIOMETER_NAME_INTERNAL "StandardInplaneEnc"
*HW_GONIOMETER_RADIUS-0 "90.0"
*HW_GONIOMETER_RADIUS-1 "114.0"
*HW_GONIOMETER_RADIUS-2 "190.0"
*HW_GONIOMETER_RADIUS-3 "300.0"
*HW_GONIOMETER_RADIUS-4 "187.0"
*HW_GONIOMETER_RADIUS-5 "300.0"
*HW_GONIOMETER_RADIUS-6 "113.0000"
*HW_GONIOMETER_RADIUS-7 "331.0"
*HW_I_CBO_ID "CBO0021"
*HW_I_CBO_NAME "CBO"
*HW_I_CBO_NAME_INTERNAL "CBO"
*HW_I_MONOCHRO_ID "ICR0021"
*HW_I_MONOCHRO_NAME "Ge(220)x2"
*HW_I_MONOCHRO_NAME_INTERNAL "Ge(220)x2"
*HW_I_OPT_ID-0 "CBO0021"
*HW_I_OPT_ID-1 "ISL0021"
*HW_I_PRIMARY_NAME_INTERNAL "Standard"
*HW_I_SLIT_ID "ISL0021"
*HW_I_SLIT_NAME "Auto"
*HW_I_SLIT_NAME_INTERNAL "Auto"
*HW_R_ATTENUATER_AUTOMODE "1"
*HW_R_ATTENUATER_ID "ATN0021"
*HW_R_ATTENUATER_NAME "Auto"
*HW_R_ATTENUATOR_NAME_INTERNAL "Auto"
*HW_R_OPT_ID-0 "RSS0021"
*HW_R_OPT_ID-1 "RCR0022"
*HW_R_OPT_ID-2 "RSO0021"
*HW_R_OPT_ID-3 "RRS0021"
*HW_R_OPT_ID-4 "ATN0021"
*HW_R_ROD_ID "RCR0022"
*HW_R_ROD_NAME "ROD_adaptor"
*HW_R_ROD_NAME_INTERNAL "ROD_adaptor"
*HW_R_RPS_ID "RSO0021"
*HW_R_RPS_NAME "RPS_adaptor"
*HW_R_RPS_NAME_INTERNAL "RPS_adaptor"
*HW_R_RS_ID "RRS0021"
*HW_R_RS_NAME "Auto"
*HW_R_RS_NAME_INTERNAL "Auto"
*HW_R_SS_ID "RSS0021"
*HW_R_SS_NAME "Auto"
*HW_R_SS_NAME_INTERNAL "Auto"
*HW_ROBOT_NAME "No_unit"
*HW_ROBOT_NAME_INTERNAL "No_unit"
*HW_SAMPLE_CAMERA_NAME "None"
*HW_SAMPLE_CAMERA_NAME_INTERNAL "None"
*HW_SAMPLE_HOLDER_ID "SMP0021"
*HW_SAMPLE_HOLDER_NAME "Z_ChiPhi"
*HW_SAMPLE_HOLDER_NAME_INTERNAL "Z_ChiPhi"
*HW_SAMPLE_NAME "CenterSlit"
*HW_SAMPLE_NAME_INTERNAL "CenterSlit"
*HW_SAMPLE_PLATE_NAME "HeightReference"
*HW_SAMPLE_PLATE_NAME_INTERNAL "HeightReference"
*HW_SAMPLE_SPACER_NAME "None"
*HW_SAMPLE_SPACER_NAME_INTERNAL "None"
*HW_USERINFO_CATALOG_NO ""
*HW_USERINFO_INSTRUMENT_ID ""
*HW_USERINFO_INSTRUMENT_NAME ""
*HW_USERINFO_INSTRUMENT_NO ""
*HW_USERINFO_MODEL ""
*HW_USERINFO_ORDER_NO ""
*HW_USERINFO_SERIAL_NO ""
*HW_USERINFO_VERIFY_INSTRUMENT_ID "00-07-fe-01-03-ce"
*HW_VER_RCD_COUNTER_UNIT "1.0.1"
*HW_VER_RCD_CPU "3.3.7"
*HW_VER_RCD_FPGA "1.2.2"
*HW_VER_RCD_GONIO_UNIT "6.2.0"
*HW_VER_RCD_INCIDENT_UNIT "6.2.0"
*HW_VER_RCD_RECEIVING_UNIT "6.2.0"
*HW_VER_RCD_TYPE "RINC"
*HW_VER_XGC_CPU "3.3.7"
*HW_VER_XGC_CW "1.2.0"
*HW_VER_XGC_HV "1.2.0"
*HW_VER_XGC_RS1 "1.3.4"
*HW_VER_XGC_RS2 "N/A"
*HW_VER_XGC_RT "1.2.0"
*HW_VER_XGC_TYPE "RINC"
*HW_XG_CURRENT_UNIT "mA"
*HW_XG_FOCUS "0.4mm x 8mm"
*HW_XG_FOCUS_TYPE "Fine"
*HW_XG_TARGET_ATOMIC_NUMBER "29"
*HW_XG_TARGET_NAME "Cu"
*HW_XG_TYPE "ROTA"
*HW_XG_VOLTAGE_UNIT "kV"
*HW_XG_WAVE_LENGTH_ALPHA1 "1.540593"
*HW_XG_WAVE_LENGTH_ALPHA2 "1.544414"
*HW_XG_WAVE_LENGTH_BETA "1.392246"
*HW_XG_WAVE_LENGTH_UNIT "Angstrom"
*MEAS_COND_AXIS_NAME_INTERNAL-0 "ThetaS"
*MEAS_COND_AXIS_NAME_INTERNAL-1 "ThetaD"
*MEAS_COND_AXIS_NAME_INTERNAL-10 "PrimaryGeometry"
*MEAS_COND_AXIS_NAME_INTERNAL-100 "IncidentMonochromator"
*MEAS_COND_AXIS_NAME_INTERNAL-101 "ReceivingOptics"
*MEAS_COND_AXIS_NAME_INTERNAL-102 "CounterMonochromatorKind"
*MEAS_COND_AXIS_NAME_INTERNAL-11 "PrimaryMirrorType"
*MEAS_COND_AXIS_NAME_INTERNAL-12 "CBOType"
*MEAS_COND_AXIS_NAME_INTERNAL-13 "CBO-M"
*MEAS_COND_AXIS_NAME_INTERNAL-14 "CBO"
*MEAS_COND_AXIS_NAME_INTERNAL-15 "IncidentMonochromator-OmegaM"
*MEAS_COND_AXIS_NAME_INTERNAL-16 "IncidentSollerSlit"
*MEAS_COND_AXIS_NAME_INTERNAL-17 "IncidentSlitBox"
*MEAS_COND_AXIS_NAME_INTERNAL-18 "IncidentSlitBox-_Axis"
*MEAS_COND_AXIS_NAME_INTERNAL-19 "SlitDS"
*MEAS_COND_AXIS_NAME_INTERNAL-2 "TwoTheta"
*MEAS_COND_AXIS_NAME_INTERNAL-20 "Zs"
*MEAS_COND_AXIS_NAME_INTERNAL-21 "IncidentAxdSlit"
*MEAS_COND_AXIS_NAME_INTERNAL-22 "LLS"
*MEAS_COND_AXIS_NAME_INTERNAL-23 "DHLSlit"
*MEAS_COND_AXIS_NAME_INTERNAL-24 "Chi"
*MEAS_COND_AXIS_NAME_INTERNAL-25 "Phi"
*MEAS_COND_AXIS_NAME_INTERNAL-26 "Z"
*MEAS_COND_AXIS_NAME_INTERNAL-27 "Alpha"
*MEAS_COND_AXIS_NAME_INTERNAL-28 "Beta"
*MEAS_COND_AXIS_NAME_INTERNAL-29 "TwoThetaChiPhi"
*MEAS_COND_AXIS_NAME_INTERNAL-3 "Omega"
*MEAS_COND_AXIS_NAME_INTERNAL-30 "AlphaI"
*MEAS_COND_AXIS_NAME_INTERNAL-31 "BetaI"
*MEAS_COND_AXIS_NAME_INTERNAL-32 "TwoThetaB"
*MEAS_COND_AXIS_NAME_INTERNAL-33 "Rx"
*MEAS_COND_AXIS_NAME_INTERNAL-34 "Ry"
*MEAS_COND_AXIS_NAME_INTERNAL-35 "ReceivingSlitBox1"
*MEAS_COND_AXIS_NAME_INTERNAL-36 "ReceivingSlitBox1-_Axis"
*MEAS_COND_AXIS_NAME_INTERNAL-37 "SlitSS"
*MEAS_COND_AXIS_NAME_INTERNAL-38 "Filter"
*MEAS_COND_AXIS_NAME_INTERNAL-39 "PSA"
*MEAS_COND_AXIS_NAME_INTERNAL-4 "TwoThetaTheta"
*MEAS_COND_AXIS_NAME_INTERNAL-40 "ReceivingSollerSlit"
*MEAS_COND_AXIS_NAME_INTERNAL-41 "ReceivingSlitBox2"
*MEAS_COND_AXIS_NAME_INTERNAL-42 "ReceivingSlitBox2-_Axis"
*MEAS_COND_AXIS_NAME_INTERNAL-43 "SlitRS"
*MEAS_COND_AXIS_NAME_INTERNAL-44 "ReceivingSlitBox2-Zd"
*MEAS_COND_AXIS_NAME_INTERNAL-45 "Filter2"
*MEAS_COND_AXIS_NAME_INTERNAL-46 "Attenuator"
*MEAS_COND_AXIS_NAME_INTERNAL-47 "HV"
*MEAS_COND_AXIS_NAME_INTERNAL-48 "PHA"
*MEAS_COND_AXIS_NAME_INTERNAL-49 "DedicatedHolder"
*MEAS_COND_AXIS_NAME_INTERNAL-5 "TwoThetaOmega"
*MEAS_COND_AXIS_NAME_INTERNAL-50 "Target_TargetTime"
*MEAS_COND_AXIS_NAME_INTERNAL-51 "Target_XrayOnTime"
*MEAS_COND_AXIS_NAME_INTERNAL-52 "Target_TMPTime"
*MEAS_COND_AXIS_NAME_INTERNAL-53 "Target_RPTime"
*MEAS_COND_AXIS_NAME_INTERNAL-54 "Target_FilamentTime"
*MEAS_COND_AXIS_NAME_INTERNAL-55 "Target_IG"
*MEAS_COND_AXIS_NAME_INTERNAL-56 "Target_GP"
*MEAS_COND_AXIS_NAME_INTERNAL-57 "Target_FC"
*MEAS_COND_AXIS_NAME_INTERNAL-58 "HVPS_Bias"
*MEAS_COND_AXIS_NAME_INTERNAL-59 "HVPS_HVPSTime"
*MEAS_COND_AXIS_NAME_INTERNAL-6 "OmegaTwoTheta"
*MEAS_COND_AXIS_NAME_INTERNAL-60 "HVPS_Type1Time"
*MEAS_COND_AXIS_NAME_INTERNAL-61 "HVPS_Type2Time"
*MEAS_COND_AXIS_NAME_INTERNAL-62 "HVPS_Type3Time"
*MEAS_COND_AXIS_NAME_INTERNAL-63 "CW_IERTime"
*MEAS_COND_AXIS_NAME_INTERNAL-64 "CW_ECTime"
*MEAS_COND_AXIS_NAME_INTERNAL-65 "CW_Flow1"
*MEAS_COND_AXIS_NAME_INTERNAL-66 "CW_Temperature1"
*MEAS_COND_AXIS_NAME_INTERNAL-67 "CW_Pressure1"
*MEAS_COND_AXIS_NAME_INTERNAL-68 "CW_PressureIn"
*MEAS_COND_AXIS_NAME_INTERNAL-69 "CW_PressureOut"
*MEAS_COND_AXIS_NAME_INTERNAL-7 "TwoThetaChi"
*MEAS_COND_AXIS_NAME_INTERNAL-70 "CW_Flow2"
*MEAS_COND_AXIS_NAME_INTERNAL-71 "CW_Temperature2"
*MEAS_COND_AXIS_NAME_INTERNAL-72 "CW_Pressure2"
*MEAS_COND_AXIS_NAME_INTERNAL-73 "RE_EnclosureTemp"
*MEAS_COND_AXIS_NAME_INTERNAL-74 "RE_EnclosureHummidity"
*MEAS_COND_AXIS_NAME_INTERNAL-75 "RE_CabinetTemp"
*MEAS_COND_AXIS_NAME_INTERNAL-76 "RE_RPTemp"
*MEAS_COND_AXIS_NAME_INTERNAL-77 "RE_ShutterAXrayOnTime"
*MEAS_COND_AXIS_NAME_INTERNAL-78 "RE_ShutterATimes"
*MEAS_COND_AXIS_NAME_INTERNAL-79 "RE_ShutterAOpenCloseTime"
*MEAS_COND_AXIS_NAME_INTERNAL-8 "GonioDirectBeamStop"
*MEAS_COND_AXIS_NAME_INTERNAL-80 "RE_ShutterACloseOpenTime"
*MEAS_COND_AXIS_NAME_INTERNAL-81 "RE_ShutterBXrayOnTime"
*MEAS_COND_AXIS_NAME_INTERNAL-82 "RE_ShutterBTimes"
*MEAS_COND_AXIS_NAME_INTERNAL-83 "RE_ShutterBOpenCloseTime"
*MEAS_COND_AXIS_NAME_INTERNAL-84 "RE_ShutterBCloseOpenTime"
*MEAS_COND_AXIS_NAME_INTERNAL-85 "RE_XrayWarningRamp"
*MEAS_COND_AXIS_NAME_INTERNAL-86 "RE_ShutterAInstallation"
*MEAS_COND_AXIS_NAME_INTERNAL-87 "RE_ShutterARamp"
*MEAS_COND_AXIS_NAME_INTERNAL-88 "RE_ShutterBInstallation"
*MEAS_COND_AXIS_NAME_INTERNAL-89 "RE_ShutterBRamp"
*MEAS_COND_AXIS_NAME_INTERNAL-9 "Ts"
*MEAS_COND_AXIS_NAME_INTERNAL-90 "RE_ExtShutterCLS"
*MEAS_COND_AXIS_NAME_INTERNAL-91 "RE_ExtXrayOFF"
*MEAS_COND_AXIS_NAME_INTERNAL-92 "RE_ExtSafetyCircuit"
*MEAS_COND_AXIS_NAME_INTERNAL-93 "Version_CPU"
*MEAS_COND_AXIS_NAME_INTERNAL-94 "Version_RS1"
*MEAS_COND_AXIS_NAME_INTERNAL-95 "Version_RS2"
*MEAS_COND_AXIS_NAME_INTERNAL-96 "Version_HV"
*MEAS_COND_AXIS_NAME_INTERNAL-97 "Version_CW"
*MEAS_COND_AXIS_NAME_INTERNAL-98 "Version_RT"
*MEAS_COND_AXIS_NAME_INTERNAL-99 "IncidentPrimary"
*MEAS_COND_AXIS_NAME-0 "ThetaS"
*MEAS_COND_AXIS_NAME-1 "ThetaD"
*MEAS_COND_AXIS_NAME-10 "PrimaryGeometry"
*MEAS_COND_AXIS_NAME-100 "IncidentMonochromator"
*MEAS_COND_AXIS_NAME-101 "ReceivingOptics"
*MEAS_COND_AXIS_NAME-102 "CounterMonochromatorKind"
*MEAS_COND_AXIS_NAME-11 "PrimaryMirrorType"
*MEAS_COND_AXIS_NAME-12 "CBOType"
*MEAS_COND_AXIS_NAME-13 "CBO-M"
*MEAS_COND_AXIS_NAME-14 "CBO"
*MEAS_COND_AXIS_NAME-15 "IncidentMonochromator-OmegaM"
*MEAS_COND_AXIS_NAME-16 "IncidentSollerSlit"
*MEAS_COND_AXIS_NAME-17 "IncidentSlitBox"
*MEAS_COND_AXIS_NAME-18 "IncidentSlitBox-_Axis"
*MEAS_COND_AXIS_NAME-19 "SlitDS"
*MEAS_COND_AXIS_NAME-2 "TwoTheta"
*MEAS_COND_AXIS_NAME-20 "Zs"
*MEAS_COND_AXIS_NAME-21 "IncidentAxdSlit"
*MEAS_COND_AXIS_NAME-22 "LLS"
*MEAS_COND_AXIS_NAME-23 "DHLSlit"
*MEAS_COND_AXIS_NAME-24 "Chi"
*MEAS_COND_AXIS_NAME-25 "Phi"
*MEAS_COND_AXIS_NAME-26 "Z"
*MEAS_COND_AXIS_NAME-27 "Alpha"
*MEAS_COND_AXIS_NAME-28 "Beta"
*MEAS_COND_AXIS_NAME-29 "TwoThetaChiPhi"
*MEAS_COND_AXIS_NAME-3 "Omega"
*MEAS_COND_AXIS_NAME-30 "AlphaI"
*MEAS_COND_AXIS_NAME-31 "BetaI"
*MEAS_COND_AXIS_NAME-32 "TwoThetaB"
*MEAS_COND_AXIS_NAME-33 "Rx"
*MEAS_COND_AXIS_NAME-34 "Ry"
*MEAS_COND_AXIS_NAME-35 "ReceivingSlitBox1"
*MEAS_COND_AXIS_NAME-36 "ReceivingSlitBox1-_Axis"
*MEAS_COND_AXIS_NAME-37 "SlitSS"
*MEAS_COND_AXIS_NAME-38 "Filter"
*MEAS_COND_AXIS_NAME-39 "PSA"
*MEAS_COND_AXIS_NAME-4 "TwoThetaTheta"
*MEAS_COND_AXIS_NAME-40 "ReceivingSollerSlit"
*MEAS_COND_AXIS_NAME-41 "ReceivingSlitBox2"
*MEAS_COND_AXIS_NAME-42 "ReceivingSlitBox2-_Axis"
*MEAS_COND_AXIS_NAME-43 "SlitRS"
*MEAS_COND_AXIS_NAME-44 "ReceivingSlitBox2-Zd"
*MEAS_COND_AXIS_NAME-45 "Filter2"
*MEAS_COND_AXIS_NAME-46 "Attenuator"
*MEAS_COND_AXIS_NAME-47 "HV"
*MEAS_COND_AXIS_NAME-48 "PHA"
*MEAS_COND_AXIS_NAME-49 "DedicatedHolder"
*MEAS_COND_AXIS_NAME-5 "TwoThetaOmega"
*MEAS_COND_AXIS_NAME-50 "Target_TargetTime"
*MEAS_COND_AXIS_NAME-51 "Target_XrayOnTime"
*MEAS_COND_AXIS_NAME-52 "Target_TMPTime"
*MEAS_COND_AXIS_NAME-53 "Target_RPTime"
*MEAS_COND_AXIS_NAME-54 "Target_FilamentTime"
*MEAS_COND_AXIS_NAME-55 "Target_IG"
*MEAS_COND_AXIS_NAME-56 "Target_GP"
*MEAS_COND_AXIS_NAME-57 "Target_FC"
*MEAS_COND_AXIS_NAME-58 "HVPS_Bias"
*MEAS_COND_AXIS_NAME-59 "HVPS_HVPSTime"
*MEAS_COND_AXIS_NAME-6 "OmegaTwoTheta"
*MEAS_COND_AXIS_NAME-60 "HVPS_Type1Time"
*MEAS_COND_AXIS_NAME-61 "HVPS_Type2Time"
*MEAS_COND_AXIS_NAME-62 "HVPS_Type3Time"
*MEAS_COND_AXIS_NAME-63 "CW_IERTime"
*MEAS_COND_AXIS_NAME-64 "CW_ECTime"
*MEAS_COND_AXIS_NAME-65 "CW_Flow1"
*MEAS_COND_AXIS_NAME-66 "CW_Temperature1"
*MEAS_COND_AXIS_NAME-67 "CW_Pressure1"
*MEAS_COND_AXIS_NAME-68 "CW_PressureIn"
*MEAS_COND_AXIS_NAME-69 "CW_PressureOut"
*MEAS_COND_AXIS_NAME-7 "TwoThetaChi"
*MEAS_COND_AXIS_NAME-70 "CW_Flow2"
*MEAS_COND_AXIS_NAME-71 "CW_Temperature2"
*MEAS_COND_AXIS_NAME-72 "CW_Pressure2"
*MEAS_COND_AXIS_NAME-73 "RE_EnclosureTemp"
*MEAS_COND_AXIS_NAME-74 "RE_EnclosureHummidity"
*MEAS_COND_AXIS_NAME-75 "RE_CabinetTemp"
*MEAS_COND_AXIS_NAME-76 "RE_RPTemp"
*MEAS_COND_AXIS_NAME-77 "RE_ShutterAXrayOnTime"
*MEAS_COND_AXIS_NAME-78 "RE_ShutterATimes"
*MEAS_COND_AXIS_NAME-79 "RE_ShutterAOpenCloseTime"
*MEAS_COND_AXIS_NAME-8 "GonioDirectBeamStop"
*MEAS_COND_AXIS_NAME-80 "RE_ShutterACloseOpenTime"
*MEAS_COND_AXIS_NAME-81 "RE_ShutterBXrayOnTime"
*MEAS_COND_AXIS_NAME-82 "RE_ShutterBTimes"
*MEAS_COND_AXIS_NAME-83 "RE_ShutterBOpenCloseTime"
*MEAS_COND_AXIS_NAME-84 "RE_ShutterBCloseOpenTime"
*MEAS_COND_AXIS_NAME-85 "RE_XrayWarningRamp"
*MEAS_COND_AXIS_NAME-86 "RE_ShutterAInstallation"
*MEAS_COND_AXIS_NAME-87 "RE_ShutterARamp"
*MEAS_COND_AXIS_NAME-88 "RE_ShutterBInstallation"
*MEAS_COND_AXIS_NAME-89 "RE_ShutterBRamp"
*MEAS_COND_AXIS_NAME-9 "Ts"
*MEAS_COND_AXIS_NAME-90 "RE_ExtShutterCLS"
*MEAS_COND_AXIS_NAME-91 "RE_ExtXrayOFF"
*MEAS_COND_AXIS_NAME-92 "RE_ExtSafetyCircuit"
*MEAS_COND_AXIS_NAME-93 "Version_CPU"
*MEAS_COND_AXIS_NAME-94 "Version_RS1"
*MEAS_COND_AXIS_NAME-95 "Version_RS2"
*MEAS_COND_AXIS_NAME-96 "Version_HV"
*MEAS_COND_AXIS_NAME-97 "Version_CW"
*MEAS_COND_AXIS_NAME-98 "Version_RT"
*MEAS_COND_AXIS_NAME-99 "IncidentPrimary"
*MEAS_COND_AXIS_OFFSET-0 "1.096"
*MEAS_COND_AXIS_OFFSET-1 "0.141"
*MEAS_COND_AXIS_OFFSET-10 "0"
*MEAS_COND_AXIS_OFFSET-100 "0"
*MEAS_COND_AXIS_OFFSET-101 "0"
*MEAS_COND_AXIS_OFFSET-102 "0"
*MEAS_COND_AXIS_OFFSET-11 "0"
*MEAS_COND_AXIS_OFFSET-12 "0"
*MEAS_COND_AXIS_OFFSET-13 "0"
*MEAS_COND_AXIS_OFFSET-14 "0"
*MEAS_COND_AXIS_OFFSET-15 "0"
*MEAS_COND_AXIS_OFFSET-16 "0"
*MEAS_COND_AXIS_OFFSET-17 "0"
*MEAS_COND_AXIS_OFFSET-18 "0"
*MEAS_COND_AXIS_OFFSET-19 "0"
*MEAS_COND_AXIS_OFFSET-2 "1.237"
*MEAS_COND_AXIS_OFFSET-20 "0"
*MEAS_COND_AXIS_OFFSET-21 "0"
*MEAS_COND_AXIS_OFFSET-22 "0"
*MEAS_COND_AXIS_OFFSET-23 "0"
*MEAS_COND_AXIS_OFFSET-24 "0"
*MEAS_COND_AXIS_OFFSET-25 "0"
*MEAS_COND_AXIS_OFFSET-26 "0"
*MEAS_COND_AXIS_OFFSET-27 "0"
*MEAS_COND_AXIS_OFFSET-28 "0"
*MEAS_COND_AXIS_OFFSET-29 "0"
*MEAS_COND_AXIS_OFFSET-3 "1.096"
*MEAS_COND_AXIS_OFFSET-30 "0"
*MEAS_COND_AXIS_OFFSET-31 "0"
*MEAS_COND_AXIS_OFFSET-32 "0"
*MEAS_COND_AXIS_OFFSET-33 "0"
*MEAS_COND_AXIS_OFFSET-34 "0"
*MEAS_COND_AXIS_OFFSET-35 "0"
*MEAS_COND_AXIS_OFFSET-36 "0"
*MEAS_COND_AXIS_OFFSET-37 "0"
*MEAS_COND_AXIS_OFFSET-38 "0"
*MEAS_COND_AXIS_OFFSET-39 "0"
*MEAS_COND_AXIS_OFFSET-4 "0"
*MEAS_COND_AXIS_OFFSET-40 "0"
*MEAS_COND_AXIS_OFFSET-41 "0"
*MEAS_COND_AXIS_OFFSET-42 "0"
*MEAS_COND_AXIS_OFFSET-43 "0"
*MEAS_COND_AXIS_OFFSET-44 "0"
*MEAS_COND_AXIS_OFFSET-45 "0"
*MEAS_COND_AXIS_OFFSET-46 "0"
*MEAS_COND_AXIS_OFFSET-47 "0"
*MEAS_COND_AXIS_OFFSET-48 "0"
*MEAS_COND_AXIS_OFFSET-49 "0"
*MEAS_COND_AXIS_OFFSET-5 "0"
*MEAS_COND_AXIS_OFFSET-50 "0"
*MEAS_COND_AXIS_OFFSET-51 "0"
*MEAS_COND_AXIS_OFFSET-52 "0"
*MEAS_COND_AXIS_OFFSET-53 "0"
*MEAS_COND_AXIS_OFFSET-54 "0"
*MEAS_COND_AXIS_OFFSET-55 "0"
*MEAS_COND_AXIS_OFFSET-56 "0"
*MEAS_COND_AXIS_OFFSET-57 "0"
*MEAS_COND_AXIS_OFFSET-58 "0"
*MEAS_COND_AXIS_OFFSET-59 "0"
*MEAS_COND_AXIS_OFFSET-6 "0"
*MEAS_COND_AXIS_OFFSET-60 "0"
*MEAS_COND_AXIS_OFFSET-61 "0"
*MEAS_COND_AXIS_OFFSET-62 "0"
*MEAS_COND_AXIS_OFFSET-63 "0"
*MEAS_COND_AXIS_OFFSET-64 "0"
*MEAS_COND_AXIS_OFFSET-65 "0"
*MEAS_COND_AXIS_OFFSET-66 "0"
*MEAS_COND_AXIS_OFFSET-67 "0"
*MEAS_COND_AXIS_OFFSET-68 "0"
*MEAS_COND_AXIS_OFFSET-69 "0"
*MEAS_COND_AXIS_OFFSET-7 "0"
*MEAS_COND_AXIS_OFFSET-70 "0"
*MEAS_COND_AXIS_OFFSET-71 "0"
*MEAS_COND_AXIS_OFFSET-72 "0"
*MEAS_COND_AXIS_OFFSET-73 "0"
*MEAS_COND_AXIS_OFFSET-74 "0"
*MEAS_COND_AXIS_OFFSET-75 "0"
*MEAS_COND_AXIS_OFFSET-76 "0"
*MEAS_COND_AXIS_OFFSET-77 "0"
*MEAS_COND_AXIS_OFFSET-78 "0"
*MEAS_COND_AXIS_OFFSET-79 "0"
*MEAS_COND_AXIS_OFFSET-8 "0"
*MEAS_COND_AXIS_OFFSET-80 "0"
*MEAS_COND_AXIS_OFFSET-81 "0"
*MEAS_COND_AXIS_OFFSET-82 "0"
*MEAS_COND_AXIS_OFFSET-83 "0"
*MEAS_COND_AXIS_OFFSET-84 "0"
*MEAS_COND_AXIS_OFFSET-85 "0"
*MEAS_COND_AXIS_OFFSET-86 "0"
*MEAS_COND_AXIS_OFFSET-87 "0"
*MEAS_COND_AXIS_OFFSET-88 "0"
*MEAS_COND_AXIS_OFFSET-89 "0"
*MEAS_COND_AXIS_OFFSET-9 "0"
*MEAS_COND_AXIS_OFFSET-90 "0"
*MEAS_COND_AXIS_OFFSET-91 "0"
*MEAS_COND_AXIS_OFFSET-92 "0"
*MEAS_COND_AXIS_OFFSET-93 "0"
*MEAS_COND_AXIS_OFFSET-94 "0"
*MEAS_COND_AXIS_OFFSET-95 "0"
*MEAS_COND_AXIS_OFFSET-96 "0"
*MEAS_COND_AXIS_OFFSET-97 "0"
*MEAS_COND_AXIS_OFFSET-98 "0"
*MEAS_COND_AXIS_OFFSET-99 "0"
*MEAS_COND_AXIS_POSITION-0 "1.4928"
*MEAS_COND_AXIS_POSITION-1 "1.5072"
*MEAS_COND_AXIS_POSITION-10 "Right"
*MEAS_COND_AXIS_POSITION-100 "Ge(220)x2"
*MEAS_COND_AXIS_POSITION-101 "PSA_open"
*MEAS_COND_AXIS_POSITION-102 "None"
*MEAS_COND_AXIS_POSITION-11 "None"
*MEAS_COND_AXIS_POSITION-12 "Type1"
*MEAS_COND_AXIS_POSITION-13 "0"
*MEAS_COND_AXIS_POSITION-14 "PB"
*MEAS_COND_AXIS_POSITION-15 "0"
*MEAS_COND_AXIS_POSITION-16 "Soller_slit_open_s"
*MEAS_COND_AXIS_POSITION-17 "0.500mm"
*MEAS_COND_AXIS_POSITION-18 "0.500000"
*MEAS_COND_AXIS_POSITION-19 "0.500mm"
*MEAS_COND_AXIS_POSITION-2 "3.0000"
*MEAS_COND_AXIS_POSITION-20 "-1.9968750"
*MEAS_COND_AXIS_POSITION-21 "5mm"
*MEAS_COND_AXIS_POSITION-22 "5mm"
*MEAS_COND_AXIS_POSITION-23 "5mm"
*MEAS_COND_AXIS_POSITION-24 "0.000"
*MEAS_COND_AXIS_POSITION-25 "0.000"
*MEAS_COND_AXIS_POSITION-26 "-0.9462"
*MEAS_COND_AXIS_POSITION-27 "90.000"
*MEAS_COND_AXIS_POSITION-28 "0.000"
*MEAS_COND_AXIS_POSITION-29 "-0.148"
*MEAS_COND_AXIS_POSITION-3 "1.4928"
*MEAS_COND_AXIS_POSITION-30 "87.19"
*MEAS_COND_AXIS_POSITION-31 "-0.220"
*MEAS_COND_AXIS_POSITION-32 "3.0036"
*MEAS_COND_AXIS_POSITION-33 "0.00000"
*MEAS_COND_AXIS_POSITION-34 "0.03216"
*MEAS_COND_AXIS_POSITION-35 "1.000mm"
*MEAS_COND_AXIS_POSITION-36 "1.000000"
*MEAS_COND_AXIS_POSITION-37 "1.000mm"
*MEAS_COND_AXIS_POSITION-38 "None"
*MEAS_COND_AXIS_POSITION-39 "PSA_open"
*MEAS_COND_AXIS_POSITION-4 "3.0000"
*MEAS_COND_AXIS_POSITION-40 "Soller_slit_5.0deg"
*MEAS_COND_AXIS_POSITION-41 "1.000mm"
*MEAS_COND_AXIS_POSITION-42 "1.000000"
*MEAS_COND_AXIS_POSITION-43 "1.000mm"
*MEAS_COND_AXIS_POSITION-44 "-0.5221875"
*MEAS_COND_AXIS_POSITION-45 "None"
*MEAS_COND_AXIS_POSITION-46 "Open"
*MEAS_COND_AXIS_POSITION-47 "647.0"
*MEAS_COND_AXIS_POSITION-48 "545.00"
*MEAS_COND_AXIS_POSITION-49 "None"
*MEAS_COND_AXIS_POSITION-5 "3.0000"
*MEAS_COND_AXIS_POSITION-50 ""
*MEAS_COND_AXIS_POSITION-51 ""
*MEAS_COND_AXIS_POSITION-52 ""
*MEAS_COND_AXIS_POSITION-53 ""
*MEAS_COND_AXIS_POSITION-54 ""
*MEAS_COND_AXIS_POSITION-55 ""
*MEAS_COND_AXIS_POSITION-56 ""
*MEAS_COND_AXIS_POSITION-57 ""
*MEAS_COND_AXIS_POSITION-58 ""
*MEAS_COND_AXIS_POSITION-59 ""
*MEAS_COND_AXIS_POSITION-6 "1.4928"
*MEAS_COND_AXIS_POSITION-60 ""
*MEAS_COND_AXIS_POSITION-61 ""
*MEAS_COND_AXIS_POSITION-62 ""
*MEAS_COND_AXIS_POSITION-63 ""
*MEAS_COND_AXIS_POSITION-64 ""
*MEAS_COND_AXIS_POSITION-65 ""
*MEAS_COND_AXIS_POSITION-66 ""
*MEAS_COND_AXIS_POSITION-67 ""
*MEAS_COND_AXIS_POSITION-68 ""
*MEAS_COND_AXIS_POSITION-69 ""
*MEAS_COND_AXIS_POSITION-7 "-0.1470"
*MEAS_COND_AXIS_POSITION-70 ""
*MEAS_COND_AXIS_POSITION-71 ""
*MEAS_COND_AXIS_POSITION-72 ""
*MEAS_COND_AXIS_POSITION-73 ""
*MEAS_COND_AXIS_POSITION-74 ""
*MEAS_COND_AXIS_POSITION-75 ""
*MEAS_COND_AXIS_POSITION-76 ""
*MEAS_COND_AXIS_POSITION-77 ""
*MEAS_COND_AXIS_POSITION-78 ""
*MEAS_COND_AXIS_POSITION-79 ""
*MEAS_COND_AXIS_POSITION-8 "None"
*MEAS_COND_AXIS_POSITION-80 ""
*MEAS_COND_AXIS_POSITION-81 ""
*MEAS_COND_AXIS_POSITION-82 ""
*MEAS_COND_AXIS_POSITION-83 ""
*MEAS_COND_AXIS_POSITION-84 ""
*MEAS_COND_AXIS_POSITION-85 ""
*MEAS_COND_AXIS_POSITION-86 ""
*MEAS_COND_AXIS_POSITION-87 ""
*MEAS_COND_AXIS_POSITION-88 ""
*MEAS_COND_AXIS_POSITION-89 ""
*MEAS_COND_AXIS_POSITION-9 "-5.4938125"
*MEAS_COND_AXIS_POSITION-90 ""
*MEAS_COND_AXIS_POSITION-91 ""
*MEAS_COND_AXIS_POSITION-92 ""
*MEAS_COND_AXIS_POSITION-93 ""
*MEAS_COND_AXIS_POSITION-94 ""
*MEAS_COND_AXIS_POSITION-95 ""
*MEAS_COND_AXIS_POSITION-96 ""
*MEAS_COND_AXIS_POSITION-97 ""
*MEAS_COND_AXIS_POSITION-98 ""
*MEAS_COND_AXIS_POSITION-99 "Standard"
*MEAS_COND_AXIS_RESOLUTION-0 "0.0001"
*MEAS_COND_AXIS_RESOLUTION-1 "0.0001"
*MEAS_COND_AXIS_RESOLUTION-10 ""
*MEAS_COND_AXIS_RESOLUTION-11 ""
*MEAS_COND_AXIS_RESOLUTION-12 ""
*MEAS_COND_AXIS_RESOLUTION-13 "1"
*MEAS_COND_AXIS_RESOLUTION-14 ""
*MEAS_COND_AXIS_RESOLUTION-15 "1"
*MEAS_COND_AXIS_RESOLUTION-16 ""
*MEAS_COND_AXIS_RESOLUTION-17 "1/1600"
*MEAS_COND_AXIS_RESOLUTION-18 "1/1600"
*MEAS_COND_AXIS_RESOLUTION-19 "1/1600"
*MEAS_COND_AXIS_RESOLUTION-2 "0.0001"
*MEAS_COND_AXIS_RESOLUTION-20 "0.0003125"
*MEAS_COND_AXIS_RESOLUTION-21 ""
*MEAS_COND_AXIS_RESOLUTION-22 ""
*MEAS_COND_AXIS_RESOLUTION-23 ""
*MEAS_COND_AXIS_RESOLUTION-24 "0.001"
*MEAS_COND_AXIS_RESOLUTION-25 "0.002"
*MEAS_COND_AXIS_RESOLUTION-26 "0.0001"
*MEAS_COND_AXIS_RESOLUTION-27 "0.001"
*MEAS_COND_AXIS_RESOLUTION-28 "0.002"
*MEAS_COND_AXIS_RESOLUTION-29 "0.004"
*MEAS_COND_AXIS_RESOLUTION-3 "0.0001"
*MEAS_COND_AXIS_RESOLUTION-30 "0.01"
*MEAS_COND_AXIS_RESOLUTION-31 "0.002"
*MEAS_COND_AXIS_RESOLUTION-32 "0.0001"
*MEAS_COND_AXIS_RESOLUTION-33 "0.00099"
*MEAS_COND_AXIS_RESOLUTION-34 "0.00134"
*MEAS_COND_AXIS_RESOLUTION-35 "1/1600"
*MEAS_COND_AXIS_RESOLUTION-36 "1/1600"
*MEAS_COND_AXIS_RESOLUTION-37 "1/1600"
*MEAS_COND_AXIS_RESOLUTION-38 ""
*MEAS_COND_AXIS_RESOLUTION-39 ""
*MEAS_COND_AXIS_RESOLUTION-4 "0.0002"
*MEAS_COND_AXIS_RESOLUTION-40 ""
*MEAS_COND_AXIS_RESOLUTION-41 "1/1600"
*MEAS_COND_AXIS_RESOLUTION-42 "1/1600"
*MEAS_COND_AXIS_RESOLUTION-43 "1/1600"
*MEAS_COND_AXIS_RESOLUTION-44 "0.0003125"
*MEAS_COND_AXIS_RESOLUTION-45 ""
*MEAS_COND_AXIS_RESOLUTION-46 "1/800"
*MEAS_COND_AXIS_RESOLUTION-47 "0.5"
*MEAS_COND_AXIS_RESOLUTION-48 "1.25"
*MEAS_COND_AXIS_RESOLUTION-49 ""
*MEAS_COND_AXIS_RESOLUTION-5 "0.0002"
*MEAS_COND_AXIS_RESOLUTION-50 "0.010000"
*MEAS_COND_AXIS_RESOLUTION-51 "0.010000"
*MEAS_COND_AXIS_RESOLUTION-52 "0.01"
*MEAS_COND_AXIS_RESOLUTION-53 "0.010000"
*MEAS_COND_AXIS_RESOLUTION-54 "0.01"
*MEAS_COND_AXIS_RESOLUTION-55 "1.000000"
*MEAS_COND_AXIS_RESOLUTION-56 "1.000000"
*MEAS_COND_AXIS_RESOLUTION-57 "1"
*MEAS_COND_AXIS_RESOLUTION-58 "1"
*MEAS_COND_AXIS_RESOLUTION-59 "0.01"
*MEAS_COND_AXIS_RESOLUTION-6 "0.0001"
*MEAS_COND_AXIS_RESOLUTION-60 "0.01"
*MEAS_COND_AXIS_RESOLUTION-61 "0.01"
*MEAS_COND_AXIS_RESOLUTION-62 "0.01"
*MEAS_COND_AXIS_RESOLUTION-63 "0.010000"
*MEAS_COND_AXIS_RESOLUTION-64 "1"
*MEAS_COND_AXIS_RESOLUTION-65 "0.1"
*MEAS_COND_AXIS_RESOLUTION-66 "1"
*MEAS_COND_AXIS_RESOLUTION-67 "0.010000"
*MEAS_COND_AXIS_RESOLUTION-68 "0.01"
*MEAS_COND_AXIS_RESOLUTION-69 "0.01"
*MEAS_COND_AXIS_RESOLUTION-7 "0.0005"
*MEAS_COND_AXIS_RESOLUTION-70 "0.100000"
*MEAS_COND_AXIS_RESOLUTION-71 "1.000000"
*MEAS_COND_AXIS_RESOLUTION-72 "0.01"
*MEAS_COND_AXIS_RESOLUTION-73 "1.000000"
*MEAS_COND_AXIS_RESOLUTION-74 "1"
*MEAS_COND_AXIS_RESOLUTION-75 "1.000000"
*MEAS_COND_AXIS_RESOLUTION-76 "1"
*MEAS_COND_AXIS_RESOLUTION-77 "0.01"
*MEAS_COND_AXIS_RESOLUTION-78 "1"
*MEAS_COND_AXIS_RESOLUTION-79 "1"
*MEAS_COND_AXIS_RESOLUTION-8 ""
*MEAS_COND_AXIS_RESOLUTION-80 "1"
*MEAS_COND_AXIS_RESOLUTION-81 "0.01"
*MEAS_COND_AXIS_RESOLUTION-82 "1.000000"
*MEAS_COND_AXIS_RESOLUTION-83 "1.000000"
*MEAS_COND_AXIS_RESOLUTION-84 "1.000000"
*MEAS_COND_AXIS_RESOLUTION-85 "-"
*MEAS_COND_AXIS_RESOLUTION-86 "-"
*MEAS_COND_AXIS_RESOLUTION-87 "-"
*MEAS_COND_AXIS_RESOLUTION-88 "1.000000"
*MEAS_COND_AXIS_RESOLUTION-89 "-"
*MEAS_COND_AXIS_RESOLUTION-9 "0.0000625"
*MEAS_COND_AXIS_RESOLUTION-90 "-"
*MEAS_COND_AXIS_RESOLUTION-91 "-"
*MEAS_COND_AXIS_RESOLUTION-92 "1.000000"
*MEAS_COND_AXIS_RESOLUTION-93 "1.000000"
*MEAS_COND_AXIS_RESOLUTION-94 "1.000000"
*MEAS_COND_AXIS_RESOLUTION-95 "1.000000"
*MEAS_COND_AXIS_RESOLUTION-96 "1.000000"
*MEAS_COND_AXIS_RESOLUTION-97 "1.000000"
*MEAS_COND_AXIS_RESOLUTION-98 "1.000000"
*MEAS_COND_AXIS_STATE-0 "Fixed"
*MEAS_COND_AXIS_STATE-1 "Fixed"
*MEAS_COND_AXIS_STATE-10 "Fixed"
*MEAS_COND_AXIS_STATE-11 "Fixed"
*MEAS_COND_AXIS_STATE-12 "Fixed"
*MEAS_COND_AXIS_STATE-13 "Fixed"
*MEAS_COND_AXIS_STATE-14 "Fixed"
*MEAS_COND_AXIS_STATE-15 "Fixed"
*MEAS_COND_AXIS_STATE-16 "Fixed"
*MEAS_COND_AXIS_STATE-17 "Fixed"
*MEAS_COND_AXIS_STATE-18 "Fixed"
*MEAS_COND_AXIS_STATE-19 "Fixed"
*MEAS_COND_AXIS_STATE-2 "Fixed"
*MEAS_COND_AXIS_STATE-20 "Fixed"
*MEAS_COND_AXIS_STATE-21 "Fixed"
*MEAS_COND_AXIS_STATE-22 "Fixed"
*MEAS_COND_AXIS_STATE-23 "Fixed"
*MEAS_COND_AXIS_STATE-24 "Fixed"
*MEAS_COND_AXIS_STATE-25 "Fixed"
*MEAS_COND_AXIS_STATE-26 "Fixed"
*MEAS_COND_AXIS_STATE-27 "Fixed"
*MEAS_COND_AXIS_STATE-28 "Fixed"
*MEAS_COND_AXIS_STATE-29 "Fixed"
*MEAS_COND_AXIS_STATE-3 "Fixed"
*MEAS_COND_AXIS_STATE-30 "Fixed"
*MEAS_COND_AXIS_STATE-31 "Fixed"
*MEAS_COND_AXIS_STATE-32 "Fixed"
*MEAS_COND_AXIS_STATE-33 "Fixed"
*MEAS_COND_AXIS_STATE-34 "Fixed"
*MEAS_COND_AXIS_STATE-35 "Fixed"
*MEAS_COND_AXIS_STATE-36 "Fixed"
*MEAS_COND_AXIS_STATE-37 "Fixed"
*MEAS_COND_AXIS_STATE-38 "Fixed"
*MEAS_COND_AXIS_STATE-39 "Fixed"
*MEAS_COND_AXIS_STATE-4 "Fixed"
*MEAS_COND_AXIS_STATE-40 "Fixed"
*MEAS_COND_AXIS_STATE-41 "Fixed"
*MEAS_COND_AXIS_STATE-42 "Fixed"
*MEAS_COND_AXIS_STATE-43 "Fixed"
*MEAS_COND_AXIS_STATE-44 "Fixed"
*MEAS_COND_AXIS_STATE-45 "Fixed"
*MEAS_COND_AXIS_STATE-46 "Fixed"
*MEAS_COND_AXIS_STATE-47 "Fixed"
*MEAS_COND_AXIS_STATE-48 "Fixed"
*MEAS_COND_AXIS_STATE-49 "Fixed"
*MEAS_COND_AXIS_STATE-5 "Scan"
*MEAS_COND_AXIS_STATE-50 "Fixed"
*MEAS_COND_AXIS_STATE-51 "Fixed"
*MEAS_COND_AXIS_STATE-52 "Fixed"
*MEAS_COND_AXIS_STATE-53 "Fixed"
*MEAS_COND_AXIS_STATE-54 "Fixed"
*MEAS_COND_AXIS_STATE-55 "Fixed"
*MEAS_COND_AXIS_STATE-56 "Fixed"
*MEAS_COND_AXIS_STATE-57 "Fixed"
*MEAS_COND_AXIS_STATE-58 "Fixed"
*MEAS_COND_AXIS_STATE-59 "Fixed"
*MEAS_COND_AXIS_STATE-6 "Fixed"
*MEAS_COND_AXIS_STATE-60 "Fixed"
*MEAS_COND_AXIS_STATE-61 "Fixed"
*MEAS_COND_AXIS_STATE-62 "Fixed"
*MEAS_COND_AXIS_STATE-63 "Fixed"
*MEAS_COND_AXIS_STATE-64 "Fixed"
*MEAS_COND_AXIS_STATE-65 "Fixed"
*MEAS_COND_AXIS_STATE-66 "Fixed"
*MEAS_COND_AXIS_STATE-67 "Fixed"
*MEAS_COND_AXIS_STATE-68 "Fixed"
*MEAS_COND_AXIS_STATE-69 "Fixed"
*MEAS_COND_AXIS_STATE-7 "Fixed"
*MEAS_COND_AXIS_STATE-70 "Fixed"
*MEAS_COND_AXIS_STATE-71 "Fixed"
*MEAS_COND_AXIS_STATE-72 "Fixed"
*MEAS_COND_AXIS_STATE-73 "Fixed"
*MEAS_COND_AXIS_STATE-74 "Fixed"
*MEAS_COND_AXIS_STATE-75 "Fixed"
*MEAS_COND_AXIS_STATE-76 "Fixed"
*MEAS_COND_AXIS_STATE-77 "Fixed"
*MEAS_COND_AXIS_STATE-78 "Fixed"
*MEAS_COND_AXIS_STATE-79 "Fixed"
*MEAS_COND_AXIS_STATE-8 "Fixed"
*MEAS_COND_AXIS_STATE-80 "Fixed"
*MEAS_COND_AXIS_STATE-81 "Fixed"
*MEAS_COND_AXIS_STATE-82 "Fixed"
*MEAS_COND_AXIS_STATE-83 "Fixed"
*MEAS_COND_AXIS_STATE-84 "Fixed"
*MEAS_COND_AXIS_STATE-85 "Fixed"
*MEAS_COND_AXIS_STATE-86 "Fixed"
*MEAS_COND_AXIS_STATE-87 "Fixed"
*MEAS_COND_AXIS_STATE-88 "Fixed"
*MEAS_COND_AXIS_STATE-89 "Fixed"
*MEAS_COND_AXIS_STATE-9 "Fixed"
*MEAS_COND_AXIS_STATE-90 "Fixed"
*MEAS_COND_AXIS_STATE-91 "Fixed"
*MEAS_COND_AXIS_STATE-92 "Fixed"
*MEAS_COND_AXIS_STATE-93 "Fixed"
*MEAS_COND_AXIS_STATE-94 "Fixed"
*MEAS_COND_AXIS_STATE-95 "Fixed"
*MEAS_COND_AXIS_STATE-96 "Fixed"
*MEAS_COND_AXIS_STATE-97 "Fixed"
*MEAS_COND_AXIS_STATE-98 "Fixed"
*MEAS_COND_AXIS_UNIT-0 "deg"
*MEAS_COND_AXIS_UNIT-1 "deg"
*MEAS_COND_AXIS_UNIT-10 ""
*MEAS_COND_AXIS_UNIT-100 ""
*MEAS_COND_AXIS_UNIT-101 ""
*MEAS_COND_AXIS_UNIT-102 ""
*MEAS_COND_AXIS_UNIT-11 ""
*MEAS_COND_AXIS_UNIT-12 ""
*MEAS_COND_AXIS_UNIT-13 "pulse"
*MEAS_COND_AXIS_UNIT-14 ""
*MEAS_COND_AXIS_UNIT-15 "pulse"
*MEAS_COND_AXIS_UNIT-16 ""
*MEAS_COND_AXIS_UNIT-17 ""
*MEAS_COND_AXIS_UNIT-18 "mm"
*MEAS_COND_AXIS_UNIT-19 ""
*MEAS_COND_AXIS_UNIT-2 "deg"
*MEAS_COND_AXIS_UNIT-20 "mm"
*MEAS_COND_AXIS_UNIT-21 ""
*MEAS_COND_AXIS_UNIT-22 ""
*MEAS_COND_AXIS_UNIT-23 ""
*MEAS_COND_AXIS_UNIT-24 "deg"
*MEAS_COND_AXIS_UNIT-25 "deg"
*MEAS_COND_AXIS_UNIT-26 "mm"
*MEAS_COND_AXIS_UNIT-27 "deg"
*MEAS_COND_AXIS_UNIT-28 "deg"
*MEAS_COND_AXIS_UNIT-29 "deg"
*MEAS_COND_AXIS_UNIT-3 "deg"
*MEAS_COND_AXIS_UNIT-30 "deg"
*MEAS_COND_AXIS_UNIT-31 "deg"
*MEAS_COND_AXIS_UNIT-32 "deg"
*MEAS_COND_AXIS_UNIT-33 "deg"
*MEAS_COND_AXIS_UNIT-34 "deg"
*MEAS_COND_AXIS_UNIT-35 ""
*MEAS_COND_AXIS_UNIT-36 "mm"
*MEAS_COND_AXIS_UNIT-37 ""
*MEAS_COND_AXIS_UNIT-38 ""
*MEAS_COND_AXIS_UNIT-39 ""
*MEAS_COND_AXIS_UNIT-4 "deg"
*MEAS_COND_AXIS_UNIT-40 ""
*MEAS_COND_AXIS_UNIT-41 ""
*MEAS_COND_AXIS_UNIT-42 "mm"
*MEAS_COND_AXIS_UNIT-43 ""
*MEAS_COND_AXIS_UNIT-44 "mm"
*MEAS_COND_AXIS_UNIT-45 ""
*MEAS_COND_AXIS_UNIT-46 ""
*MEAS_COND_AXIS_UNIT-47 "V"
*MEAS_COND_AXIS_UNIT-48 "mV"
*MEAS_COND_AXIS_UNIT-49 ""
*MEAS_COND_AXIS_UNIT-5 "deg"
*MEAS_COND_AXIS_UNIT-50 "H"
*MEAS_COND_AXIS_UNIT-51 "H"
*MEAS_COND_AXIS_UNIT-52 "H"
*MEAS_COND_AXIS_UNIT-53 "H"
*MEAS_COND_AXIS_UNIT-54 "H"
*MEAS_COND_AXIS_UNIT-55 "mV"
*MEAS_COND_AXIS_UNIT-56 "V"
*MEAS_COND_AXIS_UNIT-57 "V"
*MEAS_COND_AXIS_UNIT-58 "V"
*MEAS_COND_AXIS_UNIT-59 "H"
*MEAS_COND_AXIS_UNIT-6 "deg"
*MEAS_COND_AXIS_UNIT-60 "H"
*MEAS_COND_AXIS_UNIT-61 "H"
*MEAS_COND_AXIS_UNIT-62 "H"
*MEAS_COND_AXIS_UNIT-63 "H"
*MEAS_COND_AXIS_UNIT-64 "uS/m"
*MEAS_COND_AXIS_UNIT-65 "L/min"
*MEAS_COND_AXIS_UNIT-66 "C"
*MEAS_COND_AXIS_UNIT-67 "MPa"
*MEAS_COND_AXIS_UNIT-68 "MPa"
*MEAS_COND_AXIS_UNIT-69 "MPa"
*MEAS_COND_AXIS_UNIT-7 "deg"
*MEAS_COND_AXIS_UNIT-70 "L/min"
*MEAS_COND_AXIS_UNIT-71 "degree"
*MEAS_COND_AXIS_UNIT-72 "MPa"
*MEAS_COND_AXIS_UNIT-73 "degree"
*MEAS_COND_AXIS_UNIT-74 "percent"
*MEAS_COND_AXIS_UNIT-75 "degree"
*MEAS_COND_AXIS_UNIT-76 "C"
*MEAS_COND_AXIS_UNIT-77 "H"
*MEAS_COND_AXIS_UNIT-78 "time"
*MEAS_COND_AXIS_UNIT-79 "msec"
*MEAS_COND_AXIS_UNIT-8 ""
*MEAS_COND_AXIS_UNIT-80 "msec"
*MEAS_COND_AXIS_UNIT-81 "H"
*MEAS_COND_AXIS_UNIT-82 "times"
*MEAS_COND_AXIS_UNIT-83 "msec"
*MEAS_COND_AXIS_UNIT-84 "msec"
*MEAS_COND_AXIS_UNIT-85 "-"
*MEAS_COND_AXIS_UNIT-86 "-"
*MEAS_COND_AXIS_UNIT-87 "-"
*MEAS_COND_AXIS_UNIT-88 ""
*MEAS_COND_AXIS_UNIT-89 "-"
*MEAS_COND_AXIS_UNIT-9 "mm"
*MEAS_COND_AXIS_UNIT-90 "-"
*MEAS_COND_AXIS_UNIT-91 "-"
*MEAS_COND_AXIS_UNIT-92 ""
*MEAS_COND_AXIS_UNIT-93 ""
*MEAS_COND_AXIS_UNIT-94 ""
*MEAS_COND_AXIS_UNIT-95 ""
*MEAS_COND_AXIS_UNIT-96 ""
*MEAS_COND_AXIS_UNIT-97 ""
*MEAS_COND_AXIS_UNIT-98 ""
*MEAS_COND_AXIS_UNIT-99 ""
*MEAS_COND_OPT_ATTR "PB-Ge(220)x2"
*MEAS_COND_OPT_NAME "User defined settings"
*MEAS_COND_XG_CURRENT "160"
*MEAS_COND_XG_VOLTAGE "45"
*MEAS_COND_XG_WAVE_TYPE "Ka1"
*MEAS_DATA_COUNT "2001"
*MEAS_SCAN_AXIS_X "TwoThetaOmega"
*MEAS_SCAN_AXIS_X_INTERNAL "TwoThetaOmega"
*MEAS_SCAN_END_TIME "09/02/2020 13:28:07"
*MEAS_SCAN_MODE "CONTINUOUS"
*MEAS_SCAN_MODE_INTERNAL "CONTINUOUS"
*MEAS_SCAN_RESOLUTION_X "0.0002"
*MEAS_SCAN_SPEED "1.0000"
*MEAS_SCAN_SPEED_UNIT "deg/min"
*MEAS_SCAN_START "0.0000"
*MEAS_SCAN_START_TIME "09/02/2020 12:47:25"
*MEAS_SCAN_STEP "0.0200"
*MEAS_SCAN_STOP "40.0000"
*MEAS_SCAN_UNIT_X "deg"
*MEAS_SCAN_UNIT_Y "counts"
*RAS_HEADER_END
*RAS_INT_START
0.0000 5943.0000 10762.7031
0.0400 6001.0000 10762.7031
0.0800 5985.0000 10762.7031
0.1200 4414.0000 10762.7031
0.1600 8208.0000 777.1638
0.2000 7786.0000 777.1638
0.2400 9285.0000 777.1638
0.2800 11130.0000 777.1638
0.3200 12664.0000 777.1638
0.3600 14183.0000 777.1638
0.4000 15408.0000 777.1638
0.4400 16675.0000 777.1638
0.4800 17588.0000 777.1638
0.5200 18738.0000 777.1638
0.5600 18975.0000 777.1638
0.6000 16331.0000 777.1638
0.6400 11887.0000 777.1638
0.6800 6800.0000 777.1638
0.7200 3973.0000 777.1638
0.7600 2445.0000 777.1638
0.8000 1856.0000 777.1638
0.8400 17426.0000 53.8780
0.8800 15044.0000 53.8780
0.9200 11583.0000 53.8780
0.9600 7723.0000 53.8780
1.0000 7202.0000 53.8780
1.0400 6180.0000 53.8780
1.0800 4044.0000 53.8780
1.1200 3569.0000 53.8780
1.1600 3506.0000 53.8780
1.2000 2481.0000 53.8780
1.2400 1812.0000 53.8780
1.2800 1914.0000 53.8780
1.3200 1610.0000 53.8780
1.3600 67647.0000 1.0000
1.4000 55991.0000 1.0000
1.4400 58771.0000 1.0000
1.4800 50223.0000 1.0000
1.5200 34876.0000 1.0000
1.5600 31302.0000 1.0000
1.6000 32991.0000 1.0000
1.6400 27183.0000 1.0000
1.6800 19372.0000 1.0000
1.7200 18537.0000 1.0000
1.7600 19283.0000 1.0000
1.8000 16235.0000 1.0000
1.8400 11918.0000 1.0000
1.8800 11467.0000 1.0000
1.9200 12115.0000 1.0000
1.9600 10511.0000 1.0000
2.0000 8060.0000 1.0000
2.0400 7686.0000 1.0000
2.0800 8501.0000 1.0000
2.1200 7544.0000 1.0000
2.1600 6022.0000 1.0000
2.2000 5715.0000 1.0000
2.2400 6402.0000 1.0000
2.2800 6089.0000 1.0000
2.3200 5013.0000 1.0000
2.3600 4743.0000 1.0000
2.4000 5176.0000 1.0000
2.4400 5240.0000 1.0000
2.4800 4375.0000 1.0000
2.5200 4139.0000 1.0000
2.5600 4431.0000 1.0000
2.6000 4482.0000 1.0000
2.6400 4006.0000 1.0000
2.6800 3630.0000 1.0000
2.7200 3951.0000 1.0000
2.7600 3863.0000 1.0000
2.8000 3587.0000 1.0000
2.8400 3278.0000 1.0000
2.8800 3284.0000 1.0000
2.9200 3386.0000 1.0000
2.9600 3077.0000 1.0000
3.0000 2728.0000 1.0000
3.0400 2959.0000 1.0000
3.0800 2933.0000 1.0000
3.1200 2662.0000 1.0000
3.1600 2501.0000 1.0000
3.2000 2413.0000 1.0000
3.2400 2392.0000 1.0000
3.2800 2164.0000 1.0000
3.3200 2131.0000 1.0000
3.3600 1862.0000 1.0000
3.4000 2021.0000 1.0000
3.4400 1719.0000 1.0000
3.4800 1600.0000 1.0000
3.5200 1517.0000 1.0000
3.5600 1534.0000 1.0000
3.6000 1406.0000 1.0000
3.6400 1243.0000 1.0000
3.6800 1204.0000 1.0000
3.7200 1258.0000 1.0000
3.7600 1133.0000 1.0000
3.8000 923.0000 1.0000
3.8400 946.0000 1.0000
3.8800 907.0000 1.0000
3.9200 849.0000 1.0000
3.9600 713.0000 1.0000
4.0000 726.0000 1.0000
4.0400 672.0000 1.0000
4.0800 573.0000 1.0000
4.1200 524.0000 1.0000
4.1600 519.0000 1.0000
4.2000 465.0000 1.0000
4.2400 449.0000 1.0000
4.2800 368.0000 1.0000
4.3200 324.0000 1.0000
4.3600 370.0000 1.0000
4.4000 314.0000 1.0000
4.4400 318.0000 1.0000
4.4800 274.0000 1.0000
4.5200 259.0000 1.0000
4.5600 247.0000 1.0000
4.6000 192.0000 1.0000
4.6400 196.0000 1.0000
4.6800 186.0000 1.0000
4.7200 175.0000 1.0000
4.7600 148.0000 1.0000
4.8000 168.0000 1.0000
4.8400 174.0000 1.0000
4.8800 144.0000 1.0000
4.9200 130.0000 1.0000
4.9600 149.0000 1.0000
5.0000 122.0000 1.0000
5.0400 134.0000 1.0000
5.0800 102.0000 1.0000
5.1200 107.0000 1.0000
5.1600 120.0000 1.0000
5.2000 107.0000 1.0000
5.2400 125.0000 1.0000
5.2800 106.0000 1.0000
5.3200 74.0000 1.0000
5.3600 93.0000 1.0000
5.4000 98.0000 1.0000
5.4400 115.0000 1.0000
5.4800 81.0000 1.0000
5.5200 98.0000 1.0000
5.5600 93.0000 1.0000
5.6000 82.0000 1.0000
5.6400 100.0000 1.0000
5.6800 83.0000 1.0000
5.7200 89.0000 1.0000
5.7600 85.0000 1.0000
5.8000 97.0000 1.0000
5.8400 88.0000 1.0000
5.8800 84.0000 1.0000
5.9200 92.0000 1.0000
5.9600 78.0000 1.0000
6.0000 86.0000 1.0000
6.0400 82.0000 1.0000
6.0800 98.0000 1.0000
6.1200 73.0000 1.0000
6.1600 85.0000 1.0000
6.2000 84.0000 1.0000
6.2400 69.0000 1.0000
6.2800 90.0000 1.0000
6.3200 71.0000 1.0000
6.3600 92.0000 1.0000
6.4000 65.0000 1.0000
6.4400 85.0000 1.0000
6.4800 78.0000 1.0000
6.5200 74.0000 1.0000
6.5600 88.0000 1.0000
6.6000 73.0000 1.0000
6.6400 64.0000 1.0000
6.6800 79.0000 1.0000
6.7200 65.0000 1.0000
6.7600 84.0000 1.0000
6.8000 72.0000 1.0000
6.8400 67.0000 1.0000
6.8800 71.0000 1.0000
6.9200 64.0000 1.0000
6.9600 57.0000 1.0000
7.0000 70.0000 1.0000
7.0400 50.0000 1.0000
7.0800 62.0000 1.0000
7.1200 55.0000 1.0000
7.1600 60.0000 1.0000
7.2000 54.0000 1.0000
7.2400 60.0000 1.0000
7.2800 57.0000 1.0000
7.3200 53.0000 1.0000
7.3600 62.0000 1.0000
7.4000 49.0000 1.0000
7.4400 64.0000 1.0000
7.4800 64.0000 1.0000
7.5200 50.0000 1.0000
7.5600 53.0000 1.0000
7.6000 71.0000 1.0000
7.6400 57.0000 1.0000
7.6800 47.0000 1.0000
7.7200 65.0000 1.0000
7.7600 51.0000 1.0000
7.8000 59.0000 1.0000
7.8400 44.0000 1.0000
7.8800 52.0000 1.0000
7.9200 60.0000 1.0000
7.9600 61.0000 1.0000
8.0000 44.0000 1.0000
8.0400 47.0000 1.0000
8.0800 41.0000 1.0000
8.1200 40.0000 1.0000
8.1600 52.0000 1.0000
8.2000 56.0000 1.0000
8.2400 54.0000 1.0000
8.2800 56.0000 1.0000
8.3200 42.0000 1.0000
8.3600 41.0000 1.0000
8.4000 61.0000 1.0000
8.4400 56.0000 1.0000
8.4800 46.0000 1.0000
8.5200 45.0000 1.0000
8.5600 49.0000 1.0000
8.6000 41.0000 1.0000
8.6400 57.0000 1.0000
8.6800 55.0000 1.0000
8.7200 52.0000 1.0000
8.7600 51.0000 1.0000
8.8000 52.0000 1.0000
8.8400 43.0000 1.0000
8.8800 37.0000 1.0000
8.9200 36.0000 1.0000
8.9600 49.0000 1.0000
9.0000 46.0000 1.0000
9.0400 41.0000 1.0000
9.0800 39.0000 1.0000
9.1200 49.0000 1.0000
9.1600 46.0000 1.0000
9.2000 55.0000 1.0000
9.2400 57.0000 1.0000
9.2800 48.0000 1.0000
9.3200 45.0000 1.0000
9.3600 38.0000 1.0000
9.4000 40.0000 1.0000
9.4400 31.0000 1.0000
9.4800 37.0000 1.0000
9.5200 46.0000 1.0000
9.5600 47.0000 1.0000
9.6000 44.0000 1.0000
9.6400 49.0000 1.0000
9.6800 35.0000 1.0000
9.7200 39.0000 1.0000
9.7600 38.0000 1.0000
9.8000 40.0000 1.0000
9.8400 33.0000 1.0000
9.8800 44.0000 1.0000
9.9200 35.0000 1.0000
9.9600 42.0000 1.0000
10.0000 45.0000 1.0000
10.0400 39.0000 1.0000
10.0800 45.0000 1.0000
10.1200 41.0000 1.0000
10.1600 41.0000 1.0000
10.2000 34.0000 1.0000
10.2400 41.0000 1.0000
10.2800 45.0000 1.0000
10.3200 37.0000 1.0000
10.3600 36.0000 1.0000
10.4000 34.0000 1.0000
10.4400 35.0000 1.0000
10.4800 27.0000 1.0000
10.5200 39.0000 1.0000
10.5600 42.0000 1.0000
10.6000 37.0000 1.0000
10.6400 30.0000 1.0000
10.6800 38.0000 1.0000
10.7200 45.0000 1.0000
10.7600 44.0000 1.0000
10.8000 50.0000 1.0000
10.8400 32.0000 1.0000
10.8800 31.0000 1.0000
10.9200 32.0000 1.0000
10.9600 35.0000 1.0000
11.0000 42.0000 1.0000
11.0400 36.0000 1.0000
11.0800 47.0000 1.0000
11.1200 27.0000 1.0000
11.1600 30.0000 1.0000
11.2000 51.0000 1.0000
11.2400 40.0000 1.0000
11.2800 45.0000 1.0000
11.3200 38.0000 1.0000
11.3600 41.0000 1.0000
11.4000 47.0000 1.0000
11.4400 41.0000 1.0000
11.4800 55.0000 1.0000
11.5200 37.0000 1.0000
11.5600 35.0000 1.0000
11.6000 43.0000 1.0000
11.6400 40.0000 1.0000
11.6800 38.0000 1.0000
11.7200 40.0000 1.0000
11.7600 45.0000 1.0000
11.8000 26.0000 1.0000
11.8400 36.0000 1.0000
11.8800 39.0000 1.0000
11.9200 30.0000 1.0000
11.9600 35.0000 1.0000
12.0000 38.0000 1.0000
12.0400 36.0000 1.0000
12.0800 39.0000 1.0000
12.1200 44.0000 1.0000
12.1600 39.0000 1.0000
12.2000 35.0000 1.0000
12.2400 37.0000 1.0000
12.2800 33.0000 1.0000
12.3200 41.0000 1.0000
12.3600 39.0000 1.0000
12.4000 42.0000 1.0000
12.4400 42.0000 1.0000
12.4800 44.0000 1.0000
12.5200 38.0000 1.0000
12.5600 28.0000 1.0000
12.6000 33.0000 1.0000
12.6400 41.0000 1.0000
12.6800 34.0000 1.0000
12.7200 37.0000 1.0000
12.7600 39.0000 1.0000
12.8000 32.0000 1.0000
12.8400 33.0000 1.0000
12.8800 48.0000 1.0000
12.9200 53.0000 1.0000
12.9600 36.0000 1.0000
13.0000 35.0000 1.0000
13.0400 29.0000 1.0000
13.0800 42.0000 1.0000
13.1200 38.0000 1.0000
13.1600 41.0000 1.0000
13.2000 54.0000 1.0000
13.2400 49.0000 1.0000
13.2800 58.0000 1.0000
13.3200 44.0000 1.0000
13.3600 45.0000 1.0000
13.4000 56.0000 1.0000
13.4400 66.0000 1.0000
13.4800 45.0000 1.0000
13.5200 54.0000 1.0000
13.5600 59.0000 1.0000
13.6000 76.0000 1.0000
13.6400 77.0000 1.0000
13.6800 68.0000 1.0000
13.7200 72.0000 1.0000
13.7600 82.0000 1.0000
13.8000 83.0000 1.0000
13.8400 76.0000 1.0000
13.8800 80.0000 1.0000
13.9200 77.0000 1.0000
13.9600 64.0000 1.0000
14.0000 52.0000 1.0000
14.0400 51.0000 1.0000
14.0800 59.0000 1.0000
14.1200 47.0000 1.0000
14.1600 39.0000 1.0000
14.2000 38.0000 1.0000
14.2400 45.0000 1.0000
14.2800 45.0000 1.0000
14.3200 44.0000 1.0000
14.3600 42.0000 1.0000
14.4000 40.0000 1.0000
14.4400 33.0000 1.0000
14.4800 35.0000 1.0000
14.5200 39.0000 1.0000
14.5600 44.0000 1.0000
14.6000 55.0000 1.0000
14.6400 34.0000 1.0000
14.6800 46.0000 1.0000
14.7200 29.0000 1.0000
14.7600 45.0000 1.0000
14.8000 36.0000 1.0000
14.8400 31.0000 1.0000
14.8800 31.0000 1.0000
14.9200 37.0000 1.0000
14.9600 44.0000 1.0000
15.0000 37.0000 1.0000
15.0400 42.0000 1.0000
15.0800 33.0000 1.0000
15.1200 37.0000 1.0000
15.1600 44.0000 1.0000
15.2000 36.0000 1.0000
15.2400 35.0000 1.0000
15.2800 45.0000 1.0000
15.3200 41.0000 1.0000
15.3600 46.0000 1.0000
15.4000 43.0000 1.0000
15.4400 38.0000 1.0000
15.4800 50.0000 1.0000
15.5200 46.0000 1.0000
15.5600 57.0000 1.0000
15.6000 38.0000 1.0000
15.6400 45.0000 1.0000
15.6800 46.0000 1.0000
15.7200 43.0000 1.0000
15.7600 42.0000 1.0000
15.8000 32.0000 1.0000
15.8400 54.0000 1.0000
15.8800 47.0000 1.0000
15.9200 52.0000 1.0000
15.9600 49.0000 1.0000
16.0000 42.0000 1.0000
16.0400 60.0000 1.0000
16.0800 49.0000 1.0000
16.1200 48.0000 1.0000
16.1600 72.0000 1.0000
16.2000 66.0000 1.0000
16.2400 77.0000 1.0000
16.2800 73.0000 1.0000
16.3200 79.0000 1.0000
16.3600 86.0000 1.0000
16.4000 101.0000 1.0000
16.4400 110.0000 1.0000
16.4800 123.0000 1.0000
16.5200 140.0000 1.0000
16.5600 148.0000 1.0000
16.6000 156.0000 1.0000
16.6400 154.0000 1.0000
16.6800 175.0000 1.0000
16.7200 172.0000 1.0000
16.7600 140.0000 1.0000
16.8000 139.0000 1.0000
16.8400 101.0000 1.0000
16.8800 115.0000 1.0000
16.9200 88.0000 1.0000
16.9600 88.0000 1.0000
17.0000 78.0000 1.0000
17.0400 65.0000 1.0000
17.0800 53.0000 1.0000
17.1200 58.0000 1.0000
17.1600 62.0000 1.0000
17.2000 44.0000 1.0000
17.2400 52.0000 1.0000
17.2800 47.0000 1.0000
17.3200 46.0000 1.0000
17.3600 33.0000 1.0000
17.4000 45.0000 1.0000
17.4400 42.0000 1.0000
17.4800 41.0000 1.0000
17.5200 41.0000 1.0000
17.5600 44.0000 1.0000
17.6000 41.0000 1.0000
17.6400 33.0000 1.0000
17.6800 37.0000 1.0000
17.7200 30.0000 1.0000
17.7600 48.0000 1.0000
17.8000 43.0000 1.0000
17.8400 42.0000 1.0000
17.8800 38.0000 1.0000
17.9200 36.0000 1.0000
17.9600 37.0000 1.0000
18.0000 38.0000 1.0000
18.0400 43.0000 1.0000
18.0800 42.0000 1.0000
18.1200 38.0000 1.0000
18.1600 48.0000 1.0000
18.2000 58.0000 1.0000
18.2400 46.0000 1.0000
18.2800 45.0000 1.0000
18.3200 64.0000 1.0000
18.3600 40.0000 1.0000
18.4000 44.0000 1.0000
18.4400 46.0000 1.0000
18.4800 46.0000 1.0000
18.5200 35.0000 1.0000
18.5600 29.0000 1.0000
18.6000 31.0000 1.0000
18.6400 39.0000 1.0000
18.6800 42.0000 1.0000
18.7200 44.0000 1.0000
18.7600 26.0000 1.0000
18.8000 27.0000 1.0000
18.8400 27.0000 1.0000
18.8800 38.0000 1.0000
18.9200 34.0000 1.0000
18.9600 22.0000 1.0000
19.0000 32.0000 1.0000
19.0400 39.0000 1.0000
19.0800 36.0000 1.0000
19.1200 36.0000 1.0000
19.1600 35.0000 1.0000
19.2000 37.0000 1.0000
19.2400 28.0000 1.0000
19.2800 27.0000 1.0000
19.3200 27.0000 1.0000
19.3600 21.0000 1.0000
19.4000 23.0000 1.0000
19.4400 29.0000 1.0000
19.4800 34.0000 1.0000
19.5200 26.0000 1.0000
19.5600 33.0000 1.0000
19.6000 37.0000 1.0000
19.6400 27.0000 1.0000
19.6800 28.0000 1.0000
19.7200 25.0000 1.0000
19.7600 35.0000 1.0000
19.8000 24.0000 1.0000
19.8400 25.0000 1.0000
19.8800 28.0000 1.0000
19.9200 31.0000 1.0000
19.9600 22.0000 1.0000
20.0000 24.0000 1.0000
20.0400 37.0000 1.0000
20.0800 30.0000 1.0000
20.1200 22.0000 1.0000
20.1600 33.0000 1.0000
20.2000 35.0000 1.0000
20.2400 36.0000 1.0000
20.2800 30.0000 1.0000
20.3200 32.0000 1.0000
20.3600 27.0000 1.0000
20.4000 37.0000 1.0000
20.4400 37.0000 1.0000
20.4800 70.0000 1.0000
20.5200 1048.0000 1.0000
20.5600 1332.0000 1.0000
20.6000 52.0000 1.0000
20.6400 27.0000 1.0000
20.6800 36.0000 1.0000
20.7200 29.0000 1.0000
20.7600 28.0000 1.0000
20.8000 38.0000 1.0000
20.8400 26.0000 1.0000
20.8800 28.0000 1.0000
20.9200 22.0000 1.0000
20.9600 32.0000 1.0000
21.0000 25.0000 1.0000
21.0400 23.0000 1.0000
21.0800 35.0000 1.0000
21.1200 34.0000 1.0000
21.1600 22.0000 1.0000
21.2000 23.0000 1.0000
21.2400 29.0000 1.0000
21.2800 34.0000 1.0000
21.3200 17.0000 1.0000
21.3600 30.0000 1.0000
21.4000 19.0000 1.0000
21.4400 25.0000 1.0000
21.4800 20.0000 1.0000
21.5200 26.0000 1.0000
21.5600 30.0000 1.0000
21.6000 25.0000 1.0000
21.6400 24.0000 1.0000
21.6800 22.0000 1.0000
21.7200 16.0000 1.0000
21.7600 30.0000 1.0000
21.8000 31.0000 1.0000
21.8400 29.0000 1.0000
21.8800 22.0000 1.0000
21.9200 30.0000 1.0000
21.9600 30.0000 1.0000
22.0000 26.0000 1.0000
22.0400 21.0000 1.0000
22.0800 30.0000 1.0000
22.1200 29.0000 1.0000
22.1600 23.0000 1.0000
22.2000 30.0000 1.0000
22.2400 31.0000 1.0000
22.2800 22.0000 1.0000
22.3200 20.0000 1.0000
22.3600 30.0000 1.0000
22.4000 30.0000 1.0000
22.4400 24.0000 1.0000
22.4800 34.0000 1.0000
22.5200 33.0000 1.0000
22.5600 25.0000 1.0000
22.6000 20.0000 1.0000
22.6400 21.0000 1.0000
22.6800 32.0000 1.0000
22.7200 23.0000 1.0000
22.7600 23.0000 1.0000
22.8000 23.0000 1.0000
22.8400 24.0000 1.0000
22.8800 24.0000 1.0000
22.9200 27.0000 1.0000
22.9600 27.0000 1.0000
23.0000 29.0000 1.0000
23.0400 20.0000 1.0000
23.0800 21.0000 1.0000
23.1200 25.0000 1.0000
23.1600 22.0000 1.0000
23.2000 28.0000 1.0000
23.2400 20.0000 1.0000
23.2800 22.0000 1.0000
23.3200 26.0000 1.0000
23.3600 33.0000 1.0000
23.4000 24.0000 1.0000
23.4400 23.0000 1.0000
23.4800 24.0000 1.0000
23.5200 26.0000 1.0000
23.5600 22.0000 1.0000
23.6000 23.0000 1.0000
23.6400 22.0000 1.0000
23.6800 34.0000 1.0000
23.7200 29.0000 1.0000
23.7600 22.0000 1.0000
23.8000 25.0000 1.0000
23.8400 20.0000 1.0000
23.8800 29.0000 1.0000
23.9200 22.0000 1.0000
23.9600 25.0000 1.0000
24.0000 21.0000 1.0000
24.0400 29.0000 1.0000
24.0800 25.0000 1.0000
24.1200 21.0000 1.0000
24.1600 17.0000 1.0000
24.2000 30.0000 1.0000
24.2400 26.0000 1.0000
24.2800 23.0000 1.0000
24.3200 22.0000 1.0000
24.3600 28.0000 1.0000
24.4000 23.0000 1.0000
24.4400 23.0000 1.0000
24.4800 28.0000 1.0000
24.5200 24.0000 1.0000
24.5600 35.0000 1.0000
24.6000 21.0000 1.0000
24.6400 32.0000 1.0000
24.6800 31.0000 1.0000
24.7200 23.0000 1.0000
24.7600 40.0000 1.0000
24.8000 30.0000 1.0000
24.8400 24.0000 1.0000
24.8800 20.0000 1.0000
24.9200 31.0000 1.0000
24.9600 21.0000 1.0000
25.0000 31.0000 1.0000
25.0400 30.0000 1.0000
25.0800 25.0000 1.0000
25.1200 36.0000 1.0000
25.1600 41.0000 1.0000
25.2000 42.0000 1.0000
25.2400 31.0000 1.0000
25.2800 29.0000 1.0000
25.3200 42.0000 1.0000
25.3600 36.0000 1.0000
25.4000 33.0000 1.0000
25.4400 24.0000 1.0000
25.4800 26.0000 1.0000
25.5200 40.0000 1.0000
25.5600 25.0000 1.0000
25.6000 30.0000 1.0000
25.6400 33.0000 1.0000
25.6800 31.0000 1.0000
25.7200 22.0000 1.0000
25.7600 36.0000 1.0000
25.8000 29.0000 1.0000
25.8400 26.0000 1.0000
25.8800 25.0000 1.0000
25.9200 24.0000 1.0000
25.9600 17.0000 1.0000
26.0000 26.0000 1.0000
26.0400 26.0000 1.0000
26.0800 17.0000 1.0000
26.1200 31.0000 1.0000
26.1600 27.0000 1.0000
26.2000 27.0000 1.0000
26.2400 21.0000 1.0000
26.2800 25.0000 1.0000
26.3200 23.0000 1.0000
26.3600 30.0000 1.0000
26.4000 26.0000 1.0000
26.4400 20.0000 1.0000
26.4800 22.0000 1.0000
26.5200 21.0000 1.0000
26.5600 19.0000 1.0000
26.6000 30.0000 1.0000
26.6400 26.0000 1.0000
26.6800 17.0000 1.0000
26.7200 23.0000 1.0000
26.7600 17.0000 1.0000
26.8000 25.0000 1.0000
26.8400 24.0000 1.0000
26.8800 19.0000 1.0000
26.9200 28.0000 1.0000
26.9600 29.0000 1.0000
27.0000 14.0000 1.0000
27.0400 22.0000 1.0000
27.0800 19.0000 1.0000
27.1200 19.0000 1.0000
27.1600 21.0000 1.0000
27.2000 21.0000 1.0000
27.2400 22.0000 1.0000
27.2800 31.0000 1.0000
27.3200 25.0000 1.0000
27.3600 25.0000 1.0000
27.4000 24.0000 1.0000
27.4400 15.0000 1.0000
27.4800 22.0000 1.0000
27.5200 28.0000 1.0000
27.5600 16.0000 1.0000
27.6000 22.0000 1.0000
27.6400 30.0000 1.0000
27.6800 22.0000 1.0000
27.7200 24.0000 1.0000
27.7600 21.0000 1.0000
27.8000 17.0000 1.0000
27.8400 18.0000 1.0000
27.8800 26.0000 1.0000
27.9200 29.0000 1.0000
27.9600 26.0000 1.0000
28.0000 25.0000 1.0000
28.0400 29.0000 1.0000
28.0800 26.0000 1.0000
28.1200 25.0000 1.0000
28.1600 20.0000 1.0000
28.2000 24.0000 1.0000
28.2400 15.0000 1.0000
28.2800 40.0000 1.0000
28.3200 18.0000 1.0000
28.3600 32.0000 1.0000
28.4000 24.0000 1.0000
28.4400 20.0000 1.0000
28.4800 24.0000 1.0000
28.5200 27.0000 1.0000
28.5600 24.0000 1.0000
28.6000 24.0000 1.0000
28.6400 20.0000 1.0000
28.6800 26.0000 1.0000
28.7200 22.0000 1.0000
28.7600 18.0000 1.0000
28.8000 20.0000 1.0000
28.8400 16.0000 1.0000
28.8800 40.0000 1.0000
28.9200 22.0000 1.0000
28.9600 23.0000 1.0000
29.0000 16.0000 1.0000
29.0400 18.0000 1.0000
29.0800 18.0000 1.0000
29.1200 14.0000 1.0000
29.1600 24.0000 1.0000
29.2000 13.0000 1.0000
29.2400 24.0000 1.0000
29.2800 25.0000 1.0000
29.3200 14.0000 1.0000
29.3600 24.0000 1.0000
29.4000 19.0000 1.0000
29.4400 28.0000 1.0000
29.4800 16.0000 1.0000
29.5200 24.0000 1.0000
29.5600 20.0000 1.0000
29.6000 27.0000 1.0000
29.6400 25.0000 1.0000
29.6800 26.0000 1.0000
29.7200 22.0000 1.0000
29.7600 21.0000 1.0000
29.8000 19.0000 1.0000
29.8400 15.0000 1.0000
29.8800 25.0000 1.0000
29.9200 22.0000 1.0000
29.9600 19.0000 1.0000
30.0000 22.0000 1.0000
30.0400 16.0000 1.0000
30.0800 25.0000 1.0000
30.1200 22.0000 1.0000
30.1600 20.0000 1.0000
30.2000 24.0000 1.0000
30.2400 20.0000 1.0000
30.2800 21.0000 1.0000
30.3200 23.0000 1.0000
30.3600 21.0000 1.0000
30.4000 24.0000 1.0000
30.4400 17.0000 1.0000
30.4800 13.0000 1.0000
30.5200 19.0000 1.0000
30.5600 13.0000 1.0000
30.6000 20.0000 1.0000
30.6400 17.0000 1.0000
30.6800 21.0000 1.0000
30.7200 18.0000 1.0000
30.7600 25.0000 1.0000
30.8000 17.0000 1.0000
30.8400 18.0000 1.0000
30.8800 30.0000 1.0000
30.9200 25.0000 1.0000
30.9600 22.0000 1.0000
31.0000 22.0000 1.0000
31.0400 24.0000 1.0000
31.0800 34.0000 1.0000
31.1200 20.0000 1.0000
31.1600 20.0000 1.0000
31.2000 16.0000 1.0000
31.2400 16.0000 1.0000
31.2800 18.0000 1.0000
31.3200 30.0000 1.0000
31.3600 23.0000 1.0000
31.4000 16.0000 1.0000
31.4400 18.0000 1.0000
31.4800 21.0000 1.0000
31.5200 21.0000 1.0000
31.5600 23.0000 1.0000
31.6000 17.0000 1.0000
31.6400 23.0000 1.0000
31.6800 28.0000 1.0000
31.7200 27.0000 1.0000
31.7600 26.0000 1.0000
31.8000 28.0000 1.0000
31.8400 29.0000 1.0000
31.8800 26.0000 1.0000
31.9200 20.0000 1.0000
31.9600 22.0000 1.0000
32.0000 22.0000 1.0000
32.0400 18.0000 1.0000
32.0800 23.0000 1.0000
32.1200 24.0000 1.0000
32.1600 16.0000 1.0000
32.2000 18.0000 1.0000
32.2400 30.0000 1.0000
32.2800 21.0000 1.0000
32.3200 16.0000 1.0000
32.3600 16.0000 1.0000
32.4000 28.0000 1.0000
32.4400 19.0000 1.0000
32.4800 26.0000 1.0000
32.5200 29.0000 1.0000
32.5600 24.0000 1.0000
32.6000 22.0000 1.0000
32.6400 22.0000 1.0000
32.6800 25.0000 1.0000
32.7200 31.0000 1.0000
32.7600 20.0000 1.0000
32.8000 20.0000 1.0000
32.8400 29.0000 1.0000
32.8800 20.0000 1.0000
32.9200 25.0000 1.0000
32.9600 22.0000 1.0000
33.0000 29.0000 1.0000
33.0400 21.0000 1.0000
33.0800 24.0000 1.0000
33.1200 26.0000 1.0000
33.1600 27.0000 1.0000
33.2000 24.0000 1.0000
33.2400 27.0000 1.0000
33.2800 22.0000 1.0000
33.3200 25.0000 1.0000
33.3600 26.0000 1.0000
33.4000 20.0000 1.0000
33.4400 14.0000 1.0000
33.4800 29.0000 1.0000
33.5200 17.0000 1.0000
33.5600 28.0000 1.0000
33.6000 16.0000 1.0000
33.6400 18.0000 1.0000
33.6800 25.0000 1.0000
33.7200 21.0000 1.0000
33.7600 16.0000 1.0000
33.8000 11.0000 1.0000
33.8400 26.0000 1.0000
33.8800 20.0000 1.0000
33.9200 16.0000 1.0000
33.9600 30.0000 1.0000
34.0000 26.0000 1.0000
34.0400 26.0000 1.0000
34.0800 20.0000 1.0000
34.1200 26.0000 1.0000
34.1600 23.0000 1.0000
34.2000 18.0000 1.0000
34.2400 20.0000 1.0000
34.2800 24.0000 1.0000
34.3200 26.0000 1.0000
34.3600 28.0000 1.0000
34.4000 26.0000 1.0000
34.4400 20.0000 1.0000
34.4800 19.0000 1.0000
34.5200 25.0000 1.0000
34.5600 26.0000 1.0000
34.6000 19.0000 1.0000
34.6400 19.0000 1.0000
34.6800 17.0000 1.0000
34.7200 19.0000 1.0000
34.7600 21.0000 1.0000
34.8000 19.0000 1.0000
34.8400 27.0000 1.0000
34.8800 32.0000 1.0000
34.9200 29.0000 1.0000
34.9600 22.0000 1.0000
35.0000 28.0000 1.0000
35.0400 13.0000 1.0000
35.0800 21.0000 1.0000
35.1200 15.0000 1.0000
35.1600 22.0000 1.0000
35.2000 14.0000 1.0000
35.2400 16.0000 1.0000
35.2800 19.0000 1.0000
35.3200 27.0000 1.0000
35.3600 18.0000 1.0000
35.4000 19.0000 1.0000
35.4400 24.0000 1.0000
35.4800 33.0000 1.0000
35.5200 22.0000 1.0000
35.5600 25.0000 1.0000
35.6000 16.0000 1.0000
35.6400 17.0000 1.0000
35.6800 28.0000 1.0000
35.7200 26.0000 1.0000
35.7600 24.0000 1.0000
35.8000 26.0000 1.0000
35.8400 24.0000 1.0000
35.8800 23.0000 1.0000
35.9200 19.0000 1.0000
35.9600 26.0000 1.0000
36.0000 20.0000 1.0000
36.0400 33.0000 1.0000
36.0800 26.0000 1.0000
36.1200 24.0000 1.0000
36.1600 22.0000 1.0000
36.2000 18.0000 1.0000
36.2400 24.0000 1.0000
36.2800 20.0000 1.0000
36.3200 28.0000 1.0000
36.3600 17.0000 1.0000
36.4000 27.0000 1.0000
36.4400 15.0000 1.0000
36.4800 23.0000 1.0000
36.5200 31.0000 1.0000
36.5600 36.0000 1.0000
36.6000 35.0000 1.0000
36.6400 36.0000 1.0000
36.6800 39.0000 1.0000
36.7200 34.0000 1.0000
36.7600 25.0000 1.0000
36.8000 33.0000 1.0000
36.8400 19.0000 1.0000
36.8800 26.0000 1.0000
36.9200 26.0000 1.0000
36.9600 25.0000 1.0000
37.0000 19.0000 1.0000
37.0400 20.0000 1.0000
37.0800 26.0000 1.0000
37.1200 36.0000 1.0000
37.1600 27.0000 1.0000
37.2000 31.0000 1.0000
37.2400 26.0000 1.0000
37.2800 25.0000 1.0000
37.3200 22.0000 1.0000
37.3600 25.0000 1.0000
37.4000 32.0000 1.0000
37.4400 20.0000 1.0000
37.4800 26.0000 1.0000
37.5200 39.0000 1.0000
37.5600 30.0000 1.0000
37.6000 18.0000 1.0000
37.6400 27.0000 1.0000
37.6800 33.0000 1.0000
37.7200 30.0000 1.0000
37.7600 29.0000 1.0000
37.8000 24.0000 1.0000
37.8400 33.0000 1.0000
37.8800 43.0000 1.0000
37.9200 31.0000 1.0000
37.9600 26.0000 1.0000
38.0000 29.0000 1.0000
38.0400 54.0000 1.0000
38.0800 54.0000 1.0000
38.1200 25.0000 1.0000
38.1600 39.0000 1.0000
38.2000 38.0000 1.0000
38.2400 56.0000 1.0000
38.2800 33.0000 1.0000
38.3200 31.0000 1.0000
38.3600 29.0000 1.0000
38.4000 62.0000 1.0000
38.4400 67.0000 1.0000
38.4800 55.0000 1.0000
38.5200 34.0000 1.0000
38.5600 52.0000 1.0000
38.6000 71.0000 1.0000
38.6400 82.0000 1.0000
38.6800 43.0000 1.0000
38.7200 58.0000 1.0000
38.7600 122.0000 1.0000
38.8000 145.0000 1.0000
38.8400 103.0000 1.0000
38.8800 77.0000 1.0000
38.9200 120.0000 1.0000
38.9600 225.0000 1.0000
39.0000 235.0000 1.0000
39.0400 151.0000 1.0000
39.0800 117.0000 1.0000
39.1200 316.0000 1.0000
39.1600 568.0000 1.0000
39.2000 610.0000 1.0000
39.2400 460.0000 1.0000
39.2800 795.0000 1.0000
39.3200 2629.0000 1.0000
39.3600 5422.0000 1.0000
39.4000 8305.0000 1.0000
39.4400 9497.0000 1.0000
39.4800 7994.0000 1.0000
39.5200 5187.0000 1.0000
39.5600 2206.0000 1.0000
39.6000 622.0000 1.0000
39.6400 159.0000 1.0000
39.6800 254.0000 1.0000
39.7200 242.0000 1.0000
39.7600 149.0000 1.0000
39.8000 61.0000 1.0000
39.8400 61.0000 1.0000
39.8800 90.0000 1.0000
39.9200 101.0000 1.0000
39.9600 48.0000 1.0000
40.0000 31.0000 1.0000
*RAS_INT_END
*RAS_DATA_END
*DSC_DATA_END