File: example/461_test/PLD50nmFe2O3_Al2O3/HRXRD_Lab/W_Al2O3_006v2.ras
*RAS_DATA_START
*RAS_HEADER_START
*DISP_LINE_COLOR "4286611584"
*FILE_COMMENT ""
*FILE_MD5 ""
*FILE_MEMO "phi 0"
*FILE_OPERATOR "Administrator"
*FILE_PACKAGE_NAME ""
*FILE_PART_ID ""
*FILE_SAMPLE ""
*FILE_SYSTEM_NAME "SmartLab"
*FILE_TYPE "RAS_RAW"
*FILE_USERGROUP "Administrators"
*FILE_VERSION "1"
*HW_ATTACHMENT_ID "ATT0022"
*HW_ATTACHMENT_NAME "RxRy"
*HW_ATTACHMENT_NAME_INTERNAL "RxRy"
*HW_COUNTER_ID-0 "CUT0021"
*HW_COUNTER_ID-1 "CMC0020"
*HW_COUNTER_MONOCHRO_ID "CMC0020"
*HW_COUNTER_MONOCHRO_NAME "None"
*HW_COUNTER_MONOCHRO_NAME_INTERNAL "None"
*HW_COUNTER_NAME_INTERNAL "SC70"
*HW_COUNTER_NAME-0 "SC70"
*HW_COUNTER_NAME-1 "None"
*HW_COUNTER_SELECT_NAME "SC70"
*HW_EXTERNAL_CONTROLLER_NAME "None"
*HW_EXTERNAL_CONTROLLER_NAME_INTERNAL "None"
*HW_GONIOMETER_ID "GON0022"
*HW_GONIOMETER_NAME "StandardInplaneEnc"
*HW_GONIOMETER_NAME_INTERNAL "StandardInplaneEnc"
*HW_GONIOMETER_RADIUS-0 "90.0"
*HW_GONIOMETER_RADIUS-1 "114.0"
*HW_GONIOMETER_RADIUS-2 "190.0"
*HW_GONIOMETER_RADIUS-3 "300.0"
*HW_GONIOMETER_RADIUS-4 "187.0"
*HW_GONIOMETER_RADIUS-5 "300.0"
*HW_GONIOMETER_RADIUS-6 "113.0000"
*HW_GONIOMETER_RADIUS-7 "331.0"
*HW_I_CBO_ID "CBO0021"
*HW_I_CBO_NAME "CBO"
*HW_I_CBO_NAME_INTERNAL "CBO"
*HW_I_MONOCHRO_ID "ICR0021"
*HW_I_MONOCHRO_NAME "Ge(220)x2"
*HW_I_MONOCHRO_NAME_INTERNAL "Ge(220)x2"
*HW_I_OPT_ID-0 "CBO0021"
*HW_I_OPT_ID-1 "ISL0021"
*HW_I_PRIMARY_NAME_INTERNAL "Standard"
*HW_I_SLIT_ID "ISL0021"
*HW_I_SLIT_NAME "Auto"
*HW_I_SLIT_NAME_INTERNAL "Auto"
*HW_R_ATTENUATER_AUTOMODE "1"
*HW_R_ATTENUATER_ID "ATN0021"
*HW_R_ATTENUATER_NAME "Auto"
*HW_R_ATTENUATOR_NAME_INTERNAL "Auto"
*HW_R_OPT_ID-0 "RSS0021"
*HW_R_OPT_ID-1 "RCR0022"
*HW_R_OPT_ID-2 "RSO0021"
*HW_R_OPT_ID-3 "RRS0021"
*HW_R_OPT_ID-4 "ATN0021"
*HW_R_ROD_ID "RCR0022"
*HW_R_ROD_NAME "ROD_adaptor"
*HW_R_ROD_NAME_INTERNAL "ROD_adaptor"
*HW_R_RPS_ID "RSO0021"
*HW_R_RPS_NAME "RPS_adaptor"
*HW_R_RPS_NAME_INTERNAL "RPS_adaptor"
*HW_R_RS_ID "RRS0021"
*HW_R_RS_NAME "Auto"
*HW_R_RS_NAME_INTERNAL "Auto"
*HW_R_SS_ID "RSS0021"
*HW_R_SS_NAME "Auto"
*HW_R_SS_NAME_INTERNAL "Auto"
*HW_ROBOT_NAME "No_unit"
*HW_ROBOT_NAME_INTERNAL "No_unit"
*HW_SAMPLE_CAMERA_NAME "None"
*HW_SAMPLE_CAMERA_NAME_INTERNAL "None"
*HW_SAMPLE_HOLDER_ID "SMP0021"
*HW_SAMPLE_HOLDER_NAME "Z_ChiPhi"
*HW_SAMPLE_HOLDER_NAME_INTERNAL "Z_ChiPhi"
*HW_SAMPLE_NAME "WaferSample"
*HW_SAMPLE_NAME_INTERNAL "WaferSample"
*HW_SAMPLE_PLATE_NAME "ForWafer"
*HW_SAMPLE_PLATE_NAME_INTERNAL "ForWafer"
*HW_SAMPLE_SPACER_NAME "0-3mm"
*HW_SAMPLE_SPACER_NAME_INTERNAL "0-3mm"
*HW_USERINFO_CATALOG_NO ""
*HW_USERINFO_INSTRUMENT_ID ""
*HW_USERINFO_INSTRUMENT_NAME ""
*HW_USERINFO_INSTRUMENT_NO ""
*HW_USERINFO_MODEL ""
*HW_USERINFO_ORDER_NO ""
*HW_USERINFO_SERIAL_NO ""
*HW_USERINFO_VERIFY_INSTRUMENT_ID "00-07-fe-01-03-ce"
*HW_VER_RCD_COUNTER_UNIT "1.0.1"
*HW_VER_RCD_CPU "3.3.7"
*HW_VER_RCD_FPGA "1.2.2"
*HW_VER_RCD_GONIO_UNIT "6.2.0"
*HW_VER_RCD_INCIDENT_UNIT "6.2.0"
*HW_VER_RCD_RECEIVING_UNIT "6.2.0"
*HW_VER_RCD_TYPE "RINC"
*HW_VER_XGC_CPU "3.3.7"
*HW_VER_XGC_CW "1.2.0"
*HW_VER_XGC_HV "1.2.0"
*HW_VER_XGC_RS1 "1.3.4"
*HW_VER_XGC_RS2 "N/A"
*HW_VER_XGC_RT "1.2.0"
*HW_VER_XGC_TYPE "RINC"
*HW_XG_CURRENT_UNIT "mA"
*HW_XG_FOCUS "0.4mm x 8mm"
*HW_XG_FOCUS_TYPE "Fine"
*HW_XG_TARGET_ATOMIC_NUMBER "29"
*HW_XG_TARGET_NAME "Cu"
*HW_XG_TYPE "ROTA"
*HW_XG_VOLTAGE_UNIT "kV"
*HW_XG_WAVE_LENGTH_ALPHA1 "1.540593"
*HW_XG_WAVE_LENGTH_ALPHA2 "1.544414"
*HW_XG_WAVE_LENGTH_BETA "1.392246"
*HW_XG_WAVE_LENGTH_UNIT "Angstrom"
*MEAS_COND_AXIS_NAME_INTERNAL-0 "ThetaS"
*MEAS_COND_AXIS_NAME_INTERNAL-1 "ThetaD"
*MEAS_COND_AXIS_NAME_INTERNAL-10 "PrimaryGeometry"
*MEAS_COND_AXIS_NAME_INTERNAL-100 "IncidentMonochromator"
*MEAS_COND_AXIS_NAME_INTERNAL-101 "ReceivingOptics"
*MEAS_COND_AXIS_NAME_INTERNAL-102 "CounterMonochromatorKind"
*MEAS_COND_AXIS_NAME_INTERNAL-11 "PrimaryMirrorType"
*MEAS_COND_AXIS_NAME_INTERNAL-12 "CBOType"
*MEAS_COND_AXIS_NAME_INTERNAL-13 "CBO-M"
*MEAS_COND_AXIS_NAME_INTERNAL-14 "CBO"
*MEAS_COND_AXIS_NAME_INTERNAL-15 "IncidentMonochromator-OmegaM"
*MEAS_COND_AXIS_NAME_INTERNAL-16 "IncidentSollerSlit"
*MEAS_COND_AXIS_NAME_INTERNAL-17 "IncidentSlitBox"
*MEAS_COND_AXIS_NAME_INTERNAL-18 "IncidentSlitBox-_Axis"
*MEAS_COND_AXIS_NAME_INTERNAL-19 "SlitDS"
*MEAS_COND_AXIS_NAME_INTERNAL-2 "TwoTheta"
*MEAS_COND_AXIS_NAME_INTERNAL-20 "Zs"
*MEAS_COND_AXIS_NAME_INTERNAL-21 "IncidentAxdSlit"
*MEAS_COND_AXIS_NAME_INTERNAL-22 "LLS"
*MEAS_COND_AXIS_NAME_INTERNAL-23 "DHLSlit"
*MEAS_COND_AXIS_NAME_INTERNAL-24 "Chi"
*MEAS_COND_AXIS_NAME_INTERNAL-25 "Phi"
*MEAS_COND_AXIS_NAME_INTERNAL-26 "Z"
*MEAS_COND_AXIS_NAME_INTERNAL-27 "Alpha"
*MEAS_COND_AXIS_NAME_INTERNAL-28 "Beta"
*MEAS_COND_AXIS_NAME_INTERNAL-29 "TwoThetaChiPhi"
*MEAS_COND_AXIS_NAME_INTERNAL-3 "Omega"
*MEAS_COND_AXIS_NAME_INTERNAL-30 "AlphaI"
*MEAS_COND_AXIS_NAME_INTERNAL-31 "BetaI"
*MEAS_COND_AXIS_NAME_INTERNAL-32 "TwoThetaB"
*MEAS_COND_AXIS_NAME_INTERNAL-33 "Rx"
*MEAS_COND_AXIS_NAME_INTERNAL-34 "Ry"
*MEAS_COND_AXIS_NAME_INTERNAL-35 "ReceivingSlitBox1"
*MEAS_COND_AXIS_NAME_INTERNAL-36 "ReceivingSlitBox1-_Axis"
*MEAS_COND_AXIS_NAME_INTERNAL-37 "SlitSS"
*MEAS_COND_AXIS_NAME_INTERNAL-38 "Filter"
*MEAS_COND_AXIS_NAME_INTERNAL-39 "PSA"
*MEAS_COND_AXIS_NAME_INTERNAL-4 "TwoThetaTheta"
*MEAS_COND_AXIS_NAME_INTERNAL-40 "ReceivingSollerSlit"
*MEAS_COND_AXIS_NAME_INTERNAL-41 "ReceivingSlitBox2"
*MEAS_COND_AXIS_NAME_INTERNAL-42 "ReceivingSlitBox2-_Axis"
*MEAS_COND_AXIS_NAME_INTERNAL-43 "SlitRS"
*MEAS_COND_AXIS_NAME_INTERNAL-44 "ReceivingSlitBox2-Zd"
*MEAS_COND_AXIS_NAME_INTERNAL-45 "Filter2"
*MEAS_COND_AXIS_NAME_INTERNAL-46 "Attenuator"
*MEAS_COND_AXIS_NAME_INTERNAL-47 "HV"
*MEAS_COND_AXIS_NAME_INTERNAL-48 "PHA"
*MEAS_COND_AXIS_NAME_INTERNAL-49 "DedicatedHolder"
*MEAS_COND_AXIS_NAME_INTERNAL-5 "TwoThetaOmega"
*MEAS_COND_AXIS_NAME_INTERNAL-50 "Target_TargetTime"
*MEAS_COND_AXIS_NAME_INTERNAL-51 "Target_XrayOnTime"
*MEAS_COND_AXIS_NAME_INTERNAL-52 "Target_TMPTime"
*MEAS_COND_AXIS_NAME_INTERNAL-53 "Target_RPTime"
*MEAS_COND_AXIS_NAME_INTERNAL-54 "Target_FilamentTime"
*MEAS_COND_AXIS_NAME_INTERNAL-55 "Target_IG"
*MEAS_COND_AXIS_NAME_INTERNAL-56 "Target_GP"
*MEAS_COND_AXIS_NAME_INTERNAL-57 "Target_FC"
*MEAS_COND_AXIS_NAME_INTERNAL-58 "HVPS_Bias"
*MEAS_COND_AXIS_NAME_INTERNAL-59 "HVPS_HVPSTime"
*MEAS_COND_AXIS_NAME_INTERNAL-6 "OmegaTwoTheta"
*MEAS_COND_AXIS_NAME_INTERNAL-60 "HVPS_Type1Time"
*MEAS_COND_AXIS_NAME_INTERNAL-61 "HVPS_Type2Time"
*MEAS_COND_AXIS_NAME_INTERNAL-62 "HVPS_Type3Time"
*MEAS_COND_AXIS_NAME_INTERNAL-63 "CW_IERTime"
*MEAS_COND_AXIS_NAME_INTERNAL-64 "CW_ECTime"
*MEAS_COND_AXIS_NAME_INTERNAL-65 "CW_Flow1"
*MEAS_COND_AXIS_NAME_INTERNAL-66 "CW_Temperature1"
*MEAS_COND_AXIS_NAME_INTERNAL-67 "CW_Pressure1"
*MEAS_COND_AXIS_NAME_INTERNAL-68 "CW_PressureIn"
*MEAS_COND_AXIS_NAME_INTERNAL-69 "CW_PressureOut"
*MEAS_COND_AXIS_NAME_INTERNAL-7 "TwoThetaChi"
*MEAS_COND_AXIS_NAME_INTERNAL-70 "CW_Flow2"
*MEAS_COND_AXIS_NAME_INTERNAL-71 "CW_Temperature2"
*MEAS_COND_AXIS_NAME_INTERNAL-72 "CW_Pressure2"
*MEAS_COND_AXIS_NAME_INTERNAL-73 "RE_EnclosureTemp"
*MEAS_COND_AXIS_NAME_INTERNAL-74 "RE_EnclosureHummidity"
*MEAS_COND_AXIS_NAME_INTERNAL-75 "RE_CabinetTemp"
*MEAS_COND_AXIS_NAME_INTERNAL-76 "RE_RPTemp"
*MEAS_COND_AXIS_NAME_INTERNAL-77 "RE_ShutterAXrayOnTime"
*MEAS_COND_AXIS_NAME_INTERNAL-78 "RE_ShutterATimes"
*MEAS_COND_AXIS_NAME_INTERNAL-79 "RE_ShutterAOpenCloseTime"
*MEAS_COND_AXIS_NAME_INTERNAL-8 "GonioDirectBeamStop"
*MEAS_COND_AXIS_NAME_INTERNAL-80 "RE_ShutterACloseOpenTime"
*MEAS_COND_AXIS_NAME_INTERNAL-81 "RE_ShutterBXrayOnTime"
*MEAS_COND_AXIS_NAME_INTERNAL-82 "RE_ShutterBTimes"
*MEAS_COND_AXIS_NAME_INTERNAL-83 "RE_ShutterBOpenCloseTime"
*MEAS_COND_AXIS_NAME_INTERNAL-84 "RE_ShutterBCloseOpenTime"
*MEAS_COND_AXIS_NAME_INTERNAL-85 "RE_XrayWarningRamp"
*MEAS_COND_AXIS_NAME_INTERNAL-86 "RE_ShutterAInstallation"
*MEAS_COND_AXIS_NAME_INTERNAL-87 "RE_ShutterARamp"
*MEAS_COND_AXIS_NAME_INTERNAL-88 "RE_ShutterBInstallation"
*MEAS_COND_AXIS_NAME_INTERNAL-89 "RE_ShutterBRamp"
*MEAS_COND_AXIS_NAME_INTERNAL-9 "Ts"
*MEAS_COND_AXIS_NAME_INTERNAL-90 "RE_ExtShutterCLS"
*MEAS_COND_AXIS_NAME_INTERNAL-91 "RE_ExtXrayOFF"
*MEAS_COND_AXIS_NAME_INTERNAL-92 "RE_ExtSafetyCircuit"
*MEAS_COND_AXIS_NAME_INTERNAL-93 "Version_CPU"
*MEAS_COND_AXIS_NAME_INTERNAL-94 "Version_RS1"
*MEAS_COND_AXIS_NAME_INTERNAL-95 "Version_RS2"
*MEAS_COND_AXIS_NAME_INTERNAL-96 "Version_HV"
*MEAS_COND_AXIS_NAME_INTERNAL-97 "Version_CW"
*MEAS_COND_AXIS_NAME_INTERNAL-98 "Version_RT"
*MEAS_COND_AXIS_NAME_INTERNAL-99 "IncidentPrimary"
*MEAS_COND_AXIS_NAME-0 "ThetaS"
*MEAS_COND_AXIS_NAME-1 "ThetaD"
*MEAS_COND_AXIS_NAME-10 "PrimaryGeometry"
*MEAS_COND_AXIS_NAME-100 "IncidentMonochromator"
*MEAS_COND_AXIS_NAME-101 "ReceivingOptics"
*MEAS_COND_AXIS_NAME-102 "CounterMonochromatorKind"
*MEAS_COND_AXIS_NAME-11 "PrimaryMirrorType"
*MEAS_COND_AXIS_NAME-12 "CBOType"
*MEAS_COND_AXIS_NAME-13 "CBO-M"
*MEAS_COND_AXIS_NAME-14 "CBO"
*MEAS_COND_AXIS_NAME-15 "IncidentMonochromator-OmegaM"
*MEAS_COND_AXIS_NAME-16 "IncidentSollerSlit"
*MEAS_COND_AXIS_NAME-17 "IncidentSlitBox"
*MEAS_COND_AXIS_NAME-18 "IncidentSlitBox-_Axis"
*MEAS_COND_AXIS_NAME-19 "SlitDS"
*MEAS_COND_AXIS_NAME-2 "TwoTheta"
*MEAS_COND_AXIS_NAME-20 "Zs"
*MEAS_COND_AXIS_NAME-21 "IncidentAxdSlit"
*MEAS_COND_AXIS_NAME-22 "LLS"
*MEAS_COND_AXIS_NAME-23 "DHLSlit"
*MEAS_COND_AXIS_NAME-24 "Chi"
*MEAS_COND_AXIS_NAME-25 "Phi"
*MEAS_COND_AXIS_NAME-26 "Z"
*MEAS_COND_AXIS_NAME-27 "Alpha"
*MEAS_COND_AXIS_NAME-28 "Beta"
*MEAS_COND_AXIS_NAME-29 "TwoThetaChiPhi"
*MEAS_COND_AXIS_NAME-3 "Omega"
*MEAS_COND_AXIS_NAME-30 "AlphaI"
*MEAS_COND_AXIS_NAME-31 "BetaI"
*MEAS_COND_AXIS_NAME-32 "TwoThetaB"
*MEAS_COND_AXIS_NAME-33 "Rx"
*MEAS_COND_AXIS_NAME-34 "Ry"
*MEAS_COND_AXIS_NAME-35 "ReceivingSlitBox1"
*MEAS_COND_AXIS_NAME-36 "ReceivingSlitBox1-_Axis"
*MEAS_COND_AXIS_NAME-37 "SlitSS"
*MEAS_COND_AXIS_NAME-38 "Filter"
*MEAS_COND_AXIS_NAME-39 "PSA"
*MEAS_COND_AXIS_NAME-4 "TwoThetaTheta"
*MEAS_COND_AXIS_NAME-40 "ReceivingSollerSlit"
*MEAS_COND_AXIS_NAME-41 "ReceivingSlitBox2"
*MEAS_COND_AXIS_NAME-42 "ReceivingSlitBox2-_Axis"
*MEAS_COND_AXIS_NAME-43 "SlitRS"
*MEAS_COND_AXIS_NAME-44 "ReceivingSlitBox2-Zd"
*MEAS_COND_AXIS_NAME-45 "Filter2"
*MEAS_COND_AXIS_NAME-46 "Attenuator"
*MEAS_COND_AXIS_NAME-47 "HV"
*MEAS_COND_AXIS_NAME-48 "PHA"
*MEAS_COND_AXIS_NAME-49 "DedicatedHolder"
*MEAS_COND_AXIS_NAME-5 "TwoThetaOmega"
*MEAS_COND_AXIS_NAME-50 "Target_TargetTime"
*MEAS_COND_AXIS_NAME-51 "Target_XrayOnTime"
*MEAS_COND_AXIS_NAME-52 "Target_TMPTime"
*MEAS_COND_AXIS_NAME-53 "Target_RPTime"
*MEAS_COND_AXIS_NAME-54 "Target_FilamentTime"
*MEAS_COND_AXIS_NAME-55 "Target_IG"
*MEAS_COND_AXIS_NAME-56 "Target_GP"
*MEAS_COND_AXIS_NAME-57 "Target_FC"
*MEAS_COND_AXIS_NAME-58 "HVPS_Bias"
*MEAS_COND_AXIS_NAME-59 "HVPS_HVPSTime"
*MEAS_COND_AXIS_NAME-6 "OmegaTwoTheta"
*MEAS_COND_AXIS_NAME-60 "HVPS_Type1Time"
*MEAS_COND_AXIS_NAME-61 "HVPS_Type2Time"
*MEAS_COND_AXIS_NAME-62 "HVPS_Type3Time"
*MEAS_COND_AXIS_NAME-63 "CW_IERTime"
*MEAS_COND_AXIS_NAME-64 "CW_ECTime"
*MEAS_COND_AXIS_NAME-65 "CW_Flow1"
*MEAS_COND_AXIS_NAME-66 "CW_Temperature1"
*MEAS_COND_AXIS_NAME-67 "CW_Pressure1"
*MEAS_COND_AXIS_NAME-68 "CW_PressureIn"
*MEAS_COND_AXIS_NAME-69 "CW_PressureOut"
*MEAS_COND_AXIS_NAME-7 "TwoThetaChi"
*MEAS_COND_AXIS_NAME-70 "CW_Flow2"
*MEAS_COND_AXIS_NAME-71 "CW_Temperature2"
*MEAS_COND_AXIS_NAME-72 "CW_Pressure2"
*MEAS_COND_AXIS_NAME-73 "RE_EnclosureTemp"
*MEAS_COND_AXIS_NAME-74 "RE_EnclosureHummidity"
*MEAS_COND_AXIS_NAME-75 "RE_CabinetTemp"
*MEAS_COND_AXIS_NAME-76 "RE_RPTemp"
*MEAS_COND_AXIS_NAME-77 "RE_ShutterAXrayOnTime"
*MEAS_COND_AXIS_NAME-78 "RE_ShutterATimes"
*MEAS_COND_AXIS_NAME-79 "RE_ShutterAOpenCloseTime"
*MEAS_COND_AXIS_NAME-8 "GonioDirectBeamStop"
*MEAS_COND_AXIS_NAME-80 "RE_ShutterACloseOpenTime"
*MEAS_COND_AXIS_NAME-81 "RE_ShutterBXrayOnTime"
*MEAS_COND_AXIS_NAME-82 "RE_ShutterBTimes"
*MEAS_COND_AXIS_NAME-83 "RE_ShutterBOpenCloseTime"
*MEAS_COND_AXIS_NAME-84 "RE_ShutterBCloseOpenTime"
*MEAS_COND_AXIS_NAME-85 "RE_XrayWarningRamp"
*MEAS_COND_AXIS_NAME-86 "RE_ShutterAInstallation"
*MEAS_COND_AXIS_NAME-87 "RE_ShutterARamp"
*MEAS_COND_AXIS_NAME-88 "RE_ShutterBInstallation"
*MEAS_COND_AXIS_NAME-89 "RE_ShutterBRamp"
*MEAS_COND_AXIS_NAME-9 "Ts"
*MEAS_COND_AXIS_NAME-90 "RE_ExtShutterCLS"
*MEAS_COND_AXIS_NAME-91 "RE_ExtXrayOFF"
*MEAS_COND_AXIS_NAME-92 "RE_ExtSafetyCircuit"
*MEAS_COND_AXIS_NAME-93 "Version_CPU"
*MEAS_COND_AXIS_NAME-94 "Version_RS1"
*MEAS_COND_AXIS_NAME-95 "Version_RS2"
*MEAS_COND_AXIS_NAME-96 "Version_HV"
*MEAS_COND_AXIS_NAME-97 "Version_CW"
*MEAS_COND_AXIS_NAME-98 "Version_RT"
*MEAS_COND_AXIS_NAME-99 "IncidentPrimary"
*MEAS_COND_AXIS_OFFSET-0 "1.1501"
*MEAS_COND_AXIS_OFFSET-1 "0.1001"
*MEAS_COND_AXIS_OFFSET-10 "0"
*MEAS_COND_AXIS_OFFSET-100 "0"
*MEAS_COND_AXIS_OFFSET-101 "0"
*MEAS_COND_AXIS_OFFSET-102 "0"
*MEAS_COND_AXIS_OFFSET-11 "0"
*MEAS_COND_AXIS_OFFSET-12 "0"
*MEAS_COND_AXIS_OFFSET-13 "0"
*MEAS_COND_AXIS_OFFSET-14 "0"
*MEAS_COND_AXIS_OFFSET-15 "0"
*MEAS_COND_AXIS_OFFSET-16 "0"
*MEAS_COND_AXIS_OFFSET-17 "0"
*MEAS_COND_AXIS_OFFSET-18 "0"
*MEAS_COND_AXIS_OFFSET-19 "0"
*MEAS_COND_AXIS_OFFSET-2 "1.2502"
*MEAS_COND_AXIS_OFFSET-20 "0"
*MEAS_COND_AXIS_OFFSET-21 "0"
*MEAS_COND_AXIS_OFFSET-22 "0"
*MEAS_COND_AXIS_OFFSET-23 "0"
*MEAS_COND_AXIS_OFFSET-24 "0"
*MEAS_COND_AXIS_OFFSET-25 "0"
*MEAS_COND_AXIS_OFFSET-26 "0"
*MEAS_COND_AXIS_OFFSET-27 "0"
*MEAS_COND_AXIS_OFFSET-28 "0"
*MEAS_COND_AXIS_OFFSET-29 "0"
*MEAS_COND_AXIS_OFFSET-3 "1.1501"
*MEAS_COND_AXIS_OFFSET-30 "0"
*MEAS_COND_AXIS_OFFSET-31 "0"
*MEAS_COND_AXIS_OFFSET-32 "0"
*MEAS_COND_AXIS_OFFSET-33 "0"
*MEAS_COND_AXIS_OFFSET-34 "0"
*MEAS_COND_AXIS_OFFSET-35 "0"
*MEAS_COND_AXIS_OFFSET-36 "0"
*MEAS_COND_AXIS_OFFSET-37 "0"
*MEAS_COND_AXIS_OFFSET-38 "0"
*MEAS_COND_AXIS_OFFSET-39 "0"
*MEAS_COND_AXIS_OFFSET-4 "0"
*MEAS_COND_AXIS_OFFSET-40 "0"
*MEAS_COND_AXIS_OFFSET-41 "0"
*MEAS_COND_AXIS_OFFSET-42 "0"
*MEAS_COND_AXIS_OFFSET-43 "0"
*MEAS_COND_AXIS_OFFSET-44 "0"
*MEAS_COND_AXIS_OFFSET-45 "0"
*MEAS_COND_AXIS_OFFSET-46 "0"
*MEAS_COND_AXIS_OFFSET-47 "0"
*MEAS_COND_AXIS_OFFSET-48 "0"
*MEAS_COND_AXIS_OFFSET-49 "0"
*MEAS_COND_AXIS_OFFSET-5 "0"
*MEAS_COND_AXIS_OFFSET-50 "0"
*MEAS_COND_AXIS_OFFSET-51 "0"
*MEAS_COND_AXIS_OFFSET-52 "0"
*MEAS_COND_AXIS_OFFSET-53 "0"
*MEAS_COND_AXIS_OFFSET-54 "0"
*MEAS_COND_AXIS_OFFSET-55 "0"
*MEAS_COND_AXIS_OFFSET-56 "0"
*MEAS_COND_AXIS_OFFSET-57 "0"
*MEAS_COND_AXIS_OFFSET-58 "0"
*MEAS_COND_AXIS_OFFSET-59 "0"
*MEAS_COND_AXIS_OFFSET-6 "0"
*MEAS_COND_AXIS_OFFSET-60 "0"
*MEAS_COND_AXIS_OFFSET-61 "0"
*MEAS_COND_AXIS_OFFSET-62 "0"
*MEAS_COND_AXIS_OFFSET-63 "0"
*MEAS_COND_AXIS_OFFSET-64 "0"
*MEAS_COND_AXIS_OFFSET-65 "0"
*MEAS_COND_AXIS_OFFSET-66 "0"
*MEAS_COND_AXIS_OFFSET-67 "0"
*MEAS_COND_AXIS_OFFSET-68 "0"
*MEAS_COND_AXIS_OFFSET-69 "0"
*MEAS_COND_AXIS_OFFSET-7 "0"
*MEAS_COND_AXIS_OFFSET-70 "0"
*MEAS_COND_AXIS_OFFSET-71 "0"
*MEAS_COND_AXIS_OFFSET-72 "0"
*MEAS_COND_AXIS_OFFSET-73 "0"
*MEAS_COND_AXIS_OFFSET-74 "0"
*MEAS_COND_AXIS_OFFSET-75 "0"
*MEAS_COND_AXIS_OFFSET-76 "0"
*MEAS_COND_AXIS_OFFSET-77 "0"
*MEAS_COND_AXIS_OFFSET-78 "0"
*MEAS_COND_AXIS_OFFSET-79 "0"
*MEAS_COND_AXIS_OFFSET-8 "0"
*MEAS_COND_AXIS_OFFSET-80 "0"
*MEAS_COND_AXIS_OFFSET-81 "0"
*MEAS_COND_AXIS_OFFSET-82 "0"
*MEAS_COND_AXIS_OFFSET-83 "0"
*MEAS_COND_AXIS_OFFSET-84 "0"
*MEAS_COND_AXIS_OFFSET-85 "0"
*MEAS_COND_AXIS_OFFSET-86 "0"
*MEAS_COND_AXIS_OFFSET-87 "0"
*MEAS_COND_AXIS_OFFSET-88 "0"
*MEAS_COND_AXIS_OFFSET-89 "0"
*MEAS_COND_AXIS_OFFSET-9 "0"
*MEAS_COND_AXIS_OFFSET-90 "0"
*MEAS_COND_AXIS_OFFSET-91 "0"
*MEAS_COND_AXIS_OFFSET-92 "0"
*MEAS_COND_AXIS_OFFSET-93 "0"
*MEAS_COND_AXIS_OFFSET-94 "0"
*MEAS_COND_AXIS_OFFSET-95 "0"
*MEAS_COND_AXIS_OFFSET-96 "0"
*MEAS_COND_AXIS_OFFSET-97 "0"
*MEAS_COND_AXIS_OFFSET-98 "0"
*MEAS_COND_AXIS_OFFSET-99 "0"
*MEAS_COND_AXIS_POSITION-0 "20.8505"
*MEAS_COND_AXIS_POSITION-1 "20.8355"
*MEAS_COND_AXIS_POSITION-10 "Right"
*MEAS_COND_AXIS_POSITION-100 "Ge(220)x2"
*MEAS_COND_AXIS_POSITION-101 "PSA_open"
*MEAS_COND_AXIS_POSITION-102 "None"
*MEAS_COND_AXIS_POSITION-11 "None"
*MEAS_COND_AXIS_POSITION-12 "Type1"
*MEAS_COND_AXIS_POSITION-13 "0"
*MEAS_COND_AXIS_POSITION-14 "PB"
*MEAS_COND_AXIS_POSITION-15 "0"
*MEAS_COND_AXIS_POSITION-16 "Soller_slit_open_s"
*MEAS_COND_AXIS_POSITION-17 "0.500mm"
*MEAS_COND_AXIS_POSITION-18 "0.500000"
*MEAS_COND_AXIS_POSITION-19 "0.500mm"
*MEAS_COND_AXIS_POSITION-2 "41.6860"
*MEAS_COND_AXIS_POSITION-20 "-2.0256250"
*MEAS_COND_AXIS_POSITION-21 "5mm"
*MEAS_COND_AXIS_POSITION-22 "5mm"
*MEAS_COND_AXIS_POSITION-23 "5mm"
*MEAS_COND_AXIS_POSITION-24 "0.062"
*MEAS_COND_AXIS_POSITION-25 "80.400"
*MEAS_COND_AXIS_POSITION-26 "-1.0225"
*MEAS_COND_AXIS_POSITION-27 "89.938"
*MEAS_COND_AXIS_POSITION-28 "80.400"
*MEAS_COND_AXIS_POSITION-29 "0.000"
*MEAS_COND_AXIS_POSITION-3 "20.8505"
*MEAS_COND_AXIS_POSITION-30 "89.99"
*MEAS_COND_AXIS_POSITION-31 "80.400"
*MEAS_COND_AXIS_POSITION-32 "41.6860"
*MEAS_COND_AXIS_POSITION-33 "-0.12276"
*MEAS_COND_AXIS_POSITION-34 "0.01206"
*MEAS_COND_AXIS_POSITION-35 "0.700mm"
*MEAS_COND_AXIS_POSITION-36 "0.700000"
*MEAS_COND_AXIS_POSITION-37 "0.700mm"
*MEAS_COND_AXIS_POSITION-38 "None"
*MEAS_COND_AXIS_POSITION-39 "PSA_open"
*MEAS_COND_AXIS_POSITION-4 "41.6860"
*MEAS_COND_AXIS_POSITION-40 "Soller_slit_5.0deg"
*MEAS_COND_AXIS_POSITION-41 "0.700mm"
*MEAS_COND_AXIS_POSITION-42 "0.700000"
*MEAS_COND_AXIS_POSITION-43 "0.700mm"
*MEAS_COND_AXIS_POSITION-44 "-0.5287500"
*MEAS_COND_AXIS_POSITION-45 "None"
*MEAS_COND_AXIS_POSITION-46 "Open"
*MEAS_COND_AXIS_POSITION-47 "647.0"
*MEAS_COND_AXIS_POSITION-48 "545.00"
*MEAS_COND_AXIS_POSITION-49 "None"
*MEAS_COND_AXIS_POSITION-5 "41.6860"
*MEAS_COND_AXIS_POSITION-50 ""
*MEAS_COND_AXIS_POSITION-51 ""
*MEAS_COND_AXIS_POSITION-52 ""
*MEAS_COND_AXIS_POSITION-53 ""
*MEAS_COND_AXIS_POSITION-54 ""
*MEAS_COND_AXIS_POSITION-55 ""
*MEAS_COND_AXIS_POSITION-56 ""
*MEAS_COND_AXIS_POSITION-57 ""
*MEAS_COND_AXIS_POSITION-58 ""
*MEAS_COND_AXIS_POSITION-59 ""
*MEAS_COND_AXIS_POSITION-6 "20.8505"
*MEAS_COND_AXIS_POSITION-60 ""
*MEAS_COND_AXIS_POSITION-61 ""
*MEAS_COND_AXIS_POSITION-62 ""
*MEAS_COND_AXIS_POSITION-63 ""
*MEAS_COND_AXIS_POSITION-64 ""
*MEAS_COND_AXIS_POSITION-65 ""
*MEAS_COND_AXIS_POSITION-66 ""
*MEAS_COND_AXIS_POSITION-67 ""
*MEAS_COND_AXIS_POSITION-68 ""
*MEAS_COND_AXIS_POSITION-69 ""
*MEAS_COND_AXIS_POSITION-7 "0.0000"
*MEAS_COND_AXIS_POSITION-70 ""
*MEAS_COND_AXIS_POSITION-71 ""
*MEAS_COND_AXIS_POSITION-72 ""
*MEAS_COND_AXIS_POSITION-73 ""
*MEAS_COND_AXIS_POSITION-74 ""
*MEAS_COND_AXIS_POSITION-75 ""
*MEAS_COND_AXIS_POSITION-76 ""
*MEAS_COND_AXIS_POSITION-77 ""
*MEAS_COND_AXIS_POSITION-78 ""
*MEAS_COND_AXIS_POSITION-79 ""
*MEAS_COND_AXIS_POSITION-8 "None"
*MEAS_COND_AXIS_POSITION-80 ""
*MEAS_COND_AXIS_POSITION-81 ""
*MEAS_COND_AXIS_POSITION-82 ""
*MEAS_COND_AXIS_POSITION-83 ""
*MEAS_COND_AXIS_POSITION-84 ""
*MEAS_COND_AXIS_POSITION-85 ""
*MEAS_COND_AXIS_POSITION-86 ""
*MEAS_COND_AXIS_POSITION-87 ""
*MEAS_COND_AXIS_POSITION-88 ""
*MEAS_COND_AXIS_POSITION-89 ""
*MEAS_COND_AXIS_POSITION-9 "-5.5470000"
*MEAS_COND_AXIS_POSITION-90 ""
*MEAS_COND_AXIS_POSITION-91 ""
*MEAS_COND_AXIS_POSITION-92 ""
*MEAS_COND_AXIS_POSITION-93 ""
*MEAS_COND_AXIS_POSITION-94 ""
*MEAS_COND_AXIS_POSITION-95 ""
*MEAS_COND_AXIS_POSITION-96 ""
*MEAS_COND_AXIS_POSITION-97 ""
*MEAS_COND_AXIS_POSITION-98 ""
*MEAS_COND_AXIS_POSITION-99 "Standard"
*MEAS_COND_AXIS_RESOLUTION-0 "0.0001"
*MEAS_COND_AXIS_RESOLUTION-1 "0.0001"
*MEAS_COND_AXIS_RESOLUTION-10 ""
*MEAS_COND_AXIS_RESOLUTION-11 ""
*MEAS_COND_AXIS_RESOLUTION-12 ""
*MEAS_COND_AXIS_RESOLUTION-13 "1"
*MEAS_COND_AXIS_RESOLUTION-14 ""
*MEAS_COND_AXIS_RESOLUTION-15 "1"
*MEAS_COND_AXIS_RESOLUTION-16 ""
*MEAS_COND_AXIS_RESOLUTION-17 "1/1600"
*MEAS_COND_AXIS_RESOLUTION-18 "1/1600"
*MEAS_COND_AXIS_RESOLUTION-19 "1/1600"
*MEAS_COND_AXIS_RESOLUTION-2 "0.0001"
*MEAS_COND_AXIS_RESOLUTION-20 "0.0003125"
*MEAS_COND_AXIS_RESOLUTION-21 ""
*MEAS_COND_AXIS_RESOLUTION-22 ""
*MEAS_COND_AXIS_RESOLUTION-23 ""
*MEAS_COND_AXIS_RESOLUTION-24 "0.001"
*MEAS_COND_AXIS_RESOLUTION-25 "0.002"
*MEAS_COND_AXIS_RESOLUTION-26 "0.0001"
*MEAS_COND_AXIS_RESOLUTION-27 "0.001"
*MEAS_COND_AXIS_RESOLUTION-28 "0.002"
*MEAS_COND_AXIS_RESOLUTION-29 "0.004"
*MEAS_COND_AXIS_RESOLUTION-3 "0.0001"
*MEAS_COND_AXIS_RESOLUTION-30 "0.01"
*MEAS_COND_AXIS_RESOLUTION-31 "0.002"
*MEAS_COND_AXIS_RESOLUTION-32 "0.0001"
*MEAS_COND_AXIS_RESOLUTION-33 "0.00099"
*MEAS_COND_AXIS_RESOLUTION-34 "0.00134"
*MEAS_COND_AXIS_RESOLUTION-35 "1/1600"
*MEAS_COND_AXIS_RESOLUTION-36 "1/1600"
*MEAS_COND_AXIS_RESOLUTION-37 "1/1600"
*MEAS_COND_AXIS_RESOLUTION-38 ""
*MEAS_COND_AXIS_RESOLUTION-39 ""
*MEAS_COND_AXIS_RESOLUTION-4 "0.0002"
*MEAS_COND_AXIS_RESOLUTION-40 ""
*MEAS_COND_AXIS_RESOLUTION-41 "1/1600"
*MEAS_COND_AXIS_RESOLUTION-42 "1/1600"
*MEAS_COND_AXIS_RESOLUTION-43 "1/1600"
*MEAS_COND_AXIS_RESOLUTION-44 "0.0003125"
*MEAS_COND_AXIS_RESOLUTION-45 ""
*MEAS_COND_AXIS_RESOLUTION-46 "1/800"
*MEAS_COND_AXIS_RESOLUTION-47 "0.5"
*MEAS_COND_AXIS_RESOLUTION-48 "1.25"
*MEAS_COND_AXIS_RESOLUTION-49 ""
*MEAS_COND_AXIS_RESOLUTION-5 "0.0002"
*MEAS_COND_AXIS_RESOLUTION-50 "0.010000"
*MEAS_COND_AXIS_RESOLUTION-51 "0.010000"
*MEAS_COND_AXIS_RESOLUTION-52 "0.01"
*MEAS_COND_AXIS_RESOLUTION-53 "0.010000"
*MEAS_COND_AXIS_RESOLUTION-54 "0.01"
*MEAS_COND_AXIS_RESOLUTION-55 "1.000000"
*MEAS_COND_AXIS_RESOLUTION-56 "1.000000"
*MEAS_COND_AXIS_RESOLUTION-57 "1"
*MEAS_COND_AXIS_RESOLUTION-58 "1"
*MEAS_COND_AXIS_RESOLUTION-59 "0.01"
*MEAS_COND_AXIS_RESOLUTION-6 "0.0001"
*MEAS_COND_AXIS_RESOLUTION-60 "0.01"
*MEAS_COND_AXIS_RESOLUTION-61 "0.01"
*MEAS_COND_AXIS_RESOLUTION-62 "0.01"
*MEAS_COND_AXIS_RESOLUTION-63 "0.010000"
*MEAS_COND_AXIS_RESOLUTION-64 "1"
*MEAS_COND_AXIS_RESOLUTION-65 "0.1"
*MEAS_COND_AXIS_RESOLUTION-66 "1"
*MEAS_COND_AXIS_RESOLUTION-67 "0.010000"
*MEAS_COND_AXIS_RESOLUTION-68 "0.01"
*MEAS_COND_AXIS_RESOLUTION-69 "0.01"
*MEAS_COND_AXIS_RESOLUTION-7 "0.0005"
*MEAS_COND_AXIS_RESOLUTION-70 "0.100000"
*MEAS_COND_AXIS_RESOLUTION-71 "1.000000"
*MEAS_COND_AXIS_RESOLUTION-72 "0.01"
*MEAS_COND_AXIS_RESOLUTION-73 "1.000000"
*MEAS_COND_AXIS_RESOLUTION-74 "1"
*MEAS_COND_AXIS_RESOLUTION-75 "1.000000"
*MEAS_COND_AXIS_RESOLUTION-76 "1"
*MEAS_COND_AXIS_RESOLUTION-77 "0.01"
*MEAS_COND_AXIS_RESOLUTION-78 "1"
*MEAS_COND_AXIS_RESOLUTION-79 "1"
*MEAS_COND_AXIS_RESOLUTION-8 ""
*MEAS_COND_AXIS_RESOLUTION-80 "1"
*MEAS_COND_AXIS_RESOLUTION-81 "0.01"
*MEAS_COND_AXIS_RESOLUTION-82 "1.000000"
*MEAS_COND_AXIS_RESOLUTION-83 "1.000000"
*MEAS_COND_AXIS_RESOLUTION-84 "1.000000"
*MEAS_COND_AXIS_RESOLUTION-85 "-"
*MEAS_COND_AXIS_RESOLUTION-86 "-"
*MEAS_COND_AXIS_RESOLUTION-87 "-"
*MEAS_COND_AXIS_RESOLUTION-88 "1.000000"
*MEAS_COND_AXIS_RESOLUTION-89 "-"
*MEAS_COND_AXIS_RESOLUTION-9 "0.0000625"
*MEAS_COND_AXIS_RESOLUTION-90 "-"
*MEAS_COND_AXIS_RESOLUTION-91 "-"
*MEAS_COND_AXIS_RESOLUTION-92 "1.000000"
*MEAS_COND_AXIS_RESOLUTION-93 "1.000000"
*MEAS_COND_AXIS_RESOLUTION-94 "1.000000"
*MEAS_COND_AXIS_RESOLUTION-95 "1.000000"
*MEAS_COND_AXIS_RESOLUTION-96 "1.000000"
*MEAS_COND_AXIS_RESOLUTION-97 "1.000000"
*MEAS_COND_AXIS_RESOLUTION-98 "1.000000"
*MEAS_COND_AXIS_STATE-0 "Fixed"
*MEAS_COND_AXIS_STATE-1 "Fixed"
*MEAS_COND_AXIS_STATE-10 "Fixed"
*MEAS_COND_AXIS_STATE-11 "Fixed"
*MEAS_COND_AXIS_STATE-12 "Fixed"
*MEAS_COND_AXIS_STATE-13 "Fixed"
*MEAS_COND_AXIS_STATE-14 "Fixed"
*MEAS_COND_AXIS_STATE-15 "Fixed"
*MEAS_COND_AXIS_STATE-16 "Fixed"
*MEAS_COND_AXIS_STATE-17 "Fixed"
*MEAS_COND_AXIS_STATE-18 "Fixed"
*MEAS_COND_AXIS_STATE-19 "Fixed"
*MEAS_COND_AXIS_STATE-2 "Fixed"
*MEAS_COND_AXIS_STATE-20 "Fixed"
*MEAS_COND_AXIS_STATE-21 "Fixed"
*MEAS_COND_AXIS_STATE-22 "Fixed"
*MEAS_COND_AXIS_STATE-23 "Fixed"
*MEAS_COND_AXIS_STATE-24 "Fixed"
*MEAS_COND_AXIS_STATE-25 "Fixed"
*MEAS_COND_AXIS_STATE-26 "Fixed"
*MEAS_COND_AXIS_STATE-27 "Fixed"
*MEAS_COND_AXIS_STATE-28 "Fixed"
*MEAS_COND_AXIS_STATE-29 "Fixed"
*MEAS_COND_AXIS_STATE-3 "Scan"
*MEAS_COND_AXIS_STATE-30 "Fixed"
*MEAS_COND_AXIS_STATE-31 "Fixed"
*MEAS_COND_AXIS_STATE-32 "Fixed"
*MEAS_COND_AXIS_STATE-33 "Fixed"
*MEAS_COND_AXIS_STATE-34 "Fixed"
*MEAS_COND_AXIS_STATE-35 "Fixed"
*MEAS_COND_AXIS_STATE-36 "Fixed"
*MEAS_COND_AXIS_STATE-37 "Fixed"
*MEAS_COND_AXIS_STATE-38 "Fixed"
*MEAS_COND_AXIS_STATE-39 "Fixed"
*MEAS_COND_AXIS_STATE-4 "Fixed"
*MEAS_COND_AXIS_STATE-40 "Fixed"
*MEAS_COND_AXIS_STATE-41 "Fixed"
*MEAS_COND_AXIS_STATE-42 "Fixed"
*MEAS_COND_AXIS_STATE-43 "Fixed"
*MEAS_COND_AXIS_STATE-44 "Fixed"
*MEAS_COND_AXIS_STATE-45 "Fixed"
*MEAS_COND_AXIS_STATE-46 "Fixed"
*MEAS_COND_AXIS_STATE-47 "Fixed"
*MEAS_COND_AXIS_STATE-48 "Fixed"
*MEAS_COND_AXIS_STATE-49 "Fixed"
*MEAS_COND_AXIS_STATE-5 "Fixed"
*MEAS_COND_AXIS_STATE-50 "Fixed"
*MEAS_COND_AXIS_STATE-51 "Fixed"
*MEAS_COND_AXIS_STATE-52 "Fixed"
*MEAS_COND_AXIS_STATE-53 "Fixed"
*MEAS_COND_AXIS_STATE-54 "Fixed"
*MEAS_COND_AXIS_STATE-55 "Fixed"
*MEAS_COND_AXIS_STATE-56 "Fixed"
*MEAS_COND_AXIS_STATE-57 "Fixed"
*MEAS_COND_AXIS_STATE-58 "Fixed"
*MEAS_COND_AXIS_STATE-59 "Fixed"
*MEAS_COND_AXIS_STATE-6 "Fixed"
*MEAS_COND_AXIS_STATE-60 "Fixed"
*MEAS_COND_AXIS_STATE-61 "Fixed"
*MEAS_COND_AXIS_STATE-62 "Fixed"
*MEAS_COND_AXIS_STATE-63 "Fixed"
*MEAS_COND_AXIS_STATE-64 "Fixed"
*MEAS_COND_AXIS_STATE-65 "Fixed"
*MEAS_COND_AXIS_STATE-66 "Fixed"
*MEAS_COND_AXIS_STATE-67 "Fixed"
*MEAS_COND_AXIS_STATE-68 "Fixed"
*MEAS_COND_AXIS_STATE-69 "Fixed"
*MEAS_COND_AXIS_STATE-7 "Fixed"
*MEAS_COND_AXIS_STATE-70 "Fixed"
*MEAS_COND_AXIS_STATE-71 "Fixed"
*MEAS_COND_AXIS_STATE-72 "Fixed"
*MEAS_COND_AXIS_STATE-73 "Fixed"
*MEAS_COND_AXIS_STATE-74 "Fixed"
*MEAS_COND_AXIS_STATE-75 "Fixed"
*MEAS_COND_AXIS_STATE-76 "Fixed"
*MEAS_COND_AXIS_STATE-77 "Fixed"
*MEAS_COND_AXIS_STATE-78 "Fixed"
*MEAS_COND_AXIS_STATE-79 "Fixed"
*MEAS_COND_AXIS_STATE-8 "Fixed"
*MEAS_COND_AXIS_STATE-80 "Fixed"
*MEAS_COND_AXIS_STATE-81 "Fixed"
*MEAS_COND_AXIS_STATE-82 "Fixed"
*MEAS_COND_AXIS_STATE-83 "Fixed"
*MEAS_COND_AXIS_STATE-84 "Fixed"
*MEAS_COND_AXIS_STATE-85 "Fixed"
*MEAS_COND_AXIS_STATE-86 "Fixed"
*MEAS_COND_AXIS_STATE-87 "Fixed"
*MEAS_COND_AXIS_STATE-88 "Fixed"
*MEAS_COND_AXIS_STATE-89 "Fixed"
*MEAS_COND_AXIS_STATE-9 "Fixed"
*MEAS_COND_AXIS_STATE-90 "Fixed"
*MEAS_COND_AXIS_STATE-91 "Fixed"
*MEAS_COND_AXIS_STATE-92 "Fixed"
*MEAS_COND_AXIS_STATE-93 "Fixed"
*MEAS_COND_AXIS_STATE-94 "Fixed"
*MEAS_COND_AXIS_STATE-95 "Fixed"
*MEAS_COND_AXIS_STATE-96 "Fixed"
*MEAS_COND_AXIS_STATE-97 "Fixed"
*MEAS_COND_AXIS_STATE-98 "Fixed"
*MEAS_COND_AXIS_UNIT-0 "deg"
*MEAS_COND_AXIS_UNIT-1 "deg"
*MEAS_COND_AXIS_UNIT-10 ""
*MEAS_COND_AXIS_UNIT-100 ""
*MEAS_COND_AXIS_UNIT-101 ""
*MEAS_COND_AXIS_UNIT-102 ""
*MEAS_COND_AXIS_UNIT-11 ""
*MEAS_COND_AXIS_UNIT-12 ""
*MEAS_COND_AXIS_UNIT-13 "pulse"
*MEAS_COND_AXIS_UNIT-14 ""
*MEAS_COND_AXIS_UNIT-15 "pulse"
*MEAS_COND_AXIS_UNIT-16 ""
*MEAS_COND_AXIS_UNIT-17 ""
*MEAS_COND_AXIS_UNIT-18 "mm"
*MEAS_COND_AXIS_UNIT-19 ""
*MEAS_COND_AXIS_UNIT-2 "deg"
*MEAS_COND_AXIS_UNIT-20 "mm"
*MEAS_COND_AXIS_UNIT-21 ""
*MEAS_COND_AXIS_UNIT-22 ""
*MEAS_COND_AXIS_UNIT-23 ""
*MEAS_COND_AXIS_UNIT-24 "deg"
*MEAS_COND_AXIS_UNIT-25 "deg"
*MEAS_COND_AXIS_UNIT-26 "mm"
*MEAS_COND_AXIS_UNIT-27 "deg"
*MEAS_COND_AXIS_UNIT-28 "deg"
*MEAS_COND_AXIS_UNIT-29 "deg"
*MEAS_COND_AXIS_UNIT-3 "deg"
*MEAS_COND_AXIS_UNIT-30 "deg"
*MEAS_COND_AXIS_UNIT-31 "deg"
*MEAS_COND_AXIS_UNIT-32 "deg"
*MEAS_COND_AXIS_UNIT-33 "deg"
*MEAS_COND_AXIS_UNIT-34 "deg"
*MEAS_COND_AXIS_UNIT-35 ""
*MEAS_COND_AXIS_UNIT-36 "mm"
*MEAS_COND_AXIS_UNIT-37 ""
*MEAS_COND_AXIS_UNIT-38 ""
*MEAS_COND_AXIS_UNIT-39 ""
*MEAS_COND_AXIS_UNIT-4 "deg"
*MEAS_COND_AXIS_UNIT-40 ""
*MEAS_COND_AXIS_UNIT-41 ""
*MEAS_COND_AXIS_UNIT-42 "mm"
*MEAS_COND_AXIS_UNIT-43 ""
*MEAS_COND_AXIS_UNIT-44 "mm"
*MEAS_COND_AXIS_UNIT-45 ""
*MEAS_COND_AXIS_UNIT-46 ""
*MEAS_COND_AXIS_UNIT-47 "V"
*MEAS_COND_AXIS_UNIT-48 "mV"
*MEAS_COND_AXIS_UNIT-49 ""
*MEAS_COND_AXIS_UNIT-5 "deg"
*MEAS_COND_AXIS_UNIT-50 "H"
*MEAS_COND_AXIS_UNIT-51 "H"
*MEAS_COND_AXIS_UNIT-52 "H"
*MEAS_COND_AXIS_UNIT-53 "H"
*MEAS_COND_AXIS_UNIT-54 "H"
*MEAS_COND_AXIS_UNIT-55 "mV"
*MEAS_COND_AXIS_UNIT-56 "V"
*MEAS_COND_AXIS_UNIT-57 "V"
*MEAS_COND_AXIS_UNIT-58 "V"
*MEAS_COND_AXIS_UNIT-59 "H"
*MEAS_COND_AXIS_UNIT-6 "deg"
*MEAS_COND_AXIS_UNIT-60 "H"
*MEAS_COND_AXIS_UNIT-61 "H"
*MEAS_COND_AXIS_UNIT-62 "H"
*MEAS_COND_AXIS_UNIT-63 "H"
*MEAS_COND_AXIS_UNIT-64 "uS/m"
*MEAS_COND_AXIS_UNIT-65 "L/min"
*MEAS_COND_AXIS_UNIT-66 "C"
*MEAS_COND_AXIS_UNIT-67 "MPa"
*MEAS_COND_AXIS_UNIT-68 "MPa"
*MEAS_COND_AXIS_UNIT-69 "MPa"
*MEAS_COND_AXIS_UNIT-7 "deg"
*MEAS_COND_AXIS_UNIT-70 "L/min"
*MEAS_COND_AXIS_UNIT-71 "degree"
*MEAS_COND_AXIS_UNIT-72 "MPa"
*MEAS_COND_AXIS_UNIT-73 "degree"
*MEAS_COND_AXIS_UNIT-74 "percent"
*MEAS_COND_AXIS_UNIT-75 "degree"
*MEAS_COND_AXIS_UNIT-76 "C"
*MEAS_COND_AXIS_UNIT-77 "H"
*MEAS_COND_AXIS_UNIT-78 "time"
*MEAS_COND_AXIS_UNIT-79 "msec"
*MEAS_COND_AXIS_UNIT-8 ""
*MEAS_COND_AXIS_UNIT-80 "msec"
*MEAS_COND_AXIS_UNIT-81 "H"
*MEAS_COND_AXIS_UNIT-82 "times"
*MEAS_COND_AXIS_UNIT-83 "msec"
*MEAS_COND_AXIS_UNIT-84 "msec"
*MEAS_COND_AXIS_UNIT-85 "-"
*MEAS_COND_AXIS_UNIT-86 "-"
*MEAS_COND_AXIS_UNIT-87 "-"
*MEAS_COND_AXIS_UNIT-88 ""
*MEAS_COND_AXIS_UNIT-89 "-"
*MEAS_COND_AXIS_UNIT-9 "mm"
*MEAS_COND_AXIS_UNIT-90 "-"
*MEAS_COND_AXIS_UNIT-91 "-"
*MEAS_COND_AXIS_UNIT-92 ""
*MEAS_COND_AXIS_UNIT-93 ""
*MEAS_COND_AXIS_UNIT-94 ""
*MEAS_COND_AXIS_UNIT-95 ""
*MEAS_COND_AXIS_UNIT-96 ""
*MEAS_COND_AXIS_UNIT-97 ""
*MEAS_COND_AXIS_UNIT-98 ""
*MEAS_COND_AXIS_UNIT-99 ""
*MEAS_COND_OPT_ATTR "PB-Ge(220)x2"
*MEAS_COND_OPT_NAME "User defined settings"
*MEAS_COND_XG_CURRENT "160"
*MEAS_COND_XG_VOLTAGE "45"
*MEAS_COND_XG_WAVE_TYPE "Ka1"
*MEAS_DATA_COUNT "501"
*MEAS_SCAN_AXIS_X "Omega"
*MEAS_SCAN_AXIS_X_INTERNAL "Omega"
*MEAS_SCAN_END_TIME "10/07/2020 16:15:57"
*MEAS_SCAN_MODE "CONTINUOUS"
*MEAS_SCAN_MODE_INTERNAL "CONTINUOUS"
*MEAS_SCAN_RESOLUTION_X "0.0001"
*MEAS_SCAN_SPEED "0.2000"
*MEAS_SCAN_SPEED_UNIT "deg/min"
*MEAS_SCAN_START "20.8005"
*MEAS_SCAN_START_TIME "10/07/2020 16:14:41"
*MEAS_SCAN_STEP "0.0002"
*MEAS_SCAN_STOP "20.9005"
*MEAS_SCAN_UNIT_X "deg"
*MEAS_SCAN_UNIT_Y "counts"
*RAS_HEADER_END
*RAS_INT_START
20.8005 11.0000 1.0000
20.8007 12.0000 1.0000
20.8009 7.0000 1.0000
20.8011 10.0000 1.0000
20.8013 12.0000 1.0000
20.8015 13.0000 1.0000
20.8017 10.0000 1.0000
20.8019 14.0000 1.0000
20.8021 6.0000 1.0000
20.8023 11.0000 1.0000
20.8025 8.0000 1.0000
20.8027 12.0000 1.0000
20.8029 13.0000 1.0000
20.8031 16.0000 1.0000
20.8033 11.0000 1.0000
20.8035 22.0000 1.0000
20.8037 16.0000 1.0000
20.8039 14.0000 1.0000
20.8041 9.0000 1.0000
20.8043 13.0000 1.0000
20.8045 23.0000 1.0000
20.8047 16.0000 1.0000
20.8049 12.0000 1.0000
20.8051 15.0000 1.0000
20.8053 23.0000 1.0000
20.8055 16.0000 1.0000
20.8057 18.0000 1.0000
20.8059 14.0000 1.0000
20.8061 17.0000 1.0000
20.8063 12.0000 1.0000
20.8065 15.0000 1.0000
20.8067 9.0000 1.0000
20.8069 19.0000 1.0000
20.8071 14.0000 1.0000
20.8073 21.0000 1.0000
20.8075 22.0000 1.0000
20.8077 12.0000 1.0000
20.8079 21.0000 1.0000
20.8081 22.0000 1.0000
20.8083 7.0000 1.0000
20.8085 14.0000 1.0000
20.8087 19.0000 1.0000
20.8089 19.0000 1.0000
20.8091 19.0000 1.0000
20.8093 21.0000 1.0000
20.8095 28.0000 1.0000
20.8097 30.0000 1.0000
20.8099 20.0000 1.0000
20.8101 24.0000 1.0000
20.8103 26.0000 1.0000
20.8105 29.0000 1.0000
20.8107 23.0000 1.0000
20.8109 31.0000 1.0000
20.8111 23.0000 1.0000
20.8113 29.0000 1.0000
20.8115 28.0000 1.0000
20.8117 24.0000 1.0000
20.8119 24.0000 1.0000
20.8121 22.0000 1.0000
20.8123 32.0000 1.0000
20.8125 19.0000 1.0000
20.8127 28.0000 1.0000
20.8129 28.0000 1.0000
20.8131 32.0000 1.0000
20.8133 33.0000 1.0000
20.8135 37.0000 1.0000
20.8137 17.0000 1.0000
20.8139 28.0000 1.0000
20.8141 28.0000 1.0000
20.8143 40.0000 1.0000
20.8145 43.0000 1.0000
20.8147 31.0000 1.0000
20.8149 33.0000 1.0000
20.8151 31.0000 1.0000
20.8153 23.0000 1.0000
20.8155 33.0000 1.0000
20.8157 30.0000 1.0000
20.8159 39.0000 1.0000
20.8161 41.0000 1.0000
20.8163 44.0000 1.0000
20.8165 34.0000 1.0000
20.8167 29.0000 1.0000
20.8169 31.0000 1.0000
20.8171 46.0000 1.0000
20.8173 43.0000 1.0000
20.8175 47.0000 1.0000
20.8177 37.0000 1.0000
20.8179 40.0000 1.0000
20.8181 46.0000 1.0000
20.8183 46.0000 1.0000
20.8185 40.0000 1.0000
20.8187 60.0000 1.0000
20.8189 45.0000 1.0000
20.8191 41.0000 1.0000
20.8193 57.0000 1.0000
20.8195 40.0000 1.0000
20.8197 68.0000 1.0000
20.8199 65.0000 1.0000
20.8201 40.0000 1.0000
20.8203 60.0000 1.0000
20.8205 55.0000 1.0000
20.8207 48.0000 1.0000
20.8209 60.0000 1.0000
20.8211 70.0000 1.0000
20.8213 61.0000 1.0000
20.8215 69.0000 1.0000
20.8217 78.0000 1.0000
20.8219 76.0000 1.0000
20.8221 68.0000 1.0000
20.8223 79.0000 1.0000
20.8225 77.0000 1.0000
20.8227 80.0000 1.0000
20.8229 71.0000 1.0000
20.8231 74.0000 1.0000
20.8233 78.0000 1.0000
20.8235 78.0000 1.0000
20.8237 94.0000 1.0000
20.8239 75.0000 1.0000
20.8241 96.0000 1.0000
20.8243 96.0000 1.0000
20.8245 107.0000 1.0000
20.8247 73.0000 1.0000
20.8249 95.0000 1.0000
20.8251 105.0000 1.0000
20.8253 111.0000 1.0000
20.8255 120.0000 1.0000
20.8257 105.0000 1.0000
20.8259 115.0000 1.0000
20.8261 128.0000 1.0000
20.8263 89.0000 1.0000
20.8265 106.0000 1.0000
20.8267 128.0000 1.0000
20.8269 144.0000 1.0000
20.8271 144.0000 1.0000
20.8273 127.0000 1.0000
20.8275 141.0000 1.0000
20.8277 121.0000 1.0000
20.8279 156.0000 1.0000
20.8281 141.0000 1.0000
20.8283 157.0000 1.0000
20.8285 133.0000 1.0000
20.8287 154.0000 1.0000
20.8289 161.0000 1.0000
20.8291 149.0000 1.0000
20.8293 182.0000 1.0000
20.8295 145.0000 1.0000
20.8297 171.0000 1.0000
20.8299 202.0000 1.0000
20.8301 220.0000 1.0000
20.8303 218.0000 1.0000
20.8305 211.0000 1.0000
20.8307 203.0000 1.0000
20.8309 263.0000 1.0000
20.8311 259.0000 1.0000
20.8313 240.0000 1.0000
20.8315 268.0000 1.0000
20.8317 245.0000 1.0000
20.8319 262.0000 1.0000
20.8321 282.0000 1.0000
20.8323 312.0000 1.0000
20.8325 310.0000 1.0000
20.8327 310.0000 1.0000
20.8329 318.0000 1.0000
20.8331 338.0000 1.0000
20.8333 360.0000 1.0000
20.8335 375.0000 1.0000
20.8337 368.0000 1.0000
20.8339 411.0000 1.0000
20.8341 418.0000 1.0000
20.8343 447.0000 1.0000
20.8345 494.0000 1.0000
20.8347 471.0000 1.0000
20.8349 516.0000 1.0000
20.8351 560.0000 1.0000
20.8353 592.0000 1.0000
20.8355 582.0000 1.0000
20.8357 715.0000 1.0000
20.8359 707.0000 1.0000
20.8361 707.0000 1.0000
20.8363 772.0000 1.0000
20.8365 842.0000 1.0000
20.8367 874.0000 1.0000
20.8369 939.0000 1.0000
20.8371 1004.0000 1.0000
20.8373 1119.0000 1.0000
20.8375 1245.0000 1.0000
20.8377 1359.0000 1.0000
20.8379 1557.0000 1.0000
20.8381 1571.0000 1.0000
20.8383 1702.0000 1.0000
20.8385 2004.0000 1.0000
20.8387 2006.0000 1.0000
20.8389 2221.0000 1.0000
20.8391 2607.0000 1.0000
20.8393 3048.0000 1.0000
20.8395 3489.0000 1.0000
20.8397 83.0000 53.8780
20.8399 77.0000 53.8780
20.8401 87.0000 53.8780
20.8403 121.0000 53.8780
20.8405 162.0000 53.8780
20.8407 242.0000 53.8780
20.8409 271.0000 53.8780
20.8411 398.0000 53.8780
20.8413 516.0000 53.8780
20.8415 677.0000 53.8780
20.8417 835.0000 53.8780
20.8419 1216.0000 53.8780
20.8421 1490.0000 53.8780
20.8423 1897.0000 53.8780
20.8425 2285.0000 53.8780
20.8427 2757.0000 53.8780
20.8429 2948.0000 53.8780
20.8431 253.0000 777.1638
20.8433 283.0000 777.1638
20.8435 314.0000 777.1638
20.8437 331.0000 777.1638
20.8439 331.0000 777.1638
20.8441 341.0000 777.1638
20.8443 330.0000 777.1638
20.8445 319.0000 777.1638
20.8447 308.0000 777.1638
20.8449 287.0000 777.1638
20.8451 285.0000 777.1638
20.8453 220.0000 777.1638
20.8455 178.0000 777.1638
20.8457 164.0000 777.1638
20.8459 160.0000 777.1638
20.8461 124.0000 777.1638
20.8463 122.0000 777.1638
20.8465 86.0000 777.1638
20.8467 73.0000 777.1638
20.8469 735.0000 53.8780
20.8471 790.0000 53.8780
20.8473 682.0000 53.8780
20.8475 404.0000 53.8780
20.8477 269.0000 53.8780
20.8479 179.0000 53.8780
20.8481 127.0000 53.8780
20.8483 95.0000 53.8780
20.8485 70.0000 53.8780
20.8487 60.0000 53.8780
20.8489 2275.0000 1.0000
20.8491 2359.0000 1.0000
20.8493 2148.0000 1.0000
20.8495 1507.0000 1.0000
20.8497 1348.0000 1.0000
20.8499 1145.0000 1.0000
20.8501 1024.0000 1.0000
20.8503 932.0000 1.0000
20.8505 880.0000 1.0000
20.8507 807.0000 1.0000
20.8509 743.0000 1.0000
20.8511 721.0000 1.0000
20.8513 620.0000 1.0000
20.8515 603.0000 1.0000
20.8517 573.0000 1.0000
20.8519 505.0000 1.0000
20.8521 512.0000 1.0000
20.8523 495.0000 1.0000
20.8525 460.0000 1.0000
20.8527 405.0000 1.0000
20.8529 419.0000 1.0000
20.8531 380.0000 1.0000
20.8533 362.0000 1.0000
20.8535 325.0000 1.0000
20.8537 344.0000 1.0000
20.8539 347.0000 1.0000
20.8541 319.0000 1.0000
20.8543 287.0000 1.0000
20.8545 286.0000 1.0000
20.8547 283.0000 1.0000
20.8549 266.0000 1.0000
20.8551 241.0000 1.0000
20.8553 220.0000 1.0000
20.8555 251.0000 1.0000
20.8557 215.0000 1.0000
20.8559 194.0000 1.0000
20.8561 203.0000 1.0000
20.8563 203.0000 1.0000
20.8565 192.0000 1.0000
20.8567 164.0000 1.0000
20.8569 183.0000 1.0000
20.8571 157.0000 1.0000
20.8573 167.0000 1.0000
20.8575 195.0000 1.0000
20.8577 150.0000 1.0000
20.8579 113.0000 1.0000
20.8581 130.0000 1.0000
20.8583 139.0000 1.0000
20.8585 127.0000 1.0000
20.8587 123.0000 1.0000
20.8589 136.0000 1.0000
20.8591 126.0000 1.0000
20.8593 126.0000 1.0000
20.8595 129.0000 1.0000
20.8597 115.0000 1.0000
20.8599 121.0000 1.0000
20.8601 88.0000 1.0000
20.8603 104.0000 1.0000
20.8605 99.0000 1.0000
20.8607 87.0000 1.0000
20.8609 94.0000 1.0000
20.8611 89.0000 1.0000
20.8613 98.0000 1.0000
20.8615 70.0000 1.0000
20.8617 91.0000 1.0000
20.8619 93.0000 1.0000
20.8621 112.0000 1.0000
20.8623 103.0000 1.0000
20.8625 81.0000 1.0000
20.8627 79.0000 1.0000
20.8629 88.0000 1.0000
20.8631 65.0000 1.0000
20.8633 84.0000 1.0000
20.8635 81.0000 1.0000
20.8637 75.0000 1.0000
20.8639 75.0000 1.0000
20.8641 71.0000 1.0000
20.8643 51.0000 1.0000
20.8645 67.0000 1.0000
20.8647 69.0000 1.0000
20.8649 59.0000 1.0000
20.8651 74.0000 1.0000
20.8653 81.0000 1.0000
20.8655 63.0000 1.0000
20.8657 53.0000 1.0000
20.8659 63.0000 1.0000
20.8661 46.0000 1.0000
20.8663 74.0000 1.0000
20.8665 51.0000 1.0000
20.8667 56.0000 1.0000
20.8669 64.0000 1.0000
20.8671 35.0000 1.0000
20.8673 58.0000 1.0000
20.8675 47.0000 1.0000
20.8677 49.0000 1.0000
20.8679 58.0000 1.0000
20.8681 52.0000 1.0000
20.8683 52.0000 1.0000
20.8685 42.0000 1.0000
20.8687 49.0000 1.0000
20.8689 46.0000 1.0000
20.8691 52.0000 1.0000
20.8693 46.0000 1.0000
20.8695 38.0000 1.0000
20.8697 49.0000 1.0000
20.8699 47.0000 1.0000
20.8701 43.0000 1.0000
20.8703 41.0000 1.0000
20.8705 32.0000 1.0000
20.8707 22.0000 1.0000
20.8709 40.0000 1.0000
20.8711 32.0000 1.0000
20.8713 34.0000 1.0000
20.8715 43.0000 1.0000
20.8717 35.0000 1.0000
20.8719 49.0000 1.0000
20.8721 32.0000 1.0000
20.8723 32.0000 1.0000
20.8725 31.0000 1.0000
20.8727 25.0000 1.0000
20.8729 26.0000 1.0000
20.8731 25.0000 1.0000
20.8733 40.0000 1.0000
20.8735 40.0000 1.0000
20.8737 31.0000 1.0000
20.8739 29.0000 1.0000
20.8741 34.0000 1.0000
20.8743 38.0000 1.0000
20.8745 32.0000 1.0000
20.8747 21.0000 1.0000
20.8749 28.0000 1.0000
20.8751 23.0000 1.0000
20.8753 36.0000 1.0000
20.8755 24.0000 1.0000
20.8757 22.0000 1.0000
20.8759 29.0000 1.0000
20.8761 31.0000 1.0000
20.8763 28.0000 1.0000
20.8765 14.0000 1.0000
20.8767 31.0000 1.0000
20.8769 16.0000 1.0000
20.8771 19.0000 1.0000
20.8773 26.0000 1.0000
20.8775 21.0000 1.0000
20.8777 11.0000 1.0000
20.8779 22.0000 1.0000
20.8781 24.0000 1.0000
20.8783 14.0000 1.0000
20.8785 23.0000 1.0000
20.8787 12.0000 1.0000
20.8789 20.0000 1.0000
20.8791 16.0000 1.0000
20.8793 20.0000 1.0000
20.8795 14.0000 1.0000
20.8797 22.0000 1.0000
20.8799 25.0000 1.0000
20.8801 19.0000 1.0000
20.8803 21.0000 1.0000
20.8805 19.0000 1.0000
20.8807 17.0000 1.0000
20.8809 15.0000 1.0000
20.8811 15.0000 1.0000
20.8813 15.0000 1.0000
20.8815 13.0000 1.0000
20.8817 14.0000 1.0000
20.8819 16.0000 1.0000
20.8821 18.0000 1.0000
20.8823 14.0000 1.0000
20.8825 20.0000 1.0000
20.8827 13.0000 1.0000
20.8829 16.0000 1.0000
20.8831 11.0000 1.0000
20.8833 15.0000 1.0000
20.8835 18.0000 1.0000
20.8837 13.0000 1.0000
20.8839 13.0000 1.0000
20.8841 15.0000 1.0000
20.8843 11.0000 1.0000
20.8845 11.0000 1.0000
20.8847 13.0000 1.0000
20.8849 19.0000 1.0000
20.8851 13.0000 1.0000
20.8853 14.0000 1.0000
20.8855 6.0000 1.0000
20.8857 16.0000 1.0000
20.8859 19.0000 1.0000
20.8861 10.0000 1.0000
20.8863 8.0000 1.0000
20.8865 11.0000 1.0000
20.8867 10.0000 1.0000
20.8869 8.0000 1.0000
20.8871 6.0000 1.0000
20.8873 5.0000 1.0000
20.8875 8.0000 1.0000
20.8877 8.0000 1.0000
20.8879 9.0000 1.0000
20.8881 8.0000 1.0000
20.8883 7.0000 1.0000
20.8885 11.0000 1.0000
20.8887 7.0000 1.0000
20.8889 14.0000 1.0000
20.8891 6.0000 1.0000
20.8893 9.0000 1.0000
20.8895 14.0000 1.0000
20.8897 6.0000 1.0000
20.8899 7.0000 1.0000
20.8901 13.0000 1.0000
20.8903 8.0000 1.0000
20.8905 10.0000 1.0000
20.8907 6.0000 1.0000
20.8909 8.0000 1.0000
20.8911 5.0000 1.0000
20.8913 6.0000 1.0000
20.8915 7.0000 1.0000
20.8917 11.0000 1.0000
20.8919 3.0000 1.0000
20.8921 5.0000 1.0000
20.8923 8.0000 1.0000
20.8925 4.0000 1.0000
20.8927 5.0000 1.0000
20.8929 7.0000 1.0000
20.8931 4.0000 1.0000
20.8933 8.0000 1.0000
20.8935 6.0000 1.0000
20.8937 10.0000 1.0000
20.8939 6.0000 1.0000
20.8941 6.0000 1.0000
20.8943 8.0000 1.0000
20.8945 6.0000 1.0000
20.8947 2.0000 1.0000
20.8949 3.0000 1.0000
20.8951 3.0000 1.0000
20.8953 7.0000 1.0000
20.8955 6.0000 1.0000
20.8957 4.0000 1.0000
20.8959 6.0000 1.0000
20.8961 6.0000 1.0000
20.8963 6.0000 1.0000
20.8965 3.0000 1.0000
20.8967 7.0000 1.0000
20.8969 7.0000 1.0000
20.8971 6.0000 1.0000
20.8973 7.0000 1.0000
20.8975 5.0000 1.0000
20.8977 2.0000 1.0000
20.8979 6.0000 1.0000
20.8981 7.0000 1.0000
20.8983 5.0000 1.0000
20.8985 7.0000 1.0000
20.8987 3.0000 1.0000
20.8989 8.0000 1.0000
20.8991 1.0000 1.0000
20.8993 6.0000 1.0000
20.8995 4.0000 1.0000
20.8997 6.0000 1.0000
20.8999 9.0000 1.0000
20.9001 7.0000 1.0000
20.9003 1.0000 1.0000
20.9005 5.0000 1.0000
*RAS_INT_END
*RAS_DATA_END
*DSC_DATA_END