File: example/461_test/PLD50nmFe2O3_Al2O3/HRXRD_Lab/W_Al2O3_0012.ras
*RAS_DATA_START
*RAS_HEADER_START
*DISP_LINE_COLOR "4286611584"
*FILE_COMMENT ""
*FILE_MD5 ""
*FILE_MEMO "phi 0"
*FILE_OPERATOR "Administrator"
*FILE_PACKAGE_NAME ""
*FILE_PART_ID ""
*FILE_SAMPLE ""
*FILE_SYSTEM_NAME "SmartLab"
*FILE_TYPE "RAS_RAW"
*FILE_USERGROUP "Administrators"
*FILE_VERSION "1"
*HW_ATTACHMENT_ID "ATT0022"
*HW_ATTACHMENT_NAME "RxRy"
*HW_ATTACHMENT_NAME_INTERNAL "RxRy"
*HW_COUNTER_ID-0 "CUT0021"
*HW_COUNTER_ID-1 "CMC0020"
*HW_COUNTER_MONOCHRO_ID "CMC0020"
*HW_COUNTER_MONOCHRO_NAME "None"
*HW_COUNTER_MONOCHRO_NAME_INTERNAL "None"
*HW_COUNTER_NAME_INTERNAL "SC70"
*HW_COUNTER_NAME-0 "SC70"
*HW_COUNTER_NAME-1 "None"
*HW_COUNTER_SELECT_NAME "SC70"
*HW_EXTERNAL_CONTROLLER_NAME "None"
*HW_EXTERNAL_CONTROLLER_NAME_INTERNAL "None"
*HW_GONIOMETER_ID "GON0022"
*HW_GONIOMETER_NAME "StandardInplaneEnc"
*HW_GONIOMETER_NAME_INTERNAL "StandardInplaneEnc"
*HW_GONIOMETER_RADIUS-0 "90.0"
*HW_GONIOMETER_RADIUS-1 "114.0"
*HW_GONIOMETER_RADIUS-2 "190.0"
*HW_GONIOMETER_RADIUS-3 "300.0"
*HW_GONIOMETER_RADIUS-4 "187.0"
*HW_GONIOMETER_RADIUS-5 "300.0"
*HW_GONIOMETER_RADIUS-6 "113.0000"
*HW_GONIOMETER_RADIUS-7 "331.0"
*HW_I_CBO_ID "CBO0021"
*HW_I_CBO_NAME "CBO"
*HW_I_CBO_NAME_INTERNAL "CBO"
*HW_I_MONOCHRO_ID "ICR0021"
*HW_I_MONOCHRO_NAME "Ge(220)x2"
*HW_I_MONOCHRO_NAME_INTERNAL "Ge(220)x2"
*HW_I_OPT_ID-0 "CBO0021"
*HW_I_OPT_ID-1 "ISL0021"
*HW_I_PRIMARY_NAME_INTERNAL "Standard"
*HW_I_SLIT_ID "ISL0021"
*HW_I_SLIT_NAME "Auto"
*HW_I_SLIT_NAME_INTERNAL "Auto"
*HW_R_ATTENUATER_AUTOMODE "1"
*HW_R_ATTENUATER_ID "ATN0021"
*HW_R_ATTENUATER_NAME "Auto"
*HW_R_ATTENUATOR_NAME_INTERNAL "Auto"
*HW_R_OPT_ID-0 "RSS0021"
*HW_R_OPT_ID-1 "RCR0022"
*HW_R_OPT_ID-2 "RSO0021"
*HW_R_OPT_ID-3 "RRS0021"
*HW_R_OPT_ID-4 "ATN0021"
*HW_R_ROD_ID "RCR0022"
*HW_R_ROD_NAME "ROD_adaptor"
*HW_R_ROD_NAME_INTERNAL "ROD_adaptor"
*HW_R_RPS_ID "RSO0021"
*HW_R_RPS_NAME "RPS_adaptor"
*HW_R_RPS_NAME_INTERNAL "RPS_adaptor"
*HW_R_RS_ID "RRS0021"
*HW_R_RS_NAME "Auto"
*HW_R_RS_NAME_INTERNAL "Auto"
*HW_R_SS_ID "RSS0021"
*HW_R_SS_NAME "Auto"
*HW_R_SS_NAME_INTERNAL "Auto"
*HW_ROBOT_NAME "No_unit"
*HW_ROBOT_NAME_INTERNAL "No_unit"
*HW_SAMPLE_CAMERA_NAME "None"
*HW_SAMPLE_CAMERA_NAME_INTERNAL "None"
*HW_SAMPLE_HOLDER_ID "SMP0021"
*HW_SAMPLE_HOLDER_NAME "Z_ChiPhi"
*HW_SAMPLE_HOLDER_NAME_INTERNAL "Z_ChiPhi"
*HW_SAMPLE_NAME "WaferSample"
*HW_SAMPLE_NAME_INTERNAL "WaferSample"
*HW_SAMPLE_PLATE_NAME "ForWafer"
*HW_SAMPLE_PLATE_NAME_INTERNAL "ForWafer"
*HW_SAMPLE_SPACER_NAME "0-3mm"
*HW_SAMPLE_SPACER_NAME_INTERNAL "0-3mm"
*HW_USERINFO_CATALOG_NO ""
*HW_USERINFO_INSTRUMENT_ID ""
*HW_USERINFO_INSTRUMENT_NAME ""
*HW_USERINFO_INSTRUMENT_NO ""
*HW_USERINFO_MODEL ""
*HW_USERINFO_ORDER_NO ""
*HW_USERINFO_SERIAL_NO ""
*HW_USERINFO_VERIFY_INSTRUMENT_ID "00-07-fe-01-03-ce"
*HW_VER_RCD_COUNTER_UNIT "1.0.1"
*HW_VER_RCD_CPU "3.3.7"
*HW_VER_RCD_FPGA "1.2.2"
*HW_VER_RCD_GONIO_UNIT "6.2.0"
*HW_VER_RCD_INCIDENT_UNIT "6.2.0"
*HW_VER_RCD_RECEIVING_UNIT "6.2.0"
*HW_VER_RCD_TYPE "RINC"
*HW_VER_XGC_CPU "3.3.7"
*HW_VER_XGC_CW "1.2.0"
*HW_VER_XGC_HV "1.2.0"
*HW_VER_XGC_RS1 "1.3.4"
*HW_VER_XGC_RS2 "N/A"
*HW_VER_XGC_RT "1.2.0"
*HW_VER_XGC_TYPE "RINC"
*HW_XG_CURRENT_UNIT "mA"
*HW_XG_FOCUS "0.4mm x 8mm"
*HW_XG_FOCUS_TYPE "Fine"
*HW_XG_TARGET_ATOMIC_NUMBER "29"
*HW_XG_TARGET_NAME "Cu"
*HW_XG_TYPE "ROTA"
*HW_XG_VOLTAGE_UNIT "kV"
*HW_XG_WAVE_LENGTH_ALPHA1 "1.540593"
*HW_XG_WAVE_LENGTH_ALPHA2 "1.544414"
*HW_XG_WAVE_LENGTH_BETA "1.392246"
*HW_XG_WAVE_LENGTH_UNIT "Angstrom"
*MEAS_COND_AXIS_NAME_INTERNAL-0 "ThetaS"
*MEAS_COND_AXIS_NAME_INTERNAL-1 "ThetaD"
*MEAS_COND_AXIS_NAME_INTERNAL-10 "PrimaryGeometry"
*MEAS_COND_AXIS_NAME_INTERNAL-100 "IncidentMonochromator"
*MEAS_COND_AXIS_NAME_INTERNAL-101 "ReceivingOptics"
*MEAS_COND_AXIS_NAME_INTERNAL-102 "CounterMonochromatorKind"
*MEAS_COND_AXIS_NAME_INTERNAL-11 "PrimaryMirrorType"
*MEAS_COND_AXIS_NAME_INTERNAL-12 "CBOType"
*MEAS_COND_AXIS_NAME_INTERNAL-13 "CBO-M"
*MEAS_COND_AXIS_NAME_INTERNAL-14 "CBO"
*MEAS_COND_AXIS_NAME_INTERNAL-15 "IncidentMonochromator-OmegaM"
*MEAS_COND_AXIS_NAME_INTERNAL-16 "IncidentSollerSlit"
*MEAS_COND_AXIS_NAME_INTERNAL-17 "IncidentSlitBox"
*MEAS_COND_AXIS_NAME_INTERNAL-18 "IncidentSlitBox-_Axis"
*MEAS_COND_AXIS_NAME_INTERNAL-19 "SlitDS"
*MEAS_COND_AXIS_NAME_INTERNAL-2 "TwoTheta"
*MEAS_COND_AXIS_NAME_INTERNAL-20 "Zs"
*MEAS_COND_AXIS_NAME_INTERNAL-21 "IncidentAxdSlit"
*MEAS_COND_AXIS_NAME_INTERNAL-22 "LLS"
*MEAS_COND_AXIS_NAME_INTERNAL-23 "DHLSlit"
*MEAS_COND_AXIS_NAME_INTERNAL-24 "Chi"
*MEAS_COND_AXIS_NAME_INTERNAL-25 "Phi"
*MEAS_COND_AXIS_NAME_INTERNAL-26 "Z"
*MEAS_COND_AXIS_NAME_INTERNAL-27 "Alpha"
*MEAS_COND_AXIS_NAME_INTERNAL-28 "Beta"
*MEAS_COND_AXIS_NAME_INTERNAL-29 "TwoThetaChiPhi"
*MEAS_COND_AXIS_NAME_INTERNAL-3 "Omega"
*MEAS_COND_AXIS_NAME_INTERNAL-30 "AlphaI"
*MEAS_COND_AXIS_NAME_INTERNAL-31 "BetaI"
*MEAS_COND_AXIS_NAME_INTERNAL-32 "TwoThetaB"
*MEAS_COND_AXIS_NAME_INTERNAL-33 "Rx"
*MEAS_COND_AXIS_NAME_INTERNAL-34 "Ry"
*MEAS_COND_AXIS_NAME_INTERNAL-35 "ReceivingSlitBox1"
*MEAS_COND_AXIS_NAME_INTERNAL-36 "ReceivingSlitBox1-_Axis"
*MEAS_COND_AXIS_NAME_INTERNAL-37 "SlitSS"
*MEAS_COND_AXIS_NAME_INTERNAL-38 "Filter"
*MEAS_COND_AXIS_NAME_INTERNAL-39 "PSA"
*MEAS_COND_AXIS_NAME_INTERNAL-4 "TwoThetaTheta"
*MEAS_COND_AXIS_NAME_INTERNAL-40 "ReceivingSollerSlit"
*MEAS_COND_AXIS_NAME_INTERNAL-41 "ReceivingSlitBox2"
*MEAS_COND_AXIS_NAME_INTERNAL-42 "ReceivingSlitBox2-_Axis"
*MEAS_COND_AXIS_NAME_INTERNAL-43 "SlitRS"
*MEAS_COND_AXIS_NAME_INTERNAL-44 "ReceivingSlitBox2-Zd"
*MEAS_COND_AXIS_NAME_INTERNAL-45 "Filter2"
*MEAS_COND_AXIS_NAME_INTERNAL-46 "Attenuator"
*MEAS_COND_AXIS_NAME_INTERNAL-47 "HV"
*MEAS_COND_AXIS_NAME_INTERNAL-48 "PHA"
*MEAS_COND_AXIS_NAME_INTERNAL-49 "DedicatedHolder"
*MEAS_COND_AXIS_NAME_INTERNAL-5 "TwoThetaOmega"
*MEAS_COND_AXIS_NAME_INTERNAL-50 "Target_TargetTime"
*MEAS_COND_AXIS_NAME_INTERNAL-51 "Target_XrayOnTime"
*MEAS_COND_AXIS_NAME_INTERNAL-52 "Target_TMPTime"
*MEAS_COND_AXIS_NAME_INTERNAL-53 "Target_RPTime"
*MEAS_COND_AXIS_NAME_INTERNAL-54 "Target_FilamentTime"
*MEAS_COND_AXIS_NAME_INTERNAL-55 "Target_IG"
*MEAS_COND_AXIS_NAME_INTERNAL-56 "Target_GP"
*MEAS_COND_AXIS_NAME_INTERNAL-57 "Target_FC"
*MEAS_COND_AXIS_NAME_INTERNAL-58 "HVPS_Bias"
*MEAS_COND_AXIS_NAME_INTERNAL-59 "HVPS_HVPSTime"
*MEAS_COND_AXIS_NAME_INTERNAL-6 "OmegaTwoTheta"
*MEAS_COND_AXIS_NAME_INTERNAL-60 "HVPS_Type1Time"
*MEAS_COND_AXIS_NAME_INTERNAL-61 "HVPS_Type2Time"
*MEAS_COND_AXIS_NAME_INTERNAL-62 "HVPS_Type3Time"
*MEAS_COND_AXIS_NAME_INTERNAL-63 "CW_IERTime"
*MEAS_COND_AXIS_NAME_INTERNAL-64 "CW_ECTime"
*MEAS_COND_AXIS_NAME_INTERNAL-65 "CW_Flow1"
*MEAS_COND_AXIS_NAME_INTERNAL-66 "CW_Temperature1"
*MEAS_COND_AXIS_NAME_INTERNAL-67 "CW_Pressure1"
*MEAS_COND_AXIS_NAME_INTERNAL-68 "CW_PressureIn"
*MEAS_COND_AXIS_NAME_INTERNAL-69 "CW_PressureOut"
*MEAS_COND_AXIS_NAME_INTERNAL-7 "TwoThetaChi"
*MEAS_COND_AXIS_NAME_INTERNAL-70 "CW_Flow2"
*MEAS_COND_AXIS_NAME_INTERNAL-71 "CW_Temperature2"
*MEAS_COND_AXIS_NAME_INTERNAL-72 "CW_Pressure2"
*MEAS_COND_AXIS_NAME_INTERNAL-73 "RE_EnclosureTemp"
*MEAS_COND_AXIS_NAME_INTERNAL-74 "RE_EnclosureHummidity"
*MEAS_COND_AXIS_NAME_INTERNAL-75 "RE_CabinetTemp"
*MEAS_COND_AXIS_NAME_INTERNAL-76 "RE_RPTemp"
*MEAS_COND_AXIS_NAME_INTERNAL-77 "RE_ShutterAXrayOnTime"
*MEAS_COND_AXIS_NAME_INTERNAL-78 "RE_ShutterATimes"
*MEAS_COND_AXIS_NAME_INTERNAL-79 "RE_ShutterAOpenCloseTime"
*MEAS_COND_AXIS_NAME_INTERNAL-8 "GonioDirectBeamStop"
*MEAS_COND_AXIS_NAME_INTERNAL-80 "RE_ShutterACloseOpenTime"
*MEAS_COND_AXIS_NAME_INTERNAL-81 "RE_ShutterBXrayOnTime"
*MEAS_COND_AXIS_NAME_INTERNAL-82 "RE_ShutterBTimes"
*MEAS_COND_AXIS_NAME_INTERNAL-83 "RE_ShutterBOpenCloseTime"
*MEAS_COND_AXIS_NAME_INTERNAL-84 "RE_ShutterBCloseOpenTime"
*MEAS_COND_AXIS_NAME_INTERNAL-85 "RE_XrayWarningRamp"
*MEAS_COND_AXIS_NAME_INTERNAL-86 "RE_ShutterAInstallation"
*MEAS_COND_AXIS_NAME_INTERNAL-87 "RE_ShutterARamp"
*MEAS_COND_AXIS_NAME_INTERNAL-88 "RE_ShutterBInstallation"
*MEAS_COND_AXIS_NAME_INTERNAL-89 "RE_ShutterBRamp"
*MEAS_COND_AXIS_NAME_INTERNAL-9 "Ts"
*MEAS_COND_AXIS_NAME_INTERNAL-90 "RE_ExtShutterCLS"
*MEAS_COND_AXIS_NAME_INTERNAL-91 "RE_ExtXrayOFF"
*MEAS_COND_AXIS_NAME_INTERNAL-92 "RE_ExtSafetyCircuit"
*MEAS_COND_AXIS_NAME_INTERNAL-93 "Version_CPU"
*MEAS_COND_AXIS_NAME_INTERNAL-94 "Version_RS1"
*MEAS_COND_AXIS_NAME_INTERNAL-95 "Version_RS2"
*MEAS_COND_AXIS_NAME_INTERNAL-96 "Version_HV"
*MEAS_COND_AXIS_NAME_INTERNAL-97 "Version_CW"
*MEAS_COND_AXIS_NAME_INTERNAL-98 "Version_RT"
*MEAS_COND_AXIS_NAME_INTERNAL-99 "IncidentPrimary"
*MEAS_COND_AXIS_NAME-0 "ThetaS"
*MEAS_COND_AXIS_NAME-1 "ThetaD"
*MEAS_COND_AXIS_NAME-10 "PrimaryGeometry"
*MEAS_COND_AXIS_NAME-100 "IncidentMonochromator"
*MEAS_COND_AXIS_NAME-101 "ReceivingOptics"
*MEAS_COND_AXIS_NAME-102 "CounterMonochromatorKind"
*MEAS_COND_AXIS_NAME-11 "PrimaryMirrorType"
*MEAS_COND_AXIS_NAME-12 "CBOType"
*MEAS_COND_AXIS_NAME-13 "CBO-M"
*MEAS_COND_AXIS_NAME-14 "CBO"
*MEAS_COND_AXIS_NAME-15 "IncidentMonochromator-OmegaM"
*MEAS_COND_AXIS_NAME-16 "IncidentSollerSlit"
*MEAS_COND_AXIS_NAME-17 "IncidentSlitBox"
*MEAS_COND_AXIS_NAME-18 "IncidentSlitBox-_Axis"
*MEAS_COND_AXIS_NAME-19 "SlitDS"
*MEAS_COND_AXIS_NAME-2 "TwoTheta"
*MEAS_COND_AXIS_NAME-20 "Zs"
*MEAS_COND_AXIS_NAME-21 "IncidentAxdSlit"
*MEAS_COND_AXIS_NAME-22 "LLS"
*MEAS_COND_AXIS_NAME-23 "DHLSlit"
*MEAS_COND_AXIS_NAME-24 "Chi"
*MEAS_COND_AXIS_NAME-25 "Phi"
*MEAS_COND_AXIS_NAME-26 "Z"
*MEAS_COND_AXIS_NAME-27 "Alpha"
*MEAS_COND_AXIS_NAME-28 "Beta"
*MEAS_COND_AXIS_NAME-29 "TwoThetaChiPhi"
*MEAS_COND_AXIS_NAME-3 "Omega"
*MEAS_COND_AXIS_NAME-30 "AlphaI"
*MEAS_COND_AXIS_NAME-31 "BetaI"
*MEAS_COND_AXIS_NAME-32 "TwoThetaB"
*MEAS_COND_AXIS_NAME-33 "Rx"
*MEAS_COND_AXIS_NAME-34 "Ry"
*MEAS_COND_AXIS_NAME-35 "ReceivingSlitBox1"
*MEAS_COND_AXIS_NAME-36 "ReceivingSlitBox1-_Axis"
*MEAS_COND_AXIS_NAME-37 "SlitSS"
*MEAS_COND_AXIS_NAME-38 "Filter"
*MEAS_COND_AXIS_NAME-39 "PSA"
*MEAS_COND_AXIS_NAME-4 "TwoThetaTheta"
*MEAS_COND_AXIS_NAME-40 "ReceivingSollerSlit"
*MEAS_COND_AXIS_NAME-41 "ReceivingSlitBox2"
*MEAS_COND_AXIS_NAME-42 "ReceivingSlitBox2-_Axis"
*MEAS_COND_AXIS_NAME-43 "SlitRS"
*MEAS_COND_AXIS_NAME-44 "ReceivingSlitBox2-Zd"
*MEAS_COND_AXIS_NAME-45 "Filter2"
*MEAS_COND_AXIS_NAME-46 "Attenuator"
*MEAS_COND_AXIS_NAME-47 "HV"
*MEAS_COND_AXIS_NAME-48 "PHA"
*MEAS_COND_AXIS_NAME-49 "DedicatedHolder"
*MEAS_COND_AXIS_NAME-5 "TwoThetaOmega"
*MEAS_COND_AXIS_NAME-50 "Target_TargetTime"
*MEAS_COND_AXIS_NAME-51 "Target_XrayOnTime"
*MEAS_COND_AXIS_NAME-52 "Target_TMPTime"
*MEAS_COND_AXIS_NAME-53 "Target_RPTime"
*MEAS_COND_AXIS_NAME-54 "Target_FilamentTime"
*MEAS_COND_AXIS_NAME-55 "Target_IG"
*MEAS_COND_AXIS_NAME-56 "Target_GP"
*MEAS_COND_AXIS_NAME-57 "Target_FC"
*MEAS_COND_AXIS_NAME-58 "HVPS_Bias"
*MEAS_COND_AXIS_NAME-59 "HVPS_HVPSTime"
*MEAS_COND_AXIS_NAME-6 "OmegaTwoTheta"
*MEAS_COND_AXIS_NAME-60 "HVPS_Type1Time"
*MEAS_COND_AXIS_NAME-61 "HVPS_Type2Time"
*MEAS_COND_AXIS_NAME-62 "HVPS_Type3Time"
*MEAS_COND_AXIS_NAME-63 "CW_IERTime"
*MEAS_COND_AXIS_NAME-64 "CW_ECTime"
*MEAS_COND_AXIS_NAME-65 "CW_Flow1"
*MEAS_COND_AXIS_NAME-66 "CW_Temperature1"
*MEAS_COND_AXIS_NAME-67 "CW_Pressure1"
*MEAS_COND_AXIS_NAME-68 "CW_PressureIn"
*MEAS_COND_AXIS_NAME-69 "CW_PressureOut"
*MEAS_COND_AXIS_NAME-7 "TwoThetaChi"
*MEAS_COND_AXIS_NAME-70 "CW_Flow2"
*MEAS_COND_AXIS_NAME-71 "CW_Temperature2"
*MEAS_COND_AXIS_NAME-72 "CW_Pressure2"
*MEAS_COND_AXIS_NAME-73 "RE_EnclosureTemp"
*MEAS_COND_AXIS_NAME-74 "RE_EnclosureHummidity"
*MEAS_COND_AXIS_NAME-75 "RE_CabinetTemp"
*MEAS_COND_AXIS_NAME-76 "RE_RPTemp"
*MEAS_COND_AXIS_NAME-77 "RE_ShutterAXrayOnTime"
*MEAS_COND_AXIS_NAME-78 "RE_ShutterATimes"
*MEAS_COND_AXIS_NAME-79 "RE_ShutterAOpenCloseTime"
*MEAS_COND_AXIS_NAME-8 "GonioDirectBeamStop"
*MEAS_COND_AXIS_NAME-80 "RE_ShutterACloseOpenTime"
*MEAS_COND_AXIS_NAME-81 "RE_ShutterBXrayOnTime"
*MEAS_COND_AXIS_NAME-82 "RE_ShutterBTimes"
*MEAS_COND_AXIS_NAME-83 "RE_ShutterBOpenCloseTime"
*MEAS_COND_AXIS_NAME-84 "RE_ShutterBCloseOpenTime"
*MEAS_COND_AXIS_NAME-85 "RE_XrayWarningRamp"
*MEAS_COND_AXIS_NAME-86 "RE_ShutterAInstallation"
*MEAS_COND_AXIS_NAME-87 "RE_ShutterARamp"
*MEAS_COND_AXIS_NAME-88 "RE_ShutterBInstallation"
*MEAS_COND_AXIS_NAME-89 "RE_ShutterBRamp"
*MEAS_COND_AXIS_NAME-9 "Ts"
*MEAS_COND_AXIS_NAME-90 "RE_ExtShutterCLS"
*MEAS_COND_AXIS_NAME-91 "RE_ExtXrayOFF"
*MEAS_COND_AXIS_NAME-92 "RE_ExtSafetyCircuit"
*MEAS_COND_AXIS_NAME-93 "Version_CPU"
*MEAS_COND_AXIS_NAME-94 "Version_RS1"
*MEAS_COND_AXIS_NAME-95 "Version_RS2"
*MEAS_COND_AXIS_NAME-96 "Version_HV"
*MEAS_COND_AXIS_NAME-97 "Version_CW"
*MEAS_COND_AXIS_NAME-98 "Version_RT"
*MEAS_COND_AXIS_NAME-99 "IncidentPrimary"
*MEAS_COND_AXIS_OFFSET-0 "1.1501"
*MEAS_COND_AXIS_OFFSET-1 "0.1001"
*MEAS_COND_AXIS_OFFSET-10 "0"
*MEAS_COND_AXIS_OFFSET-100 "0"
*MEAS_COND_AXIS_OFFSET-101 "0"
*MEAS_COND_AXIS_OFFSET-102 "0"
*MEAS_COND_AXIS_OFFSET-11 "0"
*MEAS_COND_AXIS_OFFSET-12 "0"
*MEAS_COND_AXIS_OFFSET-13 "0"
*MEAS_COND_AXIS_OFFSET-14 "0"
*MEAS_COND_AXIS_OFFSET-15 "0"
*MEAS_COND_AXIS_OFFSET-16 "0"
*MEAS_COND_AXIS_OFFSET-17 "0"
*MEAS_COND_AXIS_OFFSET-18 "0"
*MEAS_COND_AXIS_OFFSET-19 "0"
*MEAS_COND_AXIS_OFFSET-2 "1.2502"
*MEAS_COND_AXIS_OFFSET-20 "0"
*MEAS_COND_AXIS_OFFSET-21 "0"
*MEAS_COND_AXIS_OFFSET-22 "0"
*MEAS_COND_AXIS_OFFSET-23 "0"
*MEAS_COND_AXIS_OFFSET-24 "0"
*MEAS_COND_AXIS_OFFSET-25 "0"
*MEAS_COND_AXIS_OFFSET-26 "0"
*MEAS_COND_AXIS_OFFSET-27 "0"
*MEAS_COND_AXIS_OFFSET-28 "0"
*MEAS_COND_AXIS_OFFSET-29 "0"
*MEAS_COND_AXIS_OFFSET-3 "1.1501"
*MEAS_COND_AXIS_OFFSET-30 "0"
*MEAS_COND_AXIS_OFFSET-31 "0"
*MEAS_COND_AXIS_OFFSET-32 "0"
*MEAS_COND_AXIS_OFFSET-33 "0"
*MEAS_COND_AXIS_OFFSET-34 "0"
*MEAS_COND_AXIS_OFFSET-35 "0"
*MEAS_COND_AXIS_OFFSET-36 "0"
*MEAS_COND_AXIS_OFFSET-37 "0"
*MEAS_COND_AXIS_OFFSET-38 "0"
*MEAS_COND_AXIS_OFFSET-39 "0"
*MEAS_COND_AXIS_OFFSET-4 "0"
*MEAS_COND_AXIS_OFFSET-40 "0"
*MEAS_COND_AXIS_OFFSET-41 "0"
*MEAS_COND_AXIS_OFFSET-42 "0"
*MEAS_COND_AXIS_OFFSET-43 "0"
*MEAS_COND_AXIS_OFFSET-44 "0"
*MEAS_COND_AXIS_OFFSET-45 "0"
*MEAS_COND_AXIS_OFFSET-46 "0"
*MEAS_COND_AXIS_OFFSET-47 "0"
*MEAS_COND_AXIS_OFFSET-48 "0"
*MEAS_COND_AXIS_OFFSET-49 "0"
*MEAS_COND_AXIS_OFFSET-5 "0"
*MEAS_COND_AXIS_OFFSET-50 "0"
*MEAS_COND_AXIS_OFFSET-51 "0"
*MEAS_COND_AXIS_OFFSET-52 "0"
*MEAS_COND_AXIS_OFFSET-53 "0"
*MEAS_COND_AXIS_OFFSET-54 "0"
*MEAS_COND_AXIS_OFFSET-55 "0"
*MEAS_COND_AXIS_OFFSET-56 "0"
*MEAS_COND_AXIS_OFFSET-57 "0"
*MEAS_COND_AXIS_OFFSET-58 "0"
*MEAS_COND_AXIS_OFFSET-59 "0"
*MEAS_COND_AXIS_OFFSET-6 "0"
*MEAS_COND_AXIS_OFFSET-60 "0"
*MEAS_COND_AXIS_OFFSET-61 "0"
*MEAS_COND_AXIS_OFFSET-62 "0"
*MEAS_COND_AXIS_OFFSET-63 "0"
*MEAS_COND_AXIS_OFFSET-64 "0"
*MEAS_COND_AXIS_OFFSET-65 "0"
*MEAS_COND_AXIS_OFFSET-66 "0"
*MEAS_COND_AXIS_OFFSET-67 "0"
*MEAS_COND_AXIS_OFFSET-68 "0"
*MEAS_COND_AXIS_OFFSET-69 "0"
*MEAS_COND_AXIS_OFFSET-7 "0"
*MEAS_COND_AXIS_OFFSET-70 "0"
*MEAS_COND_AXIS_OFFSET-71 "0"
*MEAS_COND_AXIS_OFFSET-72 "0"
*MEAS_COND_AXIS_OFFSET-73 "0"
*MEAS_COND_AXIS_OFFSET-74 "0"
*MEAS_COND_AXIS_OFFSET-75 "0"
*MEAS_COND_AXIS_OFFSET-76 "0"
*MEAS_COND_AXIS_OFFSET-77 "0"
*MEAS_COND_AXIS_OFFSET-78 "0"
*MEAS_COND_AXIS_OFFSET-79 "0"
*MEAS_COND_AXIS_OFFSET-8 "0"
*MEAS_COND_AXIS_OFFSET-80 "0"
*MEAS_COND_AXIS_OFFSET-81 "0"
*MEAS_COND_AXIS_OFFSET-82 "0"
*MEAS_COND_AXIS_OFFSET-83 "0"
*MEAS_COND_AXIS_OFFSET-84 "0"
*MEAS_COND_AXIS_OFFSET-85 "0"
*MEAS_COND_AXIS_OFFSET-86 "0"
*MEAS_COND_AXIS_OFFSET-87 "0"
*MEAS_COND_AXIS_OFFSET-88 "0"
*MEAS_COND_AXIS_OFFSET-89 "0"
*MEAS_COND_AXIS_OFFSET-9 "0"
*MEAS_COND_AXIS_OFFSET-90 "0"
*MEAS_COND_AXIS_OFFSET-91 "0"
*MEAS_COND_AXIS_OFFSET-92 "0"
*MEAS_COND_AXIS_OFFSET-93 "0"
*MEAS_COND_AXIS_OFFSET-94 "0"
*MEAS_COND_AXIS_OFFSET-95 "0"
*MEAS_COND_AXIS_OFFSET-96 "0"
*MEAS_COND_AXIS_OFFSET-97 "0"
*MEAS_COND_AXIS_OFFSET-98 "0"
*MEAS_COND_AXIS_OFFSET-99 "0"
*MEAS_COND_AXIS_POSITION-0 "45.3684"
*MEAS_COND_AXIS_POSITION-1 "45.3490"
*MEAS_COND_AXIS_POSITION-10 "Right"
*MEAS_COND_AXIS_POSITION-100 "Ge(220)x2"
*MEAS_COND_AXIS_POSITION-101 "PSA_open"
*MEAS_COND_AXIS_POSITION-102 "None"
*MEAS_COND_AXIS_POSITION-11 "None"
*MEAS_COND_AXIS_POSITION-12 "Type1"
*MEAS_COND_AXIS_POSITION-13 "0"
*MEAS_COND_AXIS_POSITION-14 "PB"
*MEAS_COND_AXIS_POSITION-15 "0"
*MEAS_COND_AXIS_POSITION-16 "Soller_slit_open_s"
*MEAS_COND_AXIS_POSITION-17 "0.500mm"
*MEAS_COND_AXIS_POSITION-18 "0.500000"
*MEAS_COND_AXIS_POSITION-19 "0.500mm"
*MEAS_COND_AXIS_POSITION-2 "90.7174"
*MEAS_COND_AXIS_POSITION-20 "-2.0256250"
*MEAS_COND_AXIS_POSITION-21 "5mm"
*MEAS_COND_AXIS_POSITION-22 "5mm"
*MEAS_COND_AXIS_POSITION-23 "5mm"
*MEAS_COND_AXIS_POSITION-24 "0.062"
*MEAS_COND_AXIS_POSITION-25 "80.400"
*MEAS_COND_AXIS_POSITION-26 "-1.0225"
*MEAS_COND_AXIS_POSITION-27 "89.938"
*MEAS_COND_AXIS_POSITION-28 "80.400"
*MEAS_COND_AXIS_POSITION-29 "0.000"
*MEAS_COND_AXIS_POSITION-3 "45.3684"
*MEAS_COND_AXIS_POSITION-30 "89.99"
*MEAS_COND_AXIS_POSITION-31 "80.400"
*MEAS_COND_AXIS_POSITION-32 "90.7174"
*MEAS_COND_AXIS_POSITION-33 "-0.12276"
*MEAS_COND_AXIS_POSITION-34 "0.01206"
*MEAS_COND_AXIS_POSITION-35 "0.700mm"
*MEAS_COND_AXIS_POSITION-36 "0.700000"
*MEAS_COND_AXIS_POSITION-37 "0.700mm"
*MEAS_COND_AXIS_POSITION-38 "None"
*MEAS_COND_AXIS_POSITION-39 "PSA_open"
*MEAS_COND_AXIS_POSITION-4 "90.7174"
*MEAS_COND_AXIS_POSITION-40 "Soller_slit_5.0deg"
*MEAS_COND_AXIS_POSITION-41 "0.700mm"
*MEAS_COND_AXIS_POSITION-42 "0.700000"
*MEAS_COND_AXIS_POSITION-43 "0.700mm"
*MEAS_COND_AXIS_POSITION-44 "-0.5287500"
*MEAS_COND_AXIS_POSITION-45 "None"
*MEAS_COND_AXIS_POSITION-46 "Open"
*MEAS_COND_AXIS_POSITION-47 "647.0"
*MEAS_COND_AXIS_POSITION-48 "545.00"
*MEAS_COND_AXIS_POSITION-49 "None"
*MEAS_COND_AXIS_POSITION-5 "90.7174"
*MEAS_COND_AXIS_POSITION-50 ""
*MEAS_COND_AXIS_POSITION-51 ""
*MEAS_COND_AXIS_POSITION-52 ""
*MEAS_COND_AXIS_POSITION-53 ""
*MEAS_COND_AXIS_POSITION-54 ""
*MEAS_COND_AXIS_POSITION-55 ""
*MEAS_COND_AXIS_POSITION-56 ""
*MEAS_COND_AXIS_POSITION-57 ""
*MEAS_COND_AXIS_POSITION-58 ""
*MEAS_COND_AXIS_POSITION-59 ""
*MEAS_COND_AXIS_POSITION-6 "45.3684"
*MEAS_COND_AXIS_POSITION-60 ""
*MEAS_COND_AXIS_POSITION-61 ""
*MEAS_COND_AXIS_POSITION-62 ""
*MEAS_COND_AXIS_POSITION-63 ""
*MEAS_COND_AXIS_POSITION-64 ""
*MEAS_COND_AXIS_POSITION-65 ""
*MEAS_COND_AXIS_POSITION-66 ""
*MEAS_COND_AXIS_POSITION-67 ""
*MEAS_COND_AXIS_POSITION-68 ""
*MEAS_COND_AXIS_POSITION-69 ""
*MEAS_COND_AXIS_POSITION-7 "0.0000"
*MEAS_COND_AXIS_POSITION-70 ""
*MEAS_COND_AXIS_POSITION-71 ""
*MEAS_COND_AXIS_POSITION-72 ""
*MEAS_COND_AXIS_POSITION-73 ""
*MEAS_COND_AXIS_POSITION-74 ""
*MEAS_COND_AXIS_POSITION-75 ""
*MEAS_COND_AXIS_POSITION-76 ""
*MEAS_COND_AXIS_POSITION-77 ""
*MEAS_COND_AXIS_POSITION-78 ""
*MEAS_COND_AXIS_POSITION-79 ""
*MEAS_COND_AXIS_POSITION-8 "None"
*MEAS_COND_AXIS_POSITION-80 ""
*MEAS_COND_AXIS_POSITION-81 ""
*MEAS_COND_AXIS_POSITION-82 ""
*MEAS_COND_AXIS_POSITION-83 ""
*MEAS_COND_AXIS_POSITION-84 ""
*MEAS_COND_AXIS_POSITION-85 ""
*MEAS_COND_AXIS_POSITION-86 ""
*MEAS_COND_AXIS_POSITION-87 ""
*MEAS_COND_AXIS_POSITION-88 ""
*MEAS_COND_AXIS_POSITION-89 ""
*MEAS_COND_AXIS_POSITION-9 "-5.5470000"
*MEAS_COND_AXIS_POSITION-90 ""
*MEAS_COND_AXIS_POSITION-91 ""
*MEAS_COND_AXIS_POSITION-92 ""
*MEAS_COND_AXIS_POSITION-93 ""
*MEAS_COND_AXIS_POSITION-94 ""
*MEAS_COND_AXIS_POSITION-95 ""
*MEAS_COND_AXIS_POSITION-96 ""
*MEAS_COND_AXIS_POSITION-97 ""
*MEAS_COND_AXIS_POSITION-98 ""
*MEAS_COND_AXIS_POSITION-99 "Standard"
*MEAS_COND_AXIS_RESOLUTION-0 "0.0001"
*MEAS_COND_AXIS_RESOLUTION-1 "0.0001"
*MEAS_COND_AXIS_RESOLUTION-10 ""
*MEAS_COND_AXIS_RESOLUTION-11 ""
*MEAS_COND_AXIS_RESOLUTION-12 ""
*MEAS_COND_AXIS_RESOLUTION-13 "1"
*MEAS_COND_AXIS_RESOLUTION-14 ""
*MEAS_COND_AXIS_RESOLUTION-15 "1"
*MEAS_COND_AXIS_RESOLUTION-16 ""
*MEAS_COND_AXIS_RESOLUTION-17 "1/1600"
*MEAS_COND_AXIS_RESOLUTION-18 "1/1600"
*MEAS_COND_AXIS_RESOLUTION-19 "1/1600"
*MEAS_COND_AXIS_RESOLUTION-2 "0.0001"
*MEAS_COND_AXIS_RESOLUTION-20 "0.0003125"
*MEAS_COND_AXIS_RESOLUTION-21 ""
*MEAS_COND_AXIS_RESOLUTION-22 ""
*MEAS_COND_AXIS_RESOLUTION-23 ""
*MEAS_COND_AXIS_RESOLUTION-24 "0.001"
*MEAS_COND_AXIS_RESOLUTION-25 "0.002"
*MEAS_COND_AXIS_RESOLUTION-26 "0.0001"
*MEAS_COND_AXIS_RESOLUTION-27 "0.001"
*MEAS_COND_AXIS_RESOLUTION-28 "0.002"
*MEAS_COND_AXIS_RESOLUTION-29 "0.004"
*MEAS_COND_AXIS_RESOLUTION-3 "0.0001"
*MEAS_COND_AXIS_RESOLUTION-30 "0.01"
*MEAS_COND_AXIS_RESOLUTION-31 "0.002"
*MEAS_COND_AXIS_RESOLUTION-32 "0.0001"
*MEAS_COND_AXIS_RESOLUTION-33 "0.00099"
*MEAS_COND_AXIS_RESOLUTION-34 "0.00134"
*MEAS_COND_AXIS_RESOLUTION-35 "1/1600"
*MEAS_COND_AXIS_RESOLUTION-36 "1/1600"
*MEAS_COND_AXIS_RESOLUTION-37 "1/1600"
*MEAS_COND_AXIS_RESOLUTION-38 ""
*MEAS_COND_AXIS_RESOLUTION-39 ""
*MEAS_COND_AXIS_RESOLUTION-4 "0.0002"
*MEAS_COND_AXIS_RESOLUTION-40 ""
*MEAS_COND_AXIS_RESOLUTION-41 "1/1600"
*MEAS_COND_AXIS_RESOLUTION-42 "1/1600"
*MEAS_COND_AXIS_RESOLUTION-43 "1/1600"
*MEAS_COND_AXIS_RESOLUTION-44 "0.0003125"
*MEAS_COND_AXIS_RESOLUTION-45 ""
*MEAS_COND_AXIS_RESOLUTION-46 "1/800"
*MEAS_COND_AXIS_RESOLUTION-47 "0.5"
*MEAS_COND_AXIS_RESOLUTION-48 "1.25"
*MEAS_COND_AXIS_RESOLUTION-49 ""
*MEAS_COND_AXIS_RESOLUTION-5 "0.0002"
*MEAS_COND_AXIS_RESOLUTION-50 "0.010000"
*MEAS_COND_AXIS_RESOLUTION-51 "0.010000"
*MEAS_COND_AXIS_RESOLUTION-52 "0.01"
*MEAS_COND_AXIS_RESOLUTION-53 "0.010000"
*MEAS_COND_AXIS_RESOLUTION-54 "0.01"
*MEAS_COND_AXIS_RESOLUTION-55 "1.000000"
*MEAS_COND_AXIS_RESOLUTION-56 "1.000000"
*MEAS_COND_AXIS_RESOLUTION-57 "1"
*MEAS_COND_AXIS_RESOLUTION-58 "1"
*MEAS_COND_AXIS_RESOLUTION-59 "0.01"
*MEAS_COND_AXIS_RESOLUTION-6 "0.0001"
*MEAS_COND_AXIS_RESOLUTION-60 "0.01"
*MEAS_COND_AXIS_RESOLUTION-61 "0.01"
*MEAS_COND_AXIS_RESOLUTION-62 "0.01"
*MEAS_COND_AXIS_RESOLUTION-63 "0.010000"
*MEAS_COND_AXIS_RESOLUTION-64 "1"
*MEAS_COND_AXIS_RESOLUTION-65 "0.1"
*MEAS_COND_AXIS_RESOLUTION-66 "1"
*MEAS_COND_AXIS_RESOLUTION-67 "0.010000"
*MEAS_COND_AXIS_RESOLUTION-68 "0.01"
*MEAS_COND_AXIS_RESOLUTION-69 "0.01"
*MEAS_COND_AXIS_RESOLUTION-7 "0.0005"
*MEAS_COND_AXIS_RESOLUTION-70 "0.100000"
*MEAS_COND_AXIS_RESOLUTION-71 "1.000000"
*MEAS_COND_AXIS_RESOLUTION-72 "0.01"
*MEAS_COND_AXIS_RESOLUTION-73 "1.000000"
*MEAS_COND_AXIS_RESOLUTION-74 "1"
*MEAS_COND_AXIS_RESOLUTION-75 "1.000000"
*MEAS_COND_AXIS_RESOLUTION-76 "1"
*MEAS_COND_AXIS_RESOLUTION-77 "0.01"
*MEAS_COND_AXIS_RESOLUTION-78 "1"
*MEAS_COND_AXIS_RESOLUTION-79 "1"
*MEAS_COND_AXIS_RESOLUTION-8 ""
*MEAS_COND_AXIS_RESOLUTION-80 "1"
*MEAS_COND_AXIS_RESOLUTION-81 "0.01"
*MEAS_COND_AXIS_RESOLUTION-82 "1.000000"
*MEAS_COND_AXIS_RESOLUTION-83 "1.000000"
*MEAS_COND_AXIS_RESOLUTION-84 "1.000000"
*MEAS_COND_AXIS_RESOLUTION-85 "-"
*MEAS_COND_AXIS_RESOLUTION-86 "-"
*MEAS_COND_AXIS_RESOLUTION-87 "-"
*MEAS_COND_AXIS_RESOLUTION-88 "1.000000"
*MEAS_COND_AXIS_RESOLUTION-89 "-"
*MEAS_COND_AXIS_RESOLUTION-9 "0.0000625"
*MEAS_COND_AXIS_RESOLUTION-90 "-"
*MEAS_COND_AXIS_RESOLUTION-91 "-"
*MEAS_COND_AXIS_RESOLUTION-92 "1.000000"
*MEAS_COND_AXIS_RESOLUTION-93 "1.000000"
*MEAS_COND_AXIS_RESOLUTION-94 "1.000000"
*MEAS_COND_AXIS_RESOLUTION-95 "1.000000"
*MEAS_COND_AXIS_RESOLUTION-96 "1.000000"
*MEAS_COND_AXIS_RESOLUTION-97 "1.000000"
*MEAS_COND_AXIS_RESOLUTION-98 "1.000000"
*MEAS_COND_AXIS_STATE-0 "Fixed"
*MEAS_COND_AXIS_STATE-1 "Fixed"
*MEAS_COND_AXIS_STATE-10 "Fixed"
*MEAS_COND_AXIS_STATE-11 "Fixed"
*MEAS_COND_AXIS_STATE-12 "Fixed"
*MEAS_COND_AXIS_STATE-13 "Fixed"
*MEAS_COND_AXIS_STATE-14 "Fixed"
*MEAS_COND_AXIS_STATE-15 "Fixed"
*MEAS_COND_AXIS_STATE-16 "Fixed"
*MEAS_COND_AXIS_STATE-17 "Fixed"
*MEAS_COND_AXIS_STATE-18 "Fixed"
*MEAS_COND_AXIS_STATE-19 "Fixed"
*MEAS_COND_AXIS_STATE-2 "Fixed"
*MEAS_COND_AXIS_STATE-20 "Fixed"
*MEAS_COND_AXIS_STATE-21 "Fixed"
*MEAS_COND_AXIS_STATE-22 "Fixed"
*MEAS_COND_AXIS_STATE-23 "Fixed"
*MEAS_COND_AXIS_STATE-24 "Fixed"
*MEAS_COND_AXIS_STATE-25 "Fixed"
*MEAS_COND_AXIS_STATE-26 "Fixed"
*MEAS_COND_AXIS_STATE-27 "Fixed"
*MEAS_COND_AXIS_STATE-28 "Fixed"
*MEAS_COND_AXIS_STATE-29 "Fixed"
*MEAS_COND_AXIS_STATE-3 "Scan"
*MEAS_COND_AXIS_STATE-30 "Fixed"
*MEAS_COND_AXIS_STATE-31 "Fixed"
*MEAS_COND_AXIS_STATE-32 "Fixed"
*MEAS_COND_AXIS_STATE-33 "Fixed"
*MEAS_COND_AXIS_STATE-34 "Fixed"
*MEAS_COND_AXIS_STATE-35 "Fixed"
*MEAS_COND_AXIS_STATE-36 "Fixed"
*MEAS_COND_AXIS_STATE-37 "Fixed"
*MEAS_COND_AXIS_STATE-38 "Fixed"
*MEAS_COND_AXIS_STATE-39 "Fixed"
*MEAS_COND_AXIS_STATE-4 "Fixed"
*MEAS_COND_AXIS_STATE-40 "Fixed"
*MEAS_COND_AXIS_STATE-41 "Fixed"
*MEAS_COND_AXIS_STATE-42 "Fixed"
*MEAS_COND_AXIS_STATE-43 "Fixed"
*MEAS_COND_AXIS_STATE-44 "Fixed"
*MEAS_COND_AXIS_STATE-45 "Fixed"
*MEAS_COND_AXIS_STATE-46 "Fixed"
*MEAS_COND_AXIS_STATE-47 "Fixed"
*MEAS_COND_AXIS_STATE-48 "Fixed"
*MEAS_COND_AXIS_STATE-49 "Fixed"
*MEAS_COND_AXIS_STATE-5 "Fixed"
*MEAS_COND_AXIS_STATE-50 "Fixed"
*MEAS_COND_AXIS_STATE-51 "Fixed"
*MEAS_COND_AXIS_STATE-52 "Fixed"
*MEAS_COND_AXIS_STATE-53 "Fixed"
*MEAS_COND_AXIS_STATE-54 "Fixed"
*MEAS_COND_AXIS_STATE-55 "Fixed"
*MEAS_COND_AXIS_STATE-56 "Fixed"
*MEAS_COND_AXIS_STATE-57 "Fixed"
*MEAS_COND_AXIS_STATE-58 "Fixed"
*MEAS_COND_AXIS_STATE-59 "Fixed"
*MEAS_COND_AXIS_STATE-6 "Fixed"
*MEAS_COND_AXIS_STATE-60 "Fixed"
*MEAS_COND_AXIS_STATE-61 "Fixed"
*MEAS_COND_AXIS_STATE-62 "Fixed"
*MEAS_COND_AXIS_STATE-63 "Fixed"
*MEAS_COND_AXIS_STATE-64 "Fixed"
*MEAS_COND_AXIS_STATE-65 "Fixed"
*MEAS_COND_AXIS_STATE-66 "Fixed"
*MEAS_COND_AXIS_STATE-67 "Fixed"
*MEAS_COND_AXIS_STATE-68 "Fixed"
*MEAS_COND_AXIS_STATE-69 "Fixed"
*MEAS_COND_AXIS_STATE-7 "Fixed"
*MEAS_COND_AXIS_STATE-70 "Fixed"
*MEAS_COND_AXIS_STATE-71 "Fixed"
*MEAS_COND_AXIS_STATE-72 "Fixed"
*MEAS_COND_AXIS_STATE-73 "Fixed"
*MEAS_COND_AXIS_STATE-74 "Fixed"
*MEAS_COND_AXIS_STATE-75 "Fixed"
*MEAS_COND_AXIS_STATE-76 "Fixed"
*MEAS_COND_AXIS_STATE-77 "Fixed"
*MEAS_COND_AXIS_STATE-78 "Fixed"
*MEAS_COND_AXIS_STATE-79 "Fixed"
*MEAS_COND_AXIS_STATE-8 "Fixed"
*MEAS_COND_AXIS_STATE-80 "Fixed"
*MEAS_COND_AXIS_STATE-81 "Fixed"
*MEAS_COND_AXIS_STATE-82 "Fixed"
*MEAS_COND_AXIS_STATE-83 "Fixed"
*MEAS_COND_AXIS_STATE-84 "Fixed"
*MEAS_COND_AXIS_STATE-85 "Fixed"
*MEAS_COND_AXIS_STATE-86 "Fixed"
*MEAS_COND_AXIS_STATE-87 "Fixed"
*MEAS_COND_AXIS_STATE-88 "Fixed"
*MEAS_COND_AXIS_STATE-89 "Fixed"
*MEAS_COND_AXIS_STATE-9 "Fixed"
*MEAS_COND_AXIS_STATE-90 "Fixed"
*MEAS_COND_AXIS_STATE-91 "Fixed"
*MEAS_COND_AXIS_STATE-92 "Fixed"
*MEAS_COND_AXIS_STATE-93 "Fixed"
*MEAS_COND_AXIS_STATE-94 "Fixed"
*MEAS_COND_AXIS_STATE-95 "Fixed"
*MEAS_COND_AXIS_STATE-96 "Fixed"
*MEAS_COND_AXIS_STATE-97 "Fixed"
*MEAS_COND_AXIS_STATE-98 "Fixed"
*MEAS_COND_AXIS_UNIT-0 "deg"
*MEAS_COND_AXIS_UNIT-1 "deg"
*MEAS_COND_AXIS_UNIT-10 ""
*MEAS_COND_AXIS_UNIT-100 ""
*MEAS_COND_AXIS_UNIT-101 ""
*MEAS_COND_AXIS_UNIT-102 ""
*MEAS_COND_AXIS_UNIT-11 ""
*MEAS_COND_AXIS_UNIT-12 ""
*MEAS_COND_AXIS_UNIT-13 "pulse"
*MEAS_COND_AXIS_UNIT-14 ""
*MEAS_COND_AXIS_UNIT-15 "pulse"
*MEAS_COND_AXIS_UNIT-16 ""
*MEAS_COND_AXIS_UNIT-17 ""
*MEAS_COND_AXIS_UNIT-18 "mm"
*MEAS_COND_AXIS_UNIT-19 ""
*MEAS_COND_AXIS_UNIT-2 "deg"
*MEAS_COND_AXIS_UNIT-20 "mm"
*MEAS_COND_AXIS_UNIT-21 ""
*MEAS_COND_AXIS_UNIT-22 ""
*MEAS_COND_AXIS_UNIT-23 ""
*MEAS_COND_AXIS_UNIT-24 "deg"
*MEAS_COND_AXIS_UNIT-25 "deg"
*MEAS_COND_AXIS_UNIT-26 "mm"
*MEAS_COND_AXIS_UNIT-27 "deg"
*MEAS_COND_AXIS_UNIT-28 "deg"
*MEAS_COND_AXIS_UNIT-29 "deg"
*MEAS_COND_AXIS_UNIT-3 "deg"
*MEAS_COND_AXIS_UNIT-30 "deg"
*MEAS_COND_AXIS_UNIT-31 "deg"
*MEAS_COND_AXIS_UNIT-32 "deg"
*MEAS_COND_AXIS_UNIT-33 "deg"
*MEAS_COND_AXIS_UNIT-34 "deg"
*MEAS_COND_AXIS_UNIT-35 ""
*MEAS_COND_AXIS_UNIT-36 "mm"
*MEAS_COND_AXIS_UNIT-37 ""
*MEAS_COND_AXIS_UNIT-38 ""
*MEAS_COND_AXIS_UNIT-39 ""
*MEAS_COND_AXIS_UNIT-4 "deg"
*MEAS_COND_AXIS_UNIT-40 ""
*MEAS_COND_AXIS_UNIT-41 ""
*MEAS_COND_AXIS_UNIT-42 "mm"
*MEAS_COND_AXIS_UNIT-43 ""
*MEAS_COND_AXIS_UNIT-44 "mm"
*MEAS_COND_AXIS_UNIT-45 ""
*MEAS_COND_AXIS_UNIT-46 ""
*MEAS_COND_AXIS_UNIT-47 "V"
*MEAS_COND_AXIS_UNIT-48 "mV"
*MEAS_COND_AXIS_UNIT-49 ""
*MEAS_COND_AXIS_UNIT-5 "deg"
*MEAS_COND_AXIS_UNIT-50 "H"
*MEAS_COND_AXIS_UNIT-51 "H"
*MEAS_COND_AXIS_UNIT-52 "H"
*MEAS_COND_AXIS_UNIT-53 "H"
*MEAS_COND_AXIS_UNIT-54 "H"
*MEAS_COND_AXIS_UNIT-55 "mV"
*MEAS_COND_AXIS_UNIT-56 "V"
*MEAS_COND_AXIS_UNIT-57 "V"
*MEAS_COND_AXIS_UNIT-58 "V"
*MEAS_COND_AXIS_UNIT-59 "H"
*MEAS_COND_AXIS_UNIT-6 "deg"
*MEAS_COND_AXIS_UNIT-60 "H"
*MEAS_COND_AXIS_UNIT-61 "H"
*MEAS_COND_AXIS_UNIT-62 "H"
*MEAS_COND_AXIS_UNIT-63 "H"
*MEAS_COND_AXIS_UNIT-64 "uS/m"
*MEAS_COND_AXIS_UNIT-65 "L/min"
*MEAS_COND_AXIS_UNIT-66 "C"
*MEAS_COND_AXIS_UNIT-67 "MPa"
*MEAS_COND_AXIS_UNIT-68 "MPa"
*MEAS_COND_AXIS_UNIT-69 "MPa"
*MEAS_COND_AXIS_UNIT-7 "deg"
*MEAS_COND_AXIS_UNIT-70 "L/min"
*MEAS_COND_AXIS_UNIT-71 "degree"
*MEAS_COND_AXIS_UNIT-72 "MPa"
*MEAS_COND_AXIS_UNIT-73 "degree"
*MEAS_COND_AXIS_UNIT-74 "percent"
*MEAS_COND_AXIS_UNIT-75 "degree"
*MEAS_COND_AXIS_UNIT-76 "C"
*MEAS_COND_AXIS_UNIT-77 "H"
*MEAS_COND_AXIS_UNIT-78 "time"
*MEAS_COND_AXIS_UNIT-79 "msec"
*MEAS_COND_AXIS_UNIT-8 ""
*MEAS_COND_AXIS_UNIT-80 "msec"
*MEAS_COND_AXIS_UNIT-81 "H"
*MEAS_COND_AXIS_UNIT-82 "times"
*MEAS_COND_AXIS_UNIT-83 "msec"
*MEAS_COND_AXIS_UNIT-84 "msec"
*MEAS_COND_AXIS_UNIT-85 "-"
*MEAS_COND_AXIS_UNIT-86 "-"
*MEAS_COND_AXIS_UNIT-87 "-"
*MEAS_COND_AXIS_UNIT-88 ""
*MEAS_COND_AXIS_UNIT-89 "-"
*MEAS_COND_AXIS_UNIT-9 "mm"
*MEAS_COND_AXIS_UNIT-90 "-"
*MEAS_COND_AXIS_UNIT-91 "-"
*MEAS_COND_AXIS_UNIT-92 ""
*MEAS_COND_AXIS_UNIT-93 ""
*MEAS_COND_AXIS_UNIT-94 ""
*MEAS_COND_AXIS_UNIT-95 ""
*MEAS_COND_AXIS_UNIT-96 ""
*MEAS_COND_AXIS_UNIT-97 ""
*MEAS_COND_AXIS_UNIT-98 ""
*MEAS_COND_AXIS_UNIT-99 ""
*MEAS_COND_OPT_ATTR "PB-Ge(220)x2"
*MEAS_COND_OPT_NAME "User defined settings"
*MEAS_COND_XG_CURRENT "160"
*MEAS_COND_XG_VOLTAGE "45"
*MEAS_COND_XG_WAVE_TYPE "Ka1"
*MEAS_DATA_COUNT "501"
*MEAS_SCAN_AXIS_X "Omega"
*MEAS_SCAN_AXIS_X_INTERNAL "Omega"
*MEAS_SCAN_END_TIME "10/07/2020 16:33:50"
*MEAS_SCAN_MODE "CONTINUOUS"
*MEAS_SCAN_MODE_INTERNAL "CONTINUOUS"
*MEAS_SCAN_RESOLUTION_X "0.0001"
*MEAS_SCAN_SPEED "0.2000"
*MEAS_SCAN_SPEED_UNIT "deg/min"
*MEAS_SCAN_START "45.3184"
*MEAS_SCAN_START_TIME "10/07/2020 16:32:47"
*MEAS_SCAN_STEP "0.0002"
*MEAS_SCAN_STOP "45.4184"
*MEAS_SCAN_UNIT_X "deg"
*MEAS_SCAN_UNIT_Y "counts"
*RAS_HEADER_END
*RAS_INT_START
45.3184 32.0000 1.0000
45.3186 30.0000 1.0000
45.3188 22.0000 1.0000
45.3190 31.0000 1.0000
45.3192 33.0000 1.0000
45.3194 40.0000 1.0000
45.3196 30.0000 1.0000
45.3198 44.0000 1.0000
45.3200 30.0000 1.0000
45.3202 33.0000 1.0000
45.3204 25.0000 1.0000
45.3206 31.0000 1.0000
45.3208 35.0000 1.0000
45.3210 28.0000 1.0000
45.3212 28.0000 1.0000
45.3214 41.0000 1.0000
45.3216 43.0000 1.0000
45.3218 41.0000 1.0000
45.3220 46.0000 1.0000
45.3222 46.0000 1.0000
45.3224 39.0000 1.0000
45.3226 35.0000 1.0000
45.3228 43.0000 1.0000
45.3230 37.0000 1.0000
45.3232 41.0000 1.0000
45.3234 41.0000 1.0000
45.3236 35.0000 1.0000
45.3238 46.0000 1.0000
45.3240 48.0000 1.0000
45.3242 42.0000 1.0000
45.3244 43.0000 1.0000
45.3246 35.0000 1.0000
45.3248 39.0000 1.0000
45.3250 33.0000 1.0000
45.3252 45.0000 1.0000
45.3254 46.0000 1.0000
45.3256 50.0000 1.0000
45.3258 46.0000 1.0000
45.3260 45.0000 1.0000
45.3262 45.0000 1.0000
45.3264 50.0000 1.0000
45.3266 48.0000 1.0000
45.3268 43.0000 1.0000
45.3270 40.0000 1.0000
45.3272 49.0000 1.0000
45.3274 40.0000 1.0000
45.3276 70.0000 1.0000
45.3278 50.0000 1.0000
45.3280 50.0000 1.0000
45.3282 53.0000 1.0000
45.3284 49.0000 1.0000
45.3286 56.0000 1.0000
45.3288 53.0000 1.0000
45.3290 71.0000 1.0000
45.3292 54.0000 1.0000
45.3294 64.0000 1.0000
45.3296 50.0000 1.0000
45.3298 63.0000 1.0000
45.3300 48.0000 1.0000
45.3302 59.0000 1.0000
45.3304 53.0000 1.0000
45.3306 61.0000 1.0000
45.3308 70.0000 1.0000
45.3310 66.0000 1.0000
45.3312 58.0000 1.0000
45.3314 62.0000 1.0000
45.3316 66.0000 1.0000
45.3318 64.0000 1.0000
45.3320 52.0000 1.0000
45.3322 67.0000 1.0000
45.3324 81.0000 1.0000
45.3326 80.0000 1.0000
45.3328 66.0000 1.0000
45.3330 58.0000 1.0000
45.3332 71.0000 1.0000
45.3334 78.0000 1.0000
45.3336 91.0000 1.0000
45.3338 88.0000 1.0000
45.3340 81.0000 1.0000
45.3342 102.0000 1.0000
45.3344 74.0000 1.0000
45.3346 98.0000 1.0000
45.3348 95.0000 1.0000
45.3350 88.0000 1.0000
45.3352 98.0000 1.0000
45.3354 100.0000 1.0000
45.3356 106.0000 1.0000
45.3358 99.0000 1.0000
45.3360 103.0000 1.0000
45.3362 120.0000 1.0000
45.3364 118.0000 1.0000
45.3366 108.0000 1.0000
45.3368 113.0000 1.0000
45.3370 131.0000 1.0000
45.3372 128.0000 1.0000
45.3374 163.0000 1.0000
45.3376 150.0000 1.0000
45.3378 139.0000 1.0000
45.3380 165.0000 1.0000
45.3382 160.0000 1.0000
45.3384 196.0000 1.0000
45.3386 215.0000 1.0000
45.3388 183.0000 1.0000
45.3390 227.0000 1.0000
45.3392 222.0000 1.0000
45.3394 222.0000 1.0000
45.3396 276.0000 1.0000
45.3398 316.0000 1.0000
45.3400 334.0000 1.0000
45.3402 292.0000 1.0000
45.3404 364.0000 1.0000
45.3406 371.0000 1.0000
45.3408 427.0000 1.0000
45.3410 462.0000 1.0000
45.3412 472.0000 1.0000
45.3414 510.0000 1.0000
45.3416 523.0000 1.0000
45.3418 588.0000 1.0000
45.3420 592.0000 1.0000
45.3422 696.0000 1.0000
45.3424 704.0000 1.0000
45.3426 762.0000 1.0000
45.3428 839.0000 1.0000
45.3430 898.0000 1.0000
45.3432 841.0000 1.0000
45.3434 1025.0000 1.0000
45.3436 1086.0000 1.0000
45.3438 1149.0000 1.0000
45.3440 1247.0000 1.0000
45.3442 1318.0000 1.0000
45.3444 1392.0000 1.0000
45.3446 1498.0000 1.0000
45.3448 1517.0000 1.0000
45.3450 1608.0000 1.0000
45.3452 1767.0000 1.0000
45.3454 1849.0000 1.0000
45.3456 1967.0000 1.0000
45.3458 2097.0000 1.0000
45.3460 2215.0000 1.0000
45.3462 2329.0000 1.0000
45.3464 2374.0000 1.0000
45.3466 2447.0000 1.0000
45.3468 2622.0000 1.0000
45.3470 2769.0000 1.0000
45.3472 2955.0000 1.0000
45.3474 3117.0000 1.0000
45.3476 3266.0000 1.0000
45.3478 3299.0000 1.0000
45.3480 3579.0000 1.0000
45.3482 72.0000 53.8780
45.3484 62.0000 53.8780
45.3486 77.0000 53.8780
45.3488 75.0000 53.8780
45.3490 69.0000 53.8780
45.3492 83.0000 53.8780
45.3494 81.0000 53.8780
45.3496 95.0000 53.8780
45.3498 91.0000 53.8780
45.3500 102.0000 53.8780
45.3502 94.0000 53.8780
45.3504 111.0000 53.8780
45.3506 109.0000 53.8780
45.3508 120.0000 53.8780
45.3510 116.0000 53.8780
45.3512 112.0000 53.8780
45.3514 117.0000 53.8780
45.3516 138.0000 53.8780
45.3518 139.0000 53.8780
45.3520 138.0000 53.8780
45.3522 152.0000 53.8780
45.3524 196.0000 53.8780
45.3526 156.0000 53.8780
45.3528 161.0000 53.8780
45.3530 166.0000 53.8780
45.3532 190.0000 53.8780
45.3534 176.0000 53.8780
45.3536 196.0000 53.8780
45.3538 208.0000 53.8780
45.3540 213.0000 53.8780
45.3542 193.0000 53.8780
45.3544 225.0000 53.8780
45.3546 208.0000 53.8780
45.3548 246.0000 53.8780
45.3550 246.0000 53.8780
45.3552 260.0000 53.8780
45.3554 245.0000 53.8780
45.3556 256.0000 53.8780
45.3558 302.0000 53.8780
45.3560 279.0000 53.8780
45.3562 302.0000 53.8780
45.3564 291.0000 53.8780
45.3566 315.0000 53.8780
45.3568 325.0000 53.8780
45.3570 334.0000 53.8780
45.3572 352.0000 53.8780
45.3574 374.0000 53.8780
45.3576 376.0000 53.8780
45.3578 417.0000 53.8780
45.3580 398.0000 53.8780
45.3582 407.0000 53.8780
45.3584 460.0000 53.8780
45.3586 483.0000 53.8780
45.3588 497.0000 53.8780
45.3590 479.0000 53.8780
45.3592 484.0000 53.8780
45.3594 500.0000 53.8780
45.3596 547.0000 53.8780
45.3598 516.0000 53.8780
45.3600 589.0000 53.8780
45.3602 571.0000 53.8780
45.3604 624.0000 53.8780
45.3606 656.0000 53.8780
45.3608 635.0000 53.8780
45.3610 708.0000 53.8780
45.3612 708.0000 53.8780
45.3614 717.0000 53.8780
45.3616 797.0000 53.8780
45.3618 777.0000 53.8780
45.3620 841.0000 53.8780
45.3622 887.0000 53.8780
45.3624 953.0000 53.8780
45.3626 869.0000 53.8780
45.3628 994.0000 53.8780
45.3630 1063.0000 53.8780
45.3632 1041.0000 53.8780
45.3634 1086.0000 53.8780
45.3636 1130.0000 53.8780
45.3638 1203.0000 53.8780
45.3640 1183.0000 53.8780
45.3642 1209.0000 53.8780
45.3644 1254.0000 53.8780
45.3646 1315.0000 53.8780
45.3648 1392.0000 53.8780
45.3650 1499.0000 53.8780
45.3652 1409.0000 53.8780
45.3654 1495.0000 53.8780
45.3656 1584.0000 53.8780
45.3658 1562.0000 53.8780
45.3660 1571.0000 53.8780
45.3662 1646.0000 53.8780
45.3664 1720.0000 53.8780
45.3666 1755.0000 53.8780
45.3668 1677.0000 53.8780
45.3670 1674.0000 53.8780
45.3672 1840.0000 53.8780
45.3674 1768.0000 53.8780
45.3676 1836.0000 53.8780
45.3678 1861.0000 53.8780
45.3680 1825.0000 53.8780
45.3682 1842.0000 53.8780
45.3684 1849.0000 53.8780
45.3686 1748.0000 53.8780
45.3688 1883.0000 53.8780
45.3690 1843.0000 53.8780
45.3692 1795.0000 53.8780
45.3694 1793.0000 53.8780
45.3696 1790.0000 53.8780
45.3698 1779.0000 53.8780
45.3700 1740.0000 53.8780
45.3702 1715.0000 53.8780
45.3704 1649.0000 53.8780
45.3706 1637.0000 53.8780
45.3708 1595.0000 53.8780
45.3710 1592.0000 53.8780
45.3712 1509.0000 53.8780
45.3714 1511.0000 53.8780
45.3716 1504.0000 53.8780
45.3718 1426.0000 53.8780
45.3720 1458.0000 53.8780
45.3722 1415.0000 53.8780
45.3724 1342.0000 53.8780
45.3726 1295.0000 53.8780
45.3728 1318.0000 53.8780
45.3730 1231.0000 53.8780
45.3732 1207.0000 53.8780
45.3734 1250.0000 53.8780
45.3736 1162.0000 53.8780
45.3738 1129.0000 53.8780
45.3740 1165.0000 53.8780
45.3742 1076.0000 53.8780
45.3744 1054.0000 53.8780
45.3746 970.0000 53.8780
45.3748 988.0000 53.8780
45.3750 927.0000 53.8780
45.3752 878.0000 53.8780
45.3754 916.0000 53.8780
45.3756 893.0000 53.8780
45.3758 900.0000 53.8780
45.3760 805.0000 53.8780
45.3762 823.0000 53.8780
45.3764 792.0000 53.8780
45.3766 788.0000 53.8780
45.3768 782.0000 53.8780
45.3770 717.0000 53.8780
45.3772 699.0000 53.8780
45.3774 682.0000 53.8780
45.3776 653.0000 53.8780
45.3778 661.0000 53.8780
45.3780 623.0000 53.8780
45.3782 610.0000 53.8780
45.3784 593.0000 53.8780
45.3786 594.0000 53.8780
45.3788 579.0000 53.8780
45.3790 543.0000 53.8780
45.3792 550.0000 53.8780
45.3794 530.0000 53.8780
45.3796 528.0000 53.8780
45.3798 564.0000 53.8780
45.3800 478.0000 53.8780
45.3802 419.0000 53.8780
45.3804 439.0000 53.8780
45.3806 428.0000 53.8780
45.3808 471.0000 53.8780
45.3810 435.0000 53.8780
45.3812 395.0000 53.8780
45.3814 399.0000 53.8780
45.3816 392.0000 53.8780
45.3818 404.0000 53.8780
45.3820 368.0000 53.8780
45.3822 352.0000 53.8780
45.3824 350.0000 53.8780
45.3826 336.0000 53.8780
45.3828 342.0000 53.8780
45.3830 343.0000 53.8780
45.3832 301.0000 53.8780
45.3834 313.0000 53.8780
45.3836 291.0000 53.8780
45.3838 259.0000 53.8780
45.3840 254.0000 53.8780
45.3842 222.0000 53.8780
45.3844 273.0000 53.8780
45.3846 222.0000 53.8780
45.3848 231.0000 53.8780
45.3850 229.0000 53.8780
45.3852 219.0000 53.8780
45.3854 220.0000 53.8780
45.3856 194.0000 53.8780
45.3858 207.0000 53.8780
45.3860 197.0000 53.8780
45.3862 203.0000 53.8780
45.3864 177.0000 53.8780
45.3866 180.0000 53.8780
45.3868 172.0000 53.8780
45.3870 146.0000 53.8780
45.3872 155.0000 53.8780
45.3874 144.0000 53.8780
45.3876 122.0000 53.8780
45.3878 139.0000 53.8780
45.3880 143.0000 53.8780
45.3882 114.0000 53.8780
45.3884 140.0000 53.8780
45.3886 126.0000 53.8780
45.3888 105.0000 53.8780
45.3890 115.0000 53.8780
45.3892 106.0000 53.8780
45.3894 104.0000 53.8780
45.3896 93.0000 53.8780
45.3898 94.0000 53.8780
45.3900 82.0000 53.8780
45.3902 85.0000 53.8780
45.3904 74.0000 53.8780
45.3906 87.0000 53.8780
45.3908 83.0000 53.8780
45.3910 75.0000 53.8780
45.3912 64.0000 53.8780
45.3914 84.0000 53.8780
45.3916 68.0000 53.8780
45.3918 62.0000 53.8780
45.3920 3339.0000 1.0000
45.3922 3374.0000 1.0000
45.3924 3215.0000 1.0000
45.3926 3068.0000 1.0000
45.3928 2824.0000 1.0000
45.3930 2688.0000 1.0000
45.3932 2709.0000 1.0000
45.3934 2518.0000 1.0000
45.3936 2222.0000 1.0000
45.3938 2261.0000 1.0000
45.3940 2200.0000 1.0000
45.3942 1990.0000 1.0000
45.3944 1939.0000 1.0000
45.3946 1889.0000 1.0000
45.3948 1766.0000 1.0000
45.3950 1684.0000 1.0000
45.3952 1647.0000 1.0000
45.3954 1525.0000 1.0000
45.3956 1406.0000 1.0000
45.3958 1313.0000 1.0000
45.3960 1265.0000 1.0000
45.3962 1202.0000 1.0000
45.3964 1122.0000 1.0000
45.3966 1091.0000 1.0000
45.3968 1055.0000 1.0000
45.3970 940.0000 1.0000
45.3972 942.0000 1.0000
45.3974 818.0000 1.0000
45.3976 878.0000 1.0000
45.3978 745.0000 1.0000
45.3980 713.0000 1.0000
45.3982 700.0000 1.0000
45.3984 623.0000 1.0000
45.3986 640.0000 1.0000
45.3988 579.0000 1.0000
45.3990 544.0000 1.0000
45.3992 493.0000 1.0000
45.3994 481.0000 1.0000
45.3996 469.0000 1.0000
45.3998 411.0000 1.0000
45.4000 395.0000 1.0000
45.4002 369.0000 1.0000
45.4004 303.0000 1.0000
45.4006 298.0000 1.0000
45.4008 303.0000 1.0000
45.4010 251.0000 1.0000
45.4012 300.0000 1.0000
45.4014 218.0000 1.0000
45.4016 215.0000 1.0000
45.4018 215.0000 1.0000
45.4020 202.0000 1.0000
45.4022 207.0000 1.0000
45.4024 186.0000 1.0000
45.4026 168.0000 1.0000
45.4028 162.0000 1.0000
45.4030 159.0000 1.0000
45.4032 126.0000 1.0000
45.4034 109.0000 1.0000
45.4036 128.0000 1.0000
45.4038 119.0000 1.0000
45.4040 109.0000 1.0000
45.4042 89.0000 1.0000
45.4044 80.0000 1.0000
45.4046 99.0000 1.0000
45.4048 86.0000 1.0000
45.4050 83.0000 1.0000
45.4052 63.0000 1.0000
45.4054 73.0000 1.0000
45.4056 66.0000 1.0000
45.4058 56.0000 1.0000
45.4060 67.0000 1.0000
45.4062 81.0000 1.0000
45.4064 74.0000 1.0000
45.4066 46.0000 1.0000
45.4068 64.0000 1.0000
45.4070 62.0000 1.0000
45.4072 61.0000 1.0000
45.4074 58.0000 1.0000
45.4076 54.0000 1.0000
45.4078 44.0000 1.0000
45.4080 53.0000 1.0000
45.4082 61.0000 1.0000
45.4084 61.0000 1.0000
45.4086 42.0000 1.0000
45.4088 51.0000 1.0000
45.4090 47.0000 1.0000
45.4092 48.0000 1.0000
45.4094 36.0000 1.0000
45.4096 34.0000 1.0000
45.4098 44.0000 1.0000
45.4100 45.0000 1.0000
45.4102 38.0000 1.0000
45.4104 38.0000 1.0000
45.4106 37.0000 1.0000
45.4108 37.0000 1.0000
45.4110 36.0000 1.0000
45.4112 43.0000 1.0000
45.4114 45.0000 1.0000
45.4116 42.0000 1.0000
45.4118 42.0000 1.0000
45.4120 35.0000 1.0000
45.4122 26.0000 1.0000
45.4124 35.0000 1.0000
45.4126 34.0000 1.0000
45.4128 36.0000 1.0000
45.4130 37.0000 1.0000
45.4132 37.0000 1.0000
45.4134 45.0000 1.0000
45.4136 32.0000 1.0000
45.4138 34.0000 1.0000
45.4140 38.0000 1.0000
45.4142 31.0000 1.0000
45.4144 34.0000 1.0000
45.4146 29.0000 1.0000
45.4148 31.0000 1.0000
45.4150 32.0000 1.0000
45.4152 32.0000 1.0000
45.4154 25.0000 1.0000
45.4156 31.0000 1.0000
45.4158 37.0000 1.0000
45.4160 25.0000 1.0000
45.4162 46.0000 1.0000
45.4164 25.0000 1.0000
45.4166 26.0000 1.0000
45.4168 25.0000 1.0000
45.4170 36.0000 1.0000
45.4172 29.0000 1.0000
45.4174 23.0000 1.0000
45.4176 18.0000 1.0000
45.4178 28.0000 1.0000
45.4180 30.0000 1.0000
45.4182 29.0000 1.0000
45.4184 25.0000 1.0000
*RAS_INT_END
*RAS_DATA_END
*DSC_DATA_END